Workbook
Name _ftn1: Glossary!$B$9
Name _ftnref3: Glossary!$C$6

Sheet Overview of Framework
B2: Introduction to the Equality, Diversity and Inclusion Toolkit
B4: Background | C4: Big Issue Invest, Social Value UK, and UnLtd have partnered to develop a Equality, Diversity and Inclusion (EDI) Toolkit to support social purpose organisations (SPOs). The Toolkit project aims to contribute to a society where social purpose organisations pioneer inclusive, diverse and equitable practice. By identifying barriers to inclusion, and building a framework for organisational learning and development the toolkit develops actionable steps for organisations unlock the tangible changes needed to dismantle systemic inequality.
B6: Structure | C6: The EDI Toolkit is structured by the 10 EDI factors (Sections) identified through the EDI Literature Review. The factors are then broken down into parts which form the basis for each of the criteria points. For each part, there are 3 levels that an SPO can work to progress through as their EDI practice develops. The Toolkit should therefore offer a progressive pathway for organisations to be able to follow as a guide for their next steps in developing and embedding EDI practice into their organisations.
B7: Using the Toolkit
B8: Section introductions | C8: The background and reference reading for each section are located at the top of each page.
B9: Filling in the sections | C9: After reading the background and relevant reading, please fill in Sections 1 to 10 with the answer most relevant to your organisation using the drop down options for each part. Your EDI summary is calculated in the final sheet 'EDI Score Outcomes'. There is a glossary at the end and reference links in each section to guide you through the content. For each drop down selected, fill out the 'What we have done' box on the right hand side of the selection. In this space briefly describe the evidence of this action if relevant. Evidence can come in many formats including emails, policies, or website blogs. For certain parts, guidance has been provided to the right of the 'What we have done box' to add extra context to the statement. A 'Notes' box exists in each part for organisations to track any extra information or make comments for other staff members where needed. There is no requirement to add notes.
B10: Toolkit reviews | C10: The Toolkit has been created as a live document. By evidencing the actions taken your organisation and stakeholders can track progress made over time. Suggested intervals for updating the toolkit are annual or biannual, depending on organisation preference. When used during an investment process, an annual review of progress is suggested.
B11: Developed by | C11: SVUK, UnLtd and BII
B12: Version date | C12: 44958
B13: The Diversity, Equality and Inclusion Toolkit (“DEIT”) © 2022 by The Foundation for Social Entrepreneurs trading as UnLtd (UK Company number 4180639 - unltd.org.uk) is licensed under the Creative Commons Attribution 4.0 International licence, but subject to an additional licence condition/restriction that licensees may not charge for delivery or licensing of the DEIT.

Sheet Section 1
B2: Section 1
B3: ='EDI Framework Criteria'!A2 -> Understanding EDI Concepts: Knowledge of EDI concepts and frameworks | U3: Our organisation has committed to this | V3: 2
U4: In progress | V4: 1
B5: Background information | U5: Our organisation has not yet committed to this | V5: 0
B6: This section covers your organisation's formal training on the concepts of Equality, Diversity and Inclusion (EDI) and what efforts are made to increase the understanding of these concepts. Training on these concepts provides a foundation for other areas of EDI work as it ensures all members of an organisation have a level of exposure to core EDI areas.
U7: Our organisation has implemented this | V7: 2
B8: Useful resources (select the + button on the left hand side of the screen to expand) | U8: In progress | V8: 1
B9: Resource name | D9: Description | O9: URL | U9: Our organisation has not yet implemented this | V9: 0
B10: A Phenomenological Study of “Organizational Development Targeting Diversity” in a Nonprofit Human Service OrganizationTargeting Diversity” in a Nonprofit Human Service Organization | D10: "This study explores the experiences of non-profit human service staff members engaged in “organizational development targeting diversity” (ODTD) for two years or more. This term was adapted by combining concepts in workforce diversity management (Cox, 1993; Ely & Thomas, 1996) and intra-organizational oppression (Fine, 1996; Hyde, 1998). Drawing upon Crenshaw’s (1989) theory of intersecting oppressions stemming from race, class, and gender stratification, the experiences of staff members in a nonprofit human services organization provided a window into an organization attempting to address its use of power and how to model empowerment for a disempowered clientele. This study was conducted using interviews, documents, and field notes in a phenomenological design. It was found that perceptions of power sharing within the organizational setting are shaped by participant identities. It is recommended that organizational diversity efforts openly address issues of power and strive to understand member perspectives for organizational practices and policy formation." | O10: https://fisherpub.sjfc.edu/cgi/viewcontent.cgi?article=1006&context=education_etd
B11: Ladder of Empowerment | D11: "Proposed by Elizabeth Rocha in the Journal of Planning Education and Research in 1997, the Ladder of Empowerment represents one of the first models that conceptualized individual and collective forms of empowerment. While earlier models described the dynamics of power or participation, Rocha’s Ladder addresses building power—i.e., the interrelationship of individual and collective participation and power—and the conditions that contribute to (or undermine) power building. Rocha’s Ladder of Empowerment follows several related models, including Sherry Arnstein’s Ladder of Citizen Participation and Roger Hart’s Ladder of Children’s Participation." | O11: https://organizingengagement.org/models/ladder-of-empowerment/ | U11: Our organisation has embedded this | V11: 2
B12: Ladder of Citizen Participation | D12: "Proposed by Sherry Arnstein in 1969, the Ladder of Citizen Participation is one of the most widely referenced and influential models in the field of democratic public participation. For local leaders, organizers, and facilitators who want to understand foundational theories of public engagement and participation, and the ways in which empowered public institutions and officials deny power to citizens, Arnstein’s seminal article is essential reading. The model also influenced many later models, including Elizabeth Rocha’s Ladder of Empowerment and Roger Hart’s Ladder of Children’s Participation." | O12: https://organizingengagement.org/models/ladder-of-citizen-participation/ | U12: In progress | V12: 1
B13: Home Truths: Undoing racism and delivering real diversity in the charity sector | D13: "Home Truths is not a report that asks if there is a problem with ‘race’ equity in the charity sector. It has long been known that there is an under-representation of BAME people working in the charity sector, and that under-representation is worse in senior leadership roles. Instead, in this report we have sought to reframe the ‘diversity’ debate, saying that racism is a significant and unresolved issue in the charity sector just as it is in the rest of society." | O13: https://www.acevo.org.uk/reports/home-truths/ | U13: Our organisation has not yet embedded this | V13: 0
B17: Part 1 | D17: ='EDI Framework Criteria'!B2 -> Equality, Diversity, & Inclusion Characteristics (Equality Act and beyond)
I19: Our organisation has- please select the appropriate dropdown option | J19: What we have done - please clearly state what your organisation has done | K19: Score | L19: Guidance for these statements | V19: Non commitment
B20: Level 1 | C20: ='EDI Framework Criteria'!C2 -> 1.A.1 | D20: ='EDI Framework Criteria'!D2 -> We have committed to having a training plan for staff at all levels, including board which includes material on what is meant by "EDI Characteristics". These go beyond the 9 protected characteristics in the Equalities Act (2010). It includes characteristics like class and neurodivergence too. | I20: Our organisation has not yet committed to this | K20: =INDEX($U$3:$V$13,MATCH(I20,$U$3:$U$13,0),2) -> 0 | V20: =IF(K20=0,V19,"") -> Non commitment
B22: Level 2 | C22: ='EDI Framework Criteria'!E2 -> 2.A.1 | D22: ='EDI Framework Criteria'!F2 -> We have a training plan for staff at all levels, including board. It explains EDI characteristics. These go beyond the 9 protected characteristics in the Equalities Act (2010). It includes characteristics like class and neurodivergence too. We have started to deliver training. | I22: Our organisation has not yet implemented this | K22: =INDEX($U$3:$V$13,MATCH(I22,$U$3:$U$13,0),2) -> 0
B24: Level 3 | C24: ='EDI Framework Criteria'!G2 -> 3.A.1 | D24: ='EDI Framework Criteria'!H2 -> We have a training plan for staff at all levels, including board. It explains EDI characteristics. These go beyond the 9 protected characteristics in the Equalities Act (2010). It includes characteristics like class and neurodivergence too. The training plan has been reviewed at least once. There are plans to review it as needed. Training is given to staff at all levels. | I24: Our organisation has not yet embedded this | K24: =INDEX($U$3:$V$13,MATCH(I24,$U$3:$U$13,0),2) -> 0
B27: Part 2 | D27: ='EDI Framework Criteria'!B3 -> Understanding organisational power
I29: Our organisation has- please select the appropriate dropdown option | J29: What we have done - please clearly state what your organisation has done | L29: Guidance for these statements
B30: Level 1 | C30: ='EDI Framework Criteria'!C3 -> 1.A.2 | D30: ='EDI Framework Criteria'!D3 -> We have committed to having a training plan for staff at all levels, including board. It explains what ‘organisational power’ means. | I30: Our organisation has not yet committed to this | K30: =INDEX($U$3:$V$13,MATCH(I30,$U$3:$U$13,0),2) -> 0 | V30: =IF(K30=0,V29,"") -> 0
B32: Level 2 | C32: ='EDI Framework Criteria'!E3 -> 2.A.2 | D32: ='EDI Framework Criteria'!F3 -> We have a training plan for staff at all levels, including board. It explains what ‘organisational power’ means. We’ve started some training activities. | I32: Our organisation has not yet implemented this | K32: =INDEX($U$3:$V$13,MATCH(I32,$U$3:$U$13,0),2) -> 0
B34: Level 3 | C34: ='EDI Framework Criteria'!G3 -> 3.A.2 | D34: ='EDI Framework Criteria'!H3 -> We have a training plan for staff at all levels, including board. It explains what ‘organisational power’ means. The training plan has been reviewed at least once. There are plans to review it as needed. Training is given to staff at all levels. | I34: Our organisation has not yet embedded this | K34: =INDEX($U$3:$V$13,MATCH(I34,$U$3:$U$13,0),2) -> 0
B37: Part 3 | D37: ='EDI Framework Criteria'!B4 -> Tackling organisational barriers to Equality, Diversity and Inclusion
I39: Our organisation has- please select the appropriate dropdown option | J39: What we have done - please clearly state what your organisation has done | L39: Guidance for these statements
B40: Level 1 | C40: ='EDI Framework Criteria'!C4 -> 1.A.3 | D40: ='EDI Framework Criteria'!D4 -> We have committed to having a training plan for staff at all levels, including board. It explains what ‘organisational barriers to EDI’ means. | I40: Our organisation has not yet committed to this | K40: =INDEX($U$3:$V$13,MATCH(I40,$U$3:$U$13,0),2) -> 0 | V40: =IF(K40=0,V39,"") -> 0
B42: Level 2 | C42: ='EDI Framework Criteria'!E4 -> 2.A.3 | D42: ='EDI Framework Criteria'!F4 -> We have a training plan for staff at all levels, including board. It explains what ‘organisational barriers to EDI’ means. We’ve started some training activities. | I42: Our organisation has not yet implemented this | K42: =INDEX($U$3:$V$13,MATCH(I42,$U$3:$U$13,0),2) -> 0
B44: Level 3 | C44: ='EDI Framework Criteria'!G4 -> 3.A.3 | D44: ='EDI Framework Criteria'!H4 -> We have a training plan for staff at all levels, including board. It explains what ‘organisational barriers to EDI’ means. The training plan has been reviewed at least once. There are plans to review it as needed. Training is given to staff at all levels. | I44: Our organisation has not yet embedded this | K44: =INDEX($U$3:$V$13,MATCH(I44,$U$3:$U$13,0),2) -> 0
B47: Part 4 | D47: ='EDI Framework Criteria'!B5 -> Our role in structural discrimination
I48: Our organisation has- please select the appropriate dropdown option | J48: What we have done - please clearly state what your organisation has done | L48: Guidance for these statements
B49: Level 1 | C49: ='EDI Framework Criteria'!C5 -> 1.A.4 | D49: ='EDI Framework Criteria'!D5 -> We have committed to having a training plan for staff at all levels, including board. It explains what is meant by 'structural discrimination'. | I49: Our organisation has not yet committed to this | K49: =INDEX($U$3:$V$13,MATCH(I49,$U$3:$U$13,0),2) -> 0 | V49: =IF(K49=0,V48,"") -> 0
B51: Level 2 | C51: ='EDI Framework Criteria'!E5 -> 2.A.4 | D51: ='EDI Framework Criteria'!F5 -> We have a training plan for staff at all levels, including board. It explains what is meant by 'structural discrimination'. We’ve started some training activities. | I51: Our organisation has not yet implemented this | K51: =INDEX($U$3:$V$13,MATCH(I51,$U$3:$U$13,0),2) -> 0
B53: Level 3 | C53: ='EDI Framework Criteria'!G5 -> 3.A.4 | D53: ='EDI Framework Criteria'!H5 -> We have a training plan for staff at all levels, including board. It explains what is meant by 'structural discrimination'. The training plan has been reviewed at least once. There are plans to review it as needed. Training is given to staff at all levels. | I53: Our organisation has not yet embedded this | K53: =INDEX($U$3:$V$13,MATCH(I53,$U$3:$U$13,0),2) -> 0
B56: Part 5 | D56: ='EDI Framework Criteria'!B6 -> Intersectionality
I57: Our organisation has- please select the appropriate dropdown option | J57: What we have done - please clearly state what your organisation has done | L57: Guidance for these statements
B58: Level 1 | C58: ='EDI Framework Criteria'!C6 -> 1.A.5 | D58: ='EDI Framework Criteria'!D6 -> We have a training plan for staff at all levels, including board. It explains what ‘intersectionality’ means. | I58: Our organisation has not yet committed to this | K58: =INDEX($U$3:$V$13,MATCH(I58,$U$3:$U$13,0),2) -> 0 | V58: =IF(K58=0,V57,"") -> 0
B60: Level 2 | C60: ='EDI Framework Criteria'!E6 -> 2.A.5 | D60: ='EDI Framework Criteria'!F6 -> We have a training plan for staff at all levels, including board. It explains what ‘intersectionality’ means. We’ve started some training activities. | I60: Our organisation has not yet implemented this | K60: =INDEX($U$3:$V$13,MATCH(I60,$U$3:$U$13,0),2) -> 0
B62: Level 3 | C62: ='EDI Framework Criteria'!G6 -> 3.A.5 | D62: ='EDI Framework Criteria'!H6 -> We have a training plan for staff at all levels, including board. It explains what ‘intersectionality’ means. The training plan has been reviewed at least once. There are plans to review it as needed. Training is given to staff at all levels. | I62: Our organisation has not yet embedded this | K62: =INDEX($U$3:$V$13,MATCH(I62,$U$3:$U$13,0),2) -> 0
B66: Return to overview | D66: Next section

Sheet Section 2
V1: Macro Coding
B2: Section 2 | V2: =#REF! -> #REF! | W2: =#REF! -> #REF! | X2: =#REF! -> #REF! | Y2: =#REF! -> #REF!
B3: ='EDI Framework Criteria'!A7 -> Mission and Policies | U3: Our organisation has committed to this | V3: 2
U4: In progress | V4: 1
B5: Background information | U5: Our organisation has not yet committed to this | V5: 0
B6: This section covers how your organisation outlines your commitment to Equality, Diversity and Inclusion in your mission statement. This should be created alongside people with relevant lived experiences, and where possible the mission statement should be public. Missions and policies support organisations by committing them to action in EDI both internally and externally. They also ensure all staff are aware of the EDI aims the organisation has committed to in addition to necessary resourcing and accountability for EDI work.
U7: Our organisation has implemented this | V7: 2
B8: Useful resources (select the + button on the left hand side of the screen to expand) | U8: In progress | V8: 1
B9: Resource name | D9: Description | O9: URL | U9: Our organisation has not yet implemented this | V9: 0
B10: feministkilljoys killing joy as a world making project | D10: Link provided by Anita B | O10: https://feministkilljoys.com
B11: Act Boldly - Anti-racist principles, guidance & toolkit | D11: "This guide is primarily for people with leadership responsibilities at Wellcome, including the ELT, Senior Leadership Team, Board of Governors, and funding committee chairs. While everyone at Wellcome is responsible for anti-racism in their everyday work, those in power are accountable for meeting our anti-racism commitments and for following these five anti-racist principles. Wellcome has developed this resource to help us achieve racial equity in our organisation and work. This is not legal advice, it is a framework for how to be anti-racist at Wellcome." | O11: https://cms.wellcome.org/sites/default/files/2021-06/Wellcomes-Anti-racist-principles-and-toolkit-2021.pdf | U11: Our organisation has embedded this | V11: 2
B12: The Case for Capitalizing the B in Black | D12: Link provided by Fearless Futures | O12: https://www.theatlantic.com/ideas/archive/2020/06/time-to-capitalize-blackand-white/613159/ | U12: In progress | V12: 1
B13: Diversity in Governance - NPC | D13: "This paper outlines what it means to have a truly diverse board of trustees and what it brings to an organisation. It also explores how to manage and maintain a board that is diverse." | O13: https://www.thinknpc.org/resource-hub/diversity-in-governance-the-what-why-and-how/ | U13: Our organisation has not yet embedded this | V13: 0
B18: Part 1 | D18: ='EDI Framework Criteria'!B7 -> Social mission
I20: Our organisation has- please select the appropriate dropdown option | J20: What we have done - please clearly state what your organisation has done | K20: Score | L20: Guidance for these statements | V20: Non commitment
B21: Level 1 | C21: ='EDI Framework Criteria'!C7 -> 1.B.1 | D21: ='EDI Framework Criteria'!D7 -> We have committed to producing a mission or vision statement which shows a clear organisational commitment to improving Equality, Diversity and Inclusion. | I21: Our organisation has not yet committed to this | K21: =INDEX($U$3:$V$13,MATCH(I21,$U$3:$U$13,0),2) -> 0 | V21: =IF(K21=0,V20,"") -> Non commitment
B23: Level 2 | C23: ='EDI Framework Criteria'!E7 -> 2.B.1 | D23: ='EDI Framework Criteria'!F7 -> We have a mission or vision statement which shows our commitment to improving Equality, Diversity and Inclusion. | I23: Our organisation has not yet implemented this | K23: =INDEX($U$3:$V$13,MATCH(I23,$U$3:$U$13,0),2) -> 0
B25: Level 3 | C25: ='EDI Framework Criteria'!G7 -> 3.B.1 | D25: ='EDI Framework Criteria'!H7 -> We have a mission or vision statement which shows our commitment to improving EDI. We have reviewed it at least once, and will keep making updates as our EDI work goes on. We have shared it internally and externally, and invited comments from affected people. We share this statement on a range of public materials, like terms of references and procurement materials. | I25: Our organisation has not yet embedded this | K25: =INDEX($U$3:$V$13,MATCH(I25,$U$3:$U$13,0),2) -> 0
B28: Part 2 | D28: ='EDI Framework Criteria'!B8 -> Individual responsibilities
I30: Our organisation has- please select the appropriate dropdown option | J30: What we have done - please clearly state what your organisation has done | L30: Guidance for these statements
B31: Level 1 | C31: ='EDI Framework Criteria'!C8 -> 1.B.2 | D31: ='EDI Framework Criteria'!D8 -> We are committed to creating a document that explains what people's personal responsibilities are for working towards EDI. | I31: Our organisation has not yet committed to this | K31: =INDEX($U$3:$V$13,MATCH(I31,$U$3:$U$13,0),2) -> 0 | V31: =IF(#REF!=0,V30,"") -> #REF!
B33: Level 2 | C33: ='EDI Framework Criteria'!E8 -> 2.B.2 | D33: ='EDI Framework Criteria'!F8 -> We have created a document that explains what people's personal responsibilities are for working towards EDI. | I33: Our organisation has not yet implemented this | K33: =INDEX($U$3:$V$13,MATCH(I33,$U$3:$U$13,0),2) -> 0
B35: Level 3 | C35: ='EDI Framework Criteria'!G8 -> 3.B.2 | D35: ='EDI Framework Criteria'!H8 -> We have a document that explains what everyone’s responsibilities are for working towards EDI. We have reviewed it at least once, and will keep making updates as our EDI work goes on. | I35: Our organisation has not yet embedded this | K35: =INDEX($U$3:$V$13,MATCH(I35,$U$3:$U$13,0),2) -> 0
B38: Part 3 | D38: ='EDI Framework Criteria'!B9 -> Targets for Equality, Diversity and Inclusion
I40: Our organisation has- please select the appropriate dropdown option | J40: What we have done - please clearly state what your organisation has done | L40: Guidance for these statements
B41: Level 1 | C41: ='EDI Framework Criteria'!C9 -> 1.B.3 | D41: ='EDI Framework Criteria'!D9 -> We have committed to setting relevant targets for EDI. This will include targets for outputs and outcomes. | I41: Our organisation has not yet committed to this | K41: =INDEX($U$3:$V$13,MATCH(I41,$U$3:$U$13,0),2) -> 0 | V41: =IF(K31=0,V40,"") -> 0
B43: Level 2 | C43: ='EDI Framework Criteria'!E9 -> 2.B.3 | D43: ='EDI Framework Criteria'!F9 -> We have set relevant targets for EDI. We are tracking not only outputs but also outcomes. | I43: Our organisation has not yet implemented this | K43: =INDEX($U$3:$V$13,MATCH(I43,$U$3:$U$13,0),2) -> 0
B45: Level 3 | C45: ='EDI Framework Criteria'!G9 -> 3.B.3 | D45: ='EDI Framework Criteria'!H9 -> We have set relevant targets for EDI. We are tracking not only outputs but also outcomes. Our targets have been reviewed at least once, with input from stakeholders. We have revised the targets as needed, and will keep revising them as our EDI work goes on. | I45: Our organisation has not yet embedded this | K45: =INDEX($U$3:$V$13,MATCH(I45,$U$3:$U$13,0),2) -> 0
B48: Part 4 | D48: ='EDI Framework Criteria'!B10 -> Working with marginalised groups
I50: Our organisation has- please select the appropriate dropdown option | J50: What we have done - please clearly state what your organisation has done | L50: Guidance for these statements
B51: Level 1 | C51: ='EDI Framework Criteria'!C10 -> 1.B.4 | D51: ='EDI Framework Criteria'!D10 -> We have committed to creating a policy or action plan with clear commitments to identify and support marginalised groups. | I51: Our organisation has not yet committed to this | K51: =INDEX($U$3:$V$13,MATCH(I51,$U$3:$U$13,0),2) -> 0
B53: Level 2 | C53: ='EDI Framework Criteria'!E10 -> 2.B.4 | D53: ='EDI Framework Criteria'!F10 -> We have a policy or action plan with clear commitments to identify and support marginalised groups. This has been agreed to by senior management or the board. | I53: Our organisation has not yet implemented this | K53: =INDEX($U$3:$V$13,MATCH(I53,$U$3:$U$13,0),2) -> 0
B55: Level 3 | C55: ='EDI Framework Criteria'!G10 -> 3.B.4 | D55: ='EDI Framework Criteria'!H10 -> We have a policy or action plan with clear commitments to identify and support marginalised groups. We have reviewed it at least once, and will keep making updates as our EDI work goes on. | I55: Our organisation has not yet embedded this | K55: =INDEX($U$3:$V$13,MATCH(I55,$U$3:$U$13,0),2) -> 0
B59: Previous section | D59: Next section

Sheet Section 3
B2: Section 3
B3: ='EDI Framework Criteria'!A11 -> Theory of Change | U3: Our organisation has committed to this | V3: 2
U4: In progress | V4: 1
B5: Background information | U5: Our organisation has not yet committed to this | V5: 0
B6: Developing a EDI specific theory of change allows an organisation to define how to approach EDI issues through strategic business choices and the intended and possible unintended outcomes of those choices.
U7: Our organisation has implemented this | V7: 2
B8: Useful resources (select the + button on the left hand side of the screen to expand) | U8: In progress | V8: 1
B9: Resource name | D9: Description | O9: URL | U9: Our organisation has not yet implemented this | V9: 0
B10: Theory of change in ten steps | D10: "Throughout our work and personal lives we have aims and ideas about how to achieve them, but we rarely take the time to think these through, scrutinise and articulate them. This is what a theory of change process does. It encourages us to reflect on our aims and plans, to discuss them with others and to make them explicit. We see theory of change as the foundation of charity strategy, evaluation and communication. This guide is a ten step handbook to creating a theory of change, built on many years of developing them for charities and funders. It focusses on the basics, our core approach. It gives you the information you need to do any theory of change and is directly applicable to smaller projects and charitable services." | O10: https://www.thinknpc.org/resource-hub/ten-steps/
B11: ESS Evaluation Tool: Interactive Logic Model Template | D11: A logic model tells the story of your project or programme in a diagram and a few simple words. It shows a causal connection between the need you have identified, what you do and how this makes a difference for individuals and communities. | O11: https://evaluationsupportscotland.org.uk/resources/interactive-logic-model-template/ | U11: Our organisation has embedded this | V11: 2
B12: How to Build a Theory of Change | D12: "A theory of change is a description of why a particular way of working will be effective, showing how change happens in the short, medium and long term to achieve the intended impact. It can be represented in a visual diagram, as a narrative, or both. A theory of change can be developed at the beginning of a piece of work (to help with strategic planning), or to describe an existing piece of work (so you can evaluate it). It is particularly helpful if you are planning or evaluating a complex, initiative but can also be used for more straightforward projects. See more in our summary of the uses of theory of change. It is helpful to involve a variety of stakeholders when you develop a theory of change – you could include staff, trustees, beneficiaries, partners and funders. The development process, and the thinking involved, is often as important as the diagram or narrative you produce." | O12: https://knowhow.ncvo.org.uk/how-to/how-to-build-a-theory-of-change | U12: In progress | V12: 1
U13: Our organisation has not yet embedded this | V13: 0
B16: Part 1 | D16: ='EDI Framework Criteria'!B11 -> Theory of Change
I18: Our organisation has- please select the appropriate dropdown option | J18: What we have done - please clearly state what your organisation has done | K18: Score | L18: Guidance for these statements | V18: Non commitment
B19: Level 1 | C19: ='EDI Framework Criteria'!C11 -> 1.C.1 | D19: ='EDI Framework Criteria'!D11 -> We have committed to creating a Theory of Change for how EDI outcomes are created by our activities. This will include positive and negative outcomes; cover all our stakeholder groups; and include inputs and outputs. | I19: Our organisation has not yet committed to this | K19: =INDEX($U$3:$V$13,MATCH(I19,$U$3:$U$13,0),2) -> 0 | V19: =IF(K19=0,V18,"") -> Non commitment
B21: Level 2 | C21: ='EDI Framework Criteria'!E11 -> 2.C.1 | D21: ='EDI Framework Criteria'!F11 -> We have a Theory of Change for how EDI outcomes are created by our activities. This includes positive and negative outcomes; covers all our stakeholder groups; and includes inputs and outputs. | I21: Our organisation has not yet implemented this | K21: =INDEX($U$3:$V$13,MATCH(I21,$U$3:$U$13,0),2) -> 0
B23: Level 3 | C23: ='EDI Framework Criteria'!G11 -> 3.C.1 | D23: ='EDI Framework Criteria'!H11 -> We have a Theory of Change for how EDI outcomes are created by our activities. This includes positive and negative outcomes; covers all our stakeholder groups; and includes inputs and outputs. We collect relevant EDI data and use it to update the Theory of Change. We have reviewed it at least once, and will keep making updates as our EDI work goes on. | I23: Our organisation has not yet embedded this | K23: =INDEX($U$3:$V$13,MATCH(I23,$U$3:$U$13,0),2) -> 0
B27: Previous section | D27: Next section

Sheet Section 4
B2: Section 4
B3: ='EDI Framework Criteria'!A12 -> Equality, Diversity and Inclusion Advocacy | U3: Our organisation has committed to this | V3: 2
U4: In progress | V4: 1
B5: Background information | U5: Our organisation has not yet committed to this | V5: 0
B6: EDI advocacy covers the promotion of EDI within your organisation, to both staff and a board if a board exists. This may be through training or other forms of EDI capacity building.
U7: Our organisation has implemented this | V7: 2
B8: Useful resources (select the + button on the left hand side of the screen to expand) | U8: In progress | V8: 1
B9: Resource name | D9: Description | O9: URL | U9: Our organisation has not yet implemented this | V9: 0
B10: Best practice, toolkits and resources | D10: "Our resources and toolkits are here to help you. Looking to make your policies LGBT inclusive? To learn how to empower senior leaders? Support your LGBT staff on overseas assignments? Our step-by-step resources and toolkits will guide you on your way." | O10: https://www.stonewall.org.uk/best-practice-toolkits-and-resources
B11: How to shift public attitudes on equality - A practical guide for campaigners and communicators | D11: "This guide applies a strategic communications approach to the challenge of showing inequality as structural – deeply embedded in our society and institutions, rather than the responsibility of individuals. It aims to shift thinking away from the belief that anyone can be a successful ‘self-made person’, and towards a recognition that there are still major structural barriers to equality. It is based on a six-month, qualitative and quantitative research project by ComRes for Equally Ours, which itself builds upon previous research for Equally Ours by YouGov." | O11: https://www.equallyours.org.uk/wp-content/uploads/2019/11/Talking-about-equality-guide.pdf | U11: Our organisation has embedded this | V11: 2
B12: Inclusive Language Guide - OneGSMA | D12: "Inclusive language is a form of communication that avoids using words, expressions or assumptions that would stereotype, demean or exclude people. For example, gendered language is commonly understood as language that has a biastowards a particular sex or social gender. In English, this would include using gender-specific terms referring to professions or people, such as businessman or fireman. Please note the terms used in this guide reflect the diverse identities and experiences ofBritish and American society, there might be alternative preferred terms in other regions which we look forward to capturing." | O12: https://www.gsma.com/aboutus/wp-content/uploads/2020/11/GSMA-Inclusive-Language-Guide_2020.pdf?fbclid=IwAR1DRe-CGvJqraLTEwRsVS4CucRP-M_1OOhep8ZIXa22uYA-RHasM_LgfyU | U12: In progress | V12: 1
U13: Our organisation has not yet embedded this | V13: 0
B16: Part 1 | D16: ='EDI Framework Criteria'!B12 -> Equality, Diversity and Inclusion training
I18: Our organisation has- please select the appropriate dropdown option | J18: What we have done - please clearly state what your organisation has done | K18: Score | L18: Guidance for these statements | V18: Non commitment
B19: Level 1 | C19: ='EDI Framework Criteria'!C12 -> 1.D.1 | D19: ='EDI Framework Criteria'!D12 -> We have committed to creating a training plan for staff across all levels including board level for embedding EDI practice into their organisational practice and decision making. | I19: Our organisation has not yet committed to this | K19: =INDEX($U$3:$V$13,MATCH(I19,$U$3:$U$13,0),2) -> 0 | V19: =IF(K19=0,V18,"") -> Non commitment
B21: Level 2 | C21: ='EDI Framework Criteria'!E12 -> 2.D.1 | D21: ='EDI Framework Criteria'!F12 -> A training plan for staff across all levels including board level for embedding EDI practice into organisational practice has been developed. Some training activities have started. | I21: Our organisation has not yet implemented this | K21: =INDEX($U$3:$V$13,MATCH(I21,$U$3:$U$13,0),2) -> 0
B23: Level 3 | C23: ='EDI Framework Criteria'!G12 -> 3.D.1 | D23: ='EDI Framework Criteria'!H12 -> The training plan for staff across all levels including board level for embedding EDI practice into organisational practice is in place. The plan has been reviewed at least once, with plans to continue to review as needed. Activities for all levels are underway. Training around EDI practice is included in new staff induction or training at all levels of the organisation (in line with the needs of their role). | I23: Our organisation has not yet embedded this | K23: =INDEX($U$3:$V$13,MATCH(I23,$U$3:$U$13,0),2) -> 0
B26: Part 2 | D26: ='EDI Framework Criteria'!B13 -> Equality, Diversity and Inclusion resourcing
I28: Our organisation has- please select the appropriate dropdown option | J28: What we have done - please clearly state what your organisation has done | L28: Guidance for these statements
B29: Level 1 | C29: ='EDI Framework Criteria'!C13 -> 1.D.2 | D29: ='EDI Framework Criteria'!D13 -> We have committed to creating an organisational commitment to EDI by allocating resources for EDI management and capacity building. | I29: Our organisation has not yet committed to this | K29: =INDEX($U$3:$V$13,MATCH(I29,$U$3:$U$13,0),2) -> 0 | V29: =IF(K29=0,V28,"") -> 0
B31: Level 2 | C31: ='EDI Framework Criteria'!E13 -> 2.D.2 | D31: ='EDI Framework Criteria'!F13 -> Resources have been allocated for EDI management and capacity building. | I31: Our organisation has not yet implemented this | K31: =INDEX($U$3:$V$13,MATCH(I31,$U$3:$U$13,0),2) -> 0
B33: Level 3 | C33: ='EDI Framework Criteria'!G13 -> 3.D.2 | D33: ='EDI Framework Criteria'!H13 -> Resources continue to be allocated for EDI management and capacity building, and are reviewed and revised as necessary. | I33: Our organisation has not yet embedded this | K33: =INDEX($U$3:$V$13,MATCH(I33,$U$3:$U$13,0),2) -> 0
B37: Previous section | D37: Next section

Sheet Section 5
B2: Section 5
B3: ='EDI Framework Criteria'!A14 -> Equality, Diversity and Inclusion Data Analysis and Evaluation | U3: Our organisation has committed to this | V3: 2
U4: In progress | V4: 1
B5: Background information | U5: Our organisation has not yet committed to this | V5: 0
B6: Measurement of EDI progress is an important and necessary aspect of practice. By embedding data collection in organisational activites the results of EDI strategy and activities can be analysed and assessed. Where appropriate data is also useful so areas of concern can be identified such as intersectionality of experience and unexpected outcomes.
U7: Our organisation has implemented this | V7: 2
B8: Useful resources (select the + button on the left hand side of the screen to expand) | U8: In progress | V8: 1
B9: Resource name | D9: Description | O9: URL | U9: Our organisation has not yet implemented this | V9: 0
B10: Maximise Your Impact – A Guide for Social Entrepreneurs | D10: "The Maximise Your Impact guide was developed within “Know Your Impact: Social Impact Management Tools for Young Social Entrepreneurs” by Estonian Social Enterprise Network, Koç University Social Impact Forum, Mikado Sustainable Development Consulting and Social Value UK. The “Know Your Impact: Social Impact Management Tools for Young Social Entrepreneurs” is funded by Erasmus + programme of the European Union." | O10: https://socialvalueuk.org/resource/maximise-impact/
U11: Our organisation has embedded this | V11: 2
U12: In progress | V12: 1
U13: Our organisation has not yet embedded this | V13: 0
B16: Part 1 | D16: ='EDI Framework Criteria'!B14 -> Collection of specific data, including outcomes | K16: part 1
I18: Our organisation has- please select the appropriate dropdown option | J18: What we have done - please clearly state what your organisation has done | K18: Score | L18: Guidance for these statements | V18: Non commitment
B19: Level 1 | C19: ='EDI Framework Criteria'!C14 -> 1.E.1 | D19: ='EDI Framework Criteria'!D14 -> We have committed to tracking information from all stakeholder groups to collect the following data for outcomes measurement: - Numbers of people experiencing each outcome (scale) - Extent of change for each outcome (depth) - The EDI characteristics of stakeholders | I19: Our organisation has not yet committed to this | K19: =INDEX($U$3:$V$13,MATCH(I19,$U$3:$U$13,0),2) -> 0 | V19: =IF(K19=0,V18,"") -> Non commitment
B21: Level 2 | C21: ='EDI Framework Criteria'!E14 -> 2.E.1 | D21: ='EDI Framework Criteria'!F14 -> Outcomes are starting to be measured involving all stakeholder groups. The measurement includes: - Numbers of people experiencing each outcome (scale) - Extent of change for each outcome (depth) - The EDI characteristics of stakeholders | I21: Our organisation has not yet implemented this | K21: =INDEX($U$3:$V$13,MATCH(I21,$U$3:$U$13,0),2) -> 0
B23: Level 3 | C23: ='EDI Framework Criteria'!G14 -> 3.E.1 | D23: ='EDI Framework Criteria'!H14 -> Outcomes are being measured on a regular basis. Measurement includes: - Numbers of people experiencing each outcome (scale) - Extent of change for each outcome (depth) - The EDI characteristics of stakeholders | I23: Our organisation has not yet embedded this | K23: =INDEX($U$3:$V$13,MATCH(I23,$U$3:$U$13,0),2) -> 0
B26: Part 2 | D26: ='EDI Framework Criteria'!B14 -> Collection of specific data, including outcomes | K26: part 2
I28: Our organisation has- please select the appropriate dropdown option | J28: What we have done - please clearly state what your organisation has done | L28: Guidance for these statements
B29: Level 1 | C29: ='EDI Framework Criteria'!C15 -> 1.E.7 | D29: ='EDI Framework Criteria'!D15 -> We have committed to creating a plan for which EDI characteristics to track when we are measuring outcomes. We look at all 9 protected characteristics in the Equalities Act (2010) and more, for example, socioeconomic class. | I29: Our organisation has not yet committed to this | K29: =INDEX($U$3:$V$13,MATCH(I29,$U$3:$U$13,0),2) -> 0 | V29: =IF(K29=0,V28,"") -> 0
B31: Level 2 | C31: ='EDI Framework Criteria'!E15 -> 2.E.7 | D31: ='EDI Framework Criteria'!F15 -> We identified which EDI characteristics to track when we are measuring outcomes. We look at all 9 protected characteristics in the Equalities Act (2010) and more, for example, socioeconomic class. We are integrating these into our outcomes measurement. | I31: Our organisation has not yet implemented this | K31: =INDEX($U$3:$V$13,MATCH(I31,$U$3:$U$13,0),2) -> 0
B33: Level 3 | C33: ='EDI Framework Criteria'!G15 -> 3.E.7 | D33: ='EDI Framework Criteria'!H15 -> Our stakeholders’ EDI characteristics are included in our outcomes measurement. We look at all 9 protected characteristics in the Equalities Act (2010) and more, for example, socioeconomic class. We review and revise them regularly. | I33: Our organisation has not yet embedded this | K33: =INDEX($U$3:$V$13,MATCH(I33,$U$3:$U$13,0),2) -> 0
B36: Part 3 | D36: ='EDI Framework Criteria'!B16 -> Social value verification
I38: Our organisation has- please select the appropriate dropdown option | J38: What we have done - please clearly state what your organisation has done | L38: Guidance for these statements
B39: Level 1 | C39: ='EDI Framework Criteria'!C16 -> 1.E.3 | D39: ='EDI Framework Criteria'!D16 -> We have committed to seeking feedback from a third-party on our EDI data collection and analysis. This could be through a critical friend, peer review, or through a more formal assurance provider. | I39: Our organisation has not yet committed to this | K39: =INDEX($U$3:$V$13,MATCH(I39,$U$3:$U$13,0),2) -> 0 | V39: =IF(K39=0,V38,"") -> 0
B41: Level 2 | C41: ='EDI Framework Criteria'!E16 -> 2.E.3 | D41: ='EDI Framework Criteria'!F16 -> We have had feedback from a third-party on our EDI data collection and analysis. Explanation given about choice of third party and any associated risks of choice (this could be a critical friend, peer review or a more formal assurance provider). | I41: Our organisation has not yet implemented this | K41: =INDEX($U$3:$V$13,MATCH(I41,$U$3:$U$13,0),2) -> 0
B43: Level 3 | C43: ='EDI Framework Criteria'!G16 -> 3.E.3 | D43: ='EDI Framework Criteria'!H16 -> EDI data collection and analysis are continuing to be reviewed by a third party. Any issues identified by the third party have been recorded and action taken to address the issues. Risks of choice of third party considered and addressed (this could be a critical friend, peer review or a more formal assurance provider). | I43: Our organisation has not yet embedded this | K43: =INDEX($U$3:$V$13,MATCH(I43,$U$3:$U$13,0),2) -> 0
B46: Part 4 | D46: ='EDI Framework Criteria'!B17 -> Transparency around Equality, Diversity and Inclusion practice
I48: Our organisation has- please select the appropriate dropdown option | J48: What we have done - please clearly state what your organisation has done | L48: Guidance for these statements
B49: Level 1 | C49: ='EDI Framework Criteria'!C17 -> 1.E.4 | D49: ='EDI Framework Criteria'!D17 -> We have committed to creating reports on our EDI data and practices. These will cover: - Scope of the activities, - Our audience, - Why we’re conducting analysis, - Limitations or risks of using this data, - Performance against our targets, - Recommendations for improvement. We may use different types of reporting for internal and external audiences. | I49: Our organisation has not yet committed to this | K49: =INDEX($U$3:$V$13,MATCH(I49,$U$3:$U$13,0),2) -> 0 | V49: =IF(K49=0,V48,"") -> 0
B51: Level 2 | C51: ='EDI Framework Criteria'!E17 -> 2.E.4 | D51: ='EDI Framework Criteria'!F17 -> We are starting to create reports on our EDI data and practices. These cover: - Scope of the activities, - Our audience, - Why we’re conducting analysis, - Limitations or risks of using this data, - Performance against our targets, - Recommendations for improvement. We may use different types of reporting for internal and external audiences. | I51: Our organisation has not yet implemented this | K51: =INDEX($U$3:$V$13,MATCH(I51,$U$3:$U$13,0),2) -> 0
B53: Level 3 | C53: ='EDI Framework Criteria'!G17 -> 3.E.4 | D53: ='EDI Framework Criteria'!H17 -> We regularly create reports on our EDI data and practices. These cover: - Scope of the activities, - Our audience, - Why we’re conducting analysis, - Limitations or risks of using this data, - Performance against our targets, - Recommendations for improvement. We may use different types of reporting for internal and external audiences. | I53: Our organisation has not yet embedded this | K53: =INDEX($U$3:$V$13,MATCH(I53,$U$3:$U$13,0),2) -> 0
B56: Part 5 | D56: ='EDI Framework Criteria'!B17 -> Transparency around Equality, Diversity and Inclusion practice
I58: Our organisation has- please select the appropriate dropdown option | J58: What we have done - please clearly state what your organisation has done | L58: Guidance for these statements
B59: Level 1 | C59: ='EDI Framework Criteria'!C18 -> 1.E.5 | D59: ='EDI Framework Criteria'!D18 -> We have committed to recording the limitations and risks of our EDI data collection and analysis. This will include gaps, sources of potential bias, and how far we’ve involved stakeholders. We will identify where other sources of data are needed, and how they can be compared. | I59: Our organisation has not yet committed to this | K59: =INDEX($U$3:$V$13,MATCH(I59,$U$3:$U$13,0),2) -> 0 | V59: =IF(K59=0,V58,"") -> 0
B61: Level 2 | C61: ='EDI Framework Criteria'!E18 -> 2.E.5 | D61: ='EDI Framework Criteria'!F18 -> We have recorded the limitations and risks of our EDI data collection and analysis. We have included gaps, sources of potential bias, and how far we’ve involved stakeholders. We have taken steps to identify and address limitations or risks around this data. | I61: Our organisation has not yet implemented this | K61: =INDEX($U$3:$V$13,MATCH(I61,$U$3:$U$13,0),2) -> 0
B63: Level 3 | C63: ='EDI Framework Criteria'!G18 -> 3.E.5 | D63: ='EDI Framework Criteria'!H18 -> We are continually checking for limitations and risks to our EDI data collection and analysis. We make any necessary changes to our data collection and analysis processes. | I63: Our organisation has not yet embedded this | K63: =INDEX($U$3:$V$13,MATCH(I63,$U$3:$U$13,0),2) -> 0
B66: Part 6 | D66: ='EDI Framework Criteria'!B19 -> Measuring inclusion
I68: Our organisation has- please select the appropriate dropdown option | J68: What we have done - please clearly state what your organisation has done | L68: Guidance for these statements
B69: Level 1 | C69: ='EDI Framework Criteria'!C19 -> 1.E.6 | D69: ='EDI Framework Criteria'!D19 -> We have committed to setting up a strong system for collecting and recording information on inclusion. We will collect information on inclusion. We will break that data down by relevant EDI characteristics, going beyond the 9 protected characteristics to include other areas like class or neurodivergence. | I69: Our organisation has not yet committed to this | K69: =INDEX($U$3:$V$13,MATCH(I69,$U$3:$U$13,0),2) -> 0 | V69: =IF(K69=0,V68,"") -> 0
...

Sheet Section 6
B2: Section 6
B3: ='EDI Framework Criteria'!A20 -> Stakeholder engagement: Understanding approach towards previously omitted groups in service provision and activities | U3: Our organisation has committed to this | V3: 2
U4: In progress | V4: 1
B5: Background information | U5: Our organisation has not yet committed to this | V5: 0
B6: For effective EDI practice stakeholders should be continually and robustly engaged as stakeholder preferences need to be incorporated into definitions of ‘success’. This section covers the identification and engagement of these stakeholders.
U7: Our organisation has implemented this | V7: 2
B8: Useful resources (select the + button on the left hand side of the screen to expand) | U8: In progress | V8: 1
B9: Resource name | D9: Description | O9: URL | U9: Our organisation has not yet implemented this | V9: 0
B10: AA1000 Stakeholder engagement standard | D10: "The AA1000 AccountAbility Stakeholder Engagement Standard (2015) – the most widely applied stakeholder engagement standard – establishes the global benchmark for conducting high-quality stakeholder engagement projects and programs." | O10: https://www.accountability.org/standards/aa1000-stakeholder-engagement-standard/
B11: Standard on applying Principle 1: Involve Stakeholders | D11: "Inform what gets measured and how this is measured and valued in an account of social value by involving stakeholders. This document sets out SVI’s Standard for applying Principle 1: Involve your stakeholders. Involving stakeholders is at the heart of accounting for value and plays a key role in how you apply the other social value principles: Understand what changes; Value the things that matter; Only include what is material; and Do not over-claim. The standard focuses on involving all stakeholders (not only intended beneficiaries) who experience change in their lives (outcomes) as a result of an activity or intervention." | O11: https://www.socialvalueint.org/principle-1-involve-stakeholders | U11: Our organisation has embedded this | V11: 2
B12: Stories for Impact - Stakeholder mapping tool | D12: "A stakeholder map helps you analyse and manage relationships with individuals and organisations who are impacted by your solution or who can influence whether your solution will be successful. " | O12: https://storiesforimpact.com/toolbox/stakeholder-map/ | U12: In progress | V12: 1
U13: Our organisation has not yet embedded this | V13: 0
B16: Part 1 | D16: ='EDI Framework Criteria'!B20 -> Stakeholder mapping
I18: Our organisation has- please select the appropriate dropdown option | J18: What we have done - please clearly state what your organisation has done | K18: Score | L18: Guidance for these statements | V18: Non commitment
B19: Level 1 | C19: ='EDI Framework Criteria'!C20 -> 1.F.1 | D19: ='EDI Framework Criteria'!D20 -> We have committed to mapping out our stakeholder groups (and identify sub groups) for the activities that we plan to include in our EDI practice. | I19: Our organisation has not yet committed to this | K19: =INDEX($U$3:$V$13,MATCH(I19,$U$3:$U$13,0),2) -> 0 | V19: =IF(K19=0,V18,"") -> Non commitment
B21: Level 2 | C21: ='EDI Framework Criteria'!E20 -> 2.F.1 | D21: ='EDI Framework Criteria'!F20 -> We have mapped out the stakeholder groups (and subgroups) affected by our EDI practice. | I21: Our organisation has not yet implemented this | K21: =INDEX($U$3:$V$13,MATCH(I21,$U$3:$U$13,0),2) -> 0
B23: Level 3 | C23: ='EDI Framework Criteria'!G20 -> 3.F.1 | D23: ='EDI Framework Criteria'!H20 -> We have mapped out the stakeholder groups (and subgroups) affected by our EDI practice. We review and revise this as needed. | I23: Our organisation has not yet embedded this | K23: =INDEX($U$3:$V$13,MATCH(I23,$U$3:$U$13,0),2) -> 0
B26: Part 2 | D26: ='EDI Framework Criteria'!B21 -> Stakeholder engagement
I28: Our organisation has- please select the appropriate dropdown option | J28: What we have done - please clearly state what your organisation has done | L28: Guidance for these statements
B29: Level 1 | C29: ='EDI Framework Criteria'!C21 -> 1.F.2 | D29: ='EDI Framework Criteria'!D21 -> We have committed to creating a plan to engage with people from all stakeholder groups. | I29: Our organisation has not yet committed to this | K29: =INDEX($U$3:$V$13,MATCH(I29,$U$3:$U$13,0),2) -> 0 | V29: =IF(K29=0,V28,"") -> 0
B31: Level 2 | C31: ='EDI Framework Criteria'!E21 -> 2.F.2 | D31: ='EDI Framework Criteria'!F21 -> We have created a plan to engage with people from all stakeholder groups. We are collecting feedback from stakeholders on how effective this plan is in practice. | I31: Our organisation has not yet implemented this | K31: =INDEX($U$3:$V$13,MATCH(I31,$U$3:$U$13,0),2) -> 0
B33: Level 3 | C33: ='EDI Framework Criteria'!G21 -> 3.F.2 | D33: ='EDI Framework Criteria'!H21 -> A plan to engage with people from all stakeholder groups has been developed. We are collecting feedback from stakeholders on how effective this plan is in practice. | I33: Our organisation has not yet embedded this | K33: =INDEX($U$3:$V$13,MATCH(I33,$U$3:$U$13,0),2) -> 0
B36: Part 3 | D36: ='EDI Framework Criteria'!B22 -> Defining outcomes
I38: Our organisation has- please select the appropriate dropdown option | J38: What we have done - please clearly state what your organisation has done | L38: Guidance for these statements
B39: Level 1 | C39: ='EDI Framework Criteria'!C22 -> 1.F.3 | D39: ='EDI Framework Criteria'!D22 -> We plan to involve stakeholder groups to understand the outcomes they are experiencing, and why. We will use open-ended questions to identify outcomes which are positive, negative, intended, and unintended. | I39: Our organisation has not yet committed to this | K39: =INDEX($U$3:$V$13,MATCH(I39,$U$3:$U$13,0),2) -> 0 | V39: =IF(K39=0,V38,"") -> 0
B41: Level 2 | C41: ='EDI Framework Criteria'!E22 -> 2.F.3 | D41: ='EDI Framework Criteria'!F22 -> We have involved stakeholder groups to understand the outcomes they are experiencing, and why. We have used use open-ended questions to identify outcomes which are positive, negative, intended, and unintended. | I41: Our organisation has not yet implemented this | K41: =INDEX($U$3:$V$13,MATCH(I41,$U$3:$U$13,0),2) -> 0
B43: Level 3 | C43: ='EDI Framework Criteria'!G22 -> 3.F.3 | D43: ='EDI Framework Criteria'!H22 -> Outcomes are reviewed and revised based on ongoing stakeholder engagement. | I43: Our organisation has not yet embedded this | K43: =INDEX($U$3:$V$13,MATCH(I43,$U$3:$U$13,0),2) -> 0
B46: Part 4 | D46: ='EDI Framework Criteria'!B23 -> General feedback on Equality, Diversity and Inclusion
I48: Our organisation has- please select the appropriate dropdown option | J48: What we have done - please clearly state what your organisation has done | L48: Guidance for these statements
B49: Level 1 | C49: ='EDI Framework Criteria'!C23 -> 1.F.4 | D49: ='EDI Framework Criteria'!D23 -> We have committed to establishing or adapting mechanisms for collecting and recording feedback on EDI. This could include surveys, focus groups or suggestion schemes. | I49: Our organisation has not yet committed to this | K49: =INDEX($U$3:$V$13,MATCH(I49,$U$3:$U$13,0),2) -> 0 | V49: =IF(K49=0,V48,"") -> 0
B51: Level 2 | C51: ='EDI Framework Criteria'!E23 -> 2.F.4 | D51: ='EDI Framework Criteria'!F23 -> We have in place mechanisms for collecting and recording feedback on EDI. This could include surveys, focus groups or suggestion schemes. | I51: Our organisation has not yet implemented this | K51: =INDEX($U$3:$V$13,MATCH(I51,$U$3:$U$13,0),2) -> 0
B53: Level 3 | C53: ='EDI Framework Criteria'!G23 -> 3.F.4 | D53: ='EDI Framework Criteria'!H23 -> We have reviewed feedback mechanisms at least once. We kept a record of how feedback has been responded to | I53: Our organisation has not yet embedded this | K53: =INDEX($U$3:$V$13,MATCH(I53,$U$3:$U$13,0),2) -> 0
B57: Previous section | D57: Next section

Sheet Section 7
B2: Section 7
B3: ='EDI Framework Criteria'!A24 -> Diversity management: EDI integrated into every part of the organisation’s work. | U3: Our organisation has committed to this | V3: 2
U4: In progress | V4: 1
B5: Background information | U5: Our organisation has not yet committed to this | V5: 0
B6: Diversity management tracks how EDI is integrated into every part of the organisation’s work through structures, such as EDI leads, EDI accountability, and whistleblowing processes.
U7: Our organisation has implemented this | V7: 2
B8: Useful resources (select the + button on the left hand side of the screen to expand) | U8: In progress | V8: 1
B9: Resource name | D9: Description | O9: URL | U9: Our organisation has not yet implemented this | V9: 0
B10: ISO 30415 2021(en), Human resource management — Diversity and inclusion | D10: "This document provides guidance on D&I for organizations, including their governance body, leaders, workforce and recognized representatives, and other stakeholders. It is intended to be scalable to the needs of all types of organizations in different sectors, whether in public, private, government or non-governmental organizations (NGO), regardless of size, type, activity, industry or sector, growth phase, external influences and country-specific requirements." | O10: https://www.iso.org/standard/71164.html
U11: Our organisation has embedded this | V11: 2
U12: In progress | V12: 1
U13: Our organisation has not yet embedded this | V13: 0
B16: Part 1 | D16: ='EDI Framework Criteria'!B24 -> Groups set up and tasked with Equality, Diversity and Inclusion
I18: Our organisation has- please select the appropriate dropdown option | J18: What we have done - please clearly state what your organisation has done | K18: Score | L18: Guidance for these statements | V18: Non commitment
B19: Level 1 | C19: ='EDI Framework Criteria'!C24 -> 1.G.1 | D19: ='EDI Framework Criteria'!D24 -> We have committed to identifying EDI lead/s and creating a working group or forum with representation from across the organisation. This should report to, and receive support from, the board or senior management. | I19: Our organisation has not yet committed to this | K19: =INDEX($U$3:$V$13,MATCH(I19,$U$3:$U$13,0),2) -> 0 | V19: =IF(K19=0,V18,"") -> Non commitment
B21: Level 2 | C21: ='EDI Framework Criteria'!E24 -> 2.G.1 | D21: ='EDI Framework Criteria'!F24 -> EDI lead/s and a working group or forum with representation from across the organisation have started work. They report to, and receive support from, the board or senior management. | I21: Our organisation has not yet implemented this | K21: =INDEX($U$3:$V$13,MATCH(I21,$U$3:$U$13,0),2) -> 0
B23: Level 3 | C23: ='EDI Framework Criteria'!G24 -> 3.G.1 | D23: ='EDI Framework Criteria'!H24 -> EDI lead/s and working group or forum meet regularly. They are given support by the board or senior management, and also report on their activities. | I23: Our organisation has not yet embedded this | K23: =INDEX($U$3:$V$13,MATCH(I23,$U$3:$U$13,0),2) -> 0
B26: Part 2 | D26: ='EDI Framework Criteria'!B25 -> Accountability mechanisms for Equality, Diversity and Inclusion issues
I28: Our organisation has- please select the appropriate dropdown option | J28: What we have done - please clearly state what your organisation has done | L28: Guidance for these statements
B29: Level 1 | C29: ='EDI Framework Criteria'!C25 -> 1.G.2 | D29: ='EDI Framework Criteria'!D25 -> We have committed to creating a policy or action plan to cover accountability mechanisms for EDI practice. This will outline the responsibilities of our governance, for example, our board. | I29: Our organisation has not yet committed to this | K29: =INDEX($U$3:$V$13,MATCH(I29,$U$3:$U$13,0),2) -> 0 | V29: =IF(K29=0,V28,"") -> 0
B31: Level 2 | C31: ='EDI Framework Criteria'!E25 -> 2.G.2 | D31: ='EDI Framework Criteria'!F25 -> We have created a policy or action plan to cover accountability mechanisms for EDI practice. This outlines the responsibilities of our governance, for example, our board. | I31: Our organisation has not yet implemented this | K31: =INDEX($U$3:$V$13,MATCH(I31,$U$3:$U$13,0),2) -> 0
B33: Level 3 | C33: ='EDI Framework Criteria'!G25 -> 3.G.2 | D33: ='EDI Framework Criteria'!H25 -> We have a policy or action plan in place to cover accountability mechanisms for EDI practice. It outlines the responsibilities of our governance, for example, our board. It has been reviewed at least once. We have plans to keep reviewing it as needed. | I33: Our organisation has not yet embedded this | K33: =INDEX($U$3:$V$13,MATCH(I33,$U$3:$U$13,0),2) -> 0
B36: Part 3 | D36: ='EDI Framework Criteria'!B26 -> Mechanisms have been set up to address Equality, Diversity and Inclusion incidents
I38: Our organisation has- please select the appropriate dropdown option | J38: What we have done - please clearly state what your organisation has done | L38: Guidance for these statements
B39: Level 1 | C39: ='EDI Framework Criteria'!C26 -> 1.G.3 | D39: ='EDI Framework Criteria'!D26 -> We are committed to creating or adapting an existing complaint or whistleblowing process. These processes will include support for people making the complaint. The processes will be accessible to internal and external stakeholders. | I39: Our organisation has not yet committed to this | K39: =INDEX($U$3:$V$13,MATCH(I39,$U$3:$U$13,0),2) -> 0 | V39: =IF(K39=0,V38,"") -> 0
B41: Level 2 | C41: ='EDI Framework Criteria'!E26 -> 2.G.3 | D41: ='EDI Framework Criteria'!F26 -> We have created or adapted an existing complaint or whistleblowing process. These processes include support for people making the complaint. The processes are accessible to internal and external stakeholders. | I41: Our organisation has not yet implemented this | K41: =INDEX($U$3:$V$13,MATCH(I41,$U$3:$U$13,0),2) -> 0
