Workbook

Sheet Thrive
C2: Ventures Diagnostic and Support Plan
C3: A diagnostic tool and support plan for ventures

Sheet Covering Page
A1: How to use the growth platform
B3: How to use this with the venture
B4: This is designed to be a working document, used to measure progress. After undertaking the venture's diagnostic and support plan, share this document with the venture. This will ensure a mutual understanding of stage and encourage a collaborative relationship. Our role is to work withventures as they strive for impact growth, not dictate work they must undertake.
B9: Overarching Ambition
B10: Within this tab, Venture Managers should capture and articulate the venture's overall ambition, aims for the support and success metrics against each objective.
B13: Diagnostic - start
B14: The Diagnostic tab should be used to assess and articulate the current stage of the venture and entrepreneur at the beginning of the support programme. Enter explanatory text into the relevant box indicating stage and summarise why the venture falls within this stage and not another. Only enter text into one stage box per pillar.
B19: Growth Journey
B20: Based on the outcome of the Diagnostic - start, against each support objective, detail actions which are needed to help the venture grow, when this action should be completed by, what the output of this work will be, and what resources you need. Resources may include particular models or people inside or outside of the organisation. A large selection of support tools can be found within the VM Resource Pack.
B25: Diagnostic - end
B26: The Diagnostic tab should be used to assess and articulate the current stage of the venture and entrepreneur at the end of the support programme. Enter explanatory text into the relevant box indicating stage and summarise why the venture falls within this stage and not another. Only enter text into the one stage box per pillar.
B31: Distance travelled
B32: Based on the inputs in the Diagnostic - start and Diagnostic - end tabs, a distance travelled for each support pillar will automatically populate. This will give you and the venture, an indication of improvements or deterioration during the support programme.
... B37: If you wish to make edits to the wording of the pillars, objectives, or stages, please make these on the Diagnostic - start tab. These will automatically feed through to the subsequent Growth Journey, Diagnostic - end and Distance travelled tabs.

Sheet Overarching Ambition
A1: Overarching ambition
B2: Venture Name
B4: Overarching ambition | C4: Support objectives | D4: Success criteria
B5: Describe what the venture's long term ambition is. This is a very brief summary of the venture's aims and purpose. | C5: Describe the desired outcome over the award period. What improvements does the Award Winners anticipate as a result of the support? These could involve the following (this list is not exhaustive): To achieve first trading income or order, To achieve demonstrable social impact (the level being specified if possible) To reach be financially sustainable, To grow the team, To grow geographically, To develop trading partnerships, To grow revenue and/or impact. | D5: Against each support objective, define a measurable success indicator. These could involve the following (this list is not exhaustive). Note that these are indicators which demonstrate success of objectives, as opposed to improvements in the venture, which is measured using the Growth Journey tab. Number of products/services delivered, Case study or impact report highlighting creation of demonstrable impact Reach breakeven Employing first/additional member of staff To begin opeations in a new area, Contract signed with new trading partner Growth of revenue, social impact, profit or other measure by a stated percentage or amount.

Sheet Diagnostic - start
A1: Ventures Support framework - diagnostic - start of support
B2: ='Overarching Ambition'!B2 -> Venture Name
F3: Early stage >>> | I3: <<< Ready for scale
C4: Support pillar | E4: Support objectives | F4: Unproven, no evidence | G4: Early proof, some evidence | H4: Proven, well evidenced | I4: Highly proven, significant evidence | J4: Pillar score
B5: Person / People | C5: 1. Leadership | D5: 1.1 | E5: CEO strategic leadership: decision making reflects understanding of external big picture and alignment with mission | J5: =IF(NOT(ISBLANK(F5)),1,IF(NOT(ISBLANK(G5)),2,IF(NOT(ISBLANK(H5)),3,IF(NOT(ISBLANK(I5)),4)))) -> FALSE
D6: 1.2 | E6: CEO performance management leadership: strong self-awareness, ability to drive performance management and build learning organisation, informed by a command of detail across all areas of business | J6: =IF(NOT(ISBLANK(F6)),1,IF(NOT(ISBLANK(G6)),2,IF(NOT(ISBLANK(H6)),3,IF(NOT(ISBLANK(I6)),4)))) -> FALSE
D7: 1.3 | E7: Resource allocation: ability to allocate existing resources and investment in future resources (human and financial) against core outcome-generating activities | J7: =IF(NOT(ISBLANK(F7)),1,IF(NOT(ISBLANK(G7)),2,IF(NOT(ISBLANK(H7)),3,IF(NOT(ISBLANK(I7)),4)))) -> FALSE
D8: 1.4 | E8: Sector knowledge: deep understanding of the landscape of the sector in which they operate (for example key policies, polcy makers, influential organisations and bodies) | J8: =IF(NOT(ISBLANK(F8)),1,IF(NOT(ISBLANK(G8)),2,IF(NOT(ISBLANK(H8)),3,IF(NOT(ISBLANK(I8)),4)))) -> FALSE
C9: 2. Team Building | D9: 2.1 | E9: Key functional competencies in place: finance, operations, sales, impact, HR, communications, etc | J9: =IF(NOT(ISBLANK(F9)),1,IF(NOT(ISBLANK(G9)),2,IF(NOT(ISBLANK(H9)),3,IF(NOT(ISBLANK(I9)),4)))) -> FALSE
D10: 2.2 | E10: SMT: team contains a broad mix of skills, is of an appropriate size relative to the company's maturity and has the capability to deliver and work well as a team | J10: =IF(NOT(ISBLANK(F10)),1,IF(NOT(ISBLANK(G10)),2,IF(NOT(ISBLANK(H10)),3,IF(NOT(ISBLANK(I10)),4)))) -> FALSE
D11: 2.3 | E11: Resourcing: sufficiently resourced to deliver product/service without bottleneck/over resourcing; roles and responsibilities documented and clearly communicated across organisation | J11: =IF(NOT(ISBLANK(F11)),1,IF(NOT(ISBLANK(G11)),2,IF(NOT(ISBLANK(H11)),3,IF(NOT(ISBLANK(I11)),4)))) -> FALSE
D12: 2.4 | E12: Team development: provision for team development and training in place | J12: =IF(NOT(ISBLANK(F12)),1,IF(NOT(ISBLANK(G12)),2,IF(NOT(ISBLANK(H12)),3,IF(NOT(ISBLANK(I12)),4)))) -> FALSE
C13: 3. Governance | D13: 3.1 | E13: Overall governance: governance is in place, is supporting the Management Team and is of an appropriate size for scale of business and growth plans - including formal and informal advisory roles | J13: =IF(NOT(ISBLANK(F13)),1,IF(NOT(ISBLANK(G13)),2,IF(NOT(ISBLANK(H13)),3,IF(NOT(ISBLANK(I13)),4)))) -> FALSE
D14: 3.2 | E14: Board: oversight and accountability. Oversight of strategic and organisational effectiveness, holding the CEO to account and providing fiduciary oversight | J14: =IF(NOT(ISBLANK(F14)),1,IF(NOT(ISBLANK(G14)),2,IF(NOT(ISBLANK(H14)),3,IF(NOT(ISBLANK(I14)),4)))) -> FALSE
B15: Proposition | C15: 4. Social Impact | D15: 4.1 | E15: Theory of change: is developed, understood and clearly communicated | J15: =IF(NOT(ISBLANK(F15)),1,IF(NOT(ISBLANK(G15)),2,IF(NOT(ISBLANK(H15)),3,IF(NOT(ISBLANK(I15)),4)))) -> FALSE
D16: 4.2 | E16: Key metrics: these are clearly articulated and aid in demonstrating that the venture is achieving its mission | J16: =IF(NOT(ISBLANK(F16)),1,IF(NOT(ISBLANK(G16)),2,IF(NOT(ISBLANK(H16)),3,IF(NOT(ISBLANK(I16)),4)))) -> FALSE
D17: 4.3 | E17: Data: appropriate impact indicator data has been identified and is being collected against key metrics | J17: =IF(NOT(ISBLANK(F17)),1,IF(NOT(ISBLANK(G17)),2,IF(NOT(ISBLANK(H17)),3,IF(NOT(ISBLANK(I17)),4)))) -> FALSE
D18: 4.4 | E18: Reporting: social impact is being reported, is disseminated publicly and has an element of external validation | J18: =IF(NOT(ISBLANK(F18)),1,IF(NOT(ISBLANK(G18)),2,IF(NOT(ISBLANK(H18)),3,IF(NOT(ISBLANK(I18)),4)))) -> FALSE
D19: 4.5 | E19: Social lock: social impact is 'locked' into business' structure for the long term | J19: =IF(NOT(ISBLANK(F19)),1,IF(NOT(ISBLANK(G19)),2,IF(NOT(ISBLANK(H19)),3,IF(NOT(ISBLANK(I19)),4)))) -> FALSE
C20: 5. Sales Planning | D20: 5.1 | E20: Value proposition: ability to articulate value proposition, target customers and routes to market | J20: =IF(NOT(ISBLANK(F20)),1,IF(NOT(ISBLANK(G20)),2,IF(NOT(ISBLANK(H20)),3,IF(NOT(ISBLANK(I20)),4)))) -> FALSE
D21: 5.2 | E21: Market knowledge: understanding of market and price sensitivities | J21: =IF(NOT(ISBLANK(F21)),1,IF(NOT(ISBLANK(G21)),2,IF(NOT(ISBLANK(H21)),3,IF(NOT(ISBLANK(I21)),4)))) -> FALSE
D22: 5.3 | E22: Network building: well-known and well positioned in the sector. Has to ability to build useful connections and grow their network, forming appropriate partnerships | J22: =IF(NOT(ISBLANK(F22)),1,IF(NOT(ISBLANK(G22)),2,IF(NOT(ISBLANK(H22)),3,IF(NOT(ISBLANK(I22)),4)))) -> FALSE
D23: 5.4 | E23: Understanding of sales funnel: conversion rates, customer acquisition costs and lead time known and documented | J23: =IF(NOT(ISBLANK(F23)),1,IF(NOT(ISBLANK(G23)),2,IF(NOT(ISBLANK(H23)),3,IF(NOT(ISBLANK(I23)),4)))) -> FALSE
D24: 5.5 | E24: Forecasting: ability to forecast sales growth and resource requirements for growth | J24: =IF(NOT(ISBLANK(F24)),1,IF(NOT(ISBLANK(G24)),2,IF(NOT(ISBLANK(H24)),3,IF(NOT(ISBLANK(I24)),4)))) -> FALSE
D25: 5.6 | E25: Sales process: is in place and operational across teams / people in organisation | J25: =IF(NOT(ISBLANK(F25)),1,IF(NOT(ISBLANK(G25)),2,IF(NOT(ISBLANK(H25)),3,IF(NOT(ISBLANK(I25)),4)))) -> FALSE
D26: 5.7 | E26: Comms and marketing: presence and efficacy of comms and marketing strategy | J26: =IF(NOT(ISBLANK(F26)),1,IF(NOT(ISBLANK(G26)),2,IF(NOT(ISBLANK(H26)),3,IF(NOT(ISBLANK(I26)),4)))) -> FALSE
B27: Performance | C27: 6. Legals and reporting | D27: 6.1 | E27: Incorporation: business incorporated with appropriate legal structure for growth plans | J27: =IF(NOT(ISBLANK(F27)),1,IF(NOT(ISBLANK(G27)),2,IF(NOT(ISBLANK(H27)),3,IF(NOT(ISBLANK(I27)),4)))) -> FALSE
D28: 6.2 | E28: Partner agreements: any appropriate partner agreements and service level contracts in place | J28: =IF(NOT(ISBLANK(F28)),1,IF(NOT(ISBLANK(G28)),2,IF(NOT(ISBLANK(H28)),3,IF(NOT(ISBLANK(I28)),4)))) -> FALSE
D29: 6.3 | E29: Intellectual Property: any IP corrected documented and registered | J29: =IF(NOT(ISBLANK(F29)),1,IF(NOT(ISBLANK(G29)),2,IF(NOT(ISBLANK(H29)),3,IF(NOT(ISBLANK(I29)),4)))) -> FALSE
D30: 6.4 | E30: Legal understanding: knowledge of all relevant legal requirements and procedures in place to ensure compliance (particularly data protection) | J30: =IF(NOT(ISBLANK(F30)),1,IF(NOT(ISBLANK(G30)),2,IF(NOT(ISBLANK(H30)),3,IF(NOT(ISBLANK(I30)),4)))) -> FALSE
D31: 6.5 | E31: Accountability: relevant HR processes being used by managers to hold staff accountable to performance standards | J31: =IF(NOT(ISBLANK(F31)),1,IF(NOT(ISBLANK(G31)),2,IF(NOT(ISBLANK(H31)),3,IF(NOT(ISBLANK(I31)),4)))) -> FALSE
D32: 6.6 | E32: Financial reporting: submission of externally validated Accounts to company registrar; production of accurate financial statements and quarterly Management Information/Accounts | J32: =IF(NOT(ISBLANK(F32)),1,IF(NOT(ISBLANK(G32)),2,IF(NOT(ISBLANK(H32)),3,IF(NOT(ISBLANK(I32)),4)))) -> FALSE
C33: 7. Operations and processes | D33: 7.1 | E33: Operations planning: processes and operations mapped out and documented to ensure risks and contingencies identified | J33: =IF(NOT(ISBLANK(F33)),1,IF(NOT(ISBLANK(G33)),2,IF(NOT(ISBLANK(H33)),3,IF(NOT(ISBLANK(I33)),4)))) -> FALSE
D34: 7.2 | E34: Data system: IT systems, tools and collection of data systems in place, including data security and compliance | J34: =IF(NOT(ISBLANK(F34)),1,IF(NOT(ISBLANK(G34)),2,IF(NOT(ISBLANK(H34)),3,IF(NOT(ISBLANK(I34)),4)))) -> FALSE
D35: 7.3 | E35: Tactical performance management: staff reviews, customer feedback and analyses data to make adjustments to delivery | J35: =IF(NOT(ISBLANK(F35)),1,IF(NOT(ISBLANK(G35)),2,IF(NOT(ISBLANK(H35)),3,IF(NOT(ISBLANK(I35)),4)))) -> FALSE
D36: 7.4 | E36: Strategic performance management: performance data created and disseminated in line with KPIs which can be used by managers to make decisions in order to improve outcomes of product/services | J36: =IF(NOT(ISBLANK(F36)),1,IF(NOT(ISBLANK(G36)),2,IF(NOT(ISBLANK(H36)),3,IF(NOT(ISBLANK(I36)),4)))) -> FALSE
B37: Plan | C37: 8. Growth Plan | D37: 8.1 | E37: Business / revenue model: proven and scalable demonstrated by significant track record of sales and impact | J37: =IF(NOT(ISBLANK(F37)),1,IF(NOT(ISBLANK(G37)),2,IF(NOT(ISBLANK(H37)),3,IF(NOT(ISBLANK(I37)),4)))) -> FALSE
D38: 8.2 | E38: Growth plan: robust, thoughtful growth plan in place and is being operationalised | J38: =IF(NOT(ISBLANK(F38)),1,IF(NOT(ISBLANK(G38)),2,IF(NOT(ISBLANK(H38)),3,IF(NOT(ISBLANK(I38)),4)))) -> FALSE
D39: 8.3 | E39: Growth plan communication: across team in a durable medium | J39: =IF(NOT(ISBLANK(F39)),1,IF(NOT(ISBLANK(G39)),2,IF(NOT(ISBLANK(H39)),3,IF(NOT(ISBLANK(I39)),4)))) -> FALSE
D40: 8.4 | E40: Market influence and positioning: understands the organisation's role within the wider sector and has a desire and ability to become a prominent change-maker and influential at a policy level | J40: =IF(NOT(ISBLANK(F40)),1,IF(NOT(ISBLANK(G40)),2,IF(NOT(ISBLANK(H40)),3,IF(NOT(ISBLANK(I40)),4)))) -> FALSE
...

Sheet Growth Journey
A1: Ventures Support framework - growth journey
B2: ='Overarching Ambition'!B2 -> Venture Name
F3: Action | G3: Time | H3: Output | I3: Resources (tools, people)
C4: ='Diagnostic - start'!C4 -> Support pillar | E4: ='Diagnostic - start'!E4 -> Support objectives | J4: Pillar score
B5: ='Diagnostic - start'!B5:B14 -> Person / People | C5: ='Diagnostic - start'!C5:C7 -> 1. Leadership | D5: ='Diagnostic - start'!D5 -> 1.1 | E5: ='Diagnostic - start'!E5 -> CEO strategic leadership: decision making reflects understanding of external big picture and alignment with mission | J5: ='Diagnostic - start'!J5 -> FALSE
D6: ='Diagnostic - start'!D6 -> 1.2 | E6: ='Diagnostic - start'!E6 -> CEO performance management leadership: strong self-awareness, ability to drive performance management and build learning organisation, informed by a command of detail across all areas of business | J6: ='Diagnostic - start'!J6 -> FALSE
D7: ='Diagnostic - start'!D7 -> 1.3 | E7: ='Diagnostic - start'!E7 -> Resource allocation: ability to allocate existing resources and investment in future resources (human and financial) against core outcome-generating activities | J7: ='Diagnostic - start'!J7 -> FALSE
D8: ='Diagnostic - start'!D8 -> 1.4 | E8: ='Diagnostic - start'!E8 -> Sector knowledge: deep understanding of the landscape of the sector in which they operate (for example key policies, polcy makers, influential organisations and bodies) | J8: ='Diagnostic - start'!J8 -> FALSE
C9: ='Diagnostic - start'!C9:C12 -> 2. Team Building | D9: ='Diagnostic - start'!D9 -> 2.1 | E9: ='Diagnostic - start'!E9 -> Key functional competencies in place: finance, operations, sales, impact, HR, communications, etc | J9: ='Diagnostic - start'!J9 -> FALSE
D10: ='Diagnostic - start'!D10 -> 2.2 | E10: ='Diagnostic - start'!E10 -> SMT: team contains a broad mix of skills, is of an appropriate size relative to the company's maturity and has the capability to deliver and work well as a team | J10: ='Diagnostic - start'!J10 -> FALSE
D11: ='Diagnostic - start'!D11 -> 2.3 | E11: ='Diagnostic - start'!E11 -> Resourcing: sufficiently resourced to deliver product/service without bottleneck/over resourcing; roles and responsibilities documented and clearly communicated across organisation | J11: ='Diagnostic - start'!J11 -> FALSE
D12: ='Diagnostic - start'!D12 -> 2.4 | E12: ='Diagnostic - start'!E12 -> Team development: provision for team development and training in place | J12: ='Diagnostic - start'!J12 -> FALSE
C13: ='Diagnostic - start'!C13:C14 -> 3. Governance | D13: ='Diagnostic - start'!D13 -> 3.1 | E13: ='Diagnostic - start'!E13 -> Overall governance: governance is in place, is supporting the Management Team and is of an appropriate size for scale of business and growth plans - including formal and informal advisory roles | J13: ='Diagnostic - start'!J13 -> FALSE
D14: ='Diagnostic - start'!D14 -> 3.2 | E14: ='Diagnostic - start'!E14 -> Board: oversight and accountability. Oversight of strategic and organisational effectiveness, holding the CEO to account and providing fiduciary oversight | J14: ='Diagnostic - start'!J14 -> FALSE
B15: ='Diagnostic - start'!B15:B25 -> Proposition | C15: ='Diagnostic - start'!C15:C19 -> 4. Social Impact | D15: ='Diagnostic - start'!D15 -> 4.1 | E15: ='Diagnostic - start'!E15 -> Theory of change: is developed, understood and clearly communicated | J15: ='Diagnostic - start'!J15 -> FALSE
D16: ='Diagnostic - start'!D16 -> 4.2 | E16: ='Diagnostic - start'!E16 -> Key metrics: these are clearly articulated and aid in demonstrating that the venture is achieving its mission | J16: ='Diagnostic - start'!J16 -> FALSE
D17: ='Diagnostic - start'!D17 -> 4.3 | E17: ='Diagnostic - start'!E17 -> Data: appropriate impact indicator data has been identified and is being collected against key metrics | J17: ='Diagnostic - start'!J17 -> FALSE
D18: ='Diagnostic - start'!D18 -> 4.4 | E18: ='Diagnostic - start'!E18 -> Reporting: social impact is being reported, is disseminated publicly and has an element of external validation | J18: ='Diagnostic - start'!J18 -> FALSE
D19: ='Diagnostic - start'!D19 -> 4.5 | E19: ='Diagnostic - start'!E19 -> Social lock: social impact is 'locked' into business' structure for the long term | J19: ='Diagnostic - start'!J19 -> FALSE
C20: ='Diagnostic - start'!C20:C25 -> 5. Sales Planning | D20: ='Diagnostic - start'!D20 -> 5.1 | E20: ='Diagnostic - start'!E20 -> Value proposition: ability to articulate value proposition, target customers and routes to market | J20: ='Diagnostic - start'!J20 -> FALSE
D21: ='Diagnostic - start'!D21 -> 5.2 | E21: ='Diagnostic - start'!E21 -> Market knowledge: understanding of market and price sensitivities | J21: ='Diagnostic - start'!J21 -> FALSE
D22: ='Diagnostic - start'!D22 -> 5.3 | E22: ='Diagnostic - start'!E22 -> Network building: well-known and well positioned in the sector. Has to ability to build useful connections and grow their network, forming appropriate partnerships | J22: ='Diagnostic - start'!J22 -> FALSE
D23: ='Diagnostic - start'!D23 -> 5.4 | E23: ='Diagnostic - start'!E23 -> Understanding of sales funnel: conversion rates, customer acquisition costs and lead time known and documented | J23: ='Diagnostic - start'!J23 -> FALSE
D24: ='Diagnostic - start'!D24 -> 5.5 | E24: ='Diagnostic - start'!E24 -> Forecasting: ability to forecast sales growth and resource requirements for growth | J24: ='Diagnostic - start'!J24 -> FALSE
D25: ='Diagnostic - start'!D25 -> 5.6 | E25: ='Diagnostic - start'!E25 -> Sales process: is in place and operational across teams / people in organisation | J25: ='Diagnostic - start'!J25 -> FALSE
D26: ='Diagnostic - start'!D26 -> 5.7 | E26: ='Diagnostic - start'!E26 -> Comms and marketing: presence and efficacy of comms and marketing strategy | J26: ='Diagnostic - start'!J26 -> FALSE
B27: ='Diagnostic - start'!B27:B36 -> Performance | C27: ='Diagnostic - start'!C27:C32 -> 6. Legals and reporting | D27: ='Diagnostic - start'!D27 -> 6.1 | E27: ='Diagnostic - start'!E27 -> Incorporation: business incorporated with appropriate legal structure for growth plans | J27: ='Diagnostic - start'!J27 -> FALSE
D28: ='Diagnostic - start'!D28 -> 6.2 | E28: ='Diagnostic - start'!E28 -> Partner agreements: any appropriate partner agreements and service level contracts in place | J28: ='Diagnostic - start'!J28 -> FALSE
D29: ='Diagnostic - start'!D29 -> 6.3 | E29: ='Diagnostic - start'!E29 -> Intellectual Property: any IP corrected documented and registered | J29: ='Diagnostic - start'!J29 -> FALSE
D30: ='Diagnostic - start'!D30 -> 6.4 | E30: ='Diagnostic - start'!E30 -> Legal understanding: knowledge of all relevant legal requirements and procedures in place to ensure compliance (particularly data protection) | J30: ='Diagnostic - start'!J30 -> FALSE
D31: ='Diagnostic - start'!D31 -> 6.5 | E31: ='Diagnostic - start'!E31 -> Accountability: relevant HR processes being used by managers to hold staff accountable to performance standards | J31: ='Diagnostic - start'!J31 -> FALSE
D32: ='Diagnostic - start'!D32 -> 6.6 | E32: ='Diagnostic - start'!E32 -> Financial reporting: submission of externally validated Accounts to company registrar; production of accurate financial statements and quarterly Management Information/Accounts | J32: ='Diagnostic - start'!J32 -> FALSE
C33: ='Diagnostic - start'!C33:C36 -> 7. Operations and processes | D33: ='Diagnostic - start'!D33 -> 7.1 | E33: ='Diagnostic - start'!E33 -> Operations planning: processes and operations mapped out and documented to ensure risks and contingencies identified | J33: ='Diagnostic - start'!J33 -> FALSE
D34: ='Diagnostic - start'!D34 -> 7.2 | E34: ='Diagnostic - start'!E34 -> Data system: IT systems, tools and collection of data systems in place, including data security and compliance | J34: ='Diagnostic - start'!J34 -> FALSE
D35: ='Diagnostic - start'!D35 -> 7.3 | E35: ='Diagnostic - start'!E35 -> Tactical performance management: staff reviews, customer feedback and analyses data to make adjustments to delivery | J35: ='Diagnostic - start'!J35 -> FALSE
D36: ='Diagnostic - start'!D36 -> 7.4 | E36: ='Diagnostic - start'!E36 -> Strategic performance management: performance data created and disseminated in line with KPIs which can be used by managers to make decisions in order to improve outcomes of product/services | J36: ='Diagnostic - start'!J36 -> FALSE
B37: ='Diagnostic - start'!B37:B46 -> Plan | C37: ='Diagnostic - start'!C37:C39 -> 8. Growth Plan | D37: ='Diagnostic - start'!D37 -> 8.1 | E37: ='Diagnostic - start'!E37 -> Business / revenue model: proven and scalable demonstrated by significant track record of sales and impact | J37: ='Diagnostic - start'!J37 -> FALSE
D38: ='Diagnostic - start'!D38 -> 8.2 | E38: ='Diagnostic - start'!E38 -> Growth plan: robust, thoughtful growth plan in place and is being operationalised | J38: ='Diagnostic - start'!J38 -> FALSE
D39: ='Diagnostic - start'!D39 -> 8.3 | E39: ='Diagnostic - start'!E39 -> Growth plan communication: across team in a durable medium | J39: ='Diagnostic - start'!J39 -> FALSE
D40: ='Diagnostic - start'!D40 -> 8.4 | E40: ='Diagnostic - start'!E40 -> Market influence and positioning: understands the organisation's role within the wider sector and has a desire and ability to become a prominent change-maker and influential at a policy level | J40: ='Diagnostic - start'!J40 -> FALSE
...

Sheet Diagnostic - end
A1: Ventures Support framework - diagnostic - end of support
B2: ='Overarching Ambition'!B2 -> Venture Name
F3: Early stage >>> | I3: <<< Ready for scale
C4: ='Diagnostic - start'!C4 -> Support pillar | E4: ='Diagnostic - start'!E4 -> Support objectives | F4: Unproven, no evidence | G4: Early proof, some evidence | H4: Proven, well evidenced | I4: Highly proven, significant evidence | J4: Original pillar score | K4: New pillar score
B5: ='Diagnostic - start'!B5:B14 -> Person / People | C5: ='Diagnostic - start'!C5:C7 -> 1. Leadership | D5: ='Diagnostic - start'!D5 -> 1.1 | E5: ='Diagnostic - start'!E5 -> CEO strategic leadership: decision making reflects understanding of external big picture and alignment with mission | J5: ='Diagnostic - start'!J5 -> FALSE | K5: =IF(NOT(ISBLANK(F5)),1,IF(NOT(ISBLANK(G5)),2,IF(NOT(ISBLANK(H5)),3,IF(NOT(ISBLANK(I5)),4)))) -> FALSE
D6: ='Diagnostic - start'!D6 -> 1.2 | E6: ='Diagnostic - start'!E6 -> CEO performance management leadership: strong self-awareness, ability to drive performance management and build learning organisation, informed by a command of detail across all areas of business | J6: ='Diagnostic - start'!J6 -> FALSE | K6: =IF(NOT(ISBLANK(F6)),1,IF(NOT(ISBLANK(G6)),2,IF(NOT(ISBLANK(H6)),3,IF(NOT(ISBLANK(I6)),4)))) -> FALSE
D7: ='Diagnostic - start'!D7 -> 1.3 | E7: ='Diagnostic - start'!E7 -> Resource allocation: ability to allocate existing resources and investment in future resources (human and financial) against core outcome-generating activities | J7: ='Diagnostic - start'!J7 -> FALSE | K7: =IF(NOT(ISBLANK(F7)),1,IF(NOT(ISBLANK(G7)),2,IF(NOT(ISBLANK(H7)),3,IF(NOT(ISBLANK(I7)),4)))) -> FALSE
D8: ='Diagnostic - start'!D8 -> 1.4 | E8: ='Diagnostic - start'!E8 -> Sector knowledge: deep understanding of the landscape of the sector in which they operate (for example key policies, polcy makers, influential organisations and bodies) | J8: ='Diagnostic - start'!J8 -> FALSE | K8: =IF(NOT(ISBLANK(F8)),1,IF(NOT(ISBLANK(G8)),2,IF(NOT(ISBLANK(H8)),3,IF(NOT(ISBLANK(I8)),4)))) -> FALSE
C9: ='Diagnostic - start'!C9:C12 -> 2. Team Building | D9: ='Diagnostic - start'!D9 -> 2.1 | E9: ='Diagnostic - start'!E9 -> Key functional competencies in place: finance, operations, sales, impact, HR, communications, etc | J9: ='Diagnostic - start'!J9 -> FALSE | K9: =IF(NOT(ISBLANK(F9)),1,IF(NOT(ISBLANK(G9)),2,IF(NOT(ISBLANK(H9)),3,IF(NOT(ISBLANK(I9)),4)))) -> FALSE
D10: ='Diagnostic - start'!D10 -> 2.2 | E10: ='Diagnostic - start'!E10 -> SMT: team contains a broad mix of skills, is of an appropriate size relative to the company's maturity and has the capability to deliver and work well as a team | J10: ='Diagnostic - start'!J10 -> FALSE | K10: =IF(NOT(ISBLANK(F10)),1,IF(NOT(ISBLANK(G10)),2,IF(NOT(ISBLANK(H10)),3,IF(NOT(ISBLANK(I10)),4)))) -> FALSE
D11: ='Diagnostic - start'!D11 -> 2.3 | E11: ='Diagnostic - start'!E11 -> Resourcing: sufficiently resourced to deliver product/service without bottleneck/over resourcing; roles and responsibilities documented and clearly communicated across organisation | J11: ='Diagnostic - start'!J11 -> FALSE | K11: =IF(NOT(ISBLANK(F11)),1,IF(NOT(ISBLANK(G11)),2,IF(NOT(ISBLANK(H11)),3,IF(NOT(ISBLANK(I11)),4)))) -> FALSE
D12: ='Diagnostic - start'!D12 -> 2.4 | E12: ='Diagnostic - start'!E12 -> Team development: provision for team development and training in place | J12: ='Diagnostic - start'!J12 -> FALSE | K12: =IF(NOT(ISBLANK(F12)),1,IF(NOT(ISBLANK(G12)),2,IF(NOT(ISBLANK(H12)),3,IF(NOT(ISBLANK(I12)),4)))) -> FALSE
C13: ='Diagnostic - start'!C13:C14 -> 3. Governance | D13: ='Diagnostic - start'!D13 -> 3.1 | E13: ='Diagnostic - start'!E13 -> Overall governance: governance is in place, is supporting the Management Team and is of an appropriate size for scale of business and growth plans - including formal and informal advisory roles | J13: ='Diagnostic - start'!J13 -> FALSE | K13: =IF(NOT(ISBLANK(F13)),1,IF(NOT(ISBLANK(G13)),2,IF(NOT(ISBLANK(H13)),3,IF(NOT(ISBLANK(I13)),4)))) -> FALSE
D14: ='Diagnostic - start'!D14 -> 3.2 | E14: ='Diagnostic - start'!E14 -> Board: oversight and accountability. Oversight of strategic and organisational effectiveness, holding the CEO to account and providing fiduciary oversight | J14: ='Diagnostic - start'!J14 -> FALSE | K14: =IF(NOT(ISBLANK(F14)),1,IF(NOT(ISBLANK(G14)),2,IF(NOT(ISBLANK(H14)),3,IF(NOT(ISBLANK(I14)),4)))) -> FALSE
B15: ='Diagnostic - start'!B15:B25 -> Proposition | C15: ='Diagnostic - start'!C15:C19 -> 4. Social Impact | D15: ='Diagnostic - start'!D15 -> 4.1 | E15: ='Diagnostic - start'!E15 -> Theory of change: is developed, understood and clearly communicated | J15: ='Diagnostic - start'!J15 -> FALSE | K15: =IF(NOT(ISBLANK(F15)),1,IF(NOT(ISBLANK(G15)),2,IF(NOT(ISBLANK(H15)),3,IF(NOT(ISBLANK(I15)),4)))) -> FALSE
D16: ='Diagnostic - start'!D16 -> 4.2 | E16: ='Diagnostic - start'!E16 -> Key metrics: these are clearly articulated and aid in demonstrating that the venture is achieving its mission | J16: ='Diagnostic - start'!J16 -> FALSE | K16: =IF(NOT(ISBLANK(F16)),1,IF(NOT(ISBLANK(G16)),2,IF(NOT(ISBLANK(H16)),3,IF(NOT(ISBLANK(I16)),4)))) -> FALSE
D17: ='Diagnostic - start'!D17 -> 4.3 | E17: ='Diagnostic - start'!E17 -> Data: appropriate impact indicator data has been identified and is being collected against key metrics | J17: ='Diagnostic - start'!J17 -> FALSE | K17: =IF(NOT(ISBLANK(F17)),1,IF(NOT(ISBLANK(G17)),2,IF(NOT(ISBLANK(H17)),3,IF(NOT(ISBLANK(I17)),4)))) -> FALSE
D18: ='Diagnostic - start'!D18 -> 4.4 | E18: ='Diagnostic - start'!E18 -> Reporting: social impact is being reported, is disseminated publicly and has an element of external validation | J18: ='Diagnostic - start'!J18 -> FALSE | K18: =IF(NOT(ISBLANK(F18)),1,IF(NOT(ISBLANK(G18)),2,IF(NOT(ISBLANK(H18)),3,IF(NOT(ISBLANK(I18)),4)))) -> FALSE
D19: ='Diagnostic - start'!D19 -> 4.5 | E19: ='Diagnostic - start'!E19 -> Social lock: social impact is 'locked' into business' structure for the long term | J19: ='Diagnostic - start'!J19 -> FALSE | K19: =IF(NOT(ISBLANK(F19)),1,IF(NOT(ISBLANK(G19)),2,IF(NOT(ISBLANK(H19)),3,IF(NOT(ISBLANK(I19)),4)))) -> FALSE
C20: ='Diagnostic - start'!C20:C25 -> 5. Sales Planning | D20: ='Diagnostic - start'!D20 -> 5.1 | E20: ='Diagnostic - start'!E20 -> Value proposition: ability to articulate value proposition, target customers and routes to market | J20: ='Diagnostic - start'!J20 -> FALSE | K20: =IF(NOT(ISBLANK(F20)),1,IF(NOT(ISBLANK(G20)),2,IF(NOT(ISBLANK(H20)),3,IF(NOT(ISBLANK(I20)),4)))) -> FALSE
D21: ='Diagnostic - start'!D21 -> 5.2 | E21: ='Diagnostic - start'!E21 -> Market knowledge: understanding of market and price sensitivities | J21: ='Diagnostic - start'!J21 -> FALSE | K21: =IF(NOT(ISBLANK(F21)),1,IF(NOT(ISBLANK(G21)),2,IF(NOT(ISBLANK(H21)),3,IF(NOT(ISBLANK(I21)),4)))) -> FALSE
D22: ='Diagnostic - start'!D22 -> 5.3 | E22: ='Diagnostic - start'!E22 -> Network building: well-known and well positioned in the sector. Has to ability to build useful connections and grow their network, forming appropriate partnerships | J22: ='Diagnostic - start'!J22 -> FALSE | K22: =IF(NOT(ISBLANK(F22)),1,IF(NOT(ISBLANK(G22)),2,IF(NOT(ISBLANK(H22)),3,IF(NOT(ISBLANK(I22)),4)))) -> FALSE
D23: ='Diagnostic - start'!D23 -> 5.4 | E23: ='Diagnostic - start'!E23 -> Understanding of sales funnel: conversion rates, customer acquisition costs and lead time known and documented | J23: ='Diagnostic - start'!J23 -> FALSE | K23: =IF(NOT(ISBLANK(F23)),1,IF(NOT(ISBLANK(G23)),2,IF(NOT(ISBLANK(H23)),3,IF(NOT(ISBLANK(I23)),4)))) -> FALSE
D24: ='Diagnostic - start'!D24 -> 5.5 | E24: ='Diagnostic - start'!E24 -> Forecasting: ability to forecast sales growth and resource requirements for growth | J24: ='Diagnostic - start'!J24 -> FALSE | K24: =IF(NOT(ISBLANK(F24)),1,IF(NOT(ISBLANK(G24)),2,IF(NOT(ISBLANK(H24)),3,IF(NOT(ISBLANK(I24)),4)))) -> FALSE
D25: ='Diagnostic - start'!D25 -> 5.6 | E25: ='Diagnostic - start'!E25 -> Sales process: is in place and operational across teams / people in organisation | J25: ='Diagnostic - start'!J25 -> FALSE | K25: =IF(NOT(ISBLANK(F25)),1,IF(NOT(ISBLANK(G25)),2,IF(NOT(ISBLANK(H25)),3,IF(NOT(ISBLANK(I25)),4)))) -> FALSE
D26: ='Diagnostic - start'!D26 -> 5.7 | E26: ='Diagnostic - start'!E26 -> Comms and marketing: presence and efficacy of comms and marketing strategy | J26: ='Diagnostic - start'!J26 -> FALSE | K26: =IF(NOT(ISBLANK(F26)),1,IF(NOT(ISBLANK(G26)),2,IF(NOT(ISBLANK(H26)),3,IF(NOT(ISBLANK(I26)),4)))) -> FALSE
B27: ='Diagnostic - start'!B27:B36 -> Performance | C27: ='Diagnostic - start'!C27:C32 -> 6. Legals and reporting | D27: ='Diagnostic - start'!D27 -> 6.1 | E27: ='Diagnostic - start'!E27 -> Incorporation: business incorporated with appropriate legal structure for growth plans | J27: ='Diagnostic - start'!J27 -> FALSE | K27: =IF(NOT(ISBLANK(F27)),1,IF(NOT(ISBLANK(G27)),2,IF(NOT(ISBLANK(H27)),3,IF(NOT(ISBLANK(I27)),4)))) -> FALSE
D28: ='Diagnostic - start'!D28 -> 6.2 | E28: ='Diagnostic - start'!E28 -> Partner agreements: any appropriate partner agreements and service level contracts in place | J28: ='Diagnostic - start'!J28 -> FALSE | K28: =IF(NOT(ISBLANK(F28)),1,IF(NOT(ISBLANK(G28)),2,IF(NOT(ISBLANK(H28)),3,IF(NOT(ISBLANK(I28)),4)))) -> FALSE
D29: ='Diagnostic - start'!D29 -> 6.3 | E29: ='Diagnostic - start'!E29 -> Intellectual Property: any IP corrected documented and registered | J29: ='Diagnostic - start'!J29 -> FALSE | K29: =IF(NOT(ISBLANK(F29)),1,IF(NOT(ISBLANK(G29)),2,IF(NOT(ISBLANK(H29)),3,IF(NOT(ISBLANK(I29)),4)))) -> FALSE
D30: ='Diagnostic - start'!D30 -> 6.4 | E30: ='Diagnostic - start'!E30 -> Legal understanding: knowledge of all relevant legal requirements and procedures in place to ensure compliance (particularly data protection) | J30: ='Diagnostic - start'!J30 -> FALSE | K30: =IF(NOT(ISBLANK(F30)),1,IF(NOT(ISBLANK(G30)),2,IF(NOT(ISBLANK(H30)),3,IF(NOT(ISBLANK(I30)),4)))) -> FALSE
D31: ='Diagnostic - start'!D31 -> 6.5 | E31: ='Diagnostic - start'!E31 -> Accountability: relevant HR processes being used by managers to hold staff accountable to performance standards | J31: ='Diagnostic - start'!J31 -> FALSE | K31: =IF(NOT(ISBLANK(F31)),1,IF(NOT(ISBLANK(G31)),2,IF(NOT(ISBLANK(H31)),3,IF(NOT(ISBLANK(I31)),4)))) -> FALSE
D32: ='Diagnostic - start'!D32 -> 6.6 | E32: ='Diagnostic - start'!E32 -> Financial reporting: submission of externally validated Accounts to company registrar; production of accurate financial statements and quarterly Management Information/Accounts | J32: ='Diagnostic - start'!J32 -> FALSE | K32: =IF(NOT(ISBLANK(F32)),1,IF(NOT(ISBLANK(G32)),2,IF(NOT(ISBLANK(H32)),3,IF(NOT(ISBLANK(I32)),4)))) -> FALSE
C33: ='Diagnostic - start'!C33:C36 -> 7. Operations and processes | D33: ='Diagnostic - start'!D33 -> 7.1 | E33: ='Diagnostic - start'!E33 -> Operations planning: processes and operations mapped out and documented to ensure risks and contingencies identified | J33: ='Diagnostic - start'!J33 -> FALSE | K33: =IF(NOT(ISBLANK(F33)),1,IF(NOT(ISBLANK(G33)),2,IF(NOT(ISBLANK(H33)),3,IF(NOT(ISBLANK(I33)),4)))) -> FALSE
D34: ='Diagnostic - start'!D34 -> 7.2 | E34: ='Diagnostic - start'!E34 -> Data system: IT systems, tools and collection of data systems in place, including data security and compliance | J34: ='Diagnostic - start'!J34 -> FALSE | K34: =IF(NOT(ISBLANK(F34)),1,IF(NOT(ISBLANK(G34)),2,IF(NOT(ISBLANK(H34)),3,IF(NOT(ISBLANK(I34)),4)))) -> FALSE
D35: ='Diagnostic - start'!D35 -> 7.3 | E35: ='Diagnostic - start'!E35 -> Tactical performance management: staff reviews, customer feedback and analyses data to make adjustments to delivery | J35: ='Diagnostic - start'!J35 -> FALSE | K35: =IF(NOT(ISBLANK(F35)),1,IF(NOT(ISBLANK(G35)),2,IF(NOT(ISBLANK(H35)),3,IF(NOT(ISBLANK(I35)),4)))) -> FALSE
D36: ='Diagnostic - start'!D36 -> 7.4 | E36: ='Diagnostic - start'!E36 -> Strategic performance management: performance data created and disseminated in line with KPIs which can be used by managers to make decisions in order to improve outcomes of product/services | J36: ='Diagnostic - start'!J36 -> FALSE | K36: =IF(NOT(ISBLANK(F36)),1,IF(NOT(ISBLANK(G36)),2,IF(NOT(ISBLANK(H36)),3,IF(NOT(ISBLANK(I36)),4)))) -> FALSE
B37: ='Diagnostic - start'!B37:B46 -> Plan | C37: ='Diagnostic - start'!C37:C39 -> 8. Growth Plan | D37: ='Diagnostic - start'!D37 -> 8.1 | E37: ='Diagnostic - start'!E37 -> Business / revenue model: proven and scalable demonstrated by significant track record of sales and impact | J37: ='Diagnostic - start'!J37 -> FALSE | K37: =IF(NOT(ISBLANK(F37)),1,IF(NOT(ISBLANK(G37)),2,IF(NOT(ISBLANK(H37)),3,IF(NOT(ISBLANK(I37)),4)))) -> FALSE
D38: ='Diagnostic - start'!D38 -> 8.2 | E38: ='Diagnostic - start'!E38 -> Growth plan: robust, thoughtful growth plan in place and is being operationalised | J38: ='Diagnostic - start'!J38 -> FALSE | K38: =IF(NOT(ISBLANK(F38)),1,IF(NOT(ISBLANK(G38)),2,IF(NOT(ISBLANK(H38)),3,IF(NOT(ISBLANK(I38)),4)))) -> FALSE
D39: ='Diagnostic - start'!D39 -> 8.3 | E39: ='Diagnostic - start'!E39 -> Growth plan communication: across team in a durable medium | J39: ='Diagnostic - start'!J39 -> FALSE | K39: =IF(NOT(ISBLANK(F39)),1,IF(NOT(ISBLANK(G39)),2,IF(NOT(ISBLANK(H39)),3,IF(NOT(ISBLANK(I39)),4)))) -> FALSE
D40: ='Diagnostic - start'!D40 -> 8.4 | E40: ='Diagnostic - start'!E40 -> Market influence and positioning: understands the organisation's role within the wider sector and has a desire and ability to become a prominent change-maker and influential at a policy level | J40: ='Diagnostic - start'!J40 -> FALSE | K40: =IF(NOT(ISBLANK(F40)),1,IF(NOT(ISBLANK(G40)),2,IF(NOT(ISBLANK(H40)),3,IF(NOT(ISBLANK(I40)),4)))) -> FALSE
...

Sheet Distance travelled
A1: Ventures Support framework - distance travelled
F3: 1 | G3: 3 | H3: =G3-F3 -> 2
C4: ='Diagnostic - start'!C4 -> Support pillar | E4: ='Diagnostic - start'!E4 -> Support objectives | F4: Pillar score start | G4: Pillar score end | H4: Distance travelled | I4: Pillar average
B5: ='Diagnostic - start'!B5:B14 -> Person / People | C5: ='Diagnostic - start'!C5:C7 -> 1. Leadership | D5: ='Diagnostic - start'!D5 -> 1.1 | E5: ='Diagnostic - start'!E5 -> CEO strategic leadership: decision making reflects understanding of external big picture and alignment with mission | F5: ='Diagnostic - start'!J5 -> FALSE | G5: ='Diagnostic - end'!K5 -> FALSE | H5: =G5-F5 -> 0 | I5: =AVERAGE(H5:H8) -> 0
D6: ='Diagnostic - start'!D6 -> 1.2 | E6: ='Diagnostic - start'!E6 -> CEO performance management leadership: strong self-awareness, ability to drive performance management and build learning organisation, informed by a command of detail across all areas of business | F6: ='Diagnostic - start'!J6 -> FALSE | G6: ='Diagnostic - end'!K6 -> FALSE | H6: =G6-F6 -> 0
D7: ='Diagnostic - start'!D7 -> 1.3 | E7: ='Diagnostic - start'!E7 -> Resource allocation: ability to allocate existing resources and investment in future resources (human and financial) against core outcome-generating activities | F7: ='Diagnostic - start'!J7 -> FALSE | G7: ='Diagnostic - end'!K7 -> FALSE | H7: =G7-F7 -> 0
D8: ='Diagnostic - start'!D8 -> 1.4 | E8: ='Diagnostic - start'!E8 -> Sector knowledge: deep understanding of the landscape of the sector in which they operate (for example key policies, polcy makers, influential organisations and bodies) | F8: ='Diagnostic - start'!J8 -> FALSE | G8: ='Diagnostic - end'!K8 -> FALSE | H8: =G8-F8 -> 0
C9: ='Diagnostic - start'!C9:C12 -> 2. Team Building | D9: ='Diagnostic - start'!D9 -> 2.1 | E9: ='Diagnostic - start'!E9 -> Key functional competencies in place: finance, operations, sales, impact, HR, communications, etc | F9: ='Diagnostic - start'!J9 -> FALSE | G9: ='Diagnostic - end'!K9 -> FALSE | H9: =G9-F9 -> 0 | I9: =AVERAGE(H9:H12) -> 0
D10: ='Diagnostic - start'!D10 -> 2.2 | E10: ='Diagnostic - start'!E10 -> SMT: team contains a broad mix of skills, is of an appropriate size relative to the company's maturity and has the capability to deliver and work well as a team | F10: ='Diagnostic - start'!J10 -> FALSE | G10: ='Diagnostic - end'!K10 -> FALSE | H10: =G10-F10 -> 0
D11: ='Diagnostic - start'!D11 -> 2.3 | E11: ='Diagnostic - start'!E11 -> Resourcing: sufficiently resourced to deliver product/service without bottleneck/over resourcing; roles and responsibilities documented and clearly communicated across organisation | F11: ='Diagnostic - start'!J11 -> FALSE | G11: ='Diagnostic - end'!K11 -> FALSE | H11: =G11-F11 -> 0
D12: ='Diagnostic - start'!D12 -> 2.4 | E12: ='Diagnostic - start'!E12 -> Team development: provision for team development and training in place | F12: ='Diagnostic - start'!J12 -> FALSE | G12: ='Diagnostic - end'!K12 -> FALSE | H12: =G12-F12 -> 0
C13: ='Diagnostic - start'!C13:C14 -> 3. Governance | D13: ='Diagnostic - start'!D13 -> 3.1 | E13: ='Diagnostic - start'!E13 -> Overall governance: governance is in place, is supporting the Management Team and is of an appropriate size for scale of business and growth plans - including formal and informal advisory roles | F13: ='Diagnostic - start'!J13 -> FALSE | G13: ='Diagnostic - end'!K13 -> FALSE | H13: =G13-F13 -> 0 | I13: =AVERAGE(H13:H14) -> 0
D14: ='Diagnostic - start'!D14 -> 3.2 | E14: ='Diagnostic - start'!E14 -> Board: oversight and accountability. Oversight of strategic and organisational effectiveness, holding the CEO to account and providing fiduciary oversight | F14: ='Diagnostic - start'!J14 -> FALSE | G14: ='Diagnostic - end'!K14 -> FALSE | H14: =G14-F14 -> 0
B15: ='Diagnostic - start'!B15:B25 -> Proposition | C15: ='Diagnostic - start'!C15:C19 -> 4. Social Impact | D15: ='Diagnostic - start'!D15 -> 4.1 | E15: ='Diagnostic - start'!E15 -> Theory of change: is developed, understood and clearly communicated | F15: ='Diagnostic - start'!J15 -> FALSE | G15: ='Diagnostic - end'!K15 -> FALSE | H15: =G15-F15 -> 0 | I15: =AVERAGE(H15:H19) -> 0
D16: ='Diagnostic - start'!D16 -> 4.2 | E16: ='Diagnostic - start'!E16 -> Key metrics: these are clearly articulated and aid in demonstrating that the venture is achieving its mission | F16: ='Diagnostic - start'!J16 -> FALSE | G16: ='Diagnostic - end'!K16 -> FALSE | H16: =G16-F16 -> 0
D17: ='Diagnostic - start'!D17 -> 4.3 | E17: ='Diagnostic - start'!E17 -> Data: appropriate impact indicator data has been identified and is being collected against key metrics | F17: ='Diagnostic - start'!J17 -> FALSE | G17: ='Diagnostic - end'!K17 -> FALSE | H17: =G17-F17 -> 0
D18: ='Diagnostic - start'!D18 -> 4.4 | E18: ='Diagnostic - start'!E18 -> Reporting: social impact is being reported, is disseminated publicly and has an element of external validation | F18: ='Diagnostic - start'!J18 -> FALSE | G18: ='Diagnostic - end'!K18 -> FALSE | H18: =G18-F18 -> 0
D19: ='Diagnostic - start'!D19 -> 4.5 | E19: ='Diagnostic - start'!E19 -> Social lock: social impact is 'locked' into business' structure for the long term | F19: ='Diagnostic - start'!J19 -> FALSE | G19: ='Diagnostic - end'!K19 -> FALSE | H19: =G19-F19 -> 0
C20: ='Diagnostic - start'!C20:C25 -> 5. Sales Planning | D20: ='Diagnostic - start'!D20 -> 5.1 | E20: ='Diagnostic - start'!E20 -> Value proposition: ability to articulate value proposition, target customers and routes to market | F20: ='Diagnostic - start'!J20 -> FALSE | G20: ='Diagnostic - end'!K20 -> FALSE | H20: =G20-F20 -> 0 | I20: =AVERAGE(H20:H26) -> 0
D21: ='Diagnostic - start'!D21 -> 5.2 | E21: ='Diagnostic - start'!E21 -> Market knowledge: understanding of market and price sensitivities | F21: ='Diagnostic - start'!J21 -> FALSE | G21: ='Diagnostic - end'!K21 -> FALSE | H21: =G21-F21 -> 0
D22: ='Diagnostic - start'!D22 -> 5.3 | E22: ='Diagnostic - start'!E22 -> Network building: well-known and well positioned in the sector. Has to ability to build useful connections and grow their network, forming appropriate partnerships | F22: ='Diagnostic - start'!J22 -> FALSE | G22: ='Diagnostic - end'!K22 -> FALSE | H22: =G22-F22 -> 0
D23: ='Diagnostic - start'!D23 -> 5.4 | E23: ='Diagnostic - start'!E23 -> Understanding of sales funnel: conversion rates, customer acquisition costs and lead time known and documented | F23: ='Diagnostic - start'!J23 -> FALSE | G23: ='Diagnostic - end'!K23 -> FALSE | H23: =G23-F23 -> 0
D24: ='Diagnostic - start'!D24 -> 5.5 | E24: ='Diagnostic - start'!E24 -> Forecasting: ability to forecast sales growth and resource requirements for growth | F24: ='Diagnostic - start'!J24 -> FALSE | G24: ='Diagnostic - end'!K24 -> FALSE | H24: =G24-F24 -> 0
D25: ='Diagnostic - start'!D25 -> 5.6 | E25: ='Diagnostic - start'!E25 -> Sales process: is in place and operational across teams / people in organisation | F25: ='Diagnostic - start'!J25 -> FALSE | G25: ='Diagnostic - end'!K25 -> FALSE | H25: =G25-F25 -> 0
D26: ='Diagnostic - start'!D26 -> 5.7 | E26: ='Diagnostic - start'!E26 -> Comms and marketing: presence and efficacy of comms and marketing strategy | F26: ='Diagnostic - start'!J26 -> FALSE | G26: ='Diagnostic - end'!K26 -> FALSE | H26: =G26-F26 -> 0
B27: ='Diagnostic - start'!B27:B36 -> Performance | C27: ='Diagnostic - start'!C27:C32 -> 6. Legals and reporting | D27: ='Diagnostic - start'!D27 -> 6.1 | E27: ='Diagnostic - start'!E27 -> Incorporation: business incorporated with appropriate legal structure for growth plans | F27: ='Diagnostic - start'!J27 -> FALSE | G27: ='Diagnostic - end'!K27 -> FALSE | H27: =G27-F27 -> 0 | I27: =AVERAGE(H27:H32) -> 0
D28: ='Diagnostic - start'!D28 -> 6.2 | E28: ='Diagnostic - start'!E28 -> Partner agreements: any appropriate partner agreements and service level contracts in place | F28: ='Diagnostic - start'!J28 -> FALSE | G28: ='Diagnostic - end'!K28 -> FALSE | H28: =G28-F28 -> 0
D29: ='Diagnostic - start'!D29 -> 6.3 | E29: ='Diagnostic - start'!E29 -> Intellectual Property: any IP corrected documented and registered | F29: ='Diagnostic - start'!J29 -> FALSE | G29: ='Diagnostic - end'!K29 -> FALSE | H29: =G29-F29 -> 0
D30: ='Diagnostic - start'!D30 -> 6.4 | E30: ='Diagnostic - start'!E30 -> Legal understanding: knowledge of all relevant legal requirements and procedures in place to ensure compliance (particularly data protection) | F30: ='Diagnostic - start'!J30 -> FALSE | G30: ='Diagnostic - end'!K30 -> FALSE | H30: =G30-F30 -> 0
D31: ='Diagnostic - start'!D31 -> 6.5 | E31: ='Diagnostic - start'!E31 -> Accountability: relevant HR processes being used by managers to hold staff accountable to performance standards | F31: ='Diagnostic - start'!J31 -> FALSE | G31: ='Diagnostic - end'!K31 -> FALSE | H31: =G31-F31 -> 0
D32: ='Diagnostic - start'!D32 -> 6.6 | E32: ='Diagnostic - start'!E32 -> Financial reporting: submission of externally validated Accounts to company registrar; production of accurate financial statements and quarterly Management Information/Accounts | F32: ='Diagnostic - start'!J32 -> FALSE | G32: ='Diagnostic - end'!K32 -> FALSE | H32: =G32-F32 -> 0
C33: ='Diagnostic - start'!C33:C36 -> 7. Operations and processes | D33: ='Diagnostic - start'!D33 -> 7.1 | E33: ='Diagnostic - start'!E33 -> Operations planning: processes and operations mapped out and documented to ensure risks and contingencies identified | F33: ='Diagnostic - start'!J33 -> FALSE | G33: ='Diagnostic - end'!K33 -> FALSE | H33: =G33-F33 -> 0 | I33: =AVERAGE(H33:H36) -> 0
D34: ='Diagnostic - start'!D34 -> 7.2 | E34: ='Diagnostic - start'!E34 -> Data system: IT systems, tools and collection of data systems in place, including data security and compliance | F34: ='Diagnostic - start'!J34 -> FALSE | G34: ='Diagnostic - end'!K34 -> FALSE | H34: =G34-F34 -> 0
D35: ='Diagnostic - start'!D35 -> 7.3 | E35: ='Diagnostic - start'!E35 -> Tactical performance management: staff reviews, customer feedback and analyses data to make adjustments to delivery | F35: ='Diagnostic - start'!J35 -> FALSE | G35: ='Diagnostic - end'!K35 -> FALSE | H35: =G35-F35 -> 0
D36: ='Diagnostic - start'!D36 -> 7.4 | E36: ='Diagnostic - start'!E36 -> Strategic performance management: performance data created and disseminated in line with KPIs which can be used by managers to make decisions in order to improve outcomes of product/services | F36: ='Diagnostic - start'!J36 -> FALSE | G36: ='Diagnostic - end'!K36 -> FALSE | H36: =G36-F36 -> 0
B37: ='Diagnostic - start'!B37:B46 -> Plan | C37: ='Diagnostic - start'!C37:C39 -> 8. Growth Plan | D37: ='Diagnostic - start'!D37 -> 8.1 | E37: ='Diagnostic - start'!E37 -> Business / revenue model: proven and scalable demonstrated by significant track record of sales and impact | F37: ='Diagnostic - start'!J37 -> FALSE | G37: ='Diagnostic - end'!K37 -> FALSE | H37: =G37-F37 -> 0 | I37: =AVERAGE(H37:H40) -> 0
D38: ='Diagnostic - start'!D38 -> 8.2 | E38: ='Diagnostic - start'!E38 -> Growth plan: robust, thoughtful growth plan in place and is being operationalised | F38: ='Diagnostic - start'!J38 -> FALSE | G38: ='Diagnostic - end'!K38 -> FALSE | H38: =G38-F38 -> 0
D39: ='Diagnostic - start'!D39 -> 8.3 | E39: ='Diagnostic - start'!E39 -> Growth plan communication: across team in a durable medium | F39: ='Diagnostic - start'!J39 -> FALSE | G39: ='Diagnostic - end'!K39 -> FALSE | H39: =G39-F39 -> 0
D40: ='Diagnostic - start'!D40 -> 8.4 | E40: ='Diagnostic - start'!E40 -> Market influence and positioning: understands the organisation's role within the wider sector and has a desire and ability to become a prominent change-maker and influential at a policy level | F40: ='Diagnostic - start'!J40 -> FALSE | G40: ='Diagnostic - end'!K40 -> FALSE | H40: =G40-F40 -> 0
C41: ='Diagnostic - start'!C41:C46 -> 9. Financial Modelling | D41: ='Diagnostic - start'!D41 -> 9.1 | E41: ='Diagnostic - start'!E41 -> Modelling for future growth: financial model in place that details growth plan and projections | F41: ='Diagnostic - start'!J41 -> FALSE | G41: ='Diagnostic - end'!K41 -> FALSE | H41: =G41-F41 -> 0 | I41: =AVERAGE(H41:H46) -> 0
...
