Workbook

Sheet Tracking
B2: TOTAL | C2: =COUNTIF(C5:C57,"YES") -> 53 | D2: =COUNTIF(D5:D57,"YES") -> 15 | E2: =COUNTIF(E5:E57,"YES") -> 13 | F2: =COUNTIF(F5:F57,"YES") -> 13 | G2: =COUNTIF(G5:G57,"YES") -> 3
B4: Venture name | C4: Registered? | D4: Accepted to attend workshop 1? | E4: Accepted to attend workshop 2? | F4: Completed Design Form? | G4: Started collection?
B5: Access Plymouth Ltd | C5: YES | D5: =IF(ISNUMBER(MATCH(B5,'Workshop Tracking'!$C$3:$C$31,0)),"YES","") | E5: =IF(ISNUMBER(MATCH(B5,'Workshop Tracking'!$G$3:$G$31,0)),"YES","") -> YES | F5: YES
B6: Albatross Arts CIC | C6: YES | D6: =IF(ISNUMBER(MATCH(B6,'Workshop Tracking'!$C$3:$C$31,0)),"YES","") | E6: =IF(ISNUMBER(MATCH(B6,'Workshop Tracking'!$G$3:$G$31,0)),"YES","") -> YES
B7: Articulate Cultural Trust | C7: YES | D7: =IF(ISNUMBER(MATCH(B7,'Workshop Tracking'!$C$3:$C$31,0)),"YES","") | E7: =IF(ISNUMBER(MATCH(B7,'Workshop Tracking'!$G$3:$G$31,0)),"YES","")
B8: Before I Go Solutions | C8: YES | D8: =IF(ISNUMBER(MATCH(B8,'Workshop Tracking'!$C$3:$C$31,0)),"YES","") -> YES | E8: =IF(ISNUMBER(MATCH(B8,'Workshop Tracking'!$G$3:$G$31,0)),"YES","")
B9: Bermondsey community kitchen | C9: YES | D9: =IF(ISNUMBER(MATCH(B9,'Workshop Tracking'!$C$3:$C$31,0)),"YES","") | E9: =IF(ISNUMBER(MATCH(B9,'Workshop Tracking'!$G$3:$G$31,0)),"YES","")
B10: Brightbox | C10: YES | D10: =IF(ISNUMBER(MATCH(B10,'Workshop Tracking'!$C$3:$C$31,0)),"YES","") | E10: =IF(ISNUMBER(MATCH(B10,'Workshop Tracking'!$G$3:$G$31,0)),"YES","") -> YES | F10: YES
B11: Bubba's Contact Centre | C11: YES | D11: =IF(ISNUMBER(MATCH(B11,'Workshop Tracking'!$C$3:$C$31,0)),"YES","") | E11: =IF(ISNUMBER(MATCH(B11,'Workshop Tracking'!$G$3:$G$31,0)),"YES","")
B12: BuddyHub CIC | C12: YES | D12: =IF(ISNUMBER(MATCH(B12,'Workshop Tracking'!$C$3:$C$31,0)),"YES","") | E12: =IF(ISNUMBER(MATCH(B12,'Workshop Tracking'!$G$3:$G$31,0)),"YES","") -> YES
B13: Choirs For Good | C13: YES | D13: =IF(ISNUMBER(MATCH(B13,'Workshop Tracking'!$C$3:$C$31,0)),"YES","") -> YES | E13: =IF(ISNUMBER(MATCH(B13,'Workshop Tracking'!$G$3:$G$31,0)),"YES","") | F13: YES
B14: Circle Of | C14: YES | D14: =IF(ISNUMBER(MATCH(B14,'Workshop Tracking'!$C$3:$C$31,0)),"YES","") | E14: =IF(ISNUMBER(MATCH(B14,'Workshop Tracking'!$G$3:$G$31,0)),"YES","")
B15: Creatful CIC | C15: YES | D15: =IF(ISNUMBER(MATCH(B15,'Workshop Tracking'!$C$3:$C$31,0)),"YES","") | E15: =IF(ISNUMBER(MATCH(B15,'Workshop Tracking'!$G$3:$G$31,0)),"YES","")
B16: Disability4Sport CIC | C16: YES | D16: =IF(ISNUMBER(MATCH(B16,'Workshop Tracking'!$C$3:$C$31,0)),"YES","") | E16: =IF(ISNUMBER(MATCH(B16,'Workshop Tracking'!$G$3:$G$31,0)),"YES","")
B17: East Brighton Food Cooperative | C17: YES | D17: =IF(ISNUMBER(MATCH(B17,'Workshop Tracking'!$C$3:$C$31,0)),"YES","") | E17: =IF(ISNUMBER(MATCH(B17,'Workshop Tracking'!$G$3:$G$31,0)),"YES","")
B18: Foxhole Community Garden | C18: YES | D18: =IF(ISNUMBER(MATCH(B18,'Workshop Tracking'!$C$3:$C$31,0)),"YES","") | E18: =IF(ISNUMBER(MATCH(B18,'Workshop Tracking'!$G$3:$G$31,0)),"YES","")
B19: Girls Assemble UK CIC | C19: YES | D19: =IF(ISNUMBER(MATCH(B19,'Workshop Tracking'!$C$3:$C$31,0)),"YES","") | E19: =IF(ISNUMBER(MATCH(B19,'Workshop Tracking'!$G$3:$G$31,0)),"YES","") -> YES
B20: Glasgow Girls Club CIC | C20: YES | D20: =IF(ISNUMBER(MATCH(B20,'Workshop Tracking'!$C$3:$C$31,0)),"YES","") -> YES | E20: =IF(ISNUMBER(MATCH(B20,'Workshop Tracking'!$G$3:$G$31,0)),"YES","") -> YES
B21: Good Boost | C21: YES | D21: =IF(ISNUMBER(MATCH(B21,'Workshop Tracking'!$C$3:$C$31,0)),"YES","") | E21: =IF(ISNUMBER(MATCH(B21,'Workshop Tracking'!$G$3:$G$31,0)),"YES","") | F21: YES
B22: Growing Older | C22: YES | D22: =IF(ISNUMBER(MATCH(B22,'Workshop Tracking'!$C$3:$C$31,0)),"YES","") -> YES | E22: =IF(ISNUMBER(MATCH(B22,'Workshop Tracking'!$G$3:$G$31,0)),"YES","")
B23: Hearing Partners CIC | C23: YES | D23: =IF(ISNUMBER(MATCH(B23,'Workshop Tracking'!$C$3:$C$31,0)),"YES","") -> YES | E23: =IF(ISNUMBER(MATCH(B23,'Workshop Tracking'!$G$3:$G$31,0)),"YES","") -> YES
B24: i-passuk | C24: YES | D24: =IF(ISNUMBER(MATCH(B24,'Workshop Tracking'!$C$3:$C$31,0)),"YES","") | E24: =IF(ISNUMBER(MATCH(B24,'Workshop Tracking'!$G$3:$G$31,0)),"YES","")
B25: IASSISTNI | C25: YES | D25: =IF(ISNUMBER(MATCH(B25,'Workshop Tracking'!$C$3:$C$31,0)),"YES","") | E25: =IF(ISNUMBER(MATCH(B25,'Workshop Tracking'!$G$3:$G$31,0)),"YES","")
B26: KiActiv | C26: YES | D26: =IF(ISNUMBER(MATCH(B26,'Workshop Tracking'!$C$3:$C$31,0)),"YES","") | E26: =IF(ISNUMBER(MATCH(B26,'Workshop Tracking'!$G$3:$G$31,0)),"YES","")
B27: Life Transitions Service | C27: YES | D27: =IF(ISNUMBER(MATCH(B27,'Workshop Tracking'!$C$3:$C$31,0)),"YES","") | E27: =IF(ISNUMBER(MATCH(B27,'Workshop Tracking'!$G$3:$G$31,0)),"YES","")
B28: Local Treasures | C28: YES | D28: =IF(ISNUMBER(MATCH(B28,'Workshop Tracking'!$C$3:$C$31,0)),"YES","") | E28: =IF(ISNUMBER(MATCH(B28,'Workshop Tracking'!$G$3:$G$31,0)),"YES","")
B29: MediprospectsAI Limited | C29: YES | D29: =IF(ISNUMBER(MATCH(B29,'Workshop Tracking'!$C$3:$C$31,0)),"YES","") | E29: =IF(ISNUMBER(MATCH(B29,'Workshop Tracking'!$G$3:$G$31,0)),"YES","") -> YES
B30: MorphFit Gentle Movement Project | C30: YES | D30: =IF(ISNUMBER(MATCH(B30,'Workshop Tracking'!$C$3:$C$31,0)),"YES","") | E30: =IF(ISNUMBER(MATCH(B30,'Workshop Tracking'!$G$3:$G$31,0)),"YES","")
B31: Musica Music and Wellbeing CIC | C31: YES | D31: =IF(ISNUMBER(MATCH(B31,'Workshop Tracking'!$C$3:$C$31,0)),"YES","") -> YES | E31: =IF(ISNUMBER(MATCH(B31,'Workshop Tracking'!$G$3:$G$31,0)),"YES","") | F31: YES
B32: New Ethos Nottingham 2 CIC | C32: YES | D32: =IF(ISNUMBER(MATCH(B32,'Workshop Tracking'!$C$3:$C$31,0)),"YES","") | E32: =IF(ISNUMBER(MATCH(B32,'Workshop Tracking'!$G$3:$G$31,0)),"YES","")
B33: Next Chapter NW CIC | C33: YES | D33: =IF(ISNUMBER(MATCH(B33,'Workshop Tracking'!$C$3:$C$31,0)),"YES","") | E33: =IF(ISNUMBER(MATCH(B33,'Workshop Tracking'!$G$3:$G$31,0)),"YES","") | F33: YES
B34: NorthPoint | C34: YES | D34: =IF(ISNUMBER(MATCH(B34,'Workshop Tracking'!$C$3:$C$31,0)),"YES","") -> YES | E34: =IF(ISNUMBER(MATCH(B34,'Workshop Tracking'!$G$3:$G$31,0)),"YES","") -> YES
B35: Offploy CIC | C35: YES | D35: =IF(ISNUMBER(MATCH(B35,'Workshop Tracking'!$C$3:$C$31,0)),"YES","") -> YES | E35: =IF(ISNUMBER(MATCH(B35,'Workshop Tracking'!$G$3:$G$31,0)),"YES","")
B36: Paige | C36: YES | D36: =IF(ISNUMBER(MATCH(B36,'Workshop Tracking'!$C$3:$C$31,0)),"YES","") | E36: =IF(ISNUMBER(MATCH(B36,'Workshop Tracking'!$G$3:$G$31,0)),"YES","")
B37: Pathway CTM | C37: YES | D37: =IF(ISNUMBER(MATCH(B37,'Workshop Tracking'!$C$3:$C$31,0)),"YES","") | E37: =IF(ISNUMBER(MATCH(B37,'Workshop Tracking'!$G$3:$G$31,0)),"YES","") -> YES
B38: People Speak Up | C38: YES | D38: =IF(ISNUMBER(MATCH(B38,'Workshop Tracking'!$C$3:$C$31,0)),"YES","") -> YES | E38: =IF(ISNUMBER(MATCH(B38,'Workshop Tracking'!$G$3:$G$31,0)),"YES","") -> YES | F38: YES
B39: Real-Youth | C39: YES | D39: =IF(ISNUMBER(MATCH(B39,'Workshop Tracking'!$C$3:$C$31,0)),"YES","") | E39: =IF(ISNUMBER(MATCH(B39,'Workshop Tracking'!$G$3:$G$31,0)),"YES","") | F39: YES | G39: YES
B40: ReMade Wigan CIC | C40: YES | D40: =IF(ISNUMBER(MATCH(B40,'Workshop Tracking'!$C$3:$C$31,0)),"YES","") | E40: =IF(ISNUMBER(MATCH(B40,'Workshop Tracking'!$G$3:$G$31,0)),"YES","") | F40: YES
B41: Shine Public Health | C41: YES | D41: =IF(ISNUMBER(MATCH(B41,'Workshop Tracking'!$C$3:$C$31,0)),"YES","") -> YES | E41: =IF(ISNUMBER(MATCH(B41,'Workshop Tracking'!$G$3:$G$31,0)),"YES","")
B42: Skate of Mind | C42: YES | D42: =IF(ISNUMBER(MATCH(B42,'Workshop Tracking'!$C$3:$C$31,0)),"YES","") | E42: =IF(ISNUMBER(MATCH(B42,'Workshop Tracking'!$G$3:$G$31,0)),"YES","")
...

Sheet Register
A1: ID | B1: Start time | C1: Completion time | D1: Email | E1: Column1 | F1: What is the name of your venture? | G1: What is your name? | H1: What is your email address? | I1: What is your role at your venture?​ | J1: How many beneficiaries do you work with on average in month? | K1: How long do you typically work with an individual for? | L1: How often do you work with each beneficiary? | M1: What are the key outcome areas of your work? Select maximum 3 outcomes. | N1: How long has your venture been operational? | O1: How many full-time employees does your venture currently employ? | P1: How many part-time employees does your venture currently employ?
A2: 3 | B2: 44712.376 | C2: 44712.377 | D2: anonymous | F2: Local Treasures | G2: Sarah Heyworth | H2: sarah@localtreasures.me | I2: Director | J2: Between 50 and 100 | K2: More than 12 months | L2: As required, some need more support than others | M2: Employment; | N2: I’ve been trading for more than a year | O2: 5 | P2: 1
A3: 4 | B3: 44712.633 | C3: 44712.634 | D3: anonymous | F3: Albatross Arts CIC | G3: ALEX MCEWAN | H3: hello@albatrossarts.org | I3: Creative Director / Founder | J3: Between 25 and 50 | K3: Up to a month | L3: Weekly | M3: Wellbeing;Mental health;Loneliness and social isolation; | N3: I’ve been trading for more than a year | O3: 0 | P3: 4
A4: 5 | B4: 44712.782 | C4: 44712.782 | D4: anonymous | F4: ReMade Wigan CIC | G4: Alice Coren | H4: hello@remadewigan.co.uk | I4: Director | J4: Between 10 and 25 | K4: 6 - 12 months | L4: Weekly | M4: Mental health;Confidence;Loneliness and social isolation; | N4: I’ve been trading for more than a year | O4: 1 | P4: 0
A5: 6 | B5: 44713.862 | C5: 44713.865 | D5: anonymous | F5: Utano Foundation | G5: Leocadia Foya | H5: leefoyabiz@gmail.com | I5: Founder, Programme Lead | J5: Between 10 and 25 | K5: Up to 3 months | L5: Weekly | M5: Digital Inclusion ;Loneliness and social isolation; | N5: I’ve been trading for more than a year | O5: 2 | P5: 1
A6: 7 | B6: 44713.888 | C6: 44713.889 | D6: anonymous | F6: Hearing Partners CIC | G6: Lorraine Gailey | H6: lorraine@hearingpartners.co.uk | I6: Director | J6: Between 10 and 25 | K6: Once | L6: Occassionally or one-off | M6: Wellbeing;Confidence;Loneliness and social isolation; | N6: I’ve been trading for less than a year | O6: 0 | P6: 3
A7: 8 | B7: 44718.508 | C7: 44718.51 | D7: anonymous | F7: Musica Music and Wellbeing CIC | G7: Rosie Mead | H7: rosanna@musica-music.co.uk | I7: CEO | J7: More than 100 | K7: Up to 6 months | L7: Monthly | M7: Wellbeing;Mental health;Loneliness and social isolation; | N7: I’ve been trading for more than a year | O7: 0 | P7: 2
A8: 9 | B8: 44718.55 | C8: 44718.551 | D8: anonymous | F8: Foxhole Community Garden | G8: Zoe jong | H8: Zoe@foxholecommunitygarden.org.uk | I8: Director | J8: Between 10 and 25 | K8: 6 - 12 months | L8: Weekly | M8: Wellbeing;Mental health;Loneliness and social isolation; | N8: I’ve been trading for more than a year | O8: 0 | P8: 2
A9: 10 | B9: 44718.59 | C9: 44718.591 | D9: anonymous | F9: KiActiv | G9: Tommy Parker | H9: tparker@kiactiv.com | I9: CEO | J9: More than 100 | K9: Up to 3 months | L9: 6 mentor sessions across 12-weeks, plus 24/7 technology access | M9: Wellbeing;Mental health;Physical health including long-term conditions; | N9: I’ve been trading for more than a year | O9: 5 | P9: 2
A10: 11 | B10: 44718.622 | C10: 44718.623 | D10: anonymous | F10: Shine Public Health | G10: Ronie Walters | H10: roniewalters@gmail.com | I10: Evaluation lead | J10: More than 100 | K10: More than 12 months | L10: Weekly | M10: Wellbeing;Loneliness and social isolation;Physical health including long-term conditions; | N10: I’ve been trading for less than a year | O10: 3 | P10: 0
A11: 12 | B11: 44718.749 | C11: 44718.75 | D11: anonymous | F11: Well bean machine with Active Forever | G11: Kelly Brougham | H11: Kelly@activefamiliesne.co.uk | I11: Director | J11: More than 100 | K11: Up to 6 months | L11: Weekly | M11: Wellbeing;Loneliness and social isolation;Physical health including long-term conditions; | N11: I’ve been trading for more than a year | O11: 6 | P11: 5
A12: 13 | B12: 44718.771 | C12: 44718.772 | D12: anonymous | F12: East Brighton Food Cooperative | G12: Bryan Coyle | H12: coyle.bryan@yahoo.com | I12: CEO | J12: More than 100 | K12: Up to 3 months | L12: Twice weekly | M12: Fresh meals ;Wellbeing;Loneliness and social isolation; | N12: I’ve been trading for more than a year | O12: 2 | P12: 0
A13: 14 | B13: 44718.875 | C13: 44718.876 | D13: anonymous | F13: Before I Go Solutions | G13: Jane Duncan Rogers | H13: jane@beforeigosolutions.com | I13: CEO | J13: Between 25 and 50 | K13: 6 - 12 months | L13: Weekly | M13: Getting their end of life plans done, and providing training to be able to help others do theirs ;Wellbeing;Confidence; | N13: I’ve been trading for more than a year | O13: 1 | P13: 4
... A58: 59 | B58: 44757.781 | C58: 44757.783 | D58: anonymous | F58: Paige | G58: Gregory Hargraves | H58: ghargraves04@outlook.com | I58: Founder & Head of Product Development | J58: Less than 10 | K58: Once | L58: Occassionally or one-off | M58: Productivity;Employment; | N58: I have an idea | O58: 2 | P58: 3

Sheet Workshop Tracking
A1: WORKSHOP 1 | E1: WORKSHOP 2
A3: Accepted | B3: lorraine@hearingpartners.co.uk | C3: =IFERROR(IF(A3="Accepted",INDEX(Table1[What is the name of your venture?],MATCH($B3,Table1[What is your email address?],0)),0),0) -> Hearing Partners CIC | E3: Accepted | F3: hello@albatrossarts.org | G3: =IFERROR(IF(E3="Accepted",INDEX(Table1[What is the name of your venture?],MATCH($F3,Table1[What is your email address?],0)),0),0) -> Albatross Arts CIC
A4: Accepted | B4: rosanna@musica-music.co.uk | C4: =IFERROR(IF(A4="Accepted",INDEX(Table1[What is the name of your venture?],MATCH($B4,Table1[What is your email address?],0)),0),0) -> Musica Music and Wellbeing CIC | E4: Accepted | F4: leefoyabiz@gmail.com | G4: =IFERROR(IF(E4="Accepted",INDEX(Table1[What is the name of your venture?],MATCH($F4,Table1[What is your email address?],0)),0),0) -> Utano Foundation
A5: Accepted | B5: roniewalters@gmail.com | C5: =IFERROR(IF(A5="Accepted",INDEX(Table1[What is the name of your venture?],MATCH($B5,Table1[What is your email address?],0)),0),0) -> Shine Public Health | E5: Accepted | F5: lorraine@hearingpartners.co.uk | G5: =IFERROR(IF(E5="Accepted",INDEX(Table1[What is the name of your venture?],MATCH($F5,Table1[What is your email address?],0)),0),0) -> Hearing Partners CIC
A6: Accepted | B6: Kelly@activefamiliesne.co.uk | C6: =IFERROR(IF(A6="Accepted",INDEX(Table1[What is the name of your venture?],MATCH($B6,Table1[What is your email address?],0)),0),0) -> Well bean machine with Active Forever | E6: Accepted | F6: Amy@glasgowgirlsclub.org | G6: =IFERROR(IF(E6="Accepted",INDEX(Table1[What is the name of your venture?],MATCH($F6,Table1[What is your email address?],0)),0),0) -> Glasgow Girls Club CIC
A7: Accepted | B7: jane@beforeigosolutions.com | C7: =IFERROR(IF(A7="Accepted",INDEX(Table1[What is the name of your venture?],MATCH($B7,Table1[What is your email address?],0)),0),0) -> Before I Go Solutions | E7: Accepted | F7: sophiamedine@gmail.com | G7: =IFERROR(IF(E7="Accepted",INDEX(Table1[What is the name of your venture?],MATCH($F7,Table1[What is your email address?],0)),0),0) -> Girls Assemble UK CIC
A8: Accepted | B8: Amy@glasgowgirlsclub.org | C8: =IFERROR(IF(A8="Accepted",INDEX(Table1[What is the name of your venture?],MATCH($B8,Table1[What is your email address?],0)),0),0) -> Glasgow Girls Club CIC | E8: Accepted | F8: elijah.kirby@northpointcare.co.uk | G8: =IFERROR(IF(E8="Accepted",INDEX(Table1[What is the name of your venture?],MATCH($F8,Table1[What is your email address?],0)),0),0) -> NorthPoint
A9: Accepted | B9: Lucy.holmes8@nhs.net | C9: =IFERROR(IF(A9="Accepted",INDEX(Table1[What is the name of your venture?],MATCH($B9,Table1[What is your email address?],0)),0),0) -> Wirral Cancer Prehabilitation Exercise Programme | E9: Accepted | F9: chris@pathwayctm.com | G9: =IFERROR(IF(E9="Accepted",INDEX(Table1[What is the name of your venture?],MATCH($F9,Table1[What is your email address?],0)),0),0) -> Pathway CTM
A10: Accepted | B10: isabel@lemonbalm.org.uk | C10: =IFERROR(IF(A10="Accepted",INDEX(Table1[What is the name of your venture?],MATCH($B10,Table1[What is your email address?],0)),0),0) -> Growing Older | E10: Accepted | F10: eshaw@peoplespeakup.co.uk | G10: =IFERROR(IF(E10="Accepted",INDEX(Table1[What is the name of your venture?],MATCH($F10,Table1[What is your email address?],0)),0),0) -> People Speak Up
A11: Accepted | B11: Jacob@offploy.org | C11: =IFERROR(IF(A11="Accepted",INDEX(Table1[What is the name of your venture?],MATCH($B11,Table1[What is your email address?],0)),0),0) -> Offploy CIC | E11: Accepted | F11: catherine@buddyhub.co.uk | G11: =IFERROR(IF(E11="Accepted",INDEX(Table1[What is the name of your venture?],MATCH($F11,Table1[What is your email address?],0)),0),0) -> BuddyHub CIC
A12: Accepted | B12: Jake@vibeyouth.co.uk | C12: =IFERROR(IF(A12="Accepted",INDEX(Table1[What is the name of your venture?],MATCH($B12,Table1[What is your email address?],0)),0),0) -> Vibe Youth CIC | E12: Accepted | F12: kristie@brightbox.org.uk | G12: =IFERROR(IF(E12="Accepted",INDEX(Table1[What is the name of your venture?],MATCH($F12,Table1[What is your email address?],0)),0),0) -> Brightbox
A13: Accepted | B13: alicia@choirsforgood.com | C13: =IFERROR(IF(A13="Accepted",INDEX(Table1[What is the name of your venture?],MATCH($B13,Table1[What is your email address?],0)),0),0) -> Choirs For Good | E13: Accepted | F13: admin@accessplymouth.co.uk | G13: =IFERROR(IF(E13="Accepted",INDEX(Table1[What is the name of your venture?],MATCH($F13,Table1[What is your email address?],0)),0),0) -> Access Plymouth Ltd
A14: Accepted | B14: eshaw@peoplespeakup.co.uk | C14: =IFERROR(IF(A14="Accepted",INDEX(Table1[What is the name of your venture?],MATCH($B14,Table1[What is your email address?],0)),0),0) -> People Speak Up | E14: Accepted | F14: Cleria Humphries | G14: Vida Active Club CIC
A15: Accepted | B15: weeseedsmeditations@gmail.com | C15: =IFERROR(IF(A15="Accepted",INDEX(Table1[What is the name of your venture?],MATCH($B15,Table1[What is your email address?],0)),0),0) -> Wee Seeds | E15: Accepted | F15: m.mahmudul@mediprospects.ai | G15: =IFERROR(IF(E15="Accepted",INDEX(Table1[What is the name of your venture?],MATCH($F15,Table1[What is your email address?],0)),0),0) -> MediprospectsAI Limited
A16: Accepted | B16: chiefexecutive@sudburyneighbourhoodcentre.co.uk | C16: =IFERROR(IF(A16="Accepted",INDEX(Table1[What is the name of your venture?],MATCH($B16,Table1[What is your email address?],0)),0),0) -> Sudbury Neighbourhood Centre | E16: Tentative | F16: lloydwhitely@newethosnottingham.org | G16: =IFERROR(IF(E16="Accepted",INDEX(Table1[What is the name of your venture?],MATCH($F16,Table1[What is your email address?],0)),0),0) -> 0
A17: Accepted | B17: elijah.kirby@northpointcare.co.uk | C17: =IFERROR(IF(A17="Accepted",INDEX(Table1[What is the name of your venture?],MATCH($B17,Table1[What is your email address?],0)),0),0) -> NorthPoint | E17: Declined | F17: rosanna@musica-music.co.uk | G17: =IFERROR(IF(E17="Accepted",INDEX(Table1[What is the name of your venture?],MATCH($F17,Table1[What is your email address?],0)),0),0) -> 0
A18: DECLINED | B18: chris@pathwayctm.com | C18: =IFERROR(IF(A18="Accepted",INDEX(Table1[What is the name of your venture?],MATCH($B18,Table1[What is your email address?],0)),0),0) -> 0 | E18: Unknown | F18: roniewalters@gmail.com | G18: =IFERROR(IF(E18="Accepted",INDEX(Table1[What is the name of your venture?],MATCH($F18,Table1[What is your email address?],0)),0),0) -> 0
A19: DECLINED | B19: catherine@buddyhub.co.uk | C19: =IFERROR(IF(A19="Accepted",INDEX(Table1[What is the name of your venture?],MATCH($B19,Table1[What is your email address?],0)),0),0) -> 0 | E19: Unknown | F19: Jacob@offploy.org | G19: =IFERROR(IF(E19="Accepted",INDEX(Table1[What is the name of your venture?],MATCH($F19,Table1[What is your email address?],0)),0),0) -> 0
A20: Unknown | B20: Zoe@foxholecommunitygarden.org.uk | C20: =IFERROR(IF(A20="Accepted",INDEX(Table1[What is the name of your venture?],MATCH($B20,Table1[What is your email address?],0)),0),0) -> 0 | E20: Unknown | F20: sonja@wellgroundedjobs.co.uk | G20: =IFERROR(IF(E20="Accepted",INDEX(Table1[What is the name of your venture?],MATCH($F20,Table1[What is your email address?],0)),0),0) -> 0
A21: Unknown | B21: tparker@kiactiv.com | C21: =IFERROR(IF(A21="Accepted",INDEX(Table1[What is the name of your venture?],MATCH($B21,Table1[What is your email address?],0)),0),0) -> 0 | E21: Unknown | F21: sarah@localtreasures.me | G21: =IFERROR(IF(E21="Accepted",INDEX(Table1[What is the name of your venture?],MATCH($F21,Table1[What is your email address?],0)),0),0) -> 0
A22: Unknown | B22: coyle.bryan@yahoo.com | C22: =IFERROR(IF(A22="Accepted",INDEX(Table1[What is the name of your venture?],MATCH($B22,Table1[What is your email address?],0)),0),0) -> 0 | E22: Unknown | F22: hello@remadewigan.co.uk | G22: =IFERROR(IF(E22="Accepted",INDEX(Table1[What is the name of your venture?],MATCH($F22,Table1[What is your email address?],0)),0),0) -> 0
A23: Unknown | B23: londonukuleleproject@gmail.com | C23: =IFERROR(IF(A23="Accepted",INDEX(Table1[What is the name of your venture?],MATCH($B23,Table1[What is your email address?],0)),0),0) -> 0 | E23: Unknown | F23: Zoe@foxholecommunitygarden.org.uk | G23: =IFERROR(IF(E23="Accepted",INDEX(Table1[What is the name of your venture?],MATCH($F23,Table1[What is your email address?],0)),0),0) -> 0
A24: Unknown | B24: wiseupworkshops@hotmail.com | C24: =IFERROR(IF(A24="Accepted",INDEX(Table1[What is the name of your venture?],MATCH($B24,Table1[What is your email address?],0)),0),0) -> 0 | E24: Unknown | F24: tparker@kiactiv.com | G24: =IFERROR(IF(E24="Accepted",INDEX(Table1[What is the name of your venture?],MATCH($F24,Table1[What is your email address?],0)),0),0) -> 0
A25: Unknown | B25: Treesandseasoutdooradventures@gmail.com | C25: =IFERROR(IF(A25="Accepted",INDEX(Table1[What is the name of your venture?],MATCH($B25,Table1[What is your email address?],0)),0),0) -> 0 | E25: Unknown | F25: Kelly@activefamiliesne.co.uk | G25: =IFERROR(IF(E25="Accepted",INDEX(Table1[What is the name of your venture?],MATCH($F25,Table1[What is your email address?],0)),0),0) -> 0
A26: Unknown | B26: sophiamedine@gmail.com | C26: =IFERROR(IF(A26="Accepted",INDEX(Table1[What is the name of your venture?],MATCH($B26,Table1[What is your email address?],0)),0),0) -> 0 | E26: Unknown | F26: coyle.bryan@yahoo.com | G26: =IFERROR(IF(E26="Accepted",INDEX(Table1[What is the name of your venture?],MATCH($F26,Table1[What is your email address?],0)),0),0) -> 0
... A35: Accepted | B35: sonja@wellgroundedjobs.co.uk | C35: =IFERROR(IF(A35="Accepted",INDEX(Table1[What is the name of your venture?],MATCH($B35,Table1[What is your email address?],0)),0),0) -> Well Grounded Jobs C.I.C | E35: Unknown | F35: isabel@lemonbalm.org.uk | G35: =IFERROR(IF(E35="Accepted",INDEX(Table1[What is the name of your venture?],MATCH($F35,Table1[What is your email address?],0)),0),0) -> 0
A36: Accepted | B36: info@lemonbalm.org.uk | C36: Growing Older | E36: Unknown | F36: eonacraig@articulatehub.com | G36: =IFERROR(IF(E36="Accepted",INDEX(Table1[What is the name of your venture?],MATCH($F36,Table1[What is your email address?],0)),0),0) -> 0
A37: Accepted | B37: Emily McCormick | C37: =IFERROR(IF(A37="Accepted",INDEX(Table1[What is the name of your venture?],MATCH($B37,Table1[What is your email address?],0)),0),0) -> 0 | E37: Unknown | F37: Jake@vibeyouth.co.uk | G37: =IFERROR(IF(E37="Accepted",INDEX(Table1[What is the name of your venture?],MATCH($F37,Table1[What is your email address?],0)),0),0) -> 0
A38: DECLINED | B38: Ben Wilkins | C38: =IFERROR(IF(A38="Accepted",INDEX(Table1[What is the name of your venture?],MATCH($B38,Table1[What is your email address?],0)),0),0) -> 0 | E38: Unknown | F38: alicia@choirsforgood.com | G38: =IFERROR(IF(E38="Accepted",INDEX(Table1[What is the name of your venture?],MATCH($F38,Table1[What is your email address?],0)),0),0) -> 0
A39: DECLINED | B39: steve.broome@eastsussex.gov.uk | C39: =IFERROR(IF(A39="Accepted",INDEX(Table1[What is the name of your venture?],MATCH($B39,Table1[What is your email address?],0)),0),0) -> 0 | E39: Unknown | F39: weeseedsmeditations@gmail.com | G39: =IFERROR(IF(E39="Accepted",INDEX(Table1[What is the name of your venture?],MATCH($F39,Table1[What is your email address?],0)),0),0) -> 0
A40: Unknown | B40: a.bitto@mediprospects.ai | C40: =IFERROR(IF(A40="Accepted",INDEX(Table1[What is the name of your venture?],MATCH($B40,Table1[What is your email address?],0)),0),0) -> 0 | E40: Unknown | F40: a.bitto@mediprospects.ai | G40: =IFERROR(IF(E40="Accepted",INDEX(Table1[What is the name of your venture?],MATCH($F40,Table1[What is your email address?],0)),0),0) -> 0
A41: Unknown | B41: h.bijoy@mediprospects.ai | C41: =IFERROR(IF(A41="Accepted",INDEX(Table1[What is the name of your venture?],MATCH($B41,Table1[What is your email address?],0)),0),0) -> 0 | E41: Unknown | F41: claire@nextchapternwcic.co.uk | G41: =IFERROR(IF(E41="Accepted",INDEX(Table1[What is the name of your venture?],MATCH($F41,Table1[What is your email address?],0)),0),0) -> 0
A42: Unknown | B42: james@walkthewalkcic.o.uk | C42: =IFERROR(IF(A42="Accepted",INDEX(Table1[What is the name of your venture?],MATCH($B42,Table1[What is your email address?],0)),0),0) -> 0 | E42: Unknown | F42: h.bijoy@mediprospects.ai | G42: =IFERROR(IF(E42="Accepted",INDEX(Table1[What is the name of your venture?],MATCH($F42,Table1[What is your email address?],0)),0),0) -> 0
A43: Unknown | B43: eilidhgardner1123@gmail.com | C43: =IFERROR(IF(A43="Accepted",INDEX(Table1[What is the name of your venture?],MATCH($B43,Table1[What is your email address?],0)),0),0) -> 0 | E43: Unknown | F43: a.das@mediprospects.ai | G43: =IFERROR(IF(E43="Accepted",INDEX(Table1[What is the name of your venture?],MATCH($F43,Table1[What is your email address?],0)),0),0) -> 0
A44: Unknown | B44: james@walkthewalkcic.co.uk | C44: =IFERROR(IF(A44="Accepted",INDEX(Table1[What is the name of your venture?],MATCH($B44,Table1[What is your email address?],0)),0),0) -> 0 | E44: Unknown | F44: james@walkthewalkcic.o.uk | G44: =IFERROR(IF(E44="Accepted",INDEX(Table1[What is the name of your venture?],MATCH($F44,Table1[What is your email address?],0)),0),0) -> 0
A45: Unknown | B45: manager@accessplymouth.co.uk | C45: =IFERROR(IF(A45="Accepted",INDEX(Table1[What is the name of your venture?],MATCH($B45,Table1[What is your email address?],0)),0),0) -> 0 | E45: Unknown | F45: steve.broome@eastsussex.gov.uk | G45: =IFERROR(IF(E45="Accepted",INDEX(Table1[What is the name of your venture?],MATCH($F45,Table1[What is your email address?],0)),0),0) -> 0
E46: Unknown | F46: ben.wilkins@goodboost.org | G46: =IFERROR(IF(E46="Accepted",INDEX(Table1[What is the name of your venture?],MATCH($F46,Table1[What is your email address?],0)),0),0) -> 0
E47: Unknown | F47: Gill@skateofmind.info | G47: =IFERROR(IF(E47="Accepted",INDEX(Table1[What is the name of your venture?],MATCH($F47,Table1[What is your email address?],0)),0),0) -> 0
E48: Unknown | F48: Info@Bermondseycommunitykitchen.co.uk | G48: =IFERROR(IF(E48="Accepted",INDEX(Table1[What is the name of your venture?],MATCH($F48,Table1[What is your email address?],0)),0),0) -> 0
E49: Unknown | F49: saint.sterling@real-services.co.uk | G49: =IFERROR(IF(E49="Accepted",INDEX(Table1[What is the name of your venture?],MATCH($F49,Table1[What is your email address?],0)),0),0) -> 0
...
