Workbook
Name BaseCaseIndicator: InpC!$J$7:$S$7
Name CASE_ACTIVE: InpC!$F$4
Name CHK_TOL: InpC!$F$41
Name InputRowTemplate: InpC!$E$55:$S$55
Name SMU: InpC!$F$44
Name TRK_TOL: InpC!$F$40

Sheet InpC
A1: =RIGHT(CELL("filename", A1), LEN(CELL("filename", A1)) - SEARCH("]", CELL("filename", A1))) & " - " & $F$3 -> InpC - Base case 1
K2: =IF(K4 = $F4, "q", "") -> q | L2: =IF(L4 = $F4, "q", "") | M2: =IF(M4 = $F4, "q", "") | O2: =IF(O4 = $F4, "q", "") | P2: =IF(P4 = $F4, "q", "") | Q2: =IF(Q4 = $F4, "q", "") | R2: =IF(R4 = $F4, "q", "")
F3: =INDEX(J3:S3,MATCH(F4,J4:S4)) -> Base case 1 | K3: Base case 1 | L3: Base case 2 | M3: Base case 3 | O3: Scenario 1 | P3: Scenario 2 | Q3: Scenario 3 | R3: Scenario 4
E4: Active scenario | F4: 1 | I4: =MATCH(F4, $J$4:$S$4) -> 2 | K4: 1 | L4: 2 | M4: 3 | O4: 5 | P4: 6 | Q4: 7 | R4: 8
E5: Comparison scenario | F5: 1 | I5: =MATCH(F5, $J$4:$S$4) -> 2
E6: Base case | F6: =INDEX(J6:S6,MATCH(F4,J4:S4,0)) -> 1 | I6: =MATCH(F6, $J$4:$S$4) -> 2 | K6: 1 | L6: 2 | M6: 3 | O6: 1 | P6: 1 | Q6: 2 | R6: 2
E7: Input differences | F7: =COUNTIF(I10:I38, "tu") -> 0 | K7: =IF(K6 = $F$6, "Base case", "") -> Base case | L7: =IF(L6 = $F$6, "Base case", "") | M7: =IF(M6 = $F$6, "Base case", "")
F9: Constant | G9: Unit | H9: Source
A11: TIMING ASSUMPTIONS
E13: First date of time rulers | F13: =IF( INDEX(J13:S13, $I$4) = "", INDEX(J13:R13, $I$6), INDEX(J13:S13, $I$4)) -> 44013 | G13: date | I13: {=IF( INDEX(J13:S13, I$5) = "", IF( INDEX(J13:S13, I$6) = F13, "vw", "tu"), IF(INDEX(J13:S13, I$5) = F13, "vw", "tu"))} -> vw | K13: 44013
E14: Annual year end date of first operating period | F14: =IF( INDEX(J14:S14, $I$4) = "", INDEX(J14:R14, $I$6), INDEX(J14:S14, $I$4)) -> 43921 | G14: date | I14: {=IF( INDEX(J14:S14, I$5) = "", IF( INDEX(J14:S14, I$6) = F14, "vw", "tu"), IF(INDEX(J14:S14, I$5) = F14, "vw", "tu"))} -> vw | K14: 43921
E15: Additional periods at start of operating timeline | F15: =IF( INDEX(J15:S15, $I$4) = "", INDEX(J15:R15, $I$6), INDEX(J15:S15, $I$4)) -> 2 | G15: periods | I15: {=IF( INDEX(J15:S15, I$5) = "", IF( INDEX(J15:S15, I$6) = F15, "vw", "tu"), IF(INDEX(J15:S15, I$5) = F15, "vw", "tu"))} -> vw | K15: 2
E16: Financial year end month number | F16: =IF( INDEX(J16:S16, $I$4) = "", INDEX(J16:R16, $I$6), INDEX(J16:S16, $I$4)) -> 12 | G16: month # | I16: {=IF( INDEX(J16:S16, I$5) = "", IF( INDEX(J16:S16, I$6) = F16, "vw", "tu"), IF(INDEX(J16:S16, I$5) = F16, "vw", "tu"))} -> vw | K16: 12
E17: Length of operating period | F17: =IF( INDEX(J17:S17, $I$4) = "", INDEX(J17:R17, $I$6), INDEX(J17:S17, $I$4)) -> 3 | G17: months | I17: {=IF( INDEX(J17:S17, I$5) = "", IF( INDEX(J17:S17, I$6) = F17, "vw", "tu"), IF(INDEX(J17:S17, I$5) = F17, "vw", "tu"))} -> vw | K17: 3
E19: Acquisition date | F19: =IF( INDEX(J19:S19, $I$4) = "", INDEX(J19:R19, $I$6), INDEX(J19:S19, $I$4)) -> 44286 | G19: date | I19: {=IF( INDEX(J19:S19, I$5) = "", IF( INDEX(J19:S19, I$6) = F19, "vw", "tu"), IF(INDEX(J19:S19, I$5) = F19, "vw", "tu"))} -> vw | K19: 44286
E21: Operating years remaining | F21: =IF( INDEX(J21:S21, $I$4) = "", INDEX(J21:R21, $I$6), INDEX(J21:S21, $I$4)) -> 25 | G21: years | I21: {=IF( INDEX(J21:S21, I$5) = "", IF( INDEX(J21:S21, I$6) = F21, "vw", "tu"), IF(INDEX(J21:S21, I$5) = F21, "vw", "tu"))} -> vw | K21: 25
E22: Extend PPA in the event of delay | F22: =IF( INDEX(J22:S22, $I$4) = "", INDEX(J22:R22, $I$6), INDEX(J22:S22, $I$4)) -> 0 | G22: 1 = yes, 0 = no | I22: {=IF( INDEX(J22:S22, I$5) = "", IF( INDEX(J22:S22, I$6) = F22, "vw", "tu"), IF(INDEX(J22:S22, I$5) = F22, "vw", "tu"))} -> vw | K22: 0
E23: Contract extension | F23: =IF( INDEX(J23:S23, $I$4) = "", INDEX(J23:R23, $I$6), INDEX(J23:S23, $I$4)) -> 0 | G23: years | I23: {=IF( INDEX(J23:S23, I$5) = "", IF( INDEX(J23:S23, I$6) = F23, "vw", "tu"), IF(INDEX(J23:S23, I$5) = F23, "vw", "tu"))} -> vw | K23: 0
A25: OPERATIONS
E26: Q1 seasonal adjustment | F26: =IF( INDEX(J26:S26, $I$4) = "", INDEX(J26:R26, $I$6), INDEX(J26:S26, $I$4)) -> 0.33 | G26: % of annual yield | I26: {=IF( INDEX(J26:S26, I$5) = "", IF( INDEX(J26:S26, I$6) = F26, "vw", "tu"), IF(INDEX(J26:S26, I$5) = F26, "vw", "tu"))} -> vw | K26: 0.33
E27: Q2 seasonal adjustment | F27: =IF( INDEX(J27:S27, $I$4) = "", INDEX(J27:R27, $I$6), INDEX(J27:S27, $I$4)) -> 0.36 | G27: % of annual yield | I27: {=IF( INDEX(J27:S27, I$5) = "", IF( INDEX(J27:S27, I$6) = F27, "vw", "tu"), IF(INDEX(J27:S27, I$5) = F27, "vw", "tu"))} -> vw | K27: 0.36
E28: Q3 seasonal adjustment | F28: =IF( INDEX(J28:S28, $I$4) = "", INDEX(J28:R28, $I$6), INDEX(J28:S28, $I$4)) -> 0.155 | G28: % of annual yield | I28: {=IF( INDEX(J28:S28, I$5) = "", IF( INDEX(J28:S28, I$6) = F28, "vw", "tu"), IF(INDEX(J28:S28, I$5) = F28, "vw", "tu"))} -> vw | K28: 0.155
E29: Q4 seasonal adjustment | F29: =IF( INDEX(J29:S29, $I$4) = "", INDEX(J29:R29, $I$6), INDEX(J29:S29, $I$4)) -> 0.155 | G29: % of annual yield | I29: {=IF( INDEX(J29:S29, I$5) = "", IF( INDEX(J29:S29, I$6) = F29, "vw", "tu"), IF(INDEX(J29:S29, I$5) = F29, "vw", "tu"))} -> vw | K29: 0.155
E31: Annual degredation | F31: =IF( INDEX(J31:S31, $I$4) = "", INDEX(J31:R31, $I$6), INDEX(J31:S31, $I$4)) -> 0.005 | G31: % p.a. | H31: 0 | I31: {=IF( INDEX(J31:S31, I$5) = "", IF( INDEX(J31:S31, I$6) = F31, "vw", "tu"), IF(INDEX(J31:S31, I$5) = F31, "vw", "tu"))} -> vw | K31: 0.005
E32: Year 1 P50 yield | F32: =IF( INDEX(J32:S32, $I$4) = "", INDEX(J32:R32, $I$6), INDEX(J32:S32, $I$4)) -> 250 | G32: GWh | I32: {=IF( INDEX(J32:S32, I$5) = "", IF( INDEX(J32:S32, I$6) = F32, "vw", "tu"), IF(INDEX(J32:S32, I$5) = F32, "vw", "tu"))} -> vw | K32: 250
E33: Availability | F33: =IF( INDEX(J33:S33, $I$4) = "", INDEX(J33:R33, $I$6), INDEX(J33:S33, $I$4)) -> 0.97 | G33: % | I33: {=IF( INDEX(J33:S33, I$5) = "", IF( INDEX(J33:S33, I$6) = F33, "vw", "tu"), IF(INDEX(J33:S33, I$5) = F33, "vw", "tu"))} -> vw | K33: 0.97
E34: Power tariff | F34: =IF( INDEX(J34:S34, $I$4) = "", INDEX(J34:R34, $I$6), INDEX(J34:S34, $I$4)) -> 0.065 | G34: USD / kWh | I34: {=IF( INDEX(J34:S34, I$5) = "", IF( INDEX(J34:S34, I$6) = F34, "vw", "tu"), IF(INDEX(J34:S34, I$5) = F34, "vw", "tu"))} -> vw | K34: 0.065
A38: MODEL TECHNICAL INPUTS - DO NOT CHANGE
E40: Model track tolerance level | F40: 0.001 | G40: tolerance
E41: Model check tolerance level | F41: 0.001 | G41: tolerance
E42: Months in year | F42: 12 | G42: months
E43: Number of periods in a year | F43: 4 | G43: periods
E44: Standard Monetary Unit | F44: $ 000s | G44: named "SMU"
E45: US$c / US$ | F45: 100 | G45: US$c / US$
E46: GWh to KWh conversion | F46: 1000000 | G46: kWh / GWh
E47: Units in a thousand | F47: 1000 | G47: units
B49: Timeline label
E50: Pre-forecast period | F50: Pre-fcst | G50: label
E51: Financial Close | F51: Fin Close | G51: label
E52: Operations | F52: Operations | G52: label
...

Sheet Time
A1: =RIGHT(CELL("filename", A1), LEN(CELL("filename", A1)) - SEARCH("]", CELL("filename", A1))) & " - " & InpC!F3 -> Time - Base case 1
E2: =Time!E$25 -> Model period ending | F2: 0 | G2: Error chks | J2: =Time!J$25 -> 44104 | K2: =Time!K$25 -> 44196 | L2: =Time!L$25 -> 44286 | M2: =Time!M$25 -> 44377 | N2: =Time!N$25 -> 44469 | O2: =Time!O$25 -> 44561 | P2: =Time!P$25 -> 44651 | Q2: =Time!Q$25 -> 44742 | ... GJ2: =Time!GJ$25 -> 60722
E3: =Time!E$67 -> Timeline label | F3: 0 | G3: Track chgs | J3: =Time!J$67 -> Pre-fcst | K3: =Time!K$67 -> Pre-fcst | L3: =Time!L$67 -> Fin Close | M3: =Time!M$67 -> Operations | N3: =Time!N$67 -> Operations | O3: =Time!O$67 -> Operations | P3: =Time!P$67 -> Operations | Q3: =Time!Q$67 -> Operations | ... GJ3: =Time!GJ$67 -> Post ops
E4: =Time!E$42 -> Contract year | F4: 0 | G4: Alerts | J4: =Time!J$42 -> 2020 | K4: =Time!K$42 -> 2020 | L4: =Time!L$42 -> 2020 | M4: =Time!M$42 -> 2021 | N4: =Time!N$42 -> 2021 | O4: =Time!O$42 -> 2021 | P4: =Time!P$42 -> 2021 | Q4: =Time!Q$42 -> 2022 | ... GJ4: =Time!GJ$42 -> 2065
E5: =Time!E$10 -> Model column counter | F5: Constant | G5: Unit | H5: Total | J5: =Time!J$10 -> 1 | K5: =Time!K$10 -> 2 | L5: =Time!L$10 -> 3 | M5: =Time!M$10 -> 4 | N5: =Time!N$10 -> 5 | O5: =Time!O$10 -> 6 | P5: =Time!P$10 -> 7 | Q5: =Time!Q$10 -> 8 | ... GJ5: =Time!GJ$10 -> 183
A7: TIME RULER
B9: First model column
E10: Model column counter | G10: counter | J10: =I10 + 1 -> 1 | K10: =J10 + 1 -> 2 | L10: =K10 + 1 -> 3 | M10: =L10 + 1 -> 4 | N10: =M10 + 1 -> 5 | O10: =N10 + 1 -> 6 | P10: =O10 + 1 -> 7 | Q10: =P10 + 1 -> 8 | ... GJ10: =GI10 + 1 -> 183
E11: Model column total | F11: =MAX(J10:PU10) -> 183 | G11: columns
E13: =E$10 -> Model column counter | F13: =F$10 -> 0 | G13: =G$10 -> counter | H13: =H$10 -> 0 | I13: =I$10 -> 0 | J13: =J$10 -> 1 | K13: =K$10 -> 2 | L13: =L$10 -> 3 | ... GJ13: =GJ$10 -> 183
E14: First model column flag | G14: flag | H14: =SUM(J14:GJ14) -> 1 | J14: =IF(J13 = 1, 1, 0) -> 1 | K14: =IF(K13 = 1, 1, 0) -> 0 | L14: =IF(L13 = 1, 1, 0) -> 0 | M14: =IF(M13 = 1, 1, 0) -> 0 | N14: =IF(N13 = 1, 1, 0) -> 0 | O14: =IF(O13 = 1, 1, 0) -> 0 | P14: =IF(P13 = 1, 1, 0) -> 0 | Q14: =IF(Q13 = 1, 1, 0) -> 0 | ... GJ14: =IF(GJ13 = 1, 1, 0) -> 0
B16: Model period beginning
E17: =InpC!E$13 -> First date of time rulers | F17: =InpC!F$13 -> 44013 | G17: =InpC!G$13 -> date
E18: =InpC!E$17 -> Length of operating period | F18: =InpC!F$17 -> 3 | G18: =InpC!G$17 -> months
E19: =E$14 -> First model column flag | F19: =F$14 -> 0 | G19: =G$14 -> flag | H19: =H$14 -> 1 | I19: =I$14 -> 0 | J19: =J$14 -> 1 | K19: =K$14 -> 0 | L19: =L$14 -> 0 | ... GJ19: =GJ$14 -> 0
E20: Model period beginning | G20: date | J20: =IF(J19 = 1, $F17, DATE(YEAR(I20), MONTH(I20) + $F18, DAY(1))) -> 44013 | K20: =IF(K19 = 1, $F17, DATE(YEAR(J20), MONTH(J20) + $F18, DAY(1))) -> 44105 | L20: =IF(L19 = 1, $F17, DATE(YEAR(K20), MONTH(K20) + $F18, DAY(1))) -> 44197 | M20: =IF(M19 = 1, $F17, DATE(YEAR(L20), MONTH(L20) + $F18, DAY(1))) -> 44287 | N20: =IF(N19 = 1, $F17, DATE(YEAR(M20), MONTH(M20) + $F18, DAY(1))) -> 44378 | O20: =IF(O19 = 1, $F17, DATE(YEAR(N20), MONTH(N20) + $F18, DAY(1))) -> 44470 | P20: =IF(P19 = 1, $F17, DATE(YEAR(O20), MONTH(O20) + $F18, DAY(1))) -> 44562 | Q20: =IF(Q19 = 1, $F17, DATE(YEAR(P20), MONTH(P20) + $F18, DAY(1))) -> 44652 | ... GJ20: =IF(GJ19 = 1, $F17, DATE(YEAR(GI20), MONTH(GI20) + $F18, DAY(1))) -> 60633
B22: Model period ending
E23: =InpC!E$17 -> Length of operating period | F23: =InpC!F$17 -> 3 | G23: =InpC!G$17 -> months
E24: =E$20 -> Model period beginning | F24: =F$20 -> 0 | G24: =G$20 -> date | H24: =H$20 -> 0 | I24: =I$20 -> 0 | J24: =J$20 -> 44013 | K24: =K$20 -> 44105 | L24: =L$20 -> 44197 | ... GJ24: =GJ$20 -> 60633
E25: Model period ending | G25: date | J25: =DATE(YEAR(J24), MONTH(J24) + $F23, DAY(J24) -1) -> 44104 | K25: =DATE(YEAR(K24), MONTH(K24) + $F23, DAY(K24) -1) -> 44196 | L25: =DATE(YEAR(L24), MONTH(L24) + $F23, DAY(L24) -1) -> 44286 | M25: =DATE(YEAR(M24), MONTH(M24) + $F23, DAY(M24) -1) -> 44377 | N25: =DATE(YEAR(N24), MONTH(N24) + $F23, DAY(N24) -1) -> 44469 | O25: =DATE(YEAR(O24), MONTH(O24) + $F23, DAY(O24) -1) -> 44561 | P25: =DATE(YEAR(P24), MONTH(P24) + $F23, DAY(P24) -1) -> 44651 | Q25: =DATE(YEAR(Q24), MONTH(Q24) + $F23, DAY(Q24) -1) -> 44742 | ... GJ25: =DATE(YEAR(GJ24), MONTH(GJ24) + $F23, DAY(GJ24) -1) -> 60722
B27: Contract year
E28: =InpC!E$19 -> Acquisition date | F28: =InpC!F$19 -> 44286 | G28: =InpC!G$19 -> date
E29: Contract year end month | F29: =MONTH(F28) -> 3 | G29: month
E31: =E$29 -> Contract year end month | F31: =F$29 -> 3 | G31: =G$29 -> month
E32: =E$25 -> Model period ending | F32: =F$25 -> 0 | G32: =G$25 -> date | H32: =H$25 -> 0 | I32: =I$25 -> 0 | J32: =J$25 -> 44104 | K32: =K$25 -> 44196 | L32: =L$25 -> 44286 | ... GJ32: =GJ$25 -> 60722
E33: End of contract year flag | J33: =IF( MONTH(J32) = $F31, 1, 0) -> 0 | K33: =IF( MONTH(K32) = $F31, 1, 0) -> 0 | L33: =IF( MONTH(L32) = $F31, 1, 0) -> 1 | M33: =IF( MONTH(M32) = $F31, 1, 0) -> 0 | N33: =IF( MONTH(N32) = $F31, 1, 0) -> 0 | O33: =IF( MONTH(O32) = $F31, 1, 0) -> 0 | P33: =IF( MONTH(P32) = $F31, 1, 0) -> 1 | Q33: =IF( MONTH(Q32) = $F31, 1, 0) -> 0 | ... GJ33: =IF( MONTH(GJ32) = $F31, 1, 0) -> 1
E35: =InpC!E$14 -> Annual year end date of first operating period | F35: =InpC!F$14 -> 43921 | G35: =InpC!G$14 -> date
E36: =InpC!E$42 -> Months in year | F36: =InpC!F$42 -> 12 | G36: =InpC!G$42 -> months
E37: =E$14 -> First model column flag | F37: =F$14 -> 0 | G37: =G$14 -> flag | H37: =H$14 -> 1 | I37: =I$14 -> 0 | J37: =J$14 -> 1 | K37: =K$14 -> 0 | L37: =L$14 -> 0 | ... GJ37: =GJ$14 -> 0
E38: =E$33 -> End of contract year flag | F38: =F$33 -> 0 | G38: =G$33 -> 0 | H38: =H$33 -> 0 | I38: =I$33 -> 0 | J38: =J$33 -> 0 | K38: =K$33 -> 0 | L38: =L$33 -> 1 | ... GJ38: =GJ$33 -> 1
E39: Contract year applicable to period | G39: date | J39: =IF( J37 = 1, $F35, IF( I38 = 1, EOMONTH(I39, 12), I39)) -> 43921 | K39: =IF( K37 = 1, $F35, IF( J38 = 1, EOMONTH(J39, 12), J39)) -> 43921 | L39: =IF( L37 = 1, $F35, IF( K38 = 1, EOMONTH(K39, 12), K39)) -> 43921 | M39: =IF( M37 = 1, $F35, IF( L38 = 1, EOMONTH(L39, 12), L39)) -> 44286 | N39: =IF( N37 = 1, $F35, IF( M38 = 1, EOMONTH(M39, 12), M39)) -> 44286 | O39: =IF( O37 = 1, $F35, IF( N38 = 1, EOMONTH(N39, 12), N39)) -> 44286 | P39: =IF( P37 = 1, $F35, IF( O38 = 1, EOMONTH(O39, 12), O39)) -> 44286 | Q39: =IF( Q37 = 1, $F35, IF( P38 = 1, EOMONTH(P39, 12), P39)) -> 44651 | ... GJ39: =IF( GJ37 = 1, $F35, IF( GI38 = 1, EOMONTH(GI39, 12), GI39)) -> 60357
E41: =E$39 -> Contract year applicable to period | F41: =F$39 -> 0 | G41: =G$39 -> date | H41: =H$39 -> 0 | I41: =I$39 -> 0 | J41: =J$39 -> 43921 | K41: =K$39 -> 43921 | L41: =L$39 -> 43921 | ... GJ41: =GJ$39 -> 60357
E42: Contract year | G42: year # | J42: =YEAR(J41) -> 2020 | K42: =YEAR(K41) -> 2020 | L42: =YEAR(L41) -> 2020 | M42: =YEAR(M41) -> 2021 | N42: =YEAR(N41) -> 2021 | O42: =YEAR(O41) -> 2021 | P42: =YEAR(P41) -> 2021 | Q42: =YEAR(Q41) -> 2022 | ... GJ42: =YEAR(GJ41) -> 2065
B44: Annual timeline
E45: =InpC!E$14 -> Annual year end date of first operating period | F45: =InpC!F$14 -> 43921 | G45: =InpC!G$14 -> date
E46: =InpC!E$42 -> Months in year | F46: =InpC!F$42 -> 12 | G46: =InpC!G$42 -> months
E47: =E$14 -> First model column flag | F47: =F$14 -> 0 | G47: =G$14 -> flag | H47: =H$14 -> 1 | I47: =I$14 -> 0 | J47: =J$14 -> 1 | K47: =K$14 -> 0 | L47: =L$14 -> 0 | ... GJ47: =GJ$14 -> 0
E48: Model period ending - annual | G48: date | J48: =IF(J47 = 1, $F45, EOMONTH(I48, $F46)) -> 43921 | K48: =IF(K47 = 1, $F45, EOMONTH(J48, $F46)) -> 44286 | L48: =IF(L47 = 1, $F45, EOMONTH(K48, $F46)) -> 44651 | M48: =IF(M47 = 1, $F45, EOMONTH(L48, $F46)) -> 45016 | N48: =IF(N47 = 1, $F45, EOMONTH(M48, $F46)) -> 45382 | O48: =IF(O47 = 1, $F45, EOMONTH(N48, $F46)) -> 45747 | P48: =IF(P47 = 1, $F45, EOMONTH(O48, $F46)) -> 46112 | Q48: =IF(Q47 = 1, $F45, EOMONTH(P48, $F46)) -> 46477 | ... GJ48: =IF(GJ47 = 1, $F45, EOMONTH(GI48, $F46)) -> 110394
E50: =E$67 -> Timeline label | F50: =F$67 -> 0 | G50: =G$67 -> label | H50: =H$67 -> 0 | I50: =I$67 -> 0 | J50: =J$67 -> Pre-fcst | K50: =K$67 -> Pre-fcst | L50: =L$67 -> Fin Close | ... GJ50: =GJ$67 -> Post ops
E51: =E$48 -> Model period ending - annual | F51: =F$48 -> 0 | G51: =G$48 -> date | H51: =H$48 -> 0 | I51: =I$48 -> 0 | J51: =J$48 -> 43921 | K51: =K$48 -> 44286 | L51: =L$48 -> 44651 | ... GJ51: =GJ$48 -> 110394
...

Sheet Ops
A1: =RIGHT(CELL("filename", A1), LEN(CELL("filename", A1)) - SEARCH("]", CELL("filename", A1))) & " - " & InpC!F3 -> Ops - Base case 1
E2: =Time!E$25 -> Model period ending | F2: 0 | G2: Error chks | J2: =Time!J$25 -> 44104 | K2: =Time!K$25 -> 44196 | L2: =Time!L$25 -> 44286 | M2: =Time!M$25 -> 44377 | N2: =Time!N$25 -> 44469 | O2: =Time!O$25 -> 44561 | P2: =Time!P$25 -> 44651 | Q2: =Time!Q$25 -> 44742 | ... GJ2: =Time!GJ$25 -> 60722
E3: =Time!E$67 -> Timeline label | F3: 0 | G3: Track chgs | J3: =Time!J$67 -> Pre-fcst | K3: =Time!K$67 -> Pre-fcst | L3: =Time!L$67 -> Fin Close | M3: =Time!M$67 -> Operations | N3: =Time!N$67 -> Operations | O3: =Time!O$67 -> Operations | P3: =Time!P$67 -> Operations | Q3: =Time!Q$67 -> Operations | ... GJ3: =Time!GJ$67 -> Post ops
E4: =Time!E$42 -> Contract year | F4: 0 | G4: Alerts | J4: =Time!J$42 -> 2020 | K4: =Time!K$42 -> 2020 | L4: =Time!L$42 -> 2020 | M4: =Time!M$42 -> 2021 | N4: =Time!N$42 -> 2021 | O4: =Time!O$42 -> 2021 | P4: =Time!P$42 -> 2021 | Q4: =Time!Q$42 -> 2022 | ... GJ4: =Time!GJ$42 -> 2065
E5: =Time!E$10 -> Model column counter | F5: Constant | G5: Unit | H5: Total | J5: =Time!J$10 -> 1 | K5: =Time!K$10 -> 2 | L5: =Time!L$10 -> 3 | M5: =Time!M$10 -> 4 | N5: =Time!N$10 -> 5 | O5: =Time!O$10 -> 6 | P5: =Time!P$10 -> 7 | Q5: =Time!Q$10 -> 8 | ... GJ5: =Time!GJ$10 -> 183
A8: REVENUE
B10: Degredation
E11: =InpC!E$31 -> Annual degredation | F11: =InpC!F$31 -> 0.005 | G11: =InpC!G$31 -> % p.a.
E12: =Time!E$121 -> Contract year number | F12: =Time!F$121 -> 0 | G12: =Time!G$121 -> counter | H12: =Time!H$121 -> 0 | I12: =Time!I$121 -> 0 | J12: =Time!J$121 -> 0 | K12: =Time!K$121 -> 0 | L12: =Time!L$121 -> 0 | ... GJ12: =Time!GJ$121 -> 0
E13: =Time!E$97 -> Operating period flag | F13: =Time!F$97 -> 0 | G13: =Time!G$97 -> flag | H13: =Time!H$97 -> 100 | I13: =Time!I$97 -> 0 | J13: =Time!J$97 -> 0 | K13: =Time!K$97 -> 0 | L13: =Time!L$97 -> 0 | ... GJ13: =Time!GJ$97 -> 0
E14: Compound degredation | G14: % | J14: =IF( J13 = 1, 1 / ((1 + $F11) ^ (J12 - 1)), 0) -> 0 | K14: =IF( K13 = 1, 1 / ((1 + $F11) ^ (K12 - 1)), 0) -> 0 | L14: =IF( L13 = 1, 1 / ((1 + $F11) ^ (L12 - 1)), 0) -> 0 | M14: =IF( M13 = 1, 1 / ((1 + $F11) ^ (M12 - 1)), 0) -> 1 | N14: =IF( N13 = 1, 1 / ((1 + $F11) ^ (N12 - 1)), 0) -> 1 | O14: =IF( O13 = 1, 1 / ((1 + $F11) ^ (O12 - 1)), 0) -> 1 | P14: =IF( P13 = 1, 1 / ((1 + $F11) ^ (P12 - 1)), 0) -> 1 | Q14: =IF( Q13 = 1, 1 / ((1 + $F11) ^ (Q12 - 1)), 0) -> 0.99502488 | ... GJ14: =IF( GJ13 = 1, 1 / ((1 + $F11) ^ (GJ12 - 1)), 0) -> 0
B16: Seasonality adjustment
E17: =InpC!E$26 -> Q1 seasonal adjustment | F17: =InpC!F$26 -> 0.33 | G17: =InpC!G$26 -> % of annual yield
E18: =InpC!E$27 -> Q2 seasonal adjustment | F18: =InpC!F$27 -> 0.36 | G18: =InpC!G$27 -> % of annual yield
E19: =InpC!E$28 -> Q3 seasonal adjustment | F19: =InpC!F$28 -> 0.155 | G19: =InpC!G$28 -> % of annual yield
E20: =InpC!E$29 -> Q4 seasonal adjustment | F20: =InpC!F$29 -> 0.155 | G20: =InpC!G$29 -> % of annual yield
E21: =Time!E$115 -> Period number | F21: =Time!F$115 -> 0 | G21: =Time!G$115 -> counter | H21: =Time!H$115 -> 0 | I21: =Time!I$115 -> 0 | J21: =Time!J$115 -> 0 | K21: =Time!K$115 -> 0 | L21: =Time!L$115 -> 0 | ... GJ21: =Time!GJ$115 -> 0
E22: =Time!E$97 -> Operating period flag | F22: =Time!F$97 -> 0 | G22: =Time!G$97 -> flag | H22: =Time!H$97 -> 100 | I22: =Time!I$97 -> 0 | J22: =Time!J$97 -> 0 | K22: =Time!K$97 -> 0 | L22: =Time!L$97 -> 0 | ... GJ22: =Time!GJ$97 -> 0
E23: Seasonality adjustment | G23: % | H23: =SUM(J23:GJ23) -> 25 | J23: =IF(J22 = 1, INDEX($F17:$F20, J21), 0) -> 0 | K23: =IF(K22 = 1, INDEX($F17:$F20, K21), 0) -> 0 | L23: =IF(L22 = 1, INDEX($F17:$F20, L21), 0) -> 0 | M23: =IF(M22 = 1, INDEX($F17:$F20, M21), 0) -> 0.33 | N23: =IF(N22 = 1, INDEX($F17:$F20, N21), 0) -> 0.36 | O23: =IF(O22 = 1, INDEX($F17:$F20, O21), 0) -> 0.155 | P23: =IF(P22 = 1, INDEX($F17:$F20, P21), 0) -> 0.155 | Q23: =IF(Q22 = 1, INDEX($F17:$F20, Q21), 0) -> 0.33 | ... GJ23: =IF(GJ22 = 1, INDEX($F17:$F20, GJ21), 0) -> 0
B25: Electricity generation
E26: =InpC!E$32 -> Year 1 P50 yield | F26: =InpC!F$32 -> 250 | G26: =InpC!G$32 -> GWh
E27: =InpC!E$33 -> Availability | F27: =InpC!F$33 -> 0.97 | G27: =InpC!G$33 -> %
E28: =E$14 -> Compound degredation | F28: =F$14 -> 0 | G28: =G$14 -> % | H28: =H$14 -> 0 | I28: =I$14 -> 0 | J28: =J$14 -> 0 | K28: =K$14 -> 0 | L28: =L$14 -> 0 | ... GJ28: =GJ$14 -> 0
E29: =E$23 -> Seasonality adjustment | F29: =F$23 -> 0 | G29: =G$23 -> % | H29: =H$23 -> 25 | I29: =I$23 -> 0 | J29: =J$23 -> 0 | K29: =K$23 -> 0 | L29: =L$23 -> 0 | ... GJ29: =GJ$23 -> 0
E30: Electricty generation | G30: GWh | H30: =SUM(J30:GJ30) -> 5713.9951 | J30: =$F26 * $F27 * J28 * J29 -> 0 | K30: =$F$26 * $F$27 * K$28 * K$29 -> 0 | L30: =$F$26 * $F$27 * L$28 * L$29 -> 0 | M30: =$F$26 * $F$27 * M$28 * M$29 -> 80.025 | N30: =$F$26 * $F$27 * N$28 * N$29 -> 87.3 | O30: =$F$26 * $F$27 * O$28 * O$29 -> 37.5875 | P30: =$F$26 * $F$27 * P$28 * P$29 -> 37.5875 | Q30: =$F$26 * $F$27 * Q$28 * Q$29 -> 79.626866 | R30: =$F$26 * $F$27 * R$28 * R$29 -> 86.865672 | ... GJ30: =$F$26 * $F$27 * GJ$28 * GJ$29 -> 0
B32: Electricity revenue
E33: =InpC!E$34 -> Power tariff | F33: =InpC!F$34 -> 0.065 | G33: =InpC!G$34 -> USD / kWh
E34: =InpC!E$46 -> GWh to KWh conversion | F34: =InpC!F$46 -> 1000000 | G34: =InpC!G$46 -> kWh / GWh
E35: =InpC!E$47 -> Units in a thousand | F35: =InpC!F$47 -> 1000 | G35: =InpC!G$47 -> units
E36: =E$30 -> Electricty generation | F36: =F$30 -> 0 | G36: =G$30 -> GWh | H36: =H$30 -> 5713.9951 | I36: =I$30 -> 0 | J36: =J$30 -> 0 | K36: =K$30 -> 0 | L36: =L$30 -> 0 | ... GJ36: =GJ$30 -> 0
E37: =Time!E$97 -> Operating period flag | F37: =Time!F$97 -> 0 | G37: =Time!G$97 -> flag | H37: =Time!H$97 -> 100 | I37: =Time!I$97 -> 0 | J37: =Time!J$97 -> 0 | K37: =Time!K$97 -> 0 | L37: =Time!L$97 -> 0 | ... GJ37: =Time!GJ$97 -> 0
E38: Electricity revenue | G38: =SMU -> $ 000s | H38: =SUM(J38:GJ38) -> 371409.68 | J38: =$F33 * $F34 / $F35 * J36 * J37 -> 0 | K38: =$F33 * $F34 / $F35 * K36 * K37 -> 0 | L38: =$F33 * $F34 / $F35 * L36 * L37 -> 0 | M38: =$F33 * $F34 / $F35 * M36 * M37 -> 5201.625 | N38: =$F33 * $F34 / $F35 * N36 * N37 -> 5674.5 | O38: =$F33 * $F34 / $F35 * O36 * O37 -> 2443.1875 | P38: =$F33 * $F34 / $F35 * P36 * P37 -> 2443.1875 | Q38: =$F33 * $F34 / $F35 * Q36 * Q37 -> 5175.7463 | ... GJ38: =$F33 * $F34 / $F35 * GJ36 * GJ37 -> 0
A43: END

Sheet Tmp
A1: =RIGHT(CELL("filename", A1), LEN(CELL("filename", A1)) - SEARCH("]", CELL("filename", A1))) & " - " & InpC!F3 -> Tmp - Base case 1
E2: =Time!E$25 -> Model period ending | F2: 0 | G2: Error chks | J2: =Time!J$25 -> 44104 | K2: =Time!K$25 -> 44196 | L2: =Time!L$25 -> 44286 | M2: =Time!M$25 -> 44377 | N2: =Time!N$25 -> 44469 | O2: =Time!O$25 -> 44561 | P2: =Time!P$25 -> 44651 | Q2: =Time!Q$25 -> 44742 | ... GJ2: =Time!GJ$25 -> 60722
E3: =Time!E$67 -> Timeline label | F3: 0 | G3: Track chgs | J3: =Time!J$67 -> Pre-fcst | K3: =Time!K$67 -> Pre-fcst | L3: =Time!L$67 -> Fin Close | M3: =Time!M$67 -> Operations | N3: =Time!N$67 -> Operations | O3: =Time!O$67 -> Operations | P3: =Time!P$67 -> Operations | Q3: =Time!Q$67 -> Operations | ... GJ3: =Time!GJ$67 -> Post ops
E4: =Time!E$42 -> Contract year | F4: 0 | G4: Alerts | J4: =Time!J$42 -> 2020 | K4: =Time!K$42 -> 2020 | L4: =Time!L$42 -> 2020 | M4: =Time!M$42 -> 2021 | N4: =Time!N$42 -> 2021 | O4: =Time!O$42 -> 2021 | P4: =Time!P$42 -> 2021 | Q4: =Time!Q$42 -> 2022 | ... GJ4: =Time!GJ$42 -> 2065
E5: =Time!E$10 -> Model column counter | F5: Constant | G5: Unit | H5: Total | J5: =Time!J$10 -> 1 | K5: =Time!K$10 -> 2 | L5: =Time!L$10 -> 3 | M5: =Time!M$10 -> 4 | N5: =Time!N$10 -> 5 | O5: =Time!O$10 -> 6 | P5: =Time!P$10 -> 7 | Q5: =Time!Q$10 -> 8 | ... GJ5: =Time!GJ$10 -> 183
E8: [xxx] balance BEG | J8: =I11 -> 0 | K8: =J11 -> 0 | L8: =K11 -> 0 | M8: =L11 -> 0 | N8: =M11 -> 0 | O8: =N11 -> 0 | P8: =O11 -> 0 | Q8: =P11 -> 0 | ... GJ8: =GI11 -> 0
E9: [upward flow]
E10: [downward flow]
E11: [xxx] balance | J11: =J8 + J9 - J10 -> 0 | K11: =K8 + K9 - K10 -> 0 | L11: =L8 + L9 - L10 -> 0 | M11: =M8 + M9 - M10 -> 0 | N11: =N8 + N9 - N10 -> 0 | O11: =O8 + O9 - O10 -> 0 | P11: =P8 + P9 - P10 -> 0 | Q11: =Q8 + Q9 - Q10 -> 0 | ... GJ11: =GJ8 + GJ9 - GJ10 -> 0
E14: [xxx] - initial balance | G14: =SMU -> $ 000s
E15: =Time!E$76 -> Financial close date flag | F15: =Time!F$76 -> 0 | G15: =Time!G$76 -> flag | H15: =Time!H$76 -> 1 | I15: =Time!I$76 -> 0 | J15: =Time!J$76 -> 0 | K15: =Time!K$76 -> 0 | L15: =Time!L$76 -> 1 | ... GJ15: =Time!GJ$76 -> 0
E17: [xxx] balance BEG | G17: =SMU -> $ 000s | J17: =I20 -> 0 | K17: =J20 -> 0 | L17: =K20 -> 0 | M17: =L20 -> 0 | N17: =M20 -> 0 | O17: =N20 -> 0 | P17: =O20 -> 0 | Q17: =P20 -> 0 | ... GJ17: =GI20 -> 0
E18: [upward flow]
E19: [downward flow]
E20: [xxx] balance | G20: =SMU -> $ 000s | J20: =IF( J15 = 1, $F14, J17 + J18 - J19) -> 0 | K20: =IF( K15 = 1, $F14, K17 + K18 - K19) -> 0 | L20: =IF( L15 = 1, $F14, L17 + L18 - L19) -> 0 | M20: =IF( M15 = 1, $F14, M17 + M18 - M19) -> 0 | N20: =IF( N15 = 1, $F14, N17 + N18 - N19) -> 0 | O20: =IF( O15 = 1, $F14, O17 + O18 - O19) -> 0 | P20: =IF( P15 = 1, $F14, P17 + P18 - P19) -> 0 | Q20: =IF( Q15 = 1, $F14, Q17 + Q18 - Q19) -> 0 | ... GJ20: =IF( GJ15 = 1, $F14, GJ17 + GJ18 - GJ19) -> 0
E23: Sign switch line item POS | G23: =SMU -> $ 000s | H23: =SUM(J23:GJ23) -> 18300 | J23: 100 | K23: 100 | L23: 100 | M23: 100 | N23: 100 | O23: 100 | P23: 100 | Q23: 100 | R23: 100 | S23: 100 | T23: 100 | U23: 100 | V23: 100 | W23: 100 | X23: 100 | Y23: 100 | Z23: 100 | AA23: 100 | AB23: 100 | AC23: 100 | AD23: 100 | AE23: 100 | AF23: 100 | AG23: 100 | AH23: 100 | AI23: 100 | AJ23: 100 | AK23: 100 | AL23: 100 | AM23: 100 | AN23: 100 | AO23: 100 | AP23: 100 | AQ23: 100 | AR23: 100 | AS23: 100 | AT23: 100 | AU23: 100 | AV23: 100 | AW23: 100 | AX23: 100 | AY23: 100 | AZ23: 100 | BA23: 100 | BB23: 100 | BC23: 100 | BD23: 100 | BE23: 100 | BF23: 100 | BG23: 100 | BH23: 100 | BI23: 100 | BJ23: 100 | BK23: 100 | BL23: 100 | BM23: 100 | BN23: 100 | BO23: 100 | BP23: 100 | BQ23: 100 | BR23: 100 | BS23: 100 | BT23: 100 | BU23: 100 | BV23: 100 | BW23: 100 | BX23: 100 | BY23: 100 | BZ23: 100 | CA23: 100 | CB23: 100 | CC23: 100 | CD23: 100 | CE23: 100 | CF23: 100 | CG23: 100 | CH23: 100 | CI23: 100 | CJ23: 100 | CK23: 100 | CL23: 100 | CM23: 100 | CN23: 100 | CO23: 100 | CP23: 100 | CQ23: 100 | CR23: 100 | CS23: 100 | CT23: 100 | CU23: 100 | CV23: 100 | CW23: 100 | CX23: 100 | CY23: 100 | CZ23: 100 | DA23: 100 | DB23: 100 | DC23: 100 | DD23: 100 | DE23: 100 | DF23: 100 | DG23: 100 | DH23: 100 | DI23: 100 | DJ23: 100 | DK23: 100 | DL23: 100 | DM23: 100 | DN23: 100 | DO23: 100 | DP23: 100 | DQ23: 100 | DR23: 100 | DS23: 100 | DT23: 100 | DU23: 100 | DV23: 100 | DW23: 100 | DX23: 100 | DY23: 100 | DZ23: 100 | EA23: 100 | EB23: 100 | EC23: 100 | ED23: 100 | EE23: 100 | EF23: 100 | EG23: 100 | EH23: 100 | EI23: 100 | EJ23: 100 | EK23: 100 | EL23: 100 | EM23: 100 | EN23: 100 | EO23: 100 | EP23: 100 | EQ23: 100 | ER23: 100 | ES23: 100 | ET23: 100 | EU23: 100 | EV23: 100 | EW23: 100 | EX23: 100 | EY23: 100 | EZ23: 100 | FA23: 100 | FB23: 100 | FC23: 100 | FD23: 100 | FE23: 100 | FF23: 100 | FG23: 100 | FH23: 100 | FI23: 100 | FJ23: 100 | FK23: 100 | FL23: 100 | FM23: 100 | FN23: 100 | FO23: 100 | FP23: 100 | FQ23: 100 | FR23: 100 | FS23: 100 | FT23: 100 | FU23: 100 | FV23: 100 | FW23: 100 | FX23: 100 | FY23: 100 | FZ23: 100 | GA23: 100 | GB23: 100 | GC23: 100 | GD23: 100 | GE23: 100 | GF23: 100 | GG23: 100 | GH23: 100 | GI23: 100 | GJ23: 100
E24: =LEFT(E23, LEN(E23) - 4) -> Sign switch line item | G24: =SMU -> $ 000s | H24: =SUM(J24:GJ24) -> -18300 | J24: =-1 * J23 -> -100 | K24: =-1 * K23 -> -100 | L24: =-1 * L23 -> -100 | M24: =-1 * M23 -> -100 | N24: =-1 * N23 -> -100 | O24: =-1 * O23 -> -100 | P24: =-1 * P23 -> -100 | Q24: =-1 * Q23 -> -100 | ... GJ24: =-1 * GJ23 -> -100
E27: =Ops!#REF! -> #REF!
