Workbook
Name BaseCaseIndicator: InpC!$J$7:$S$7
Name CASE_ACTIVE: InpC!$F$4
Name CHK_TOL: InpC!$F$58
Name InputRowTemplate: InpC!$E$73:$S$73
Name InputStored: InpC!$J$3:$S$3
Name OutputRowTemplate: Output!$E$67:$X$67
Name SMU: InpC!$F$61
Name TrackActive: Output!$H$5
Name TrackLiveResults: Output!$H$6:$H$74
Name TrackStoredResults: Output!$M$5:$X$5
Name TRK_TOL: InpC!$F$57

Sheet InpC
A1: =RIGHT(CELL("filename", A1), LEN(CELL("filename", A1)) - SEARCH("]", CELL("filename", A1))) & " - " & $F$3 -> InpC - Base case 1
K2: =IF(K4 = $F4, "q", "") -> q | L2: =IF(L4 = $F4, "q", "") | M2: =IF(M4 = $F4, "q", "") | O2: =IF(O4 = $F4, "q", "") | P2: =IF(P4 = $F4, "q", "") | Q2: =IF(Q4 = $F4, "q", "") | R2: =IF(R4 = $F4, "q", "")
F3: =INDEX(J3:S3,MATCH(F4,J4:S4)) -> Base case 1 | K3: Base case 1 | L3: Base case 2 | M3: Base case 3 | O3: Scenario 1 | P3: Scenario 2 | Q3: Scenario 3 | R3: Scenario 4
E4: Active scenario | F4: 1 | I4: =MATCH(F4, $J$4:$S$4) -> 2 | K4: 1 | L4: 2 | M4: 3 | O4: 5 | P4: 6 | Q4: 7 | R4: 8
E5: Comparison scenario | F5: 1 | I5: =MATCH(F5, $J$4:$S$4) -> 2
E6: Base case | F6: =INDEX(J6:S6,MATCH(F4,J4:S4,0)) -> 1 | I6: =MATCH(F6, $J$4:$S$4) -> 2 | K6: 1 | L6: 2 | M6: 3 | O6: 1 | P6: 1 | Q6: 2 | R6: 2
E7: Input differences | F7: =COUNTIF(I10:I55, "tu") -> 0 | K7: =IF(K6 = $F$6, "Base case", "") -> Base case | L7: =IF(L6 = $F$6, "Base case", "") | M7: =IF(M6 = $F$6, "Base case", "")
F9: Constant | G9: Unit | H9: Source
A11: TIMING ASSUMPTIONS
E13: First date of time rulers | F13: =IF( INDEX(J13:S13, $I$4) = "", INDEX(J13:R13, $I$6), INDEX(J13:S13, $I$4)) -> 44013 | G13: date | I13: {=IF( INDEX(J13:S13, I$5) = "", IF( INDEX(J13:S13, I$6) = F13, "vw", "tu"), IF(INDEX(J13:S13, I$5) = F13, "vw", "tu"))} -> vw | K13: 44013
E14: Annual year end date of first operating period | F14: =IF( INDEX(J14:S14, $I$4) = "", INDEX(J14:R14, $I$6), INDEX(J14:S14, $I$4)) -> 43921 | G14: date | I14: {=IF( INDEX(J14:S14, I$5) = "", IF( INDEX(J14:S14, I$6) = F14, "vw", "tu"), IF(INDEX(J14:S14, I$5) = F14, "vw", "tu"))} -> vw | K14: 43921
E15: Financial year end month number | F15: =IF( INDEX(J15:S15, $I$4) = "", INDEX(J15:R15, $I$6), INDEX(J15:S15, $I$4)) -> 12 | G15: month # | I15: {=IF( INDEX(J15:S15, I$5) = "", IF( INDEX(J15:S15, I$6) = F15, "vw", "tu"), IF(INDEX(J15:S15, I$5) = F15, "vw", "tu"))} -> vw | K15: 12
E16: Length of operating period | F16: =IF( INDEX(J16:S16, $I$4) = "", INDEX(J16:R16, $I$6), INDEX(J16:S16, $I$4)) -> 3 | G16: months | I16: {=IF( INDEX(J16:S16, I$5) = "", IF( INDEX(J16:S16, I$6) = F16, "vw", "tu"), IF(INDEX(J16:S16, I$5) = F16, "vw", "tu"))} -> vw | K16: 3
E18: Acquisition date | F18: =IF( INDEX(J18:S18, $I$4) = "", INDEX(J18:R18, $I$6), INDEX(J18:S18, $I$4)) -> 44286 | G18: date | I18: {=IF( INDEX(J18:S18, I$5) = "", IF( INDEX(J18:S18, I$6) = F18, "vw", "tu"), IF(INDEX(J18:S18, I$5) = F18, "vw", "tu"))} -> vw | K18: 44286
E20: Operating years remaining | F20: =IF( INDEX(J20:S20, $I$4) = "", INDEX(J20:R20, $I$6), INDEX(J20:S20, $I$4)) -> 25 | G20: years | I20: {=IF( INDEX(J20:S20, I$5) = "", IF( INDEX(J20:S20, I$6) = F20, "vw", "tu"), IF(INDEX(J20:S20, I$5) = F20, "vw", "tu"))} -> vw | K20: 25
E21: Contract extension | F21: =IF( INDEX(J21:S21, $I$4) = "", INDEX(J21:R21, $I$6), INDEX(J21:S21, $I$4)) -> 0 | G21: years | I21: {=IF( INDEX(J21:S21, I$5) = "", IF( INDEX(J21:S21, I$6) = F21, "vw", "tu"), IF(INDEX(J21:S21, I$5) = F21, "vw", "tu"))} -> vw | K21: 0
A23: REVENUE
E24: Q1 seasonal adjustment | F24: =IF( INDEX(J24:S24, $I$4) = "", INDEX(J24:R24, $I$6), INDEX(J24:S24, $I$4)) -> 0.33 | G24: % of annual yield | I24: {=IF( INDEX(J24:S24, I$5) = "", IF( INDEX(J24:S24, I$6) = F24, "vw", "tu"), IF(INDEX(J24:S24, I$5) = F24, "vw", "tu"))} -> vw | K24: 0.33 | L24: 0.33 | M24: 0.33
E25: Q2 seasonal adjustment | F25: =IF( INDEX(J25:S25, $I$4) = "", INDEX(J25:R25, $I$6), INDEX(J25:S25, $I$4)) -> 0.36 | G25: % of annual yield | I25: {=IF( INDEX(J25:S25, I$5) = "", IF( INDEX(J25:S25, I$6) = F25, "vw", "tu"), IF(INDEX(J25:S25, I$5) = F25, "vw", "tu"))} -> vw | K25: 0.36 | L25: 0.36 | M25: 0.36
E26: Q3 seasonal adjustment | F26: =IF( INDEX(J26:S26, $I$4) = "", INDEX(J26:R26, $I$6), INDEX(J26:S26, $I$4)) -> 0.155 | G26: % of annual yield | I26: {=IF( INDEX(J26:S26, I$5) = "", IF( INDEX(J26:S26, I$6) = F26, "vw", "tu"), IF(INDEX(J26:S26, I$5) = F26, "vw", "tu"))} -> vw | K26: 0.155 | L26: 0.155 | M26: 0.155
E27: Q4 seasonal adjustment | F27: =IF( INDEX(J27:S27, $I$4) = "", INDEX(J27:R27, $I$6), INDEX(J27:S27, $I$4)) -> 0.155 | G27: % of annual yield | I27: {=IF( INDEX(J27:S27, I$5) = "", IF( INDEX(J27:S27, I$6) = F27, "vw", "tu"), IF(INDEX(J27:S27, I$5) = F27, "vw", "tu"))} -> vw | K27: 0.155 | L27: 0.155 | M27: 0.155
E29: Annual degradation | F29: =IF( INDEX(J29:S29, $I$4) = "", INDEX(J29:R29, $I$6), INDEX(J29:S29, $I$4)) -> 0.005 | G29: % p.a. | I29: {=IF( INDEX(J29:S29, I$5) = "", IF( INDEX(J29:S29, I$6) = F29, "vw", "tu"), IF(INDEX(J29:S29, I$5) = F29, "vw", "tu"))} -> vw | K29: 0.005 | L29: 0.005 | M29: 0.005
E30: Year 1 P50 yield | F30: =IF( INDEX(J30:S30, $I$4) = "", INDEX(J30:R30, $I$6), INDEX(J30:S30, $I$4)) -> 250 | G30: GWh | I30: {=IF( INDEX(J30:S30, I$5) = "", IF( INDEX(J30:S30, I$6) = F30, "vw", "tu"), IF(INDEX(J30:S30, I$5) = F30, "vw", "tu"))} -> vw | K30: 250 | L30: 250 | M30: 250
E31: Availability | F31: =IF( INDEX(J31:S31, $I$4) = "", INDEX(J31:R31, $I$6), INDEX(J31:S31, $I$4)) -> 0.97 | G31: % | I31: {=IF( INDEX(J31:S31, I$5) = "", IF( INDEX(J31:S31, I$6) = F31, "vw", "tu"), IF(INDEX(J31:S31, I$5) = F31, "vw", "tu"))} -> vw | K31: 0.97 | L31: 0.97 | M31: 0.97
E33: Power tariff | F33: =IF( INDEX(J33:S33, $I$4) = "", INDEX(J33:R33, $I$6), INDEX(J33:S33, $I$4)) -> 0.065 | G33: USD / kWh | I33: {=IF( INDEX(J33:S33, I$5) = "", IF( INDEX(J33:S33, I$6) = F33, "vw", "tu"), IF(INDEX(J33:S33, I$5) = F33, "vw", "tu"))} -> vw | K33: 0.065 | L33: 0.065 | M33: 0.065
A35: OPERATING COSTS
E36: Annual fixed real O&M cost | F36: =IF( INDEX(J36:S36, $I$4) = "", INDEX(J36:R36, $I$6), INDEX(J36:S36, $I$4)) -> 1500 | G36: =SMU -> $ 000s | I36: {=IF( INDEX(J36:S36, I$5) = "", IF( INDEX(J36:S36, I$6) = F36, "vw", "tu"), IF(INDEX(J36:S36, I$5) = F36, "vw", "tu"))} -> vw | K36: 1500 | L36: 1500 | M36: 1500
A38: FIXED ASSET
E39: Useful life of asset | F39: =IF( INDEX(J39:S39, $I$4) = "", INDEX(J39:R39, $I$6), INDEX(J39:S39, $I$4)) -> 25 | G39: years | I39: {=IF( INDEX(J39:S39, I$5) = "", IF( INDEX(J39:S39, I$6) = F39, "vw", "tu"), IF(INDEX(J39:S39, I$5) = F39, "vw", "tu"))} -> vw | K39: 25 | L39: 25 | M39: 25
A41: WORKING CAPITAL
E42: Accounts receivable days | F42: =IF( INDEX(J42:S42, $I$4) = "", INDEX(J42:R42, $I$6), INDEX(J42:S42, $I$4)) -> 60 | G42: days | I42: {=IF( INDEX(J42:S42, I$5) = "", IF( INDEX(J42:S42, I$6) = F42, "vw", "tu"), IF(INDEX(J42:S42, I$5) = F42, "vw", "tu"))} -> vw | K42: 60 | L42: 60 | M42: 60
E43: Accounts payable days | F43: =IF( INDEX(J43:S43, $I$4) = "", INDEX(J43:R43, $I$6), INDEX(J43:S43, $I$4)) -> 30 | G43: days | I43: {=IF( INDEX(J43:S43, I$5) = "", IF( INDEX(J43:S43, I$6) = F43, "vw", "tu"), IF(INDEX(J43:S43, I$5) = F43, "vw", "tu"))} -> vw | K43: 30 | L43: 30 | M43: 30
A45: OPENING BALANCES
E46: Retained earnings - initial balance | F46: =IF( INDEX(J46:S46, $I$4) = "", INDEX(J46:R46, $I$6), INDEX(J46:S46, $I$4)) -> 0 | G46: =SMU -> $ 000s | I46: {=IF( INDEX(J46:S46, I$5) = "", IF( INDEX(J46:S46, I$6) = F46, "vw", "tu"), IF(INDEX(J46:S46, I$5) = F46, "vw", "tu"))} -> vw | K46: 0 | L46: 0 | M46: 0
E47: Retained cash - initial balance | F47: =IF( INDEX(J47:S47, $I$4) = "", INDEX(J47:R47, $I$6), INDEX(J47:S47, $I$4)) -> 0 | G47: =SMU -> $ 000s | I47: {=IF( INDEX(J47:S47, I$5) = "", IF( INDEX(J47:S47, I$6) = F47, "vw", "tu"), IF(INDEX(J47:S47, I$5) = F47, "vw", "tu"))} -> vw | K47: 0 | L47: 0 | M47: 0
E48: Accounts receivable - initial balance | F48: =IF( INDEX(J48:S48, $I$4) = "", INDEX(J48:R48, $I$6), INDEX(J48:S48, $I$4)) -> 0 | G48: =SMU -> $ 000s | I48: {=IF( INDEX(J48:S48, I$5) = "", IF( INDEX(J48:S48, I$6) = F48, "vw", "tu"), IF(INDEX(J48:S48, I$5) = F48, "vw", "tu"))} -> vw | K48: 0 | L48: 0 | M48: 0
E49: Accounts payable - initial balance | F49: =IF( INDEX(J49:S49, $I$4) = "", INDEX(J49:R49, $I$6), INDEX(J49:S49, $I$4)) -> 0 | G49: =SMU -> $ 000s | I49: {=IF( INDEX(J49:S49, I$5) = "", IF( INDEX(J49:S49, I$6) = F49, "vw", "tu"), IF(INDEX(J49:S49, I$5) = F49, "vw", "tu"))} -> vw | K49: 0 | L49: 0 | M49: 0
E50: Fixed asset - initial balance | F50: =IF( INDEX(J50:S50, $I$4) = "", INDEX(J50:R50, $I$6), INDEX(J50:S50, $I$4)) -> 100000 | G50: =SMU -> $ 000s | I50: {=IF( INDEX(J50:S50, I$5) = "", IF( INDEX(J50:S50, I$6) = F50, "vw", "tu"), IF(INDEX(J50:S50, I$5) = F50, "vw", "tu"))} -> vw | K50: 100000 | L50: 100000 | M50: 100000
E51: Share capital - initial balance | F51: =IF( INDEX(J51:S51, $I$4) = "", INDEX(J51:R51, $I$6), INDEX(J51:S51, $I$4)) -> 100000 | G51: =SMU -> $ 000s | I51: {=IF( INDEX(J51:S51, I$5) = "", IF( INDEX(J51:S51, I$6) = F51, "vw", "tu"), IF(INDEX(J51:S51, I$5) = F51, "vw", "tu"))} -> vw | K51: 100000 | L51: 100000 | M51: 100000
A55: MODEL TECHNICAL INPUTS - DO NOT CHANGE
...

Sheet Time
A1: =RIGHT(CELL("filename", A1), LEN(CELL("filename", A1)) - SEARCH("]", CELL("filename", A1))) & " - " & InpC!F3 -> Time - Base case 1
E2: =Time!E$25 -> Model period ending | F2: =Check!$F$9 -> 0 | G2: Error chks | J2: =Time!J$25 -> 44104 | K2: =Time!K$25 -> 44196 | L2: =Time!L$25 -> 44286 | M2: =Time!M$25 -> 44377 | N2: =Time!N$25 -> 44469 | O2: =Time!O$25 -> 44561 | P2: =Time!P$25 -> 44651 | Q2: =Time!Q$25 -> 44742 | ... EA2: =Time!EA$25 -> 55153
E3: =Time!E$67 -> Timeline label | F3: =Output!J2 -> 0 | G3: Track chgs | J3: =Time!J$67 -> Pre-fcst | K3: =Time!K$67 -> Pre-fcst | L3: =Time!L$67 -> Fin Close | M3: =Time!M$67 -> Operations | N3: =Time!N$67 -> Operations | O3: =Time!O$67 -> Operations | P3: =Time!P$67 -> Operations | Q3: =Time!Q$67 -> Operations | ... EA3: =Time!EA$67 -> Post ops
E4: =Time!E$42 -> Contract year | F4: =Check!$F$21 -> 0 | G4: Alerts | J4: =Time!J$42 -> 2020 | K4: =Time!K$42 -> 2020 | L4: =Time!L$42 -> 2020 | M4: =Time!M$42 -> 2021 | N4: =Time!N$42 -> 2021 | O4: =Time!O$42 -> 2021 | P4: =Time!P$42 -> 2021 | Q4: =Time!Q$42 -> 2022 | ... EA4: =Time!EA$42 -> 2050
E5: =Time!E$10 -> Model column counter | F5: Constant | G5: Unit | H5: Total | J5: =Time!J$10 -> 1 | K5: =Time!K$10 -> 2 | L5: =Time!L$10 -> 3 | M5: =Time!M$10 -> 4 | N5: =Time!N$10 -> 5 | O5: =Time!O$10 -> 6 | P5: =Time!P$10 -> 7 | Q5: =Time!Q$10 -> 8 | ... EA5: =Time!EA$10 -> 122
A7: TIME RULER
B9: First model column
E10: Model column counter | G10: counter | J10: =I10 + 1 -> 1 | K10: =J10 + 1 -> 2 | L10: =K10 + 1 -> 3 | M10: =L10 + 1 -> 4 | N10: =M10 + 1 -> 5 | O10: =N10 + 1 -> 6 | P10: =O10 + 1 -> 7 | Q10: =P10 + 1 -> 8 | ... EA10: =DZ10 + 1 -> 122
E11: Model column total | F11: =MAX(J10:EA10) -> 122 | G11: columns
E13: =E$10 -> Model column counter | F13: =F$10 -> 0 | G13: =G$10 -> counter | H13: =H$10 -> 0 | I13: =I$10 -> 0 | J13: =J$10 -> 1 | K13: =K$10 -> 2 | L13: =L$10 -> 3 | ... EA13: =EA$10 -> 122
E14: First model column flag | G14: flag | H14: =SUM(J14:EA14) -> 1 | J14: =IF(J13 = 1, 1, 0) -> 1 | K14: =IF(K13 = 1, 1, 0) -> 0 | L14: =IF(L13 = 1, 1, 0) -> 0 | M14: =IF(M13 = 1, 1, 0) -> 0 | N14: =IF(N13 = 1, 1, 0) -> 0 | O14: =IF(O13 = 1, 1, 0) -> 0 | P14: =IF(P13 = 1, 1, 0) -> 0 | Q14: =IF(Q13 = 1, 1, 0) -> 0 | ... EA14: =IF(EA13 = 1, 1, 0) -> 0
B16: Model period beginning
E17: =InpC!E$13 -> First date of time rulers | F17: =InpC!F$13 -> 44013 | G17: =InpC!G$13 -> date
E18: =InpC!E$16 -> Length of operating period | F18: =InpC!F$16 -> 3 | G18: =InpC!G$16 -> months
E19: =E$14 -> First model column flag | F19: =F$14 -> 0 | G19: =G$14 -> flag | H19: =H$14 -> 1 | I19: =I$14 -> 0 | J19: =J$14 -> 1 | K19: =K$14 -> 0 | L19: =L$14 -> 0 | ... EA19: =EA$14 -> 0
E20: Model period beginning | G20: date | J20: =IF(J19 = 1, $F17, DATE(YEAR(I20), MONTH(I20) + $F18, DAY(1))) -> 44013 | K20: =IF(K19 = 1, $F17, DATE(YEAR(J20), MONTH(J20) + $F18, DAY(1))) -> 44105 | L20: =IF(L19 = 1, $F17, DATE(YEAR(K20), MONTH(K20) + $F18, DAY(1))) -> 44197 | M20: =IF(M19 = 1, $F17, DATE(YEAR(L20), MONTH(L20) + $F18, DAY(1))) -> 44287 | N20: =IF(N19 = 1, $F17, DATE(YEAR(M20), MONTH(M20) + $F18, DAY(1))) -> 44378 | O20: =IF(O19 = 1, $F17, DATE(YEAR(N20), MONTH(N20) + $F18, DAY(1))) -> 44470 | P20: =IF(P19 = 1, $F17, DATE(YEAR(O20), MONTH(O20) + $F18, DAY(1))) -> 44562 | Q20: =IF(Q19 = 1, $F17, DATE(YEAR(P20), MONTH(P20) + $F18, DAY(1))) -> 44652 | ... EA20: =IF(EA19 = 1, $F17, DATE(YEAR(DZ20), MONTH(DZ20) + $F18, DAY(1))) -> 55062
B22: Model period ending
E23: =InpC!E$16 -> Length of operating period | F23: =InpC!F$16 -> 3 | G23: =InpC!G$16 -> months
E24: =E$20 -> Model period beginning | F24: =F$20 -> 0 | G24: =G$20 -> date | H24: =H$20 -> 0 | I24: =I$20 -> 0 | J24: =J$20 -> 44013 | K24: =K$20 -> 44105 | L24: =L$20 -> 44197 | ... EA24: =EA$20 -> 55062
E25: Model period ending | G25: date | J25: =DATE(YEAR(J24), MONTH(J24) + $F23, DAY(J24) -1) -> 44104 | K25: =DATE(YEAR(K24), MONTH(K24) + $F23, DAY(K24) -1) -> 44196 | L25: =DATE(YEAR(L24), MONTH(L24) + $F23, DAY(L24) -1) -> 44286 | M25: =DATE(YEAR(M24), MONTH(M24) + $F23, DAY(M24) -1) -> 44377 | N25: =DATE(YEAR(N24), MONTH(N24) + $F23, DAY(N24) -1) -> 44469 | O25: =DATE(YEAR(O24), MONTH(O24) + $F23, DAY(O24) -1) -> 44561 | P25: =DATE(YEAR(P24), MONTH(P24) + $F23, DAY(P24) -1) -> 44651 | Q25: =DATE(YEAR(Q24), MONTH(Q24) + $F23, DAY(Q24) -1) -> 44742 | ... EA25: =DATE(YEAR(EA24), MONTH(EA24) + $F23, DAY(EA24) -1) -> 55153
B27: Contract year
E28: =InpC!E$18 -> Acquisition date | F28: =InpC!F$18 -> 44286 | G28: =InpC!G$18 -> date
E29: Contract year end month | F29: =MONTH(F28) -> 3 | G29: month
E31: =E$29 -> Contract year end month | F31: =F$29 -> 3 | G31: =G$29 -> month
E32: =E$25 -> Model period ending | F32: =F$25 -> 0 | G32: =G$25 -> date | H32: =H$25 -> 0 | I32: =I$25 -> 0 | J32: =J$25 -> 44104 | K32: =K$25 -> 44196 | L32: =L$25 -> 44286 | ... EA32: =EA$25 -> 55153
E33: End of contract year flag | J33: =IF( MONTH(J32) = $F31, 1, 0) -> 0 | K33: =IF( MONTH(K32) = $F31, 1, 0) -> 0 | L33: =IF( MONTH(L32) = $F31, 1, 0) -> 1 | M33: =IF( MONTH(M32) = $F31, 1, 0) -> 0 | N33: =IF( MONTH(N32) = $F31, 1, 0) -> 0 | O33: =IF( MONTH(O32) = $F31, 1, 0) -> 0 | P33: =IF( MONTH(P32) = $F31, 1, 0) -> 1 | Q33: =IF( MONTH(Q32) = $F31, 1, 0) -> 0 | ... EA33: =IF( MONTH(EA32) = $F31, 1, 0) -> 0
E35: =InpC!E$14 -> Annual year end date of first operating period | F35: =InpC!F$14 -> 43921 | G35: =InpC!G$14 -> date
E36: =InpC!E$59 -> Months in year | F36: =InpC!F$59 -> 12 | G36: =InpC!G$59 -> months
E37: =E$14 -> First model column flag | F37: =F$14 -> 0 | G37: =G$14 -> flag | H37: =H$14 -> 1 | I37: =I$14 -> 0 | J37: =J$14 -> 1 | K37: =K$14 -> 0 | L37: =L$14 -> 0 | ... EA37: =EA$14 -> 0
E38: =E$33 -> End of contract year flag | F38: =F$33 -> 0 | G38: =G$33 -> 0 | H38: =H$33 -> 0 | I38: =I$33 -> 0 | J38: =J$33 -> 0 | K38: =K$33 -> 0 | L38: =L$33 -> 1 | ... EA38: =EA$33 -> 0
E39: Contract year applicable to period | G39: date | J39: =IF( J37 = 1, $F35, IF( I38 = 1, EOMONTH(I39, 12), I39)) -> 43921 | K39: =IF( K37 = 1, $F35, IF( J38 = 1, EOMONTH(J39, 12), J39)) -> 43921 | L39: =IF( L37 = 1, $F35, IF( K38 = 1, EOMONTH(K39, 12), K39)) -> 43921 | M39: =IF( M37 = 1, $F35, IF( L38 = 1, EOMONTH(L39, 12), L39)) -> 44286 | N39: =IF( N37 = 1, $F35, IF( M38 = 1, EOMONTH(M39, 12), M39)) -> 44286 | O39: =IF( O37 = 1, $F35, IF( N38 = 1, EOMONTH(N39, 12), N39)) -> 44286 | P39: =IF( P37 = 1, $F35, IF( O38 = 1, EOMONTH(O39, 12), O39)) -> 44286 | Q39: =IF( Q37 = 1, $F35, IF( P38 = 1, EOMONTH(P39, 12), P39)) -> 44651 | ... EA39: =IF( EA37 = 1, $F35, IF( DZ38 = 1, EOMONTH(DZ39, 12), DZ39)) -> 54878
E41: =E$39 -> Contract year applicable to period | F41: =F$39 -> 0 | G41: =G$39 -> date | H41: =H$39 -> 0 | I41: =I$39 -> 0 | J41: =J$39 -> 43921 | K41: =K$39 -> 43921 | L41: =L$39 -> 43921 | ... EA41: =EA$39 -> 54878
E42: Contract year | G42: year # | J42: =YEAR(J41) -> 2020 | K42: =YEAR(K41) -> 2020 | L42: =YEAR(L41) -> 2020 | M42: =YEAR(M41) -> 2021 | N42: =YEAR(N41) -> 2021 | O42: =YEAR(O41) -> 2021 | P42: =YEAR(P41) -> 2021 | Q42: =YEAR(Q41) -> 2022 | ... EA42: =YEAR(EA41) -> 2050
B44: Annual timeline
E45: =InpC!E$14 -> Annual year end date of first operating period | F45: =InpC!F$14 -> 43921 | G45: =InpC!G$14 -> date
E46: =InpC!E$59 -> Months in year | F46: =InpC!F$59 -> 12 | G46: =InpC!G$59 -> months
E47: =E$14 -> First model column flag | F47: =F$14 -> 0 | G47: =G$14 -> flag | H47: =H$14 -> 1 | I47: =I$14 -> 0 | J47: =J$14 -> 1 | K47: =K$14 -> 0 | L47: =L$14 -> 0 | ... EA47: =EA$14 -> 0
E48: Model period ending - annual | G48: date | J48: =IF(J47 = 1, $F45, EOMONTH(I48, $F46)) -> 43921 | K48: =IF(K47 = 1, $F45, EOMONTH(J48, $F46)) -> 44286 | L48: =IF(L47 = 1, $F45, EOMONTH(K48, $F46)) -> 44651 | M48: =IF(M47 = 1, $F45, EOMONTH(L48, $F46)) -> 45016 | N48: =IF(N47 = 1, $F45, EOMONTH(M48, $F46)) -> 45382 | O48: =IF(O47 = 1, $F45, EOMONTH(N48, $F46)) -> 45747 | P48: =IF(P47 = 1, $F45, EOMONTH(O48, $F46)) -> 46112 | Q48: =IF(Q47 = 1, $F45, EOMONTH(P48, $F46)) -> 46477 | ... EA48: =IF(EA47 = 1, $F45, EOMONTH(DZ48, $F46)) -> 88115
E50: =E$67 -> Timeline label | F50: =F$67 -> 0 | G50: =G$67 -> label | H50: =H$67 -> 0 | I50: =I$67 -> 0 | J50: =J$67 -> Pre-fcst | K50: =K$67 -> Pre-fcst | L50: =L$67 -> Fin Close | ... EA50: =EA$67 -> Post ops
E51: =E$48 -> Model period ending - annual | F51: =F$48 -> 0 | G51: =G$48 -> date | H51: =H$48 -> 0 | I51: =I$48 -> 0 | J51: =J$48 -> 43921 | K51: =K$48 -> 44286 | L51: =L$48 -> 44651 | ... EA51: =EA$48 -> 88115
...

Sheet Ops
A1: =RIGHT(CELL("filename", A1), LEN(CELL("filename", A1)) - SEARCH("]", CELL("filename", A1))) & " - " & InpC!F3 -> Ops - Base case 1
E2: =Time!E$25 -> Model period ending | F2: =Check!$F$9 -> 0 | G2: Error chks | J2: =Time!J$25 -> 44104 | K2: =Time!K$25 -> 44196 | L2: =Time!L$25 -> 44286 | M2: =Time!M$25 -> 44377 | N2: =Time!N$25 -> 44469 | O2: =Time!O$25 -> 44561 | P2: =Time!P$25 -> 44651 | Q2: =Time!Q$25 -> 44742 | ... EA2: =Time!EA$25 -> 55153
E3: =Time!E$67 -> Timeline label | F3: =Output!J2 -> 0 | G3: Track chgs | J3: =Time!J$67 -> Pre-fcst | K3: =Time!K$67 -> Pre-fcst | L3: =Time!L$67 -> Fin Close | M3: =Time!M$67 -> Operations | N3: =Time!N$67 -> Operations | O3: =Time!O$67 -> Operations | P3: =Time!P$67 -> Operations | Q3: =Time!Q$67 -> Operations | ... EA3: =Time!EA$67 -> Post ops
E4: =Time!E$42 -> Contract year | F4: =Check!$F$21 -> 0 | G4: Alerts | J4: =Time!J$42 -> 2020 | K4: =Time!K$42 -> 2020 | L4: =Time!L$42 -> 2020 | M4: =Time!M$42 -> 2021 | N4: =Time!N$42 -> 2021 | O4: =Time!O$42 -> 2021 | P4: =Time!P$42 -> 2021 | Q4: =Time!Q$42 -> 2022 | ... EA4: =Time!EA$42 -> 2050
E5: =Time!E$10 -> Model column counter | F5: Constant | G5: Unit | H5: Total | J5: =Time!J$10 -> 1 | K5: =Time!K$10 -> 2 | L5: =Time!L$10 -> 3 | M5: =Time!M$10 -> 4 | N5: =Time!N$10 -> 5 | O5: =Time!O$10 -> 6 | P5: =Time!P$10 -> 7 | Q5: =Time!Q$10 -> 8 | ... EA5: =Time!EA$10 -> 122
A8: REVENUE
B10: Degradation
E11: =InpC!E$29 -> Annual degradation | F11: =InpC!F$29 -> 0.005 | G11: =InpC!G$29 -> % p.a.
E12: =Time!E$132 -> Contract year number | F12: =Time!F$132 -> 0 | G12: =Time!G$132 -> counter | H12: =Time!H$132 -> 0 | I12: =Time!I$132 -> 0 | J12: =Time!J$132 -> 0 | K12: =Time!K$132 -> 0 | L12: =Time!L$132 -> 0 | ... EA12: =Time!EA$132 -> 0
E13: =Time!E$97 -> Operating period flag | F13: =Time!F$97 -> 0 | G13: =Time!G$97 -> flag | H13: =Time!H$97 -> 100 | I13: =Time!I$97 -> 0 | J13: =Time!J$97 -> 0 | K13: =Time!K$97 -> 0 | L13: =Time!L$97 -> 0 | ... EA13: =Time!EA$97 -> 0
E14: Compound degradation | G14: % | J14: =IF( J13 = 1, 1 / ((1 + $F11) ^ (J12 - 1)), 0) -> 0 | K14: =IF( K13 = 1, 1 / ((1 + $F11) ^ (K12 - 1)), 0) -> 0 | L14: =IF( L13 = 1, 1 / ((1 + $F11) ^ (L12 - 1)), 0) -> 0 | M14: =IF( M13 = 1, 1 / ((1 + $F11) ^ (M12 - 1)), 0) -> 1 | N14: =IF( N13 = 1, 1 / ((1 + $F11) ^ (N12 - 1)), 0) -> 1 | O14: =IF( O13 = 1, 1 / ((1 + $F11) ^ (O12 - 1)), 0) -> 1 | P14: =IF( P13 = 1, 1 / ((1 + $F11) ^ (P12 - 1)), 0) -> 1 | Q14: =IF( Q13 = 1, 1 / ((1 + $F11) ^ (Q12 - 1)), 0) -> 0.99502488 | ... EA14: =IF( EA13 = 1, 1 / ((1 + $F11) ^ (EA12 - 1)), 0) -> 0
B16: Seasonality adjustment
E17: =InpC!E$24 -> Q1 seasonal adjustment | F17: =InpC!F$24 -> 0.33 | G17: =InpC!G$24 -> % of annual yield
E18: =InpC!E$25 -> Q2 seasonal adjustment | F18: =InpC!F$25 -> 0.36 | G18: =InpC!G$25 -> % of annual yield
E19: =InpC!E$26 -> Q3 seasonal adjustment | F19: =InpC!F$26 -> 0.155 | G19: =InpC!G$26 -> % of annual yield
E20: =InpC!E$27 -> Q4 seasonal adjustment | F20: =InpC!F$27 -> 0.155 | G20: =InpC!G$27 -> % of annual yield
E21: =Time!E$126 -> Period number | F21: =Time!F$126 -> 0 | G21: =Time!G$126 -> counter | H21: =Time!H$126 -> 0 | I21: =Time!I$126 -> 0 | J21: =Time!J$126 -> 0 | K21: =Time!K$126 -> 0 | L21: =Time!L$126 -> 0 | ... EA21: =Time!EA$126 -> 0
E22: =Time!E$97 -> Operating period flag | F22: =Time!F$97 -> 0 | G22: =Time!G$97 -> flag | H22: =Time!H$97 -> 100 | I22: =Time!I$97 -> 0 | J22: =Time!J$97 -> 0 | K22: =Time!K$97 -> 0 | L22: =Time!L$97 -> 0 | ... EA22: =Time!EA$97 -> 0
E23: Seasonality adjustment | G23: % | H23: =SUM(J23:GJ23) -> 25 | J23: =IF(J22 = 1, INDEX($F17:$F20, J21), 0) -> 0 | K23: =IF(K22 = 1, INDEX($F17:$F20, K21), 0) -> 0 | L23: =IF(L22 = 1, INDEX($F17:$F20, L21), 0) -> 0 | M23: =IF(M22 = 1, INDEX($F17:$F20, M21), 0) -> 0.33 | N23: =IF(N22 = 1, INDEX($F17:$F20, N21), 0) -> 0.36 | O23: =IF(O22 = 1, INDEX($F17:$F20, O21), 0) -> 0.155 | P23: =IF(P22 = 1, INDEX($F17:$F20, P21), 0) -> 0.155 | Q23: =IF(Q22 = 1, INDEX($F17:$F20, Q21), 0) -> 0.33 | ... EA23: =IF(EA22 = 1, INDEX($F17:$F20, EA21), 0) -> 0
B25: Electricity generation
E26: =InpC!E$30 -> Year 1 P50 yield | F26: =InpC!F$30 -> 250 | G26: =InpC!G$30 -> GWh
E27: =InpC!E$31 -> Availability | F27: =InpC!F$31 -> 0.97 | G27: =InpC!G$31 -> %
E28: =E$14 -> Compound degradation | F28: =F$14 -> 0 | G28: =G$14 -> % | H28: =H$14 -> 0 | I28: =I$14 -> 0 | J28: =J$14 -> 0 | K28: =K$14 -> 0 | L28: =L$14 -> 0 | ... EA28: =EA$14 -> 0
E29: =E$23 -> Seasonality adjustment | F29: =F$23 -> 0 | G29: =G$23 -> % | H29: =H$23 -> 25 | I29: =I$23 -> 0 | J29: =J$23 -> 0 | K29: =K$23 -> 0 | L29: =L$23 -> 0 | ... EA29: =EA$23 -> 0
E30: Electricity generation | G30: GWh | H30: =SUM(J30:GJ30) -> 5713.9951 | J30: =$F26 * $F27 * J28 * J29 -> 0 | K30: =$F26 * $F27 * K28 * K29 -> 0 | L30: =$F26 * $F27 * L28 * L29 -> 0 | M30: =$F26 * $F27 * M28 * M29 -> 80.025 | N30: =$F26 * $F27 * N28 * N29 -> 87.3 | O30: =$F26 * $F27 * O28 * O29 -> 37.5875 | P30: =$F26 * $F27 * P28 * P29 -> 37.5875 | Q30: =$F26 * $F27 * Q28 * Q29 -> 79.626866 | ... EA30: =$F26 * $F27 * EA28 * EA29 -> 0
B32: Electricity revenue
E33: =InpC!E$33 -> Power tariff | F33: =InpC!F$33 -> 0.065 | G33: =InpC!G$33 -> USD / kWh
E34: =InpC!E$63 -> GWh to kWh conversion | F34: =InpC!F$63 -> 1000000 | G34: =InpC!G$63 -> kWh / GWh
E35: =InpC!E$64 -> Units in a thousand | F35: =InpC!F$64 -> 1000 | G35: =InpC!G$64 -> units
E36: =E$30 -> Electricity generation | F36: =F$30 -> 0 | G36: =G$30 -> GWh | H36: =H$30 -> 5713.9951 | I36: =I$30 -> 0 | J36: =J$30 -> 0 | K36: =K$30 -> 0 | L36: =L$30 -> 0 | ... EA36: =EA$30 -> 0
E37: =Time!E$97 -> Operating period flag | F37: =Time!F$97 -> 0 | G37: =Time!G$97 -> flag | H37: =Time!H$97 -> 100 | I37: =Time!I$97 -> 0 | J37: =Time!J$97 -> 0 | K37: =Time!K$97 -> 0 | L37: =Time!L$97 -> 0 | ... EA37: =Time!EA$97 -> 0
E38: Electricity revenue | G38: =SMU -> $ 000s | H38: =SUM(J38:GJ38) -> 371409.68 | J38: =$F33 * $F34 / $F35 * J36 * J37 -> 0 | K38: =$F33 * $F34 / $F35 * K36 * K37 -> 0 | L38: =$F33 * $F34 / $F35 * L36 * L37 -> 0 | M38: =$F33 * $F34 / $F35 * M36 * M37 -> 5201.625 | N38: =$F33 * $F34 / $F35 * N36 * N37 -> 5674.5 | O38: =$F33 * $F34 / $F35 * O36 * O37 -> 2443.1875 | P38: =$F33 * $F34 / $F35 * P36 * P37 -> 2443.1875 | Q38: =$F33 * $F34 / $F35 * Q36 * Q37 -> 5175.7463 | ... EA38: =$F33 * $F34 / $F35 * EA36 * EA37 -> 0
A41: ACCOUNTS RECEIVABLE
B43: Forecast accounts receivable balance
E44: =InpC!E$42 -> Accounts receivable days | F44: =InpC!F$42 -> 60 | G44: =InpC!G$42 -> days
E45: =E$38 -> Electricity revenue | F45: =F$38 -> 0 | G45: =G$38 -> $ 000s | H45: =H$38 -> 371409.68 | I45: =I$38 -> 0 | J45: =J$38 -> 0 | K45: =K$38 -> 0 | L45: =L$38 -> 0 | ... EA45: =EA$38 -> 0
E46: =Time!E$138 -> Days in period | F46: =Time!F$138 -> 0 | G46: =Time!G$138 -> days | H46: =Time!H$138 -> 0 | I46: =Time!I$138 -> 0 | J46: =Time!J$138 -> 92 | K46: =Time!K$138 -> 92 | L46: =Time!L$138 -> 90 | ... EA46: =Time!EA$138 -> 92
E47: Forecast accounts receivable balance | G47: =SMU -> $ 000s | J47: =J45 / J46 * $F44 -> 0 | K47: =K45 / K46 * $F44 -> 0 | L47: =L45 / L46 * $F44 -> 0 | M47: =M45 / M46 * $F44 -> 3429.6429 | N47: =N45 / N46 * $F44 -> 3700.7609 | O47: =O45 / O46 * $F44 -> 1593.3832 | P47: =P45 / P46 * $F44 -> 1628.7917 | Q47: =Q45 / Q46 * $F44 -> 3412.58 | ... EA47: =EA45 / EA46 * $F44 -> 0
B49: Cash received from invoices
E50: =E$38 -> Electricity revenue | F50: =F$38 -> 0 | G50: =G$38 -> $ 000s | H50: =H$38 -> 371409.68 | I50: =I$38 -> 0 | J50: =J$38 -> 0 | K50: =K$38 -> 0 | L50: =L$38 -> 0 | ... EA50: =EA$38 -> 0
...

Sheet Asset
A1: =RIGHT(CELL("filename", A1), LEN(CELL("filename", A1)) - SEARCH("]", CELL("filename", A1))) & " - " & InpC!F3 -> Asset - Base case 1
E2: =Time!E$25 -> Model period ending | F2: =Check!$F$9 -> 0 | G2: Error chks | J2: =Time!J$25 -> 44104 | K2: =Time!K$25 -> 44196 | L2: =Time!L$25 -> 44286 | M2: =Time!M$25 -> 44377 | N2: =Time!N$25 -> 44469 | O2: =Time!O$25 -> 44561 | P2: =Time!P$25 -> 44651 | Q2: =Time!Q$25 -> 44742 | ... EA2: =Time!EA$25 -> 55153
E3: =Time!E$67 -> Timeline label | F3: =Output!J2 -> 0 | G3: Track chgs | J3: =Time!J$67 -> Pre-fcst | K3: =Time!K$67 -> Pre-fcst | L3: =Time!L$67 -> Fin Close | M3: =Time!M$67 -> Operations | N3: =Time!N$67 -> Operations | O3: =Time!O$67 -> Operations | P3: =Time!P$67 -> Operations | Q3: =Time!Q$67 -> Operations | ... EA3: =Time!EA$67 -> Post ops
E4: =Time!E$42 -> Contract year | F4: =Check!$F$21 -> 0 | G4: Alerts | J4: =Time!J$42 -> 2020 | K4: =Time!K$42 -> 2020 | L4: =Time!L$42 -> 2020 | M4: =Time!M$42 -> 2021 | N4: =Time!N$42 -> 2021 | O4: =Time!O$42 -> 2021 | P4: =Time!P$42 -> 2021 | Q4: =Time!Q$42 -> 2022 | ... EA4: =Time!EA$42 -> 2050
E5: =Time!E$10 -> Model column counter | F5: Constant | G5: Unit | H5: Total | J5: =Time!J$10 -> 1 | K5: =Time!K$10 -> 2 | L5: =Time!L$10 -> 3 | M5: =Time!M$10 -> 4 | N5: =Time!N$10 -> 5 | O5: =Time!O$10 -> 6 | P5: =Time!P$10 -> 7 | Q5: =Time!Q$10 -> 8 | ... EA5: =Time!EA$10 -> 122
A8: FIXED ASSET
B10: Depreciation
E11: =InpC!E$50 -> Fixed asset - initial balance | F11: =InpC!F$50 -> 100000 | G11: =InpC!G$50 -> $ 000s
E12: =InpC!E$39 -> Useful life of asset | F12: =InpC!F$39 -> 25 | G12: =InpC!G$39 -> years
E13: =InpC!E$60 -> Number of periods in a year | F13: =InpC!F$60 -> 4 | G13: =InpC!G$60 -> periods
E14: =Time!E$109 -> Useful life of asset flag | F14: =Time!F$109 -> 0 | G14: =Time!G$109 -> flag | H14: =Time!H$109 -> 100 | I14: =Time!I$109 -> 0 | J14: =Time!J$109 -> 0 | K14: =Time!K$109 -> 0 | L14: =Time!L$109 -> 0 | ... EA14: =Time!EA$109 -> 0
E15: Depreciation of fixed asset POS | G15: =SMU -> $ 000s | H15: =SUM(J15:EA15) -> 100000 | J15: =$F11 / $F12 / $F13 * J14 -> 0 | K15: =$F11 / $F12 / $F13 * K14 -> 0 | L15: =$F11 / $F12 / $F13 * L14 -> 0 | M15: =$F11 / $F12 / $F13 * M14 -> 1000 | N15: =$F11 / $F12 / $F13 * N14 -> 1000 | O15: =$F11 / $F12 / $F13 * O14 -> 1000 | P15: =$F11 / $F12 / $F13 * P14 -> 1000 | Q15: =$F11 / $F12 / $F13 * Q14 -> 1000 | ... EA15: =$F11 / $F12 / $F13 * EA14 -> 0
E16: =LEFT(E15, LEN(E15) - 4) -> Depreciation of fixed asset | G16: =SMU -> $ 000s | H16: =SUM(J16:EA16) -> -100000 | J16: =-1 * J15 -> 0 | K16: =-1 * K15 -> 0 | L16: =-1 * L15 -> 0 | M16: =-1 * M15 -> -1000 | N16: =-1 * N15 -> -1000 | O16: =-1 * O15 -> -1000 | P16: =-1 * P15 -> -1000 | Q16: =-1 * Q15 -> -1000 | ... EA16: =-1 * EA15 -> 0
B18: Fixed asset balance
E20: =InpC!E$50 -> Fixed asset - initial balance | F20: =InpC!F$50 -> 100000 | G20: =InpC!G$50 -> $ 000s
E21: =Time!E$76 -> Financial close date flag | F21: =Time!F$76 -> 0 | G21: =Time!G$76 -> flag | H21: =Time!H$76 -> 1 | I21: =Time!I$76 -> 0 | J21: =Time!J$76 -> 0 | K21: =Time!K$76 -> 0 | L21: =Time!L$76 -> 1 | ... EA21: =Time!EA$76 -> 0
E23: Fixed asset balance BEG | G23: =SMU -> $ 000s | J23: =I26 -> 0 | K23: =J26 -> 0 | L23: =K26 -> 0 | M23: =L26 -> 100000 | N23: =M26 -> 99000 | O23: =N26 -> 98000 | P23: =O26 -> 97000 | Q23: =P26 -> 96000 | ... EA23: =DZ26 -> 0
E24: [Additional capex]
E25: =E$15 -> Depreciation of fixed asset POS | F25: =F$15 -> 0 | G25: =G$15 -> $ 000s | H25: =H$15 -> 100000 | I25: =I$15 -> 0 | J25: =J$15 -> 0 | K25: =K$15 -> 0 | L25: =L$15 -> 0 | ... EA25: =EA$15 -> 0
E26: Fixed asset balance | G26: =SMU -> $ 000s | J26: =IF( J21 = 1, $F20, J23 + J24 - J25) -> 0 | K26: =IF( K21 = 1, $F20, K23 + K24 - K25) -> 0 | L26: =IF( L21 = 1, $F20, L23 + L24 - L25) -> 100000 | M26: =IF( M21 = 1, $F20, M23 + M24 - M25) -> 99000 | N26: =IF( N21 = 1, $F20, N23 + N24 - N25) -> 98000 | O26: =IF( O21 = 1, $F20, O23 + O24 - O25) -> 97000 | P26: =IF( P21 = 1, $F20, P23 + P24 - P25) -> 96000 | Q26: =IF( Q21 = 1, $F20, Q23 + Q24 - Q25) -> 95000 | ... EA26: =IF( EA21 = 1, $F20, EA23 + EA24 - EA25) -> 0
A30: END

Sheet Equity
A1: =RIGHT(CELL("filename", A1), LEN(CELL("filename", A1)) - SEARCH("]", CELL("filename", A1))) & " - " & InpC!F3 -> Equity - Base case 1
E2: =Time!E$25 -> Model period ending | F2: =Check!$F$9 -> 0 | G2: Error chks | J2: =Time!J$25 -> 44104 | K2: =Time!K$25 -> 44196 | L2: =Time!L$25 -> 44286 | M2: =Time!M$25 -> 44377 | N2: =Time!N$25 -> 44469 | O2: =Time!O$25 -> 44561 | P2: =Time!P$25 -> 44651 | Q2: =Time!Q$25 -> 44742 | ... EA2: =Time!EA$25 -> 55153
E3: =Time!E$67 -> Timeline label | F3: =Output!J2 -> 0 | G3: Track chgs | J3: =Time!J$67 -> Pre-fcst | K3: =Time!K$67 -> Pre-fcst | L3: =Time!L$67 -> Fin Close | M3: =Time!M$67 -> Operations | N3: =Time!N$67 -> Operations | O3: =Time!O$67 -> Operations | P3: =Time!P$67 -> Operations | Q3: =Time!Q$67 -> Operations | ... EA3: =Time!EA$67 -> Post ops
E4: =Time!E$42 -> Contract year | F4: =Check!$F$21 -> 0 | G4: Alerts | J4: =Time!J$42 -> 2020 | K4: =Time!K$42 -> 2020 | L4: =Time!L$42 -> 2020 | M4: =Time!M$42 -> 2021 | N4: =Time!N$42 -> 2021 | O4: =Time!O$42 -> 2021 | P4: =Time!P$42 -> 2021 | Q4: =Time!Q$42 -> 2022 | ... EA4: =Time!EA$42 -> 2050
E5: =Time!E$10 -> Model column counter | F5: Constant | G5: Unit | H5: Total | J5: =Time!J$10 -> 1 | K5: =Time!K$10 -> 2 | L5: =Time!L$10 -> 3 | M5: =Time!M$10 -> 4 | N5: =Time!N$10 -> 5 | O5: =Time!O$10 -> 6 | P5: =Time!P$10 -> 7 | Q5: =Time!Q$10 -> 8 | ... EA5: =Time!EA$10 -> 122
A8: SHARE CAPITAL
E10: =InpC!E$51 -> Share capital - initial balance | F10: =InpC!F$51 -> 100000 | G10: =InpC!G$51 -> $ 000s
E11: =Time!E$76 -> Financial close date flag | F11: =Time!F$76 -> 0 | G11: =Time!G$76 -> flag | H11: =Time!H$76 -> 1 | I11: =Time!I$76 -> 0 | J11: =Time!J$76 -> 0 | K11: =Time!K$76 -> 0 | L11: =Time!L$76 -> 1 | ... EA11: =Time!EA$76 -> 0
E13: Share capital balance BEG | G13: =SMU -> $ 000s | J13: =I16 -> 0 | K13: =J16 -> 0 | L13: =K16 -> 0 | M13: =L16 -> 100000 | N13: =M16 -> 100000 | O13: =N16 -> 100000 | P13: =O16 -> 100000 | Q13: =P16 -> 100000 | ... EA13: =DZ16 -> 100000
E14: [Additional share capital issued]
E15: [Share capital buy back / redemption]
E16: Share capital balance | G16: =SMU -> $ 000s | J16: =IF( J11 = 1, $F10, J13 + J14 - J15) -> 0 | K16: =IF( K11 = 1, $F10, K13 + K14 - K15) -> 0 | L16: =IF( L11 = 1, $F10, L13 + L14 - L15) -> 100000 | M16: =IF( M11 = 1, $F10, M13 + M14 - M15) -> 100000 | N16: =IF( N11 = 1, $F10, N13 + N14 - N15) -> 100000 | O16: =IF( O11 = 1, $F10, O13 + O14 - O15) -> 100000 | P16: =IF( P11 = 1, $F10, P13 + P14 - P15) -> 100000 | Q16: =IF( Q11 = 1, $F10, Q13 + Q14 - Q15) -> 100000 | ... EA16: =IF( EA11 = 1, $F10, EA13 + EA14 - EA15) -> 100000
A20: RETAINED EARNINGS
E22: =InpC!E$46 -> Retained earnings - initial balance | F22: =InpC!F$46 -> 0 | G22: =InpC!G$46 -> $ 000s
E23: =Time!E$76 -> Financial close date flag | F23: =Time!F$76 -> 0 | G23: =Time!G$76 -> flag | H23: =Time!H$76 -> 1 | I23: =Time!I$76 -> 0 | J23: =Time!J$76 -> 0 | K23: =Time!K$76 -> 0 | L23: =Time!L$76 -> 1 | ... EA23: =Time!EA$76 -> 0
E25: Retained earnings balance BEG | G25: =SMU -> $ 000s | J25: =I28 -> 0 | K25: =J28 -> 0 | L25: =K28 -> 0 | M25: =L28 -> 0 | N25: =M28 -> 2305.3984 | O25: =N28 -> 1577.2524 | P25: =O28 -> 0 | Q25: =P28 -> 0 | ... EA25: =DZ28 -> 0
E26: ='FS Qtr'!E$22 -> Profit after tax | F26: ='FS Qtr'!F$22 -> 0 | G26: ='FS Qtr'!G$22 -> $ 000s | H26: ='FS Qtr'!H$22 -> 222667.04 | I26: ='FS Qtr'!I$22 -> 0 | J26: ='FS Qtr'!J$22 -> 0 | K26: ='FS Qtr'!K$22 -> 0 | L26: ='FS Qtr'!L$22 -> 0 | ... EA26: ='FS Qtr'!EA$22 -> 0
E27: =E$56 -> Dividends paid POS | F27: =F$56 -> 0 | G27: =G$56 -> $ 000s | H27: =H$56 -> 222667.04 | I27: =I$56 -> 0 | J27: =J$56 -> 0 | K27: =K$56 -> 0 | L27: =L$56 -> 0 | ... EA27: =EA$56 -> 0
E28: Retained earnings balance | G28: =SMU -> $ 000s | J28: =IF( J23 = 1, $F22, J25 + J26 - J27) -> 0 | K28: =IF( K23 = 1, $F22, K25 + K26 - K27) -> 0 | L28: =IF( L23 = 1, $F22, L25 + L26 - L27) -> 0 | M28: =IF( M23 = 1, $F22, M25 + M26 - M27) -> 2305.3984 | N28: =IF( N23 = 1, $F22, N25 + N26 - N27) -> 1577.2524 | O28: =IF( O23 = 1, $F22, O25 + O26 - O27) -> 0 | P28: =IF( P23 = 1, $F22, P25 + P26 - P27) -> 0 | Q28: =IF( Q23 = 1, $F22, Q25 + Q26 - Q27) -> 0 | ... EA28: =IF( EA23 = 1, $F22, EA25 + EA26 - EA27) -> 0
A31: RETAINED CASH
E33: =InpC!E$47 -> Retained cash - initial balance | F33: =InpC!F$47 -> 0 | G33: =InpC!G$47 -> $ 000s
E34: =Time!E$76 -> Financial close date flag | F34: =Time!F$76 -> 0 | G34: =Time!G$76 -> flag | H34: =Time!H$76 -> 1 | I34: =Time!I$76 -> 0 | J34: =Time!J$76 -> 0 | K34: =Time!K$76 -> 0 | L34: =Time!L$76 -> 1 | ... EA34: =Time!EA$76 -> 0
E36: Retained cash balance BEG | G36: =SMU -> $ 000s | J36: =I39 -> 0 | K36: =J39 -> 0 | L36: =K39 -> 0 | M36: =L39 -> 0 | N36: =M39 -> 0 | O36: =N39 -> 0 | P36: =O39 -> 1530.7429 | Q36: =P39 -> 2498.7271 | ... EA36: =DZ39 -> 100000
E37: ='FS Qtr'!E$50 -> Cash flow available for dividends | F37: ='FS Qtr'!F$50 -> 0 | G37: ='FS Qtr'!G$50 -> $ 000s | H37: ='FS Qtr'!H$50 -> 322667.04 | I37: ='FS Qtr'!I$50 -> 0 | J37: ='FS Qtr'!J$50 -> 0 | K37: ='FS Qtr'!K$50 -> 0 | L37: ='FS Qtr'!L$50 -> 0 | ... EA37: ='FS Qtr'!EA$50 -> 0
E38: =E$56 -> Dividends paid POS | F38: =F$56 -> 0 | G38: =G$56 -> $ 000s | H38: =H$56 -> 222667.04 | I38: =I$56 -> 0 | J38: =J$56 -> 0 | K38: =K$56 -> 0 | L38: =L$56 -> 0 | ... EA38: =EA$56 -> 0
E39: Retained cash balance | G39: =SMU -> $ 000s | J39: =IF( J34 = 1, $F33, J36 + J37 - J38) -> 0 | K39: =IF( K34 = 1, $F33, K36 + K37 - K38) -> 0 | L39: =IF( L34 = 1, $F33, L36 + L37 - L38) -> 0 | M39: =IF( M34 = 1, $F33, M36 + M37 - M38) -> 0 | N39: =IF( N34 = 1, $F33, N36 + N37 - N38) -> 0 | O39: =IF( O34 = 1, $F33, O36 + O37 - O38) -> 1530.7429 | P39: =IF( P34 = 1, $F33, P36 + P37 - P38) -> 2498.7271 | Q39: =IF( Q34 = 1, $F33, Q36 + Q37 - Q38) -> 1714.1681 | ... EA39: =IF( EA34 = 1, $F33, EA36 + EA37 - EA38) -> 100000
A41: DIVIDENDS
B43: Earnings available for dividend
E44: =E$25 -> Retained earnings balance BEG | F44: =F$25 -> 0 | G44: =G$25 -> $ 000s | H44: =H$25 -> 0 | I44: =I$25 -> 0 | J44: =J$25 -> 0 | K44: =K$25 -> 0 | L44: =L$25 -> 0 | ... EA44: =EA$25 -> 0
E45: ='FS Qtr'!E$22 -> Profit after tax | F45: ='FS Qtr'!F$22 -> 0 | G45: ='FS Qtr'!G$22 -> $ 000s | H45: ='FS Qtr'!H$22 -> 222667.04 | I45: ='FS Qtr'!I$22 -> 0 | J45: ='FS Qtr'!J$22 -> 0 | K45: ='FS Qtr'!K$22 -> 0 | L45: ='FS Qtr'!L$22 -> 0 | ... EA45: ='FS Qtr'!EA$22 -> 0
E46: Earnings available for dividend | G46: =SMU -> $ 000s | J46: =SUM(J44:J45) -> 0 | K46: =SUM(K44:K45) -> 0 | L46: =SUM(L44:L45) -> 0 | M46: =SUM(M44:M45) -> 3824.75 | N46: =SUM(N44:N45) -> 6601.139 | O46: =SUM(O44:O45) -> 2639.7867 | P46: =SUM(P44:P45) -> 1060.6311 | Q46: =SUM(Q44:Q45) -> 3791.277 | ... EA46: =SUM(EA44:EA45) -> 0
B48: Cash available for dividend
E49: =E$36 -> Retained cash balance BEG | F49: =F$36 -> 0 | G49: =G$36 -> $ 000s | H49: =H$36 -> 0 | I49: =I$36 -> 0 | J49: =J$36 -> 0 | K49: =K$36 -> 0 | L49: =L$36 -> 0 | ... EA49: =EA$36 -> 100000
E50: ='FS Qtr'!E$50 -> Cash flow available for dividends | F50: ='FS Qtr'!F$50 -> 0 | G50: ='FS Qtr'!G$50 -> $ 000s | H50: ='FS Qtr'!H$50 -> 322667.04 | I50: ='FS Qtr'!I$50 -> 0 | J50: ='FS Qtr'!J$50 -> 0 | K50: ='FS Qtr'!K$50 -> 0 | L50: ='FS Qtr'!L$50 -> 0 | ... EA50: ='FS Qtr'!EA$50 -> 0
E51: Cash available for dividend | G51: =SMU -> $ 000s | J51: =SUM(J49:J50) -> 0 | K51: =SUM(K49:K50) -> 0 | L51: =SUM(L49:L50) -> 0 | M51: =SUM(M49:M50) -> 1519.3516 | N51: =SUM(N49:N50) -> 5023.8866 | O51: =SUM(O49:O50) -> 4170.5296 | P51: =SUM(P49:P50) -> 3559.3582 | Q51: =SUM(Q49:Q50) -> 5505.4452 | ... EA51: =SUM(EA49:EA50) -> 100000
B53: Dividends paid
E54: =E$46 -> Earnings available for dividend | F54: =F$46 -> 0 | G54: =G$46 -> $ 000s | H54: =H$46 -> 0 | I54: =I$46 -> 0 | J54: =J$46 -> 0 | K54: =K$46 -> 0 | L54: =L$46 -> 0 | ... EA54: =EA$46 -> 0
E55: =E$51 -> Cash available for dividend | F55: =F$51 -> 0 | G55: =G$51 -> $ 000s | H55: =H$51 -> 0 | I55: =I$51 -> 0 | J55: =J$51 -> 0 | K55: =K$51 -> 0 | L55: =L$51 -> 0 | ... EA55: =EA$51 -> 100000
E56: Dividends paid POS | G56: =SMU -> $ 000s | H56: =SUM(J56:EA56) -> 222667.04 | J56: =MAX(0, MIN(J54:J55)) -> 0 | K56: =MAX(0, MIN(K54:K55)) -> 0 | L56: =MAX(0, MIN(L54:L55)) -> 0 | M56: =MAX(0, MIN(M54:M55)) -> 1519.3516 | N56: =MAX(0, MIN(N54:N55)) -> 5023.8866 | O56: =MAX(0, MIN(O54:O55)) -> 2639.7867 | P56: =MAX(0, MIN(P54:P55)) -> 1060.6311 | Q56: =MAX(0, MIN(Q54:Q55)) -> 3791.277 | ... EA56: =MAX(0, MIN(EA54:EA55)) -> 0
E57: =LEFT(E56, LEN(E56) - 4) -> Dividends paid | G57: =SMU -> $ 000s | H57: =SUM(J57:EA57) -> -222667.04 | J57: =-1 * J56 -> 0 | K57: =-1 * K56 -> 0 | L57: =-1 * L56 -> 0 | M57: =-1 * M56 -> -1519.3516 | N57: =-1 * N56 -> -5023.8866 | O57: =-1 * O56 -> -2639.7867 | P57: =-1 * P56 -> -1060.6311 | Q57: =-1 * Q56 -> -3791.277 | ... EA57: =-1 * EA56 -> 0
...

Sheet Metrics
A1: =RIGHT(CELL("filename", A1), LEN(CELL("filename", A1)) - SEARCH("]", CELL("filename", A1))) & " - " & InpC!F3 -> Metrics - Base case 1
E2: =Time!E$25 -> Model period ending | F2: =Check!$F$9 -> 0 | G2: Error chks | J2: =Time!J$25 -> 44104 | K2: =Time!K$25 -> 44196 | L2: =Time!L$25 -> 44286 | M2: =Time!M$25 -> 44377 | N2: =Time!N$25 -> 44469 | O2: =Time!O$25 -> 44561 | P2: =Time!P$25 -> 44651 | Q2: =Time!Q$25 -> 44742 | ... EA2: =Time!EA$25 -> 55153
E3: =Time!E$67 -> Timeline label | F3: =Output!J2 -> 0 | G3: Track chgs | J3: =Time!J$67 -> Pre-fcst | K3: =Time!K$67 -> Pre-fcst | L3: =Time!L$67 -> Fin Close | M3: =Time!M$67 -> Operations | N3: =Time!N$67 -> Operations | O3: =Time!O$67 -> Operations | P3: =Time!P$67 -> Operations | Q3: =Time!Q$67 -> Operations | ... EA3: =Time!EA$67 -> Post ops
E4: =Time!E$42 -> Contract year | F4: =Check!$F$21 -> 0 | G4: Alerts | J4: =Time!J$42 -> 2020 | K4: =Time!K$42 -> 2020 | L4: =Time!L$42 -> 2020 | M4: =Time!M$42 -> 2021 | N4: =Time!N$42 -> 2021 | O4: =Time!O$42 -> 2021 | P4: =Time!P$42 -> 2021 | Q4: =Time!Q$42 -> 2022 | ... EA4: =Time!EA$42 -> 2050
E5: =Time!E$10 -> Model column counter | F5: Constant | G5: Unit | H5: Total | J5: =Time!J$10 -> 1 | K5: =Time!K$10 -> 2 | L5: =Time!L$10 -> 3 | M5: =Time!M$10 -> 4 | N5: =Time!N$10 -> 5 | O5: =Time!O$10 -> 6 | P5: =Time!P$10 -> 7 | Q5: =Time!Q$10 -> 8 | ... EA5: =Time!EA$10 -> 122
A7: IRR
B9: Equity IRR
E10: =InpC!E$51 -> Share capital - initial balance | F10: =InpC!F$51 -> 100000 | G10: =InpC!G$51 -> $ 000s
E11: =InpC!E$65 -> Small negative value for XIRR | F11: =InpC!F$65 -> -1e-07 | G11: =InpC!G$65 -> $ 000s
E12: =Time!E$76 -> Financial close date flag | F12: =Time!F$76 -> 0 | G12: =Time!G$76 -> flag | H12: =Time!H$76 -> 1 | I12: =Time!I$76 -> 0 | J12: =Time!J$76 -> 0 | K12: =Time!K$76 -> 0 | L12: =Time!L$76 -> 1 | ... EA12: =Time!EA$76 -> 0
E13: =Time!E$14 -> First model column flag | F13: =Time!F$14 -> 0 | G13: =Time!G$14 -> flag | H13: =Time!H$14 -> 1 | I13: =Time!I$14 -> 0 | J13: =Time!J$14 -> 1 | K13: =Time!K$14 -> 0 | L13: =Time!L$14 -> 0 | ... EA13: =Time!EA$14 -> 0
E14: =Equity!E$56 -> Dividends paid POS | F14: =Equity!F$56 -> 0 | G14: =Equity!G$56 -> $ 000s | H14: =Equity!H$56 -> 222667.04 | I14: =Equity!I$56 -> 0 | J14: =Equity!J$56 -> 0 | K14: =Equity!K$56 -> 0 | L14: =Equity!L$56 -> 0 | ... EA14: =Equity!EA$56 -> 0
E15: [Share capital redemption]
E16: Net cashflow to / (from) equity | G16: =SMU -> $ 000s | H16: =SUM(J16:EA16) -> 122667.04 | J16: =$F11 * J13 + -1 * $F10 * J12 + J14 + J15 -> -1e-07 | K16: =$F11 * K13 + -1 * $F10 * K12 + K14 + K15 -> 0 | L16: =$F11 * L13 + -1 * $F10 * L12 + L14 + L15 -> -100000 | M16: =$F11 * M13 + -1 * $F10 * M12 + M14 + M15 -> 1519.3516 | N16: =$F11 * N13 + -1 * $F10 * N12 + N14 + N15 -> 5023.8866 | O16: =$F11 * O13 + -1 * $F10 * O12 + O14 + O15 -> 2639.7867 | P16: =$F11 * P13 + -1 * $F10 * P12 + P14 + P15 -> 1060.6311 | Q16: =$F11 * Q13 + -1 * $F10 * Q12 + Q14 + Q15 -> 3791.277 | ... EA16: =$F11 * EA13 + -1 * $F10 * EA12 + EA14 + EA15 -> 0
E18: =E$16 -> Net cashflow to / (from) equity | F18: =F$16 -> 0 | G18: =G$16 -> $ 000s | H18: =H$16 -> 122667.04 | I18: =I$16 -> 0 | J18: =J$16 -> -1e-07 | K18: =K$16 -> 0 | L18: =L$16 -> -100000 | ... EA18: =EA$16 -> 0
E19: =Time!E$25 -> Model period ending | F19: =Time!F$25 -> 0 | G19: =Time!G$25 -> date | H19: =Time!H$25 -> 0 | I19: =Time!I$25 -> 0 | J19: =Time!J$25 -> 44104 | K19: =Time!K$25 -> 44196 | L19: =Time!L$25 -> 44286 | ... EA19: =Time!EA$25 -> 55153
E20: Equity IRR | F20: =XIRR(J18:EA18, J19:EA19) -> 0.084725401 | G20: %

Sheet FS Qtr
A1: =RIGHT(CELL("filename", A1), LEN(CELL("filename", A1)) - SEARCH("]", CELL("filename", A1))) & " - " & InpC!F3 -> FS Qtr - Base case 1
E2: =Time!E$25 -> Model period ending | F2: =Check!$F$9 -> 0 | G2: Error chks | J2: =Time!J$25 -> 44104 | K2: =Time!K$25 -> 44196 | L2: =Time!L$25 -> 44286 | M2: =Time!M$25 -> 44377 | N2: =Time!N$25 -> 44469 | O2: =Time!O$25 -> 44561 | P2: =Time!P$25 -> 44651 | Q2: =Time!Q$25 -> 44742 | ... EA2: =Time!EA$25 -> 55153
E3: =Time!E$67 -> Timeline label | F3: =Output!J2 -> 0 | G3: Track chgs | J3: =Time!J$67 -> Pre-fcst | K3: =Time!K$67 -> Pre-fcst | L3: =Time!L$67 -> Fin Close | M3: =Time!M$67 -> Operations | N3: =Time!N$67 -> Operations | O3: =Time!O$67 -> Operations | P3: =Time!P$67 -> Operations | Q3: =Time!Q$67 -> Operations | ... EA3: =Time!EA$67 -> Post ops
E4: =Time!E$42 -> Contract year | F4: =Check!$F$21 -> 0 | G4: Alerts | J4: =Time!J$42 -> 2020 | K4: =Time!K$42 -> 2020 | L4: =Time!L$42 -> 2020 | M4: =Time!M$42 -> 2021 | N4: =Time!N$42 -> 2021 | O4: =Time!O$42 -> 2021 | P4: =Time!P$42 -> 2021 | Q4: =Time!Q$42 -> 2022 | ... EA4: =Time!EA$42 -> 2050
E5: =Time!E$10 -> Model column counter | F5: Constant | G5: Unit | H5: Total | J5: =Time!J$10 -> 1 | K5: =Time!K$10 -> 2 | L5: =Time!L$10 -> 3 | M5: =Time!M$10 -> 4 | N5: =Time!N$10 -> 5 | O5: =Time!O$10 -> 6 | P5: =Time!P$10 -> 7 | Q5: =Time!Q$10 -> 8 | ... EA5: =Time!EA$10 -> 122
A7: INCOME STATEMENT
E9: =Ops!E$38 -> Electricity revenue | F9: =Ops!F$38 -> 0 | G9: =Ops!G$38 -> $ 000s | H9: =Ops!H$38 -> 371409.68 | I9: =Ops!I$38 -> 0 | J9: =Ops!J$38 -> 0 | K9: =Ops!K$38 -> 0 | L9: =Ops!L$38 -> 0 | ... EA9: =Ops!EA$38 -> 0
E10: =Ops!E$98 -> O&M cost | F10: =Ops!F$98 -> 0 | G10: =Ops!G$98 -> $ 000s | H10: =Ops!H$98 -> -48742.638 | I10: =Ops!I$98 -> 0 | J10: =Ops!J$98 -> 0 | K10: =Ops!K$98 -> 0 | L10: =Ops!L$98 -> 0 | ... EA10: =Ops!EA$98 -> 0
E11: EBITDA | G11: =SMU -> $ 000s | H11: =SUM(J11:EA11) -> 322667.04 | J11: =SUM(J9:J10) -> 0 | K11: =SUM(K9:K10) -> 0 | L11: =SUM(L9:L10) -> 0 | M11: =SUM(M9:M10) -> 4824.75 | N11: =SUM(N9:N10) -> 5295.7406 | O11: =SUM(O9:O10) -> 2062.5343 | P11: =SUM(P9:P10) -> 2060.6311 | Q11: =SUM(Q9:Q10) -> 4791.277 | ... EA11: =SUM(EA9:EA10) -> 0
E13: =Asset!E$16 -> Depreciation of fixed asset | F13: =Asset!F$16 -> 0 | G13: =Asset!G$16 -> $ 000s | H13: =Asset!H$16 -> -100000 | I13: =Asset!I$16 -> 0 | J13: =Asset!J$16 -> 0 | K13: =Asset!K$16 -> 0 | L13: =Asset!L$16 -> 0 | ... EA13: =Asset!EA$16 -> 0
E14: EBIT | G14: =SMU -> $ 000s | H14: =SUM(J14:EA14) -> 222667.04 | J14: =J11 + SUM(J13:J13) -> 0 | K14: =K11 + SUM(K13:K13) -> 0 | L14: =L11 + SUM(L13:L13) -> 0 | M14: =M11 + SUM(M13:M13) -> 3824.75 | N14: =N11 + SUM(N13:N13) -> 4295.7406 | O14: =O11 + SUM(O13:O13) -> 1062.5343 | P14: =P11 + SUM(P13:P13) -> 1060.6311 | Q14: =Q11 + SUM(Q13:Q13) -> 3791.277 | ... EA14: =EA11 + SUM(EA13:EA13) -> 0
E16: [Senior debt interest]
E17: [Refi facility interest]
E18: [RCF interest expense]
E19: Profit before tax | G19: =SMU -> $ 000s | H19: =SUM(J19:EA19) -> 222667.04 | J19: =J14 + SUM(J16:J18) -> 0 | K19: =K14 + SUM(K16:K18) -> 0 | L19: =L14 + SUM(L16:L18) -> 0 | M19: =M14 + SUM(M16:M18) -> 3824.75 | N19: =N14 + SUM(N16:N18) -> 4295.7406 | O19: =O14 + SUM(O16:O18) -> 1062.5343 | P19: =P14 + SUM(P16:P18) -> 1060.6311 | Q19: =Q14 + SUM(Q16:Q18) -> 3791.277 | ... EA19: =EA14 + SUM(EA16:EA18) -> 0
E21: [Corporate income tax expense]
E22: Profit after tax | G22: =SMU -> $ 000s | H22: =SUM(J22:EA22) -> 222667.04 | J22: =J19 + J21 -> 0 | K22: =K19 + K21 -> 0 | L22: =L19 + L21 -> 0 | M22: =M19 + M21 -> 3824.75 | N22: =N19 + N21 -> 4295.7406 | O22: =O19 + O21 -> 1062.5343 | P22: =P19 + P21 -> 1060.6311 | Q22: =Q19 + Q21 -> 3791.277 | ... EA22: =EA19 + EA21 -> 0
E24: =Equity!E$57 -> Dividends paid | F24: =Equity!F$57 -> 0 | G24: =Equity!G$57 -> $ 000s | H24: =Equity!H$57 -> -222667.04 | I24: =Equity!I$57 -> 0 | J24: =Equity!J$57 -> 0 | K24: =Equity!K$57 -> 0 | L24: =Equity!L$57 -> 0 | ... EA24: =Equity!EA$57 -> 0
E25: Net income after dividends | G25: =SMU -> $ 000s | H25: =SUM(J25:EA25) -> 0 | J25: =J22 + J24 -> 0 | K25: =K22 + K24 -> 0 | L25: =L22 + L24 -> 0 | M25: =M22 + M24 -> 2305.3984 | N25: =N22 + N24 -> -728.14597 | O25: =O22 + O24 -> -1577.2524 | P25: =P22 + P24 -> 0 | Q25: =Q22 + Q24 -> 0 | ... EA25: =EA22 + EA24 -> 0
A28: CASH FLOW STATEMENT
E30: =Ops!E$53 -> Cash received from invoices | F30: =Ops!F$53 -> 0 | G30: =Ops!G$53 -> $ 000s | H30: =Ops!H$53 -> 371409.68 | I30: =Ops!I$53 -> 0 | J30: =Ops!J$53 -> 0 | K30: =Ops!K$53 -> 0 | L30: =Ops!L$53 -> 0 | ... EA30: =Ops!EA$53 -> 0
E31: =Ops!E$114 -> Cash paid for operating costs | F31: =Ops!F$114 -> 0 | G31: =Ops!G$114 -> $ 000s | H31: =Ops!H$114 -> -48742.638 | I31: =Ops!I$114 -> 0 | J31: =Ops!J$114 -> 0 | K31: =Ops!K$114 -> 0 | L31: =Ops!L$114 -> 0 | ... EA31: =Ops!EA$114 -> 0
E32: [Corporate income tax expense]
E33: Cash flow available for senior debt service | G33: =SMU -> $ 000s | H33: =SUM(J33:EA33) -> 322667.04 | J33: =SUM(J30:J32) -> 0 | K33: =SUM(K30:K32) -> 0 | L33: =SUM(L30:L32) -> 0 | M33: =SUM(M30:M32) -> 1519.3516 | N33: =SUM(N30:N32) -> 5023.8866 | O33: =SUM(O30:O32) -> 4170.5296 | P33: =SUM(P30:P32) -> 2028.6153 | Q33: =SUM(Q30:Q32) -> 3006.718 | ... EA33: =SUM(EA30:EA32) -> 0
E35: [Senior debt interest]
E36: [Senior debt repayment]
E37: Cash flow available for refinancing facility | G37: =SMU -> $ 000s | H37: =SUM(J37:EA37) -> 322667.04 | J37: =J33 + SUM(J35:J36) -> 0 | K37: =K33 + SUM(K35:K36) -> 0 | L37: =L33 + SUM(L35:L36) -> 0 | M37: =M33 + SUM(M35:M36) -> 1519.3516 | N37: =N33 + SUM(N35:N36) -> 5023.8866 | O37: =O33 + SUM(O35:O36) -> 4170.5296 | P37: =P33 + SUM(P35:P36) -> 2028.6153 | Q37: =Q33 + SUM(Q35:Q36) -> 3006.718 | ... EA37: =EA33 + SUM(EA35:EA36) -> 0
E39: [Refi facility drawdown]
E40: [Refi facility repayment]
E41: [Refi facility interest]
E42: Cash flow available for revolving credit facility | G42: =SMU -> $ 000s | H42: =SUM(J42:EA42) -> 322667.04 | J42: =J37 + SUM(J39:J41) -> 0 | K42: =K37 + SUM(K39:K41) -> 0 | L42: =L37 + SUM(L39:L41) -> 0 | M42: =M37 + SUM(M39:M41) -> 1519.3516 | N42: =N37 + SUM(N39:N41) -> 5023.8866 | O42: =O37 + SUM(O39:O41) -> 4170.5296 | P42: =P37 + SUM(P39:P41) -> 2028.6153 | Q42: =Q37 + SUM(Q39:Q41) -> 3006.718 | ... EA42: =EA37 + SUM(EA39:EA41) -> 0
E44: [RCF drawdown]
E45: [RCF repayment]
E46: [RCF interest expense paid]
E47: Cash available for shareholders | G47: =SMU -> $ 000s | H47: =SUM(J47:EA47) -> 322667.04 | J47: =J42 + SUM(J44:J46) -> 0 | K47: =K42 + SUM(K44:K46) -> 0 | L47: =L42 + SUM(L44:L46) -> 0 | M47: =M42 + SUM(M44:M46) -> 1519.3516 | N47: =N42 + SUM(N44:N46) -> 5023.8866 | O47: =O42 + SUM(O44:O46) -> 4170.5296 | P47: =P42 + SUM(P44:P46) -> 2028.6153 | Q47: =Q42 + SUM(Q44:Q46) -> 3006.718 | ... EA47: =EA42 + SUM(EA44:EA46) -> 0
E49: [Share capital redemption]
E50: Cash flow available for dividends | G50: =SMU -> $ 000s | H50: =SUM(J50:EA50) -> 322667.04 | J50: =J47 + J49 -> 0 | K50: =K47 + K49 -> 0 | L50: =L47 + L49 -> 0 | M50: =M47 + M49 -> 1519.3516 | N50: =N47 + N49 -> 5023.8866 | O50: =O47 + O49 -> 4170.5296 | P50: =P47 + P49 -> 2028.6153 | Q50: =Q47 + Q49 -> 3006.718 | ... EA50: =EA47 + EA49 -> 0
E52: =Equity!E$57 -> Dividends paid | F52: =Equity!F$57 -> 0 | G52: =Equity!G$57 -> $ 000s | H52: =Equity!H$57 -> -222667.04 | I52: =Equity!I$57 -> 0 | J52: =Equity!J$57 -> 0 | K52: =Equity!K$57 -> 0 | L52: =Equity!L$57 -> 0 | ... EA52: =Equity!EA$57 -> 0
E53: Net cash flow after dividends | G53: =SMU -> $ 000s | H53: =SUM(J53:EA53) -> 100000 | J53: =J50 + J52 -> 0 | K53: =K50 + K52 -> 0 | L53: =L50 + L52 -> 0 | M53: =M50 + M52 -> 0 | N53: =N50 + N52 -> 0 | O53: =O50 + O52 -> 1530.7429 | P53: =P50 + P52 -> 967.98426 | Q53: =Q50 + Q52 -> -784.55901 | ... EA53: =EA50 + EA52 -> 0
A56: BALANCE SHEET
...

Sheet FS Ann
A1: =RIGHT(CELL("filename", A1), LEN(CELL("filename", A1)) - SEARCH("]", CELL("filename", A1))) & " - " & InpC!F3 -> FS Ann - Base case 1
E2: =Time!E$48 -> Model period ending - annual | F2: =Check!$F$9 -> 0 | G2: Error chks | J2: =Time!J$48 -> 43921 | K2: =Time!K$48 -> 44286 | L2: =Time!L$48 -> 44651 | M2: =Time!M$48 -> 45016 | N2: =Time!N$48 -> 45382 | O2: =Time!O$48 -> 45747 | P2: =Time!P$48 -> 46112 | Q2: =Time!Q$48 -> 46477 | ... AN2: =Time!AN$48 -> 54878
E3: =Time!E$53 -> Timeline label - annual | F3: =Output!J2 -> 0 | G3: Track chgs | J3: =Time!J$53 -> Pre-fcst | K3: =Time!K$53 -> Operations | L3: =Time!L$53 -> Operations | M3: =Time!M$53 -> Operations | N3: =Time!N$53 -> Operations | O3: =Time!O$53 -> Operations | P3: =Time!P$53 -> Operations | Q3: =Time!Q$53 -> Operations | ... AN3: =Time!AN$53 -> Post ops
E4: =Time!E$42 -> Contract year | F4: =Check!$F$21 -> 0 | G4: Alerts | J4: =YEAR(J2) -> 2020 | K4: =YEAR(K2) -> 2021 | L4: =YEAR(L2) -> 2022 | M4: =YEAR(M2) -> 2023 | N4: =YEAR(N2) -> 2024 | O4: =YEAR(O2) -> 2025 | P4: =YEAR(P2) -> 2026 | Q4: =YEAR(Q2) -> 2027 | ... AN4: =YEAR(AN2) -> 2050
E5: =Time!E$10 -> Model column counter | F5: Constant | G5: Unit | H5: Total | J5: =Time!J$10 -> 1 | K5: =Time!K$10 -> 2 | L5: =Time!L$10 -> 3 | M5: =Time!M$10 -> 4 | N5: =Time!N$10 -> 5 | O5: =Time!O$10 -> 6 | P5: =Time!P$10 -> 7 | Q5: =Time!Q$10 -> 8 | ... AN5: =Time!AN$10 -> 31
A7: INCOME STATEMENT
E9: ='FS Qtr'!E9 -> Electricity revenue | F9: ='FS Qtr'!F9 -> 0 | G9: ='FS Qtr'!G9 -> $ 000s | H9: =SUM(J9:AN9) -> 371409.68 | J9: =SUMIFS('FS Qtr'!$J9:$EA9, 'FS Qtr'!$J$4:$EA$4, 'FS Ann'!J$4) -> 0 | K9: =SUMIFS('FS Qtr'!$J9:$EA9, 'FS Qtr'!$J$4:$EA$4, 'FS Ann'!K$4) -> 15762.5 | L9: =SUMIFS('FS Qtr'!$J9:$EA9, 'FS Qtr'!$J$4:$EA$4, 'FS Ann'!L$4) -> 15684.08 | M9: =SUMIFS('FS Qtr'!$J9:$EA9, 'FS Qtr'!$J$4:$EA$4, 'FS Ann'!M$4) -> 15606.049 | N9: =SUMIFS('FS Qtr'!$J9:$EA9, 'FS Qtr'!$J$4:$EA$4, 'FS Ann'!N$4) -> 15528.407 | O9: =SUMIFS('FS Qtr'!$J9:$EA9, 'FS Qtr'!$J$4:$EA$4, 'FS Ann'!O$4) -> 15451.152 | P9: =SUMIFS('FS Qtr'!$J9:$EA9, 'FS Qtr'!$J$4:$EA$4, 'FS Ann'!P$4) -> 15374.28 | Q9: =SUMIFS('FS Qtr'!$J9:$EA9, 'FS Qtr'!$J$4:$EA$4, 'FS Ann'!Q$4) -> 15297.791 | ... AN9: =SUMIFS('FS Qtr'!$J9:$EA9, 'FS Qtr'!$J$4:$EA$4, 'FS Ann'!AN$4) -> 0
E10: ='FS Qtr'!E10 -> O&M cost | F10: ='FS Qtr'!F10 -> 0 | G10: ='FS Qtr'!G10 -> $ 000s | H10: =SUM(J10:AN10) -> -48742.638 | J10: =SUMIFS('FS Qtr'!$J10:$EA10, 'FS Qtr'!$J$4:$EA$4, 'FS Ann'!J$4) -> 0 | K10: =SUMIFS('FS Qtr'!$J10:$EA10, 'FS Qtr'!$J$4:$EA$4, 'FS Ann'!K$4) -> -1518.844 | L10: =SUMIFS('FS Qtr'!$J10:$EA10, 'FS Qtr'!$J$4:$EA$4, 'FS Ann'!L$4) -> -1549.4495 | M10: =SUMIFS('FS Qtr'!$J10:$EA10, 'FS Qtr'!$J$4:$EA$4, 'FS Ann'!M$4) -> -1580.6716 | N10: =SUMIFS('FS Qtr'!$J10:$EA10, 'FS Qtr'!$J$4:$EA$4, 'FS Ann'!N$4) -> -1612.523 | O10: =SUMIFS('FS Qtr'!$J10:$EA10, 'FS Qtr'!$J$4:$EA$4, 'FS Ann'!O$4) -> -1645.0161 | P10: =SUMIFS('FS Qtr'!$J10:$EA10, 'FS Qtr'!$J$4:$EA$4, 'FS Ann'!P$4) -> -1678.164 | Q10: =SUMIFS('FS Qtr'!$J10:$EA10, 'FS Qtr'!$J$4:$EA$4, 'FS Ann'!Q$4) -> -1711.9798 | ... AN10: =SUMIFS('FS Qtr'!$J10:$EA10, 'FS Qtr'!$J$4:$EA$4, 'FS Ann'!AN$4) -> 0
E11: EBITDA | G11: =SMU -> $ 000s | H11: =SUM(J11:AN11) -> 322667.04 | J11: =SUM(J9:J10) -> 0 | K11: =SUM(K9:K10) -> 14243.656 | L11: =SUM(L9:L10) -> 14134.63 | M11: =SUM(M9:M10) -> 14025.378 | N11: =SUM(N9:N10) -> 13915.884 | O11: =SUM(O9:O10) -> 13806.135 | P11: =SUM(P9:P10) -> 13696.116 | Q11: =SUM(Q9:Q10) -> 13585.811 | ... AN11: =SUM(AN9:AN10) -> 0
E13: ='FS Qtr'!E13 -> Depreciation of fixed asset | F13: ='FS Qtr'!F13 -> 0 | G13: ='FS Qtr'!G13 -> $ 000s | H13: =SUM(J13:AN13) -> -100000 | J13: =SUMIFS('FS Qtr'!$J13:$EA13, 'FS Qtr'!$J$4:$EA$4, 'FS Ann'!J$4) -> 0 | K13: =SUMIFS('FS Qtr'!$J13:$EA13, 'FS Qtr'!$J$4:$EA$4, 'FS Ann'!K$4) -> -4000 | L13: =SUMIFS('FS Qtr'!$J13:$EA13, 'FS Qtr'!$J$4:$EA$4, 'FS Ann'!L$4) -> -4000 | M13: =SUMIFS('FS Qtr'!$J13:$EA13, 'FS Qtr'!$J$4:$EA$4, 'FS Ann'!M$4) -> -4000 | N13: =SUMIFS('FS Qtr'!$J13:$EA13, 'FS Qtr'!$J$4:$EA$4, 'FS Ann'!N$4) -> -4000 | O13: =SUMIFS('FS Qtr'!$J13:$EA13, 'FS Qtr'!$J$4:$EA$4, 'FS Ann'!O$4) -> -4000 | P13: =SUMIFS('FS Qtr'!$J13:$EA13, 'FS Qtr'!$J$4:$EA$4, 'FS Ann'!P$4) -> -4000 | Q13: =SUMIFS('FS Qtr'!$J13:$EA13, 'FS Qtr'!$J$4:$EA$4, 'FS Ann'!Q$4) -> -4000 | ... AN13: =SUMIFS('FS Qtr'!$J13:$EA13, 'FS Qtr'!$J$4:$EA$4, 'FS Ann'!AN$4) -> 0
E14: EBIT | G14: =SMU -> $ 000s | H14: =SUM(J14:AN14) -> 222667.04 | J14: =J11 + J13 -> 0 | K14: =K11 + K13 -> 10243.656 | L14: =L11 + L13 -> 10134.63 | M14: =M11 + M13 -> 10025.378 | N14: =N11 + N13 -> 9915.8844 | O14: =O11 + O13 -> 9806.1355 | P14: =P11 + P13 -> 9696.1162 | Q14: =Q11 + Q13 -> 9585.8114 | ... AN14: =AN11 + AN13 -> 0
E16: ='FS Qtr'!E16 -> [Senior debt interest] | F16: ='FS Qtr'!F16 -> 0 | G16: ='FS Qtr'!G16 -> 0 | H16: =SUM(J16:AN16) -> 0 | J16: =SUMIFS('FS Qtr'!$J16:$EA16, 'FS Qtr'!$J$4:$EA$4, 'FS Ann'!J$4) -> 0 | K16: =SUMIFS('FS Qtr'!$J16:$EA16, 'FS Qtr'!$J$4:$EA$4, 'FS Ann'!K$4) -> 0 | L16: =SUMIFS('FS Qtr'!$J16:$EA16, 'FS Qtr'!$J$4:$EA$4, 'FS Ann'!L$4) -> 0 | M16: =SUMIFS('FS Qtr'!$J16:$EA16, 'FS Qtr'!$J$4:$EA$4, 'FS Ann'!M$4) -> 0 | N16: =SUMIFS('FS Qtr'!$J16:$EA16, 'FS Qtr'!$J$4:$EA$4, 'FS Ann'!N$4) -> 0 | O16: =SUMIFS('FS Qtr'!$J16:$EA16, 'FS Qtr'!$J$4:$EA$4, 'FS Ann'!O$4) -> 0 | P16: =SUMIFS('FS Qtr'!$J16:$EA16, 'FS Qtr'!$J$4:$EA$4, 'FS Ann'!P$4) -> 0 | Q16: =SUMIFS('FS Qtr'!$J16:$EA16, 'FS Qtr'!$J$4:$EA$4, 'FS Ann'!Q$4) -> 0 | ... AN16: =SUMIFS('FS Qtr'!$J16:$EA16, 'FS Qtr'!$J$4:$EA$4, 'FS Ann'!AN$4) -> 0
E17: ='FS Qtr'!E17 -> [Refi facility interest] | F17: ='FS Qtr'!F17 -> 0 | G17: ='FS Qtr'!G17 -> 0 | H17: =SUM(J17:AN17) -> 0 | J17: =SUMIFS('FS Qtr'!$J17:$EA17, 'FS Qtr'!$J$4:$EA$4, 'FS Ann'!J$4) -> 0 | K17: =SUMIFS('FS Qtr'!$J17:$EA17, 'FS Qtr'!$J$4:$EA$4, 'FS Ann'!K$4) -> 0 | L17: =SUMIFS('FS Qtr'!$J17:$EA17, 'FS Qtr'!$J$4:$EA$4, 'FS Ann'!L$4) -> 0 | M17: =SUMIFS('FS Qtr'!$J17:$EA17, 'FS Qtr'!$J$4:$EA$4, 'FS Ann'!M$4) -> 0 | N17: =SUMIFS('FS Qtr'!$J17:$EA17, 'FS Qtr'!$J$4:$EA$4, 'FS Ann'!N$4) -> 0 | O17: =SUMIFS('FS Qtr'!$J17:$EA17, 'FS Qtr'!$J$4:$EA$4, 'FS Ann'!O$4) -> 0 | P17: =SUMIFS('FS Qtr'!$J17:$EA17, 'FS Qtr'!$J$4:$EA$4, 'FS Ann'!P$4) -> 0 | Q17: =SUMIFS('FS Qtr'!$J17:$EA17, 'FS Qtr'!$J$4:$EA$4, 'FS Ann'!Q$4) -> 0 | ... AN17: =SUMIFS('FS Qtr'!$J17:$EA17, 'FS Qtr'!$J$4:$EA$4, 'FS Ann'!AN$4) -> 0
E18: ='FS Qtr'!E18 -> [RCF interest expense] | F18: ='FS Qtr'!F18 -> 0 | G18: ='FS Qtr'!G18 -> 0 | H18: =SUM(J18:AN18) -> 0 | J18: =SUMIFS('FS Qtr'!$J18:$EA18, 'FS Qtr'!$J$4:$EA$4, 'FS Ann'!J$4) -> 0 | K18: =SUMIFS('FS Qtr'!$J18:$EA18, 'FS Qtr'!$J$4:$EA$4, 'FS Ann'!K$4) -> 0 | L18: =SUMIFS('FS Qtr'!$J18:$EA18, 'FS Qtr'!$J$4:$EA$4, 'FS Ann'!L$4) -> 0 | M18: =SUMIFS('FS Qtr'!$J18:$EA18, 'FS Qtr'!$J$4:$EA$4, 'FS Ann'!M$4) -> 0 | N18: =SUMIFS('FS Qtr'!$J18:$EA18, 'FS Qtr'!$J$4:$EA$4, 'FS Ann'!N$4) -> 0 | O18: =SUMIFS('FS Qtr'!$J18:$EA18, 'FS Qtr'!$J$4:$EA$4, 'FS Ann'!O$4) -> 0 | P18: =SUMIFS('FS Qtr'!$J18:$EA18, 'FS Qtr'!$J$4:$EA$4, 'FS Ann'!P$4) -> 0 | Q18: =SUMIFS('FS Qtr'!$J18:$EA18, 'FS Qtr'!$J$4:$EA$4, 'FS Ann'!Q$4) -> 0 | ... AN18: =SUMIFS('FS Qtr'!$J18:$EA18, 'FS Qtr'!$J$4:$EA$4, 'FS Ann'!AN$4) -> 0
E19: EBT | G19: =SMU -> $ 000s | H19: =SUM(J19:AN19) -> 222667.04 | J19: =J14 + SUM(J16:J18) -> 0 | K19: =K14 + SUM(K16:K18) -> 10243.656 | L19: =L14 + SUM(L16:L18) -> 10134.63 | M19: =M14 + SUM(M16:M18) -> 10025.378 | N19: =N14 + SUM(N16:N18) -> 9915.8844 | O19: =O14 + SUM(O16:O18) -> 9806.1355 | P19: =P14 + SUM(P16:P18) -> 9696.1162 | Q19: =Q14 + SUM(Q16:Q18) -> 9585.8114 | ... AN19: =AN14 + SUM(AN16:AN18) -> 0
E21: ='FS Qtr'!E21 -> [Corporate income tax expense] | F21: ='FS Qtr'!F21 -> 0 | G21: ='FS Qtr'!G21 -> 0 | H21: =SUM(J21:AN21) -> 0 | J21: =SUMIFS('FS Qtr'!$J21:$EA21, 'FS Qtr'!$J$4:$EA$4, 'FS Ann'!J$4) -> 0 | K21: =SUMIFS('FS Qtr'!$J21:$EA21, 'FS Qtr'!$J$4:$EA$4, 'FS Ann'!K$4) -> 0 | L21: =SUMIFS('FS Qtr'!$J21:$EA21, 'FS Qtr'!$J$4:$EA$4, 'FS Ann'!L$4) -> 0 | M21: =SUMIFS('FS Qtr'!$J21:$EA21, 'FS Qtr'!$J$4:$EA$4, 'FS Ann'!M$4) -> 0 | N21: =SUMIFS('FS Qtr'!$J21:$EA21, 'FS Qtr'!$J$4:$EA$4, 'FS Ann'!N$4) -> 0 | O21: =SUMIFS('FS Qtr'!$J21:$EA21, 'FS Qtr'!$J$4:$EA$4, 'FS Ann'!O$4) -> 0 | P21: =SUMIFS('FS Qtr'!$J21:$EA21, 'FS Qtr'!$J$4:$EA$4, 'FS Ann'!P$4) -> 0 | Q21: =SUMIFS('FS Qtr'!$J21:$EA21, 'FS Qtr'!$J$4:$EA$4, 'FS Ann'!Q$4) -> 0 | ... AN21: =SUMIFS('FS Qtr'!$J21:$EA21, 'FS Qtr'!$J$4:$EA$4, 'FS Ann'!AN$4) -> 0
E22: EBT | G22: =SMU -> $ 000s | H22: =SUM(J22:AN22) -> 222667.04 | J22: =J19 + J21 -> 0 | K22: =K19 + K21 -> 10243.656 | L22: =L19 + L21 -> 10134.63 | M22: =M19 + M21 -> 10025.378 | N22: =N19 + N21 -> 9915.8844 | O22: =O19 + O21 -> 9806.1355 | P22: =P19 + P21 -> 9696.1162 | Q22: =Q19 + Q21 -> 9585.8114 | ... AN22: =AN19 + AN21 -> 0
E24: ='FS Qtr'!E24 -> Dividends paid | F24: ='FS Qtr'!F24 -> 0 | G24: ='FS Qtr'!G24 -> $ 000s | H24: =SUM(J24:AN24) -> -222667.04 | J24: =SUMIFS('FS Qtr'!$J24:$EA24, 'FS Qtr'!$J$4:$EA$4, 'FS Ann'!J$4) -> 0 | K24: =SUMIFS('FS Qtr'!$J24:$EA24, 'FS Qtr'!$J$4:$EA$4, 'FS Ann'!K$4) -> -10243.656 | L24: =SUMIFS('FS Qtr'!$J24:$EA24, 'FS Qtr'!$J$4:$EA$4, 'FS Ann'!L$4) -> -10134.63 | M24: =SUMIFS('FS Qtr'!$J24:$EA24, 'FS Qtr'!$J$4:$EA$4, 'FS Ann'!M$4) -> -10025.378 | N24: =SUMIFS('FS Qtr'!$J24:$EA24, 'FS Qtr'!$J$4:$EA$4, 'FS Ann'!N$4) -> -9915.8844 | O24: =SUMIFS('FS Qtr'!$J24:$EA24, 'FS Qtr'!$J$4:$EA$4, 'FS Ann'!O$4) -> -9806.1355 | P24: =SUMIFS('FS Qtr'!$J24:$EA24, 'FS Qtr'!$J$4:$EA$4, 'FS Ann'!P$4) -> -9696.1162 | Q24: =SUMIFS('FS Qtr'!$J24:$EA24, 'FS Qtr'!$J$4:$EA$4, 'FS Ann'!Q$4) -> -9585.8114 | ... AN24: =SUMIFS('FS Qtr'!$J24:$EA24, 'FS Qtr'!$J$4:$EA$4, 'FS Ann'!AN$4) -> 0
E25: Net income | G25: =SMU -> $ 000s | H25: =SUM(J25:AN25) -> 0 | J25: =J22 + J24 -> 0 | K25: =K22 + K24 -> 0 | L25: =L22 + L24 -> 0 | M25: =M22 + M24 -> 0 | N25: =N22 + N24 -> 0 | O25: =O22 + O24 -> 0 | P25: =P22 + P24 -> 0 | Q25: =Q22 + Q24 -> 0 | ... AN25: =AN22 + AN24 -> 0
A28: CASH FLOW STATEMENT
