Workbook
Name BaseCaseIndicator: InpC!$J$7:$S$7
Name CASE_ACTIVE: InpC!$F$4
Name CHK_TOL: InpC!$F$72
Name InputRowTemplate: InpC!$E$87:$S$87
Name InputStored: InpC!$J$3:$S$3
Name OutputRowTemplate: Output!$E$69:$AF$69
Name SMU: InpC!$F$75
Name TrackActive: Output!$H$5
Name TrackLiveResults: Output!$H$6:$H$76
Name TrackStoredResults: Output!$M$5:$AF$5
Name TRK_TOL: InpC!$F$71

Sheet InpC
A1: =RIGHT(CELL("filename", A1), LEN(CELL("filename", A1)) - SEARCH("]", CELL("filename", A1))) & " - " & $F$3 -> InpC - Base case 1
K2: =IF(K4 = $F4, "q", "") -> q | L2: =IF(L4 = $F4, "q", "") | M2: =IF(M4 = $F4, "q", "") | O2: =IF(O4 = $F4, "q", "") | P2: =IF(P4 = $F4, "q", "") | Q2: =IF(Q4 = $F4, "q", "") | R2: =IF(R4 = $F4, "q", "")
F3: =INDEX(J3:S3,MATCH(F4,J4:S4)) -> Base case 1 | K3: Base case 1 | L3: Base case 2 | M3: Base case 3 | O3: Scenario 1 | P3: Scenario 2 | Q3: Scenario 3 | R3: Scenario 4
E4: Active scenario | F4: 1 | I4: =MATCH(F4, $J$4:$S$4) -> 2 | K4: 1 | L4: 2 | M4: 3 | O4: 5 | P4: 6 | Q4: 7 | R4: 8
E5: Comparison scenario | F5: 1 | I5: =MATCH(F5, $J$4:$S$4) -> 2
E6: Base case | F6: =INDEX(J6:S6,MATCH(F4,J4:S4,0)) -> 1 | I6: =MATCH(F6, $J$4:$S$4) -> 2 | K6: 1 | L6: 2 | M6: 3 | O6: 1 | P6: 1 | Q6: 2 | R6: 2
E7: Input differences | F7: =COUNTIF(I10:I69, "tu") -> 0 | K7: =IF(K6 = $F$6, "Base case", "") -> Base case | L7: =IF(L6 = $F$6, "Base case", "") | M7: =IF(M6 = $F$6, "Base case", "")
F9: Constant | G9: Unit | H9: Source
A11: TIMING ASSUMPTIONS
E13: First date of time rulers | F13: =IF( INDEX(J13:S13, $I$4) = "", INDEX(J13:R13, $I$6), INDEX(J13:S13, $I$4)) -> 44013 | G13: date | I13: {=IF( INDEX(J13:S13, I$5) = "", IF( INDEX(J13:S13, I$6) = F13, "vw", "tu"), IF(INDEX(J13:S13, I$5) = F13, "vw", "tu"))} -> vw | K13: 44013
E14: Annual year end date of first operating period | F14: =IF( INDEX(J14:S14, $I$4) = "", INDEX(J14:R14, $I$6), INDEX(J14:S14, $I$4)) -> 43921 | G14: date | I14: {=IF( INDEX(J14:S14, I$5) = "", IF( INDEX(J14:S14, I$6) = F14, "vw", "tu"), IF(INDEX(J14:S14, I$5) = F14, "vw", "tu"))} -> vw | K14: 43921
E15: Financial year end month number | F15: =IF( INDEX(J15:S15, $I$4) = "", INDEX(J15:R15, $I$6), INDEX(J15:S15, $I$4)) -> 12 | G15: month # | I15: {=IF( INDEX(J15:S15, I$5) = "", IF( INDEX(J15:S15, I$6) = F15, "vw", "tu"), IF(INDEX(J15:S15, I$5) = F15, "vw", "tu"))} -> vw | K15: 12
E16: Length of operating period | F16: =IF( INDEX(J16:S16, $I$4) = "", INDEX(J16:R16, $I$6), INDEX(J16:S16, $I$4)) -> 3 | G16: months | I16: {=IF( INDEX(J16:S16, I$5) = "", IF( INDEX(J16:S16, I$6) = F16, "vw", "tu"), IF(INDEX(J16:S16, I$5) = F16, "vw", "tu"))} -> vw | K16: 3
E18: Acquisition date | F18: =IF( INDEX(J18:S18, $I$4) = "", INDEX(J18:R18, $I$6), INDEX(J18:S18, $I$4)) -> 44286 | G18: date | I18: {=IF( INDEX(J18:S18, I$5) = "", IF( INDEX(J18:S18, I$6) = F18, "vw", "tu"), IF(INDEX(J18:S18, I$5) = F18, "vw", "tu"))} -> vw | K18: 44286
E20: Operating years remaining | F20: =IF( INDEX(J20:S20, $I$4) = "", INDEX(J20:R20, $I$6), INDEX(J20:S20, $I$4)) -> 25 | G20: years | I20: {=IF( INDEX(J20:S20, I$5) = "", IF( INDEX(J20:S20, I$6) = F20, "vw", "tu"), IF(INDEX(J20:S20, I$5) = F20, "vw", "tu"))} -> vw | K20: 25
E21: Contract extension | F21: =IF( INDEX(J21:S21, $I$4) = "", INDEX(J21:R21, $I$6), INDEX(J21:S21, $I$4)) -> 0 | G21: years | I21: {=IF( INDEX(J21:S21, I$5) = "", IF( INDEX(J21:S21, I$6) = F21, "vw", "tu"), IF(INDEX(J21:S21, I$5) = F21, "vw", "tu"))} -> vw | K21: 0
A23: REVENUE
E24: Q1 seasonal adjustment | F24: =IF( INDEX(J24:S24, $I$4) = "", INDEX(J24:R24, $I$6), INDEX(J24:S24, $I$4)) -> 0.33 | G24: % of annual yield | I24: {=IF( INDEX(J24:S24, I$5) = "", IF( INDEX(J24:S24, I$6) = F24, "vw", "tu"), IF(INDEX(J24:S24, I$5) = F24, "vw", "tu"))} -> vw | K24: 0.33 | L24: 0.33 | M24: 0.33
E25: Q2 seasonal adjustment | F25: =IF( INDEX(J25:S25, $I$4) = "", INDEX(J25:R25, $I$6), INDEX(J25:S25, $I$4)) -> 0.36 | G25: % of annual yield | I25: {=IF( INDEX(J25:S25, I$5) = "", IF( INDEX(J25:S25, I$6) = F25, "vw", "tu"), IF(INDEX(J25:S25, I$5) = F25, "vw", "tu"))} -> vw | K25: 0.36 | L25: 0.36 | M25: 0.36
E26: Q3 seasonal adjustment | F26: =IF( INDEX(J26:S26, $I$4) = "", INDEX(J26:R26, $I$6), INDEX(J26:S26, $I$4)) -> 0.155 | G26: % of annual yield | I26: {=IF( INDEX(J26:S26, I$5) = "", IF( INDEX(J26:S26, I$6) = F26, "vw", "tu"), IF(INDEX(J26:S26, I$5) = F26, "vw", "tu"))} -> vw | K26: 0.155 | L26: 0.155 | M26: 0.155
E27: Q4 seasonal adjustment | F27: =IF( INDEX(J27:S27, $I$4) = "", INDEX(J27:R27, $I$6), INDEX(J27:S27, $I$4)) -> 0.155 | G27: % of annual yield | I27: {=IF( INDEX(J27:S27, I$5) = "", IF( INDEX(J27:S27, I$6) = F27, "vw", "tu"), IF(INDEX(J27:S27, I$5) = F27, "vw", "tu"))} -> vw | K27: 0.155 | L27: 0.155 | M27: 0.155
E29: Annual degradation | F29: =IF( INDEX(J29:S29, $I$4) = "", INDEX(J29:R29, $I$6), INDEX(J29:S29, $I$4)) -> 0.005 | G29: % p.a. | I29: {=IF( INDEX(J29:S29, I$5) = "", IF( INDEX(J29:S29, I$6) = F29, "vw", "tu"), IF(INDEX(J29:S29, I$5) = F29, "vw", "tu"))} -> vw | K29: 0.005 | L29: 0.005 | M29: 0.005
E30: Year 1 P50 yield | F30: =IF( INDEX(J30:S30, $I$4) = "", INDEX(J30:R30, $I$6), INDEX(J30:S30, $I$4)) -> 250 | G30: GWh | I30: {=IF( INDEX(J30:S30, I$5) = "", IF( INDEX(J30:S30, I$6) = F30, "vw", "tu"), IF(INDEX(J30:S30, I$5) = F30, "vw", "tu"))} -> vw | K30: 250 | L30: 250 | M30: 250
E31: Availability | F31: =IF( INDEX(J31:S31, $I$4) = "", INDEX(J31:R31, $I$6), INDEX(J31:S31, $I$4)) -> 0.97 | G31: % | I31: {=IF( INDEX(J31:S31, I$5) = "", IF( INDEX(J31:S31, I$6) = F31, "vw", "tu"), IF(INDEX(J31:S31, I$5) = F31, "vw", "tu"))} -> vw | K31: 0.97 | L31: 0.97 | M31: 0.97
E33: Power tariff | F33: =IF( INDEX(J33:S33, $I$4) = "", INDEX(J33:R33, $I$6), INDEX(J33:S33, $I$4)) -> 0.065 | G33: USD / kWh | I33: {=IF( INDEX(J33:S33, I$5) = "", IF( INDEX(J33:S33, I$6) = F33, "vw", "tu"), IF(INDEX(J33:S33, I$5) = F33, "vw", "tu"))} -> vw | K33: 0.065 | L33: 0.065 | M33: 0.065
A36: OPERATING COSTS
E37: Annual fixed real O&M cost | F37: =IF( INDEX(J37:S37, $I$4) = "", INDEX(J37:R37, $I$6), INDEX(J37:S37, $I$4)) -> 1500 | G37: =SMU -> $ 000s | I37: {=IF( INDEX(J37:S37, I$5) = "", IF( INDEX(J37:S37, I$6) = F37, "vw", "tu"), IF(INDEX(J37:S37, I$5) = F37, "vw", "tu"))} -> vw | K37: 1500 | L37: 1500 | M37: 1500
A40: FIXED ASSET
E41: Useful life of asset | F41: =IF( INDEX(J41:S41, $I$4) = "", INDEX(J41:R41, $I$6), INDEX(J41:S41, $I$4)) -> 25 | G41: years | I41: {=IF( INDEX(J41:S41, I$5) = "", IF( INDEX(J41:S41, I$6) = F41, "vw", "tu"), IF(INDEX(J41:S41, I$5) = F41, "vw", "tu"))} -> vw | K41: 25 | L41: 25 | M41: 25
A44: SENIOR DEBT
E45: Senior debt repayment period | F45: =IF( INDEX(J45:S45, $I$4) = "", INDEX(J45:R45, $I$6), INDEX(J45:S45, $I$4)) -> 10 | G45: years | I45: {=IF( INDEX(J45:S45, I$5) = "", IF( INDEX(J45:S45, I$6) = F45, "vw", "tu"), IF(INDEX(J45:S45, I$5) = F45, "vw", "tu"))} -> vw | K45: 10 | L45: 10 | M45: 10
E46: Senior debt leverage | F46: =IF( INDEX(J46:S46, $I$4) = "", INDEX(J46:R46, $I$6), INDEX(J46:S46, $I$4)) -> 0.7 | G46: % | I46: {=IF( INDEX(J46:S46, I$5) = "", IF( INDEX(J46:S46, I$6) = F46, "vw", "tu"), IF(INDEX(J46:S46, I$5) = F46, "vw", "tu"))} -> vw | K46: 0.7 | L46: 0.7 | M46: 0.7
E47: Senior debt principal repayment profile selection | F47: =IF( INDEX(J47:S47, $I$4) = "", INDEX(J47:R47, $I$6), INDEX(J47:S47, $I$4)) -> 3 | G47: profile selection | I47: {=IF( INDEX(J47:S47, I$5) = "", IF( INDEX(J47:S47, I$6) = F47, "vw", "tu"), IF(INDEX(J47:S47, I$5) = F47, "vw", "tu"))} -> vw | K47: 3 | L47: 1 | M47: 1
E48: Senior debt swap rate | F48: =IF( INDEX(J48:S48, $I$4) = "", INDEX(J48:R48, $I$6), INDEX(J48:S48, $I$4)) -> 0.025 | G48: % p.a. | I48: {=IF( INDEX(J48:S48, I$5) = "", IF( INDEX(J48:S48, I$6) = F48, "vw", "tu"), IF(INDEX(J48:S48, I$5) = F48, "vw", "tu"))} -> vw | K48: 0.025 | L48: 0.025 | M48: 0.025
E49: Senior debt margin | F49: =IF( INDEX(J49:S49, $I$4) = "", INDEX(J49:R49, $I$6), INDEX(J49:S49, $I$4)) -> 0.035 | G49: % p.a. | I49: {=IF( INDEX(J49:S49, I$5) = "", IF( INDEX(J49:S49, I$6) = F49, "vw", "tu"), IF(INDEX(J49:S49, I$5) = F49, "vw", "tu"))} -> vw | K49: 0.035 | L49: 0.035 | M49: 0.035
E50: Senior debt day count convention | F50: =IF( INDEX(J50:S50, $I$4) = "", INDEX(J50:R50, $I$6), INDEX(J50:S50, $I$4)) -> 360 | G50: days / year | I50: {=IF( INDEX(J50:S50, I$5) = "", IF( INDEX(J50:S50, I$6) = F50, "vw", "tu"), IF(INDEX(J50:S50, I$5) = F50, "vw", "tu"))} -> vw | K50: 360 | L50: 360 | M50: 360
E51: DSCR for debt sizing | F51: =IF( INDEX(J51:S51, $I$4) = "", INDEX(J51:R51, $I$6), INDEX(J51:S51, $I$4)) -> 1.3 | G51: ratio | I51: {=IF( INDEX(J51:S51, I$5) = "", IF( INDEX(J51:S51, I$6) = F51, "vw", "tu"), IF(INDEX(J51:S51, I$5) = F51, "vw", "tu"))} -> vw | K51: 1.3 | L51: 1.3 | M51: 1.3
E52: Senior debt sizing method | F52: =IF( INDEX(J52:S52, $I$4) = "", INDEX(J52:R52, $I$6), INDEX(J52:S52, $I$4)) -> 2 | G52: 1 = leverage, 2 = DSCR | I52: {=IF( INDEX(J52:S52, I$5) = "", IF( INDEX(J52:S52, I$6) = F52, "vw", "tu"), IF(INDEX(J52:S52, I$5) = F52, "vw", "tu"))} -> vw | K52: 2 | L52: 2 | M52: 2
A56: WORKING CAPITAL
E57: Accounts receivable days | F57: =IF( INDEX(J57:S57, $I$4) = "", INDEX(J57:R57, $I$6), INDEX(J57:S57, $I$4)) -> 60 | G57: days | I57: {=IF( INDEX(J57:S57, I$5) = "", IF( INDEX(J57:S57, I$6) = F57, "vw", "tu"), IF(INDEX(J57:S57, I$5) = F57, "vw", "tu"))} -> vw | K57: 60 | L57: 60 | M57: 60
...

Sheet Time
A1: =RIGHT(CELL("filename", A1), LEN(CELL("filename", A1)) - SEARCH("]", CELL("filename", A1))) & " - " & InpC!F3 -> Time - Base case 1
E2: =Time!E$25 -> Model period ending | F2: =Check!$F$9 -> 0 | G2: Error chks | J2: =Time!J$25 -> 44104 | K2: =Time!K$25 -> 44196 | L2: =Time!L$25 -> 44286 | M2: =Time!M$25 -> 44377 | N2: =Time!N$25 -> 44469 | O2: =Time!O$25 -> 44561 | P2: =Time!P$25 -> 44651 | Q2: =Time!Q$25 -> 44742 | ... EA2: =Time!EA$25 -> 55153
E3: =Time!E$67 -> Timeline label | F3: =Output!J2 -> 0 | G3: Track chgs | J3: =Time!J$67 -> Pre-fcst | K3: =Time!K$67 -> Pre-fcst | L3: =Time!L$67 -> Fin Close | M3: =Time!M$67 -> Operations | N3: =Time!N$67 -> Operations | O3: =Time!O$67 -> Operations | P3: =Time!P$67 -> Operations | Q3: =Time!Q$67 -> Operations | ... EA3: =Time!EA$67 -> Post ops
E4: =Time!E$42 -> Contract year | F4: =Check!$F$21 -> 0 | G4: Alerts | J4: =Time!J$42 -> 2020 | K4: =Time!K$42 -> 2020 | L4: =Time!L$42 -> 2020 | M4: =Time!M$42 -> 2021 | N4: =Time!N$42 -> 2021 | O4: =Time!O$42 -> 2021 | P4: =Time!P$42 -> 2021 | Q4: =Time!Q$42 -> 2022 | ... EA4: =Time!EA$42 -> 2050
E5: =Time!E$10 -> Model column counter | F5: Constant | G5: Unit | H5: Total | J5: =Time!J$10 -> 1 | K5: =Time!K$10 -> 2 | L5: =Time!L$10 -> 3 | M5: =Time!M$10 -> 4 | N5: =Time!N$10 -> 5 | O5: =Time!O$10 -> 6 | P5: =Time!P$10 -> 7 | Q5: =Time!Q$10 -> 8 | ... EA5: =Time!EA$10 -> 122
A7: TIME RULER
B9: First model column
E10: Model column counter | G10: counter | J10: =I10 + 1 -> 1 | K10: =J10 + 1 -> 2 | L10: =K10 + 1 -> 3 | M10: =L10 + 1 -> 4 | N10: =M10 + 1 -> 5 | O10: =N10 + 1 -> 6 | P10: =O10 + 1 -> 7 | Q10: =P10 + 1 -> 8 | ... EA10: =DZ10 + 1 -> 122
E11: Model column total | F11: =MAX(J10:EA10) -> 122 | G11: columns
E13: =E$10 -> Model column counter | F13: =F$10 -> 0 | G13: =G$10 -> counter | H13: =H$10 -> 0 | I13: =I$10 -> 0 | J13: =J$10 -> 1 | K13: =K$10 -> 2 | L13: =L$10 -> 3 | ... EA13: =EA$10 -> 122
E14: First model column flag | G14: flag | H14: =SUM(J14:EA14) -> 1 | J14: =IF(J13 = 1, 1, 0) -> 1 | K14: =IF(K13 = 1, 1, 0) -> 0 | L14: =IF(L13 = 1, 1, 0) -> 0 | M14: =IF(M13 = 1, 1, 0) -> 0 | N14: =IF(N13 = 1, 1, 0) -> 0 | O14: =IF(O13 = 1, 1, 0) -> 0 | P14: =IF(P13 = 1, 1, 0) -> 0 | Q14: =IF(Q13 = 1, 1, 0) -> 0 | ... EA14: =IF(EA13 = 1, 1, 0) -> 0
B16: Model period beginning
E17: =InpC!E$13 -> First date of time rulers | F17: =InpC!F$13 -> 44013 | G17: =InpC!G$13 -> date
E18: =InpC!E$16 -> Length of operating period | F18: =InpC!F$16 -> 3 | G18: =InpC!G$16 -> months
E19: =E$14 -> First model column flag | F19: =F$14 -> 0 | G19: =G$14 -> flag | H19: =H$14 -> 1 | I19: =I$14 -> 0 | J19: =J$14 -> 1 | K19: =K$14 -> 0 | L19: =L$14 -> 0 | ... EA19: =EA$14 -> 0
E20: Model period beginning | G20: date | J20: =IF(J19 = 1, $F17, DATE(YEAR(I20), MONTH(I20) + $F18, DAY(1))) -> 44013 | K20: =IF(K19 = 1, $F17, DATE(YEAR(J20), MONTH(J20) + $F18, DAY(1))) -> 44105 | L20: =IF(L19 = 1, $F17, DATE(YEAR(K20), MONTH(K20) + $F18, DAY(1))) -> 44197 | M20: =IF(M19 = 1, $F17, DATE(YEAR(L20), MONTH(L20) + $F18, DAY(1))) -> 44287 | N20: =IF(N19 = 1, $F17, DATE(YEAR(M20), MONTH(M20) + $F18, DAY(1))) -> 44378 | O20: =IF(O19 = 1, $F17, DATE(YEAR(N20), MONTH(N20) + $F18, DAY(1))) -> 44470 | P20: =IF(P19 = 1, $F17, DATE(YEAR(O20), MONTH(O20) + $F18, DAY(1))) -> 44562 | Q20: =IF(Q19 = 1, $F17, DATE(YEAR(P20), MONTH(P20) + $F18, DAY(1))) -> 44652 | ... EA20: =IF(EA19 = 1, $F17, DATE(YEAR(DZ20), MONTH(DZ20) + $F18, DAY(1))) -> 55062
B22: Model period ending
E23: =InpC!E$16 -> Length of operating period | F23: =InpC!F$16 -> 3 | G23: =InpC!G$16 -> months
E24: =E$20 -> Model period beginning | F24: =F$20 -> 0 | G24: =G$20 -> date | H24: =H$20 -> 0 | I24: =I$20 -> 0 | J24: =J$20 -> 44013 | K24: =K$20 -> 44105 | L24: =L$20 -> 44197 | ... EA24: =EA$20 -> 55062
E25: Model period ending | G25: date | J25: =DATE(YEAR(J24), MONTH(J24) + $F23, DAY(J24) -1) -> 44104 | K25: =DATE(YEAR(K24), MONTH(K24) + $F23, DAY(K24) -1) -> 44196 | L25: =DATE(YEAR(L24), MONTH(L24) + $F23, DAY(L24) -1) -> 44286 | M25: =DATE(YEAR(M24), MONTH(M24) + $F23, DAY(M24) -1) -> 44377 | N25: =DATE(YEAR(N24), MONTH(N24) + $F23, DAY(N24) -1) -> 44469 | O25: =DATE(YEAR(O24), MONTH(O24) + $F23, DAY(O24) -1) -> 44561 | P25: =DATE(YEAR(P24), MONTH(P24) + $F23, DAY(P24) -1) -> 44651 | Q25: =DATE(YEAR(Q24), MONTH(Q24) + $F23, DAY(Q24) -1) -> 44742 | ... EA25: =DATE(YEAR(EA24), MONTH(EA24) + $F23, DAY(EA24) -1) -> 55153
B27: Contract year
E28: =InpC!E$18 -> Acquisition date | F28: =InpC!F$18 -> 44286 | G28: =InpC!G$18 -> date
E29: Contract year end month | F29: =MONTH(F28) -> 3 | G29: month
E31: =E$29 -> Contract year end month | F31: =F$29 -> 3 | G31: =G$29 -> month
E32: =E$25 -> Model period ending | F32: =F$25 -> 0 | G32: =G$25 -> date | H32: =H$25 -> 0 | I32: =I$25 -> 0 | J32: =J$25 -> 44104 | K32: =K$25 -> 44196 | L32: =L$25 -> 44286 | ... EA32: =EA$25 -> 55153
E33: End of contract year flag | J33: =IF( MONTH(J32) = $F31, 1, 0) -> 0 | K33: =IF( MONTH(K32) = $F31, 1, 0) -> 0 | L33: =IF( MONTH(L32) = $F31, 1, 0) -> 1 | M33: =IF( MONTH(M32) = $F31, 1, 0) -> 0 | N33: =IF( MONTH(N32) = $F31, 1, 0) -> 0 | O33: =IF( MONTH(O32) = $F31, 1, 0) -> 0 | P33: =IF( MONTH(P32) = $F31, 1, 0) -> 1 | Q33: =IF( MONTH(Q32) = $F31, 1, 0) -> 0 | ... EA33: =IF( MONTH(EA32) = $F31, 1, 0) -> 0
E35: =InpC!E$14 -> Annual year end date of first operating period | F35: =InpC!F$14 -> 43921 | G35: =InpC!G$14 -> date
E36: =InpC!E$73 -> Months in year | F36: =InpC!F$73 -> 12 | G36: =InpC!G$73 -> months
E37: =E$14 -> First model column flag | F37: =F$14 -> 0 | G37: =G$14 -> flag | H37: =H$14 -> 1 | I37: =I$14 -> 0 | J37: =J$14 -> 1 | K37: =K$14 -> 0 | L37: =L$14 -> 0 | ... EA37: =EA$14 -> 0
E38: =E$33 -> End of contract year flag | F38: =F$33 -> 0 | G38: =G$33 -> 0 | H38: =H$33 -> 0 | I38: =I$33 -> 0 | J38: =J$33 -> 0 | K38: =K$33 -> 0 | L38: =L$33 -> 1 | ... EA38: =EA$33 -> 0
E39: Contract year applicable to period | G39: date | J39: =IF( J37 = 1, $F35, IF( I38 = 1, EOMONTH(I39, 12), I39)) -> 43921 | K39: =IF( K37 = 1, $F35, IF( J38 = 1, EOMONTH(J39, 12), J39)) -> 43921 | L39: =IF( L37 = 1, $F35, IF( K38 = 1, EOMONTH(K39, 12), K39)) -> 43921 | M39: =IF( M37 = 1, $F35, IF( L38 = 1, EOMONTH(L39, 12), L39)) -> 44286 | N39: =IF( N37 = 1, $F35, IF( M38 = 1, EOMONTH(M39, 12), M39)) -> 44286 | O39: =IF( O37 = 1, $F35, IF( N38 = 1, EOMONTH(N39, 12), N39)) -> 44286 | P39: =IF( P37 = 1, $F35, IF( O38 = 1, EOMONTH(O39, 12), O39)) -> 44286 | Q39: =IF( Q37 = 1, $F35, IF( P38 = 1, EOMONTH(P39, 12), P39)) -> 44651 | ... EA39: =IF( EA37 = 1, $F35, IF( DZ38 = 1, EOMONTH(DZ39, 12), DZ39)) -> 54878
E41: =E$39 -> Contract year applicable to period | F41: =F$39 -> 0 | G41: =G$39 -> date | H41: =H$39 -> 0 | I41: =I$39 -> 0 | J41: =J$39 -> 43921 | K41: =K$39 -> 43921 | L41: =L$39 -> 43921 | ... EA41: =EA$39 -> 54878
E42: Contract year | G42: year # | J42: =YEAR(J41) -> 2020 | K42: =YEAR(K41) -> 2020 | L42: =YEAR(L41) -> 2020 | M42: =YEAR(M41) -> 2021 | N42: =YEAR(N41) -> 2021 | O42: =YEAR(O41) -> 2021 | P42: =YEAR(P41) -> 2021 | Q42: =YEAR(Q41) -> 2022 | ... EA42: =YEAR(EA41) -> 2050
B44: Annual timeline
E45: =InpC!E$14 -> Annual year end date of first operating period | F45: =InpC!F$14 -> 43921 | G45: =InpC!G$14 -> date
E46: =InpC!E$73 -> Months in year | F46: =InpC!F$73 -> 12 | G46: =InpC!G$73 -> months
E47: =E$14 -> First model column flag | F47: =F$14 -> 0 | G47: =G$14 -> flag | H47: =H$14 -> 1 | I47: =I$14 -> 0 | J47: =J$14 -> 1 | K47: =K$14 -> 0 | L47: =L$14 -> 0 | ... EA47: =EA$14 -> 0
E48: Model period ending - annual | G48: date | J48: =IF(J47 = 1, $F45, EOMONTH(I48, $F46)) -> 43921 | K48: =IF(K47 = 1, $F45, EOMONTH(J48, $F46)) -> 44286 | L48: =IF(L47 = 1, $F45, EOMONTH(K48, $F46)) -> 44651 | M48: =IF(M47 = 1, $F45, EOMONTH(L48, $F46)) -> 45016 | N48: =IF(N47 = 1, $F45, EOMONTH(M48, $F46)) -> 45382 | O48: =IF(O47 = 1, $F45, EOMONTH(N48, $F46)) -> 45747 | P48: =IF(P47 = 1, $F45, EOMONTH(O48, $F46)) -> 46112 | Q48: =IF(Q47 = 1, $F45, EOMONTH(P48, $F46)) -> 46477 | ... EA48: =IF(EA47 = 1, $F45, EOMONTH(DZ48, $F46)) -> 88115
E50: =E$67 -> Timeline label | F50: =F$67 -> 0 | G50: =G$67 -> label | H50: =H$67 -> 0 | I50: =I$67 -> 0 | J50: =J$67 -> Pre-fcst | K50: =K$67 -> Pre-fcst | L50: =L$67 -> Fin Close | ... EA50: =EA$67 -> Post ops
E51: =E$48 -> Model period ending - annual | F51: =F$48 -> 0 | G51: =G$48 -> date | H51: =H$48 -> 0 | I51: =I$48 -> 0 | J51: =J$48 -> 43921 | K51: =K$48 -> 44286 | L51: =L$48 -> 44651 | ... EA51: =EA$48 -> 88115
...

Sheet Ops
A1: =RIGHT(CELL("filename", A1), LEN(CELL("filename", A1)) - SEARCH("]", CELL("filename", A1))) & " - " & InpC!F3 -> Ops - Base case 1
E2: =Time!E$25 -> Model period ending | F2: =Check!$F$9 -> 0 | G2: Error chks | J2: =Time!J$25 -> 44104 | K2: =Time!K$25 -> 44196 | L2: =Time!L$25 -> 44286 | M2: =Time!M$25 -> 44377 | N2: =Time!N$25 -> 44469 | O2: =Time!O$25 -> 44561 | P2: =Time!P$25 -> 44651 | Q2: =Time!Q$25 -> 44742 | ... EA2: =Time!EA$25 -> 55153
E3: =Time!E$67 -> Timeline label | F3: =Output!J2 -> 0 | G3: Track chgs | J3: =Time!J$67 -> Pre-fcst | K3: =Time!K$67 -> Pre-fcst | L3: =Time!L$67 -> Fin Close | M3: =Time!M$67 -> Operations | N3: =Time!N$67 -> Operations | O3: =Time!O$67 -> Operations | P3: =Time!P$67 -> Operations | Q3: =Time!Q$67 -> Operations | ... EA3: =Time!EA$67 -> Post ops
E4: =Time!E$42 -> Contract year | F4: =Check!$F$21 -> 0 | G4: Alerts | J4: =Time!J$42 -> 2020 | K4: =Time!K$42 -> 2020 | L4: =Time!L$42 -> 2020 | M4: =Time!M$42 -> 2021 | N4: =Time!N$42 -> 2021 | O4: =Time!O$42 -> 2021 | P4: =Time!P$42 -> 2021 | Q4: =Time!Q$42 -> 2022 | ... EA4: =Time!EA$42 -> 2050
E5: =Time!E$10 -> Model column counter | F5: Constant | G5: Unit | H5: Total | J5: =Time!J$10 -> 1 | K5: =Time!K$10 -> 2 | L5: =Time!L$10 -> 3 | M5: =Time!M$10 -> 4 | N5: =Time!N$10 -> 5 | O5: =Time!O$10 -> 6 | P5: =Time!P$10 -> 7 | Q5: =Time!Q$10 -> 8 | ... EA5: =Time!EA$10 -> 122
A8: REVENUE
B10: Degradation
E11: =InpC!E$29 -> Annual degradation | F11: =InpC!F$29 -> 0.005 | G11: =InpC!G$29 -> % p.a.
E12: =Time!E$143 -> Contract year number | F12: =Time!F$143 -> 0 | G12: =Time!G$143 -> counter | H12: =Time!H$143 -> 0 | I12: =Time!I$143 -> 0 | J12: =Time!J$143 -> 0 | K12: =Time!K$143 -> 0 | L12: =Time!L$143 -> 0 | ... EA12: =Time!EA$143 -> 0
E13: =Time!E$97 -> Operating period flag | F13: =Time!F$97 -> 0 | G13: =Time!G$97 -> flag | H13: =Time!H$97 -> 100 | I13: =Time!I$97 -> 0 | J13: =Time!J$97 -> 0 | K13: =Time!K$97 -> 0 | L13: =Time!L$97 -> 0 | ... EA13: =Time!EA$97 -> 0
E14: Compound degradation | G14: % | J14: =IF( J13 = 1, 1 / ((1 + $F11) ^ (J12 - 1)), 0) -> 0 | K14: =IF( K13 = 1, 1 / ((1 + $F11) ^ (K12 - 1)), 0) -> 0 | L14: =IF( L13 = 1, 1 / ((1 + $F11) ^ (L12 - 1)), 0) -> 0 | M14: =IF( M13 = 1, 1 / ((1 + $F11) ^ (M12 - 1)), 0) -> 1 | N14: =IF( N13 = 1, 1 / ((1 + $F11) ^ (N12 - 1)), 0) -> 1 | O14: =IF( O13 = 1, 1 / ((1 + $F11) ^ (O12 - 1)), 0) -> 1 | P14: =IF( P13 = 1, 1 / ((1 + $F11) ^ (P12 - 1)), 0) -> 1 | Q14: =IF( Q13 = 1, 1 / ((1 + $F11) ^ (Q12 - 1)), 0) -> 0.99502488 | ... EA14: =IF( EA13 = 1, 1 / ((1 + $F11) ^ (EA12 - 1)), 0) -> 0
B16: Seasonality adjustment
E17: =InpC!E$24 -> Q1 seasonal adjustment | F17: =InpC!F$24 -> 0.33 | G17: =InpC!G$24 -> % of annual yield
E18: =InpC!E$25 -> Q2 seasonal adjustment | F18: =InpC!F$25 -> 0.36 | G18: =InpC!G$25 -> % of annual yield
E19: =InpC!E$26 -> Q3 seasonal adjustment | F19: =InpC!F$26 -> 0.155 | G19: =InpC!G$26 -> % of annual yield
E20: =InpC!E$27 -> Q4 seasonal adjustment | F20: =InpC!F$27 -> 0.155 | G20: =InpC!G$27 -> % of annual yield
E21: =Time!E$137 -> Period number | F21: =Time!F$137 -> 0 | G21: =Time!G$137 -> counter | H21: =Time!H$137 -> 0 | I21: =Time!I$137 -> 0 | J21: =Time!J$137 -> 0 | K21: =Time!K$137 -> 0 | L21: =Time!L$137 -> 0 | ... EA21: =Time!EA$137 -> 0
E22: =Time!E$97 -> Operating period flag | F22: =Time!F$97 -> 0 | G22: =Time!G$97 -> flag | H22: =Time!H$97 -> 100 | I22: =Time!I$97 -> 0 | J22: =Time!J$97 -> 0 | K22: =Time!K$97 -> 0 | L22: =Time!L$97 -> 0 | ... EA22: =Time!EA$97 -> 0
E23: Seasonality adjustment | G23: % | H23: =SUM(J23:GJ23) -> 25 | J23: =IF(J22 = 1, INDEX($F17:$F20, J21), 0) -> 0 | K23: =IF(K22 = 1, INDEX($F17:$F20, K21), 0) -> 0 | L23: =IF(L22 = 1, INDEX($F17:$F20, L21), 0) -> 0 | M23: =IF(M22 = 1, INDEX($F17:$F20, M21), 0) -> 0.33 | N23: =IF(N22 = 1, INDEX($F17:$F20, N21), 0) -> 0.36 | O23: =IF(O22 = 1, INDEX($F17:$F20, O21), 0) -> 0.155 | P23: =IF(P22 = 1, INDEX($F17:$F20, P21), 0) -> 0.155 | Q23: =IF(Q22 = 1, INDEX($F17:$F20, Q21), 0) -> 0.33 | ... EA23: =IF(EA22 = 1, INDEX($F17:$F20, EA21), 0) -> 0
B25: Electricity generation
E26: =InpC!E$30 -> Year 1 P50 yield | F26: =InpC!F$30 -> 250 | G26: =InpC!G$30 -> GWh
E27: =InpC!E$31 -> Availability | F27: =InpC!F$31 -> 0.97 | G27: =InpC!G$31 -> %
E28: =E$14 -> Compound degradation | F28: =F$14 -> 0 | G28: =G$14 -> % | H28: =H$14 -> 0 | I28: =I$14 -> 0 | J28: =J$14 -> 0 | K28: =K$14 -> 0 | L28: =L$14 -> 0 | ... EA28: =EA$14 -> 0
E29: =E$23 -> Seasonality adjustment | F29: =F$23 -> 0 | G29: =G$23 -> % | H29: =H$23 -> 25 | I29: =I$23 -> 0 | J29: =J$23 -> 0 | K29: =K$23 -> 0 | L29: =L$23 -> 0 | ... EA29: =EA$23 -> 0
E30: Electricity generation | G30: GWh | H30: =SUM(J30:GJ30) -> 5713.9951 | J30: =$F26 * $F27 * J28 * J29 -> 0 | K30: =$F26 * $F27 * K28 * K29 -> 0 | L30: =$F26 * $F27 * L28 * L29 -> 0 | M30: =$F26 * $F27 * M28 * M29 -> 80.025 | N30: =$F26 * $F27 * N28 * N29 -> 87.3 | O30: =$F26 * $F27 * O28 * O29 -> 37.5875 | P30: =$F26 * $F27 * P28 * P29 -> 37.5875 | Q30: =$F26 * $F27 * Q28 * Q29 -> 79.626866 | ... EA30: =$F26 * $F27 * EA28 * EA29 -> 0
B32: Electricity revenue
E33: =InpC!E$33 -> Power tariff | F33: =InpC!F$33 -> 0.065 | G33: =InpC!G$33 -> USD / kWh
E34: =InpC!E$77 -> GWh to kWh conversion | F34: =InpC!F$77 -> 1000000 | G34: =InpC!G$77 -> kWh / GWh
E35: =InpC!E$78 -> Units in a thousand | F35: =InpC!F$78 -> 1000 | G35: =InpC!G$78 -> units
E36: =E$30 -> Electricity generation | F36: =F$30 -> 0 | G36: =G$30 -> GWh | H36: =H$30 -> 5713.9951 | I36: =I$30 -> 0 | J36: =J$30 -> 0 | K36: =K$30 -> 0 | L36: =L$30 -> 0 | ... EA36: =EA$30 -> 0
E37: =Time!E$97 -> Operating period flag | F37: =Time!F$97 -> 0 | G37: =Time!G$97 -> flag | H37: =Time!H$97 -> 100 | I37: =Time!I$97 -> 0 | J37: =Time!J$97 -> 0 | K37: =Time!K$97 -> 0 | L37: =Time!L$97 -> 0 | ... EA37: =Time!EA$97 -> 0
E38: Electricity revenue | G38: =SMU -> $ 000s | H38: =SUM(J38:GJ38) -> 371409.68 | J38: =$F33 * $F34 / $F35 * J36 * J37 -> 0 | K38: =$F33 * $F34 / $F35 * K36 * K37 -> 0 | L38: =$F33 * $F34 / $F35 * L36 * L37 -> 0 | M38: =$F33 * $F34 / $F35 * M36 * M37 -> 5201.625 | N38: =$F33 * $F34 / $F35 * N36 * N37 -> 5674.5 | O38: =$F33 * $F34 / $F35 * O36 * O37 -> 2443.1875 | P38: =$F33 * $F34 / $F35 * P36 * P37 -> 2443.1875 | Q38: =$F33 * $F34 / $F35 * Q36 * Q37 -> 5175.7463 | ... EA38: =$F33 * $F34 / $F35 * EA36 * EA37 -> 0
A41: ACCOUNTS RECEIVABLE
B43: Forecast accounts receivable balance
E44: =InpC!E$57 -> Accounts receivable days | F44: =InpC!F$57 -> 60 | G44: =InpC!G$57 -> days
E45: =E$38 -> Electricity revenue | F45: =F$38 -> 0 | G45: =G$38 -> $ 000s | H45: =H$38 -> 371409.68 | I45: =I$38 -> 0 | J45: =J$38 -> 0 | K45: =K$38 -> 0 | L45: =L$38 -> 0 | ... EA45: =EA$38 -> 0
E46: =Time!E$149 -> Days in period | F46: =Time!F$149 -> 0 | G46: =Time!G$149 -> days | H46: =Time!H$149 -> 0 | I46: =Time!I$149 -> 0 | J46: =Time!J$149 -> 92 | K46: =Time!K$149 -> 92 | L46: =Time!L$149 -> 90 | ... EA46: =Time!EA$149 -> 92
E47: Forecast accounts receivable balance | G47: =SMU -> $ 000s | J47: =J45 / J46 * $F44 -> 0 | K47: =K45 / K46 * $F44 -> 0 | L47: =L45 / L46 * $F44 -> 0 | M47: =M45 / M46 * $F44 -> 3429.6429 | N47: =N45 / N46 * $F44 -> 3700.7609 | O47: =O45 / O46 * $F44 -> 1593.3832 | P47: =P45 / P46 * $F44 -> 1628.7917 | Q47: =Q45 / Q46 * $F44 -> 3412.58 | ... EA47: =EA45 / EA46 * $F44 -> 0
B49: Cash received from invoices
E50: =E$38 -> Electricity revenue | F50: =F$38 -> 0 | G50: =G$38 -> $ 000s | H50: =H$38 -> 371409.68 | I50: =I$38 -> 0 | J50: =J$38 -> 0 | K50: =K$38 -> 0 | L50: =L$38 -> 0 | ... EA50: =EA$38 -> 0
...

Sheet Asset
A1: =RIGHT(CELL("filename", A1), LEN(CELL("filename", A1)) - SEARCH("]", CELL("filename", A1))) & " - " & InpC!F3 -> Asset - Base case 1
E2: =Time!E$25 -> Model period ending | F2: =Check!$F$9 -> 0 | G2: Error chks | J2: =Time!J$25 -> 44104 | K2: =Time!K$25 -> 44196 | L2: =Time!L$25 -> 44286 | M2: =Time!M$25 -> 44377 | N2: =Time!N$25 -> 44469 | O2: =Time!O$25 -> 44561 | P2: =Time!P$25 -> 44651 | Q2: =Time!Q$25 -> 44742 | ... EA2: =Time!EA$25 -> 55153
E3: =Time!E$67 -> Timeline label | F3: =Output!J2 -> 0 | G3: Track chgs | J3: =Time!J$67 -> Pre-fcst | K3: =Time!K$67 -> Pre-fcst | L3: =Time!L$67 -> Fin Close | M3: =Time!M$67 -> Operations | N3: =Time!N$67 -> Operations | O3: =Time!O$67 -> Operations | P3: =Time!P$67 -> Operations | Q3: =Time!Q$67 -> Operations | ... EA3: =Time!EA$67 -> Post ops
E4: =Time!E$42 -> Contract year | F4: =Check!$F$21 -> 0 | G4: Alerts | J4: =Time!J$42 -> 2020 | K4: =Time!K$42 -> 2020 | L4: =Time!L$42 -> 2020 | M4: =Time!M$42 -> 2021 | N4: =Time!N$42 -> 2021 | O4: =Time!O$42 -> 2021 | P4: =Time!P$42 -> 2021 | Q4: =Time!Q$42 -> 2022 | ... EA4: =Time!EA$42 -> 2050
E5: =Time!E$10 -> Model column counter | F5: Constant | G5: Unit | H5: Total | J5: =Time!J$10 -> 1 | K5: =Time!K$10 -> 2 | L5: =Time!L$10 -> 3 | M5: =Time!M$10 -> 4 | N5: =Time!N$10 -> 5 | O5: =Time!O$10 -> 6 | P5: =Time!P$10 -> 7 | Q5: =Time!Q$10 -> 8 | ... EA5: =Time!EA$10 -> 122
A8: FIXED ASSET
B10: Depreciation
E11: =InpC!E$65 -> Fixed asset - initial balance | F11: =InpC!F$65 -> 100000 | G11: =InpC!G$65 -> $ 000s
E12: =InpC!E$41 -> Useful life of asset | F12: =InpC!F$41 -> 25 | G12: =InpC!G$41 -> years
E13: =InpC!E$74 -> Number of periods in a year | F13: =InpC!F$74 -> 4 | G13: =InpC!G$74 -> periods
E14: =Time!E$109 -> Useful life of asset flag | F14: =Time!F$109 -> 0 | G14: =Time!G$109 -> flag | H14: =Time!H$109 -> 100 | I14: =Time!I$109 -> 0 | J14: =Time!J$109 -> 0 | K14: =Time!K$109 -> 0 | L14: =Time!L$109 -> 0 | ... EA14: =Time!EA$109 -> 0
E15: Depreciation of fixed asset POS | G15: =SMU -> $ 000s | H15: =SUM(J15:EA15) -> 100000 | J15: =$F11 / $F12 / $F13 * J14 -> 0 | K15: =$F11 / $F12 / $F13 * K14 -> 0 | L15: =$F11 / $F12 / $F13 * L14 -> 0 | M15: =$F11 / $F12 / $F13 * M14 -> 1000 | N15: =$F11 / $F12 / $F13 * N14 -> 1000 | O15: =$F11 / $F12 / $F13 * O14 -> 1000 | P15: =$F11 / $F12 / $F13 * P14 -> 1000 | Q15: =$F11 / $F12 / $F13 * Q14 -> 1000 | ... EA15: =$F11 / $F12 / $F13 * EA14 -> 0
E16: =LEFT(E15, LEN(E15) - 4) -> Depreciation of fixed asset | G16: =SMU -> $ 000s | H16: =SUM(J16:EA16) -> -100000 | J16: =-1 * J15 -> 0 | K16: =-1 * K15 -> 0 | L16: =-1 * L15 -> 0 | M16: =-1 * M15 -> -1000 | N16: =-1 * N15 -> -1000 | O16: =-1 * O15 -> -1000 | P16: =-1 * P15 -> -1000 | Q16: =-1 * Q15 -> -1000 | ... EA16: =-1 * EA15 -> 0
B18: Fixed asset balance
E20: =InpC!E$65 -> Fixed asset - initial balance | F20: =InpC!F$65 -> 100000 | G20: =InpC!G$65 -> $ 000s
E21: =Time!E$76 -> Financial close date flag | F21: =Time!F$76 -> 0 | G21: =Time!G$76 -> flag | H21: =Time!H$76 -> 1 | I21: =Time!I$76 -> 0 | J21: =Time!J$76 -> 0 | K21: =Time!K$76 -> 0 | L21: =Time!L$76 -> 1 | ... EA21: =Time!EA$76 -> 0
E23: Fixed asset balance BEG | G23: =SMU -> $ 000s | J23: =I26 -> 0 | K23: =J26 -> 0 | L23: =K26 -> 0 | M23: =L26 -> 100000 | N23: =M26 -> 99000 | O23: =N26 -> 98000 | P23: =O26 -> 97000 | Q23: =P26 -> 96000 | ... EA23: =DZ26 -> 0
E24: [Additional capex]
E25: =E$15 -> Depreciation of fixed asset POS | F25: =F$15 -> 0 | G25: =G$15 -> $ 000s | H25: =H$15 -> 100000 | I25: =I$15 -> 0 | J25: =J$15 -> 0 | K25: =K$15 -> 0 | L25: =L$15 -> 0 | ... EA25: =EA$15 -> 0
E26: Fixed asset balance | G26: =SMU -> $ 000s | J26: =IF( J21 = 1, $F20, J23 + J24 - J25) -> 0 | K26: =IF( K21 = 1, $F20, K23 + K24 - K25) -> 0 | L26: =IF( L21 = 1, $F20, L23 + L24 - L25) -> 100000 | M26: =IF( M21 = 1, $F20, M23 + M24 - M25) -> 99000 | N26: =IF( N21 = 1, $F20, N23 + N24 - N25) -> 98000 | O26: =IF( O21 = 1, $F20, O23 + O24 - O25) -> 97000 | P26: =IF( P21 = 1, $F20, P23 + P24 - P25) -> 96000 | Q26: =IF( Q21 = 1, $F20, Q23 + Q24 - Q25) -> 95000 | ... EA26: =IF( EA21 = 1, $F20, EA23 + EA24 - EA25) -> 0
A30: END

Sheet Debt
A1: =RIGHT(CELL("filename", A1), LEN(CELL("filename", A1)) - SEARCH("]", CELL("filename", A1))) & " - " & InpC!F3 -> Debt - Base case 1
E2: =Time!E$25 -> Model period ending | F2: =Check!$F$9 -> 0 | G2: Error chks | J2: =Time!J$25 -> 44104 | K2: =Time!K$25 -> 44196 | L2: =Time!L$25 -> 44286 | M2: =Time!M$25 -> 44377 | N2: =Time!N$25 -> 44469 | O2: =Time!O$25 -> 44561 | P2: =Time!P$25 -> 44651 | Q2: =Time!Q$25 -> 44742 | ... EA2: =Time!EA$25 -> 55153
E3: =Time!E$67 -> Timeline label | F3: =Output!J2 -> 0 | G3: Track chgs | J3: =Time!J$67 -> Pre-fcst | K3: =Time!K$67 -> Pre-fcst | L3: =Time!L$67 -> Fin Close | M3: =Time!M$67 -> Operations | N3: =Time!N$67 -> Operations | O3: =Time!O$67 -> Operations | P3: =Time!P$67 -> Operations | Q3: =Time!Q$67 -> Operations | ... EA3: =Time!EA$67 -> Post ops
E4: =Time!E$42 -> Contract year | F4: =Check!$F$21 -> 0 | G4: Alerts | J4: =Time!J$42 -> 2020 | K4: =Time!K$42 -> 2020 | L4: =Time!L$42 -> 2020 | M4: =Time!M$42 -> 2021 | N4: =Time!N$42 -> 2021 | O4: =Time!O$42 -> 2021 | P4: =Time!P$42 -> 2021 | Q4: =Time!Q$42 -> 2022 | ... EA4: =Time!EA$42 -> 2050
E5: =Time!E$10 -> Model column counter | F5: Constant | G5: Unit | H5: Total | J5: =Time!J$10 -> 1 | K5: =Time!K$10 -> 2 | L5: =Time!L$10 -> 3 | M5: =Time!M$10 -> 4 | N5: =Time!N$10 -> 5 | O5: =Time!O$10 -> 6 | P5: =Time!P$10 -> 7 | Q5: =Time!Q$10 -> 8 | ... EA5: =Time!EA$10 -> 122
A7: SENIOR DEBT
B9: Debt capacity
E10: ='FS Qtr'!E$33 -> Cash flow available for senior debt service | F10: ='FS Qtr'!F$33 -> 0 | G10: ='FS Qtr'!G$33 -> $ 000s | H10: ='FS Qtr'!H$33 -> 322667.04 | I10: ='FS Qtr'!I$33 -> 0 | J10: ='FS Qtr'!J$33 -> 0 | K10: ='FS Qtr'!K$33 -> 0 | L10: ='FS Qtr'!L$33 -> 0 | ... EA10: ='FS Qtr'!EA$33 -> 0
E11: =Time!E$125 -> Senior debt repayment period flag | F11: =Time!F$125 -> 0 | G11: =Time!G$125 -> flag | H11: =Time!H$125 -> 40 | I11: =Time!I$125 -> 0 | J11: =Time!J$125 -> 0 | K11: =Time!K$125 -> 0 | L11: =Time!L$125 -> 0 | ... EA11: =Time!EA$125 -> 0
E12: CFADS during debt term | G12: =SMU -> $ 000s | H12: =SUM(J12:EA12) -> 136095.43 | J12: =J10 * J11 -> 0 | K12: =K10 * K11 -> 0 | L12: =L10 * L11 -> 0 | M12: =M10 * M11 -> 1519.3516 | N12: =N10 * N11 -> 5023.8866 | O12: =O10 * O11 -> 4170.5296 | P12: =P10 * P11 -> 2028.6153 | Q12: =Q10 * Q11 -> 3006.718 | ... EA12: =EA10 * EA11 -> 0
E14: =InpC!E$51 -> DSCR for debt sizing | F14: =InpC!F$51 -> 1.3 | G14: =InpC!G$51 -> ratio
E15: =E$12 -> CFADS during debt term | F15: =F$12 -> 0 | G15: =G$12 -> $ 000s | H15: =H$12 -> 136095.43 | I15: =I$12 -> 0 | J15: =J$12 -> 0 | K15: =K$12 -> 0 | L15: =L$12 -> 0 | ... EA15: =EA$12 -> 0
E16: Debt service at target DSCR | G16: =SMU -> $ 000s | H16: =SUM(J16:EA16) -> 104688.79 | J16: =J15 / $F14 -> 0 | K16: =K15 / $F14 -> 0 | L16: =L15 / $F14 -> 0 | M16: =M15 / $F14 -> 1168.732 | N16: =N15 / $F14 -> 3864.5282 | O16: =O15 / $F14 -> 3208.0997 | P16: =P15 / $F14 -> 1560.4733 | Q16: =Q15 / $F14 -> 2312.86 | ... EA16: =EA15 / $F14 -> 0
E18: =Time!E$76 -> Financial close date flag | F18: =Time!F$76 -> 0 | G18: =Time!G$76 -> flag | H18: =Time!H$76 -> 1 | I18: =Time!I$76 -> 0 | J18: =Time!J$76 -> 0 | K18: =Time!K$76 -> 0 | L18: =Time!L$76 -> 1 | ... EA18: =Time!EA$76 -> 0
E19: =E$77 -> Senior debt period interest rate | F19: =F$77 -> 0 | G19: =G$77 -> rate | H19: =H$77 -> 0 | I19: =I$77 -> 0 | J19: =J$77 -> 0.015333333 | K19: =K$77 -> 0.015333333 | L19: =L$77 -> 0.015 | ... EA19: =EA$77 -> 0.015333333
E20: Senior debt discount factor | G20: ratio | J20: =IF( J18 = 1, 1, I20 / (1 + J19)) -> 0 | K20: =IF( K18 = 1, 1, J20 / (1 + K19)) -> 0 | L20: =IF( L18 = 1, 1, K20 / (1 + L19)) -> 1 | M20: =IF( M18 = 1, 1, L20 / (1 + M19)) -> 0.98505992 | N20: =IF( N18 = 1, 1, M20 / (1 + N19)) -> 0.97018377 | O20: =IF( O18 = 1, 1, N20 / (1 + O19)) -> 0.95553228 | P20: =IF( P18 = 1, 1, O20 / (1 + P19)) -> 0.94141111 | Q20: =IF( Q18 = 1, 1, P20 / (1 + Q19)) -> 0.92734636 | ... EA20: =IF( EA18 = 1, 1, DZ20 / (1 + EA19)) -> 0.16570915
E22: =E$16 -> Debt service at target DSCR | F22: =F$16 -> 0 | G22: =G$16 -> $ 000s | H22: =H$16 -> 104688.79 | I22: =I$16 -> 0 | J22: =J$16 -> 0 | K22: =K$16 -> 0 | L22: =L$16 -> 0 | ... EA22: =EA$16 -> 0
E23: =E$20 -> Senior debt discount factor | F23: =F$20 -> 0 | G23: =G$20 -> ratio | H23: =H$20 -> 0 | I23: =I$20 -> 0 | J23: =J$20 -> 0 | K23: =K$20 -> 0 | L23: =L$20 -> 1 | ... EA23: =EA$20 -> 0.16570915
E24: Debt capacity at target ratio | F24: =SUMPRODUCT(J22:EA22, J23:EA23) -> 78175.933 | G24: =SMU -> $ 000s
B27: Senior debt initial drawdown
E28: =InpC!E$52 -> Senior debt sizing method | F28: =InpC!F$52 -> 2 | G28: =InpC!G$52 -> 1 = leverage, 2 = DSCR
E29: =InpC!E$46 -> Senior debt leverage | F29: =InpC!F$46 -> 0.7 | G29: =InpC!G$46 -> %
E30: =InpC!E$65 -> Fixed asset - initial balance | F30: =InpC!F$65 -> 100000 | G30: =InpC!G$65 -> $ 000s
E31: =E$24 -> Debt capacity at target ratio | F31: =F$24 -> 78175.933 | G31: =G$24 -> $ 000s
E32: Senior debt initial drawdown | F32: =IF( F28 = 1, F29 * F30, F31) -> 78175.933 | G32: =SMU -> $ 000s
B34: Senior debt principal repayment
C35: Level principal repayment
E36: =E$32 -> Senior debt initial drawdown | F36: =F$32 -> 78175.933 | G36: =G$32 -> $ 000s
E37: =InpC!E$45 -> Senior debt repayment period | F37: =InpC!F$45 -> 10 | G37: =InpC!G$45 -> years
E38: =InpC!E$74 -> Number of periods in a year | F38: =InpC!F$74 -> 4 | G38: =InpC!G$74 -> periods
E39: =Time!E$125 -> Senior debt repayment period flag | F39: =Time!F$125 -> 0 | G39: =Time!G$125 -> flag | H39: =Time!H$125 -> 40 | I39: =Time!I$125 -> 0 | J39: =Time!J$125 -> 0 | K39: =Time!K$125 -> 0 | L39: =Time!L$125 -> 0 | ... EA39: =Time!EA$125 -> 0
E40: Senior debt straight line principal repayment | G40: =SMU -> $ 000s | H40: =SUM(J40:EA40) -> 78175.933 | J40: =$F36 / $F37 / $F38 * J39 -> 0 | K40: =$F36 / $F37 / $F38 * K39 -> 0 | L40: =$F36 / $F37 / $F38 * L39 -> 0 | M40: =$F36 / $F37 / $F38 * M39 -> 1954.3983 | N40: =$F36 / $F37 / $F38 * N39 -> 1954.3983 | O40: =$F36 / $F37 / $F38 * O39 -> 1954.3983 | P40: =$F36 / $F37 / $F38 * P39 -> 1954.3983 | Q40: =$F36 / $F37 / $F38 * Q39 -> 1954.3983 | ... EA40: =$F36 / $F37 / $F38 * EA39 -> 0
C42: Amortising debt repayment
E43: =E$20 -> Senior debt discount factor | F43: =F$20 -> 0 | G43: =G$20 -> ratio | H43: =H$20 -> 0 | I43: =I$20 -> 0 | J43: =J$20 -> 0 | K43: =K$20 -> 0 | L43: =L$20 -> 1 | ... EA43: =EA$20 -> 0.16570915
E44: =Time!E$125 -> Senior debt repayment period flag | F44: =Time!F$125 -> 0 | G44: =Time!G$125 -> flag | H44: =Time!H$125 -> 40 | I44: =Time!I$125 -> 0 | J44: =Time!J$125 -> 0 | K44: =Time!K$125 -> 0 | L44: =Time!L$125 -> 0 | ... EA44: =Time!EA$125 -> 0
E45: Sum of senior debt discount factors | F45: =SUMPRODUCT(J43:EA43, J44:EA44) -> 29.796052 | G45: ratio
E47: =E$32 -> Senior debt initial drawdown | F47: =F$32 -> 78175.933 | G47: =G$32 -> $ 000s
E48: =E$45 -> Sum of senior debt discount factors | F48: =F$45 -> 29.796052 | G48: =G$45 -> ratio
E49: Senior debt periodic amortising debt service | F49: =F47 / F48 -> 2623.701 | G49: =SMU -> $ 000s
E51: =E$49 -> Senior debt periodic amortising debt service | F51: =F$49 -> 2623.701 | G51: =G$49 -> $ 000s
...

Sheet Equity
A1: =RIGHT(CELL("filename", A1), LEN(CELL("filename", A1)) - SEARCH("]", CELL("filename", A1))) & " - " & InpC!F3 -> Equity - Base case 1
E2: =Time!E$25 -> Model period ending | F2: =Check!$F$9 -> 0 | G2: Error chks | J2: =Time!J$25 -> 44104 | K2: =Time!K$25 -> 44196 | L2: =Time!L$25 -> 44286 | M2: =Time!M$25 -> 44377 | N2: =Time!N$25 -> 44469 | O2: =Time!O$25 -> 44561 | P2: =Time!P$25 -> 44651 | Q2: =Time!Q$25 -> 44742 | ... EA2: =Time!EA$25 -> 55153
E3: =Time!E$67 -> Timeline label | F3: =Output!J2 -> 0 | G3: Track chgs | J3: =Time!J$67 -> Pre-fcst | K3: =Time!K$67 -> Pre-fcst | L3: =Time!L$67 -> Fin Close | M3: =Time!M$67 -> Operations | N3: =Time!N$67 -> Operations | O3: =Time!O$67 -> Operations | P3: =Time!P$67 -> Operations | Q3: =Time!Q$67 -> Operations | ... EA3: =Time!EA$67 -> Post ops
E4: =Time!E$42 -> Contract year | F4: =Check!$F$21 -> 0 | G4: Alerts | J4: =Time!J$42 -> 2020 | K4: =Time!K$42 -> 2020 | L4: =Time!L$42 -> 2020 | M4: =Time!M$42 -> 2021 | N4: =Time!N$42 -> 2021 | O4: =Time!O$42 -> 2021 | P4: =Time!P$42 -> 2021 | Q4: =Time!Q$42 -> 2022 | ... EA4: =Time!EA$42 -> 2050
E5: =Time!E$10 -> Model column counter | F5: Constant | G5: Unit | H5: Total | J5: =Time!J$10 -> 1 | K5: =Time!K$10 -> 2 | L5: =Time!L$10 -> 3 | M5: =Time!M$10 -> 4 | N5: =Time!N$10 -> 5 | O5: =Time!O$10 -> 6 | P5: =Time!P$10 -> 7 | Q5: =Time!Q$10 -> 8 | ... EA5: =Time!EA$10 -> 122
A8: SHARE CAPITAL
B10: Share capital initial drawdown
E11: =InpC!E$65 -> Fixed asset - initial balance | F11: =InpC!F$65 -> 100000 | G11: =InpC!G$65 -> $ 000s
E12: =Debt!E$32 -> Senior debt initial drawdown | F12: =Debt!F$32 -> 78175.933 | G12: =Debt!G$32 -> $ 000s
E13: Share capital - initial drawdown | F13: =F11 - F12 -> 21824.067 | G13: =SMU -> $ 000s
B15: Share capital redemption
E16: =E$26 -> Share capital balance BEG | F16: =F$26 -> 0 | G16: =G$26 -> $ 000s | H16: =H$26 -> 0 | I16: =I$26 -> 0 | J16: =J$26 -> 0 | K16: =K$26 -> 0 | L16: =L$26 -> 0 | ... EA16: =EA$26 -> 0
E17: =Time!E$91 -> Last operating period flag | F17: =Time!F$91 -> 0 | G17: =Time!G$91 -> flag | H17: =Time!H$91 -> 1 | I17: =Time!I$91 -> 0 | J17: =Time!J$91 -> 0 | K17: =Time!K$91 -> 0 | L17: =Time!L$91 -> 0 | ... EA17: =Time!EA$91 -> 0
E18: Share capital redemption POS | G18: =SMU -> $ 000s | H18: =SUM(J18:EA18) -> 21824.067 | J18: =J16 * J17 -> 0 | K18: =K16 * K17 -> 0 | L18: =L16 * L17 -> 0 | M18: =M16 * M17 -> 0 | N18: =N16 * N17 -> 0 | O18: =O16 * O17 -> 0 | P18: =P16 * P17 -> 0 | Q18: =Q16 * Q17 -> 0 | ... EA18: =EA16 * EA17 -> 0
E19: =LEFT(E18, LEN(E18) - 4) -> Share capital redemption | G19: =SMU -> $ 000s | H19: =SUM(J19:EA19) -> -21824.067 | J19: =-1 * J18 -> 0 | K19: =-1 * K18 -> 0 | L19: =-1 * L18 -> 0 | M19: =-1 * M18 -> 0 | N19: =-1 * N18 -> 0 | O19: =-1 * O18 -> 0 | P19: =-1 * P18 -> 0 | Q19: =-1 * Q18 -> 0 | ... EA19: =-1 * EA18 -> 0
B21: Share capital balance
E23: =E$13 -> Share capital - initial drawdown | F23: =F$13 -> 21824.067 | G23: =G$13 -> $ 000s
E24: =Time!E$76 -> Financial close date flag | F24: =Time!F$76 -> 0 | G24: =Time!G$76 -> flag | H24: =Time!H$76 -> 1 | I24: =Time!I$76 -> 0 | J24: =Time!J$76 -> 0 | K24: =Time!K$76 -> 0 | L24: =Time!L$76 -> 1 | ... EA24: =Time!EA$76 -> 0
E26: Share capital balance BEG | G26: =SMU -> $ 000s | J26: =I29 -> 0 | K26: =J29 -> 0 | L26: =K29 -> 0 | M26: =L29 -> 21824.067 | N26: =M29 -> 21824.067 | O26: =N29 -> 21824.067 | P26: =O29 -> 21824.067 | Q26: =P29 -> 21824.067 | ... EA26: =DZ29 -> 0
E27: [Additional share capital issued]
E28: =E$18 -> Share capital redemption POS | F28: =F$18 -> 0 | G28: =G$18 -> $ 000s | H28: =H$18 -> 21824.067 | I28: =I$18 -> 0 | J28: =J$18 -> 0 | K28: =K$18 -> 0 | L28: =L$18 -> 0 | ... EA28: =EA$18 -> 0
E29: Share capital balance | G29: =SMU -> $ 000s | J29: =IF( J24 = 1, $F23, J26 + J27 - J28) -> 0 | K29: =IF( K24 = 1, $F23, K26 + K27 - K28) -> 0 | L29: =IF( L24 = 1, $F23, L26 + L27 - L28) -> 21824.067 | M29: =IF( M24 = 1, $F23, M26 + M27 - M28) -> 21824.067 | N29: =IF( N24 = 1, $F23, N26 + N27 - N28) -> 21824.067 | O29: =IF( O24 = 1, $F23, O26 + O27 - O28) -> 21824.067 | P29: =IF( P24 = 1, $F23, P26 + P27 - P28) -> 21824.067 | Q29: =IF( Q24 = 1, $F23, Q26 + Q27 - Q28) -> 21824.067 | ... EA29: =IF( EA24 = 1, $F23, EA26 + EA27 - EA28) -> 0
A33: RETAINED EARNINGS
E35: =InpC!E$61 -> Retained earnings - initial balance | F35: =InpC!F$61 -> 0 | G35: =InpC!G$61 -> $ 000s
E36: =Time!E$76 -> Financial close date flag | F36: =Time!F$76 -> 0 | G36: =Time!G$76 -> flag | H36: =Time!H$76 -> 1 | I36: =Time!I$76 -> 0 | J36: =Time!J$76 -> 0 | K36: =Time!K$76 -> 0 | L36: =Time!L$76 -> 1 | ... EA36: =Time!EA$76 -> 0
E38: Retained earnings balance BEG | G38: =SMU -> $ 000s | J38: =I41 -> 0 | K38: =J41 -> 0 | L38: =K41 -> 0 | M38: =L41 -> 0 | N38: =M41 -> 2288.4621 | O38: =N41 -> 4225.8869 | P38: =O41 -> 3167.9061 | Q38: =P41 -> 2658.2359 | ... EA38: =DZ41 -> 4.5497892e-10
E39: ='FS Qtr'!E$22 -> Profit after tax | F39: ='FS Qtr'!F$22 -> 0 | G39: ='FS Qtr'!G$22 -> $ 000s | H39: ='FS Qtr'!H$22 -> 196154.18 | I39: ='FS Qtr'!I$22 -> 0 | J39: ='FS Qtr'!J$22 -> 0 | K39: ='FS Qtr'!K$22 -> 0 | L39: ='FS Qtr'!L$22 -> 0 | ... EA39: ='FS Qtr'!EA$22 -> 7.0333755e-12
E40: =E$69 -> Dividends paid POS | F40: =F$69 -> 0 | G40: =G$69 -> $ 000s | H40: =H$69 -> 196154.18 | I40: =I$69 -> 0 | J40: =J$69 -> 0 | K40: =K$69 -> 0 | L40: =L$69 -> 0 | ... EA40: =EA$69 -> 0
E41: Retained earnings balance | G41: =SMU -> $ 000s | J41: =IF( J36 = 1, $F35, J38 + J39 - J40) -> 0 | K41: =IF( K36 = 1, $F35, K38 + K39 - K40) -> 0 | L41: =IF( L36 = 1, $F35, L38 + L39 - L40) -> 0 | M41: =IF( M36 = 1, $F35, M38 + M39 - M40) -> 2288.4621 | N41: =IF( N36 = 1, $F35, N38 + N39 - N40) -> 4225.8869 | O41: =IF( O36 = 1, $F35, O38 + O39 - O40) -> 3167.9061 | P41: =IF( P36 = 1, $F35, P38 + P39 - P40) -> 2658.2359 | Q41: =IF( Q36 = 1, $F35, Q38 + Q39 - Q40) -> 4648.2006 | ... EA41: =IF( EA36 = 1, $F35, EA38 + EA39 - EA40) -> 4.620123e-10
A44: RETAINED CASH
E46: =InpC!E$62 -> Retained cash - initial balance | F46: =InpC!F$62 -> 0 | G46: =InpC!G$62 -> $ 000s
E47: =Time!E$76 -> Financial close date flag | F47: =Time!F$76 -> 0 | G47: =Time!G$76 -> flag | H47: =Time!H$76 -> 1 | I47: =Time!I$76 -> 0 | J47: =Time!J$76 -> 0 | K47: =Time!K$76 -> 0 | L47: =Time!L$76 -> 1 | ... EA47: =Time!EA$76 -> 0
E49: Retained cash balance BEG | G49: =SMU -> $ 000s | J49: =I52 -> 0 | K49: =J52 -> 0 | L49: =K52 -> 0 | M49: =L52 -> 0 | N49: =M52 -> 0 | O49: =N52 -> 0 | P49: =O52 -> 0 | Q49: =P52 -> 0 | ... EA49: =DZ52 -> 0
E50: ='FS Qtr'!E$50 -> Cash flow available for dividends | F50: ='FS Qtr'!F$50 -> 0 | G50: ='FS Qtr'!G$50 -> $ 000s | H50: ='FS Qtr'!H$50 -> 196154.18 | I50: ='FS Qtr'!I$50 -> 0 | J50: ='FS Qtr'!J$50 -> 0 | K50: ='FS Qtr'!K$50 -> 0 | L50: ='FS Qtr'!L$50 -> 0 | ... EA50: ='FS Qtr'!EA$50 -> 0
E51: =E$69 -> Dividends paid POS | F51: =F$69 -> 0 | G51: =G$69 -> $ 000s | H51: =H$69 -> 196154.18 | I51: =I$69 -> 0 | J51: =J$69 -> 0 | K51: =K$69 -> 0 | L51: =L$69 -> 0 | ... EA51: =EA$69 -> 0
E52: Retained cash balance | G52: =SMU -> $ 000s | J52: =IF( J47 = 1, $F46, J49 + J50 - J51) -> 0 | K52: =IF( K47 = 1, $F46, K49 + K50 - K51) -> 0 | L52: =IF( L47 = 1, $F46, L49 + L50 - L51) -> 0 | M52: =IF( M47 = 1, $F46, M49 + M50 - M51) -> 0 | N52: =IF( N47 = 1, $F46, N49 + N50 - N51) -> 0 | O52: =IF( O47 = 1, $F46, O49 + O50 - O51) -> 0 | P52: =IF( P47 = 1, $F46, P49 + P50 - P51) -> 0 | Q52: =IF( Q47 = 1, $F46, Q49 + Q50 - Q51) -> 0 | ... EA52: =IF( EA47 = 1, $F46, EA49 + EA50 - EA51) -> 0
A54: DIVIDENDS
B56: Earnings available for dividend
E57: =E$38 -> Retained earnings balance BEG | F57: =F$38 -> 0 | G57: =G$38 -> $ 000s | H57: =H$38 -> 0 | I57: =I$38 -> 0 | J57: =J$38 -> 0 | K57: =K$38 -> 0 | L57: =L$38 -> 0 | ... EA57: =EA$38 -> 4.5497892e-10
E58: ='FS Qtr'!E$22 -> Profit after tax | F58: ='FS Qtr'!F$22 -> 0 | G58: ='FS Qtr'!G$22 -> $ 000s | H58: ='FS Qtr'!H$22 -> 196154.18 | I58: ='FS Qtr'!I$22 -> 0 | J58: ='FS Qtr'!J$22 -> 0 | K58: ='FS Qtr'!K$22 -> 0 | L58: ='FS Qtr'!L$22 -> 0 | ... EA58: ='FS Qtr'!EA$22 -> 7.0333755e-12
...

Sheet Metrics
A1: =RIGHT(CELL("filename", A1), LEN(CELL("filename", A1)) - SEARCH("]", CELL("filename", A1))) & " - " & InpC!F3 -> Metrics - Base case 1
E2: =Time!E$25 -> Model period ending | F2: =Check!$F$9 -> 0 | G2: Error chks | J2: =Time!J$25 -> 44104 | K2: =Time!K$25 -> 44196 | L2: =Time!L$25 -> 44286 | M2: =Time!M$25 -> 44377 | N2: =Time!N$25 -> 44469 | O2: =Time!O$25 -> 44561 | P2: =Time!P$25 -> 44651 | Q2: =Time!Q$25 -> 44742 | ... EA2: =Time!EA$25 -> 55153
E3: =Time!E$67 -> Timeline label | F3: =Output!J2 -> 0 | G3: Track chgs | J3: =Time!J$67 -> Pre-fcst | K3: =Time!K$67 -> Pre-fcst | L3: =Time!L$67 -> Fin Close | M3: =Time!M$67 -> Operations | N3: =Time!N$67 -> Operations | O3: =Time!O$67 -> Operations | P3: =Time!P$67 -> Operations | Q3: =Time!Q$67 -> Operations | ... EA3: =Time!EA$67 -> Post ops
E4: =Time!E$42 -> Contract year | F4: =Check!$F$21 -> 0 | G4: Alerts | J4: =Time!J$42 -> 2020 | K4: =Time!K$42 -> 2020 | L4: =Time!L$42 -> 2020 | M4: =Time!M$42 -> 2021 | N4: =Time!N$42 -> 2021 | O4: =Time!O$42 -> 2021 | P4: =Time!P$42 -> 2021 | Q4: =Time!Q$42 -> 2022 | ... EA4: =Time!EA$42 -> 2050
E5: =Time!E$10 -> Model column counter | F5: Constant | G5: Unit | H5: Total | J5: =Time!J$10 -> 1 | K5: =Time!K$10 -> 2 | L5: =Time!L$10 -> 3 | M5: =Time!M$10 -> 4 | N5: =Time!N$10 -> 5 | O5: =Time!O$10 -> 6 | P5: =Time!P$10 -> 7 | Q5: =Time!Q$10 -> 8 | ... EA5: =Time!EA$10 -> 122
A7: IRR
B9: Equity IRR
E10: =Equity!E$13 -> Share capital - initial drawdown | F10: =Equity!F$13 -> 21824.067 | G10: =Equity!G$13 -> $ 000s
E11: =InpC!E$79 -> Small negative value for XIRR | F11: =InpC!F$79 -> -1e-07 | G11: =InpC!G$79 -> $ 000s
E12: =Time!E$76 -> Financial close date flag | F12: =Time!F$76 -> 0 | G12: =Time!G$76 -> flag | H12: =Time!H$76 -> 1 | I12: =Time!I$76 -> 0 | J12: =Time!J$76 -> 0 | K12: =Time!K$76 -> 0 | L12: =Time!L$76 -> 1 | ... EA12: =Time!EA$76 -> 0
E13: =Time!E$14 -> First model column flag | F13: =Time!F$14 -> 0 | G13: =Time!G$14 -> flag | H13: =Time!H$14 -> 1 | I13: =Time!I$14 -> 0 | J13: =Time!J$14 -> 1 | K13: =Time!K$14 -> 0 | L13: =Time!L$14 -> 0 | ... EA13: =Time!EA$14 -> 0
E14: =Equity!E$69 -> Dividends paid POS | F14: =Equity!F$69 -> 0 | G14: =Equity!G$69 -> $ 000s | H14: =Equity!H$69 -> 196154.18 | I14: =Equity!I$69 -> 0 | J14: =Equity!J$69 -> 0 | K14: =Equity!K$69 -> 0 | L14: =Equity!L$69 -> 0 | ... EA14: =Equity!EA$69 -> 0
E15: =Equity!E$18 -> Share capital redemption POS | F15: =Equity!F$18 -> 0 | G15: =Equity!G$18 -> $ 000s | H15: =Equity!H$18 -> 21824.067 | I15: =Equity!I$18 -> 0 | J15: =Equity!J$18 -> 0 | K15: =Equity!K$18 -> 0 | L15: =Equity!L$18 -> 0 | ... EA15: =Equity!EA$18 -> 0
E16: Net cashflow to / (from) equity | G16: =SMU -> $ 000s | H16: =SUM(J16:EA16) -> 196154.18 | J16: =$F11 * J13 + -1 * $F10 * J12 + J14 + J15 -> -1e-07 | K16: =$F11 * K13 + -1 * $F10 * K12 + K14 + K15 -> 0 | L16: =$F11 * L13 + -1 * $F10 * L12 + L14 + L15 -> -21824.067 | M16: =$F11 * M13 + -1 * $F10 * M12 + M14 + M15 -> 350.61961 | N16: =$F11 * N13 + -1 * $F10 * N12 + N14 + N15 -> 1159.3584 | O16: =$F11 * O13 + -1 * $F10 * O12 + O14 + O15 -> 962.4299 | P16: =$F11 * P13 + -1 * $F10 * P12 + P14 + P15 -> 468.142 | Q16: =$F11 * Q13 + -1 * $F10 * Q12 + Q14 + Q15 -> 693.85801 | ... EA16: =$F11 * EA13 + -1 * $F10 * EA12 + EA14 + EA15 -> 0
E18: =E$16 -> Net cashflow to / (from) equity | F18: =F$16 -> 0 | G18: =G$16 -> $ 000s | H18: =H$16 -> 196154.18 | I18: =I$16 -> 0 | J18: =J$16 -> -1e-07 | K18: =K$16 -> 0 | L18: =L$16 -> -21824.067 | ... EA18: =EA$16 -> 0
E19: =Time!E$25 -> Model period ending | F19: =Time!F$25 -> 0 | G19: =Time!G$25 -> date | H19: =Time!H$25 -> 0 | I19: =Time!I$25 -> 0 | J19: =Time!J$25 -> 44104 | K19: =Time!K$25 -> 44196 | L19: =Time!L$25 -> 44286 | ... EA19: =Time!EA$25 -> 55153
E20: Equity IRR | F20: =XIRR(J18:EA18, J19:EA19) -> 0.21705926 | G20: %
A23: DEBT RATIOS
B25: 3m historic DSCR
E27: ='FS Qtr'!E$33 -> Cash flow available for senior debt service | F27: ='FS Qtr'!F$33 -> 0 | G27: ='FS Qtr'!G$33 -> $ 000s | H27: ='FS Qtr'!H$33 -> 322667.04 | I27: ='FS Qtr'!I$33 -> 0 | J27: ='FS Qtr'!J$33 -> 0 | K27: ='FS Qtr'!K$33 -> 0 | L27: ='FS Qtr'!L$33 -> 0 | ... EA27: ='FS Qtr'!EA$33 -> 0
E28: =Debt!E$98 -> Senior debt service | F28: =Debt!F$98 -> 0 | G28: =Debt!G$98 -> $ 000s | H28: =Debt!H$98 -> 104688.79 | I28: =Debt!I$98 -> 0 | J28: =Debt!J$98 -> 0 | K28: =Debt!K$98 -> 0 | L28: =Debt!L$98 -> 0 | ... EA28: =Debt!EA$98 -> 0
E29: =Time!E$125 -> Senior debt repayment period flag | F29: =Time!F$125 -> 0 | G29: =Time!G$125 -> flag | H29: =Time!H$125 -> 40 | I29: =Time!I$125 -> 0 | J29: =Time!J$125 -> 0 | K29: =Time!K$125 -> 0 | L29: =Time!L$125 -> 0 | ... EA29: =Time!EA$125 -> 0
E30: 3m historic DSCR | G30: ratio | J30: =IF( J29 = 1, J27 / J28, "na") -> na | K30: =IF( K29 = 1, K27 / K28, "na") -> na | L30: =IF( L29 = 1, L27 / L28, "na") -> na | M30: =IF( M29 = 1, M27 / M28, "na") -> 1.3 | N30: =IF( N29 = 1, N27 / N28, "na") -> 1.3 | O30: =IF( O29 = 1, O27 / O28, "na") -> 1.3 | P30: =IF( P29 = 1, P27 / P28, "na") -> 1.3 | Q30: =IF( Q29 = 1, Q27 / Q28, "na") -> 1.3 | ... EA30: =IF( EA29 = 1, EA27 / EA28, "na") -> na
E31: Min 3m historic DSCR | F31: =MIN(J30:EA30) -> 1.3 | G31: ratio
E32: Avg 3m historic DSCR | F32: =AVERAGE(J30:EA30) -> 1.3 | G32: ratio

Sheet FS Qtr
A1: =RIGHT(CELL("filename", A1), LEN(CELL("filename", A1)) - SEARCH("]", CELL("filename", A1))) & " - " & InpC!F3 -> FS Qtr - Base case 1
E2: =Time!E$25 -> Model period ending | F2: =Check!$F$9 -> 0 | G2: Error chks | J2: =Time!J$25 -> 44104 | K2: =Time!K$25 -> 44196 | L2: =Time!L$25 -> 44286 | M2: =Time!M$25 -> 44377 | N2: =Time!N$25 -> 44469 | O2: =Time!O$25 -> 44561 | P2: =Time!P$25 -> 44651 | Q2: =Time!Q$25 -> 44742 | ... EA2: =Time!EA$25 -> 55153
E3: =Time!E$67 -> Timeline label | F3: =Output!J2 -> 0 | G3: Track chgs | J3: =Time!J$67 -> Pre-fcst | K3: =Time!K$67 -> Pre-fcst | L3: =Time!L$67 -> Fin Close | M3: =Time!M$67 -> Operations | N3: =Time!N$67 -> Operations | O3: =Time!O$67 -> Operations | P3: =Time!P$67 -> Operations | Q3: =Time!Q$67 -> Operations | ... EA3: =Time!EA$67 -> Post ops
E4: =Time!E$42 -> Contract year | F4: =Check!$F$21 -> 0 | G4: Alerts | J4: =Time!J$42 -> 2020 | K4: =Time!K$42 -> 2020 | L4: =Time!L$42 -> 2020 | M4: =Time!M$42 -> 2021 | N4: =Time!N$42 -> 2021 | O4: =Time!O$42 -> 2021 | P4: =Time!P$42 -> 2021 | Q4: =Time!Q$42 -> 2022 | ... EA4: =Time!EA$42 -> 2050
E5: =Time!E$10 -> Model column counter | F5: Constant | G5: Unit | H5: Total | J5: =Time!J$10 -> 1 | K5: =Time!K$10 -> 2 | L5: =Time!L$10 -> 3 | M5: =Time!M$10 -> 4 | N5: =Time!N$10 -> 5 | O5: =Time!O$10 -> 6 | P5: =Time!P$10 -> 7 | Q5: =Time!Q$10 -> 8 | ... EA5: =Time!EA$10 -> 122
A7: INCOME STATEMENT
E9: =Ops!E$38 -> Electricity revenue | F9: =Ops!F$38 -> 0 | G9: =Ops!G$38 -> $ 000s | H9: =Ops!H$38 -> 371409.68 | I9: =Ops!I$38 -> 0 | J9: =Ops!J$38 -> 0 | K9: =Ops!K$38 -> 0 | L9: =Ops!L$38 -> 0 | ... EA9: =Ops!EA$38 -> 0
E10: =Ops!E$98 -> O&M cost | F10: =Ops!F$98 -> 0 | G10: =Ops!G$98 -> $ 000s | H10: =Ops!H$98 -> -48742.638 | I10: =Ops!I$98 -> 0 | J10: =Ops!J$98 -> 0 | K10: =Ops!K$98 -> 0 | L10: =Ops!L$98 -> 0 | ... EA10: =Ops!EA$98 -> 0
E11: EBITDA | G11: =SMU -> $ 000s | H11: =SUM(J11:EA11) -> 322667.04 | J11: =SUM(J9:J10) -> 0 | K11: =SUM(K9:K10) -> 0 | L11: =SUM(L9:L10) -> 0 | M11: =SUM(M9:M10) -> 4824.75 | N11: =SUM(N9:N10) -> 5295.7406 | O11: =SUM(O9:O10) -> 2062.5343 | P11: =SUM(P9:P10) -> 2060.6311 | Q11: =SUM(Q9:Q10) -> 4791.277 | ... EA11: =SUM(EA9:EA10) -> 0
E13: =Asset!E$16 -> Depreciation of fixed asset | F13: =Asset!F$16 -> 0 | G13: =Asset!G$16 -> $ 000s | H13: =Asset!H$16 -> -100000 | I13: =Asset!I$16 -> 0 | J13: =Asset!J$16 -> 0 | K13: =Asset!K$16 -> 0 | L13: =Asset!L$16 -> 0 | ... EA13: =Asset!EA$16 -> 0
E14: EBIT | G14: =SMU -> $ 000s | H14: =SUM(J14:EA14) -> 222667.04 | J14: =J11 + SUM(J13:J13) -> 0 | K14: =K11 + SUM(K13:K13) -> 0 | L14: =L11 + SUM(L13:L13) -> 0 | M14: =M11 + SUM(M13:M13) -> 3824.75 | N14: =N11 + SUM(N13:N13) -> 4295.7406 | O14: =O11 + SUM(O13:O13) -> 1062.5343 | P14: =P11 + SUM(P13:P13) -> 1060.6311 | Q14: =Q11 + SUM(Q13:Q13) -> 3791.277 | ... EA14: =EA11 + SUM(EA13:EA13) -> 0
E16: =Debt!E$82 -> Senior debt interest | F16: =Debt!F$82 -> 0 | G16: =Debt!G$82 -> $ 000s | H16: =Debt!H$82 -> -26512.862 | I16: =Debt!I$82 -> 0 | J16: =Debt!J$82 -> 0 | K16: =Debt!K$82 -> 0 | L16: =Debt!L$82 -> 0 | ... EA16: =Debt!EA$82 -> 7.0333755e-12
E17: [Refi facility interest]
E18: [RCF interest expense]
E19: Profit before tax | G19: =SMU -> $ 000s | H19: =SUM(J19:EA19) -> 196154.18 | J19: =J14 + SUM(J16:J18) -> 0 | K19: =K14 + SUM(K16:K18) -> 0 | L19: =L14 + SUM(L16:L18) -> 0 | M19: =M14 + SUM(M16:M18) -> 2639.0817 | N19: =N14 + SUM(N16:N18) -> 3096.7833 | O19: =O14 + SUM(O16:O18) -> -95.550908 | P19: =P14 + SUM(P16:P18) -> -41.528192 | Q19: =Q14 + SUM(Q16:Q18) -> 2683.8227 | ... EA19: =EA14 + SUM(EA16:EA18) -> 7.0333755e-12
E21: [Corporate income tax expense]
E22: Profit after tax | G22: =SMU -> $ 000s | H22: =SUM(J22:EA22) -> 196154.18 | J22: =J19 + J21 -> 0 | K22: =K19 + K21 -> 0 | L22: =L19 + L21 -> 0 | M22: =M19 + M21 -> 2639.0817 | N22: =N19 + N21 -> 3096.7833 | O22: =O19 + O21 -> -95.550908 | P22: =P19 + P21 -> -41.528192 | Q22: =Q19 + Q21 -> 2683.8227 | ... EA22: =EA19 + EA21 -> 7.0333755e-12
E24: =Equity!E$70 -> Dividends paid | F24: =Equity!F$70 -> 0 | G24: =Equity!G$70 -> $ 000s | H24: =Equity!H$70 -> -196154.18 | I24: =Equity!I$70 -> 0 | J24: =Equity!J$70 -> 0 | K24: =Equity!K$70 -> 0 | L24: =Equity!L$70 -> 0 | ... EA24: =Equity!EA$70 -> 0
E25: Net income after dividends | G25: =SMU -> $ 000s | H25: =SUM(J25:EA25) -> 4.8656866e-10 | J25: =J22 + J24 -> 0 | K25: =K22 + K24 -> 0 | L25: =L22 + L24 -> 0 | M25: =M22 + M24 -> 2288.4621 | N25: =N22 + N24 -> 1937.4249 | O25: =O22 + O24 -> -1057.9808 | P25: =P22 + P24 -> -509.67019 | Q25: =Q22 + Q24 -> 1989.9647 | ... EA25: =EA22 + EA24 -> 7.0333755e-12
A28: CASH FLOW STATEMENT
E30: =Ops!E$53 -> Cash received from invoices | F30: =Ops!F$53 -> 0 | G30: =Ops!G$53 -> $ 000s | H30: =Ops!H$53 -> 371409.68 | I30: =Ops!I$53 -> 0 | J30: =Ops!J$53 -> 0 | K30: =Ops!K$53 -> 0 | L30: =Ops!L$53 -> 0 | ... EA30: =Ops!EA$53 -> 0
E31: =Ops!E$114 -> Cash paid for operating costs | F31: =Ops!F$114 -> 0 | G31: =Ops!G$114 -> $ 000s | H31: =Ops!H$114 -> -48742.638 | I31: =Ops!I$114 -> 0 | J31: =Ops!J$114 -> 0 | K31: =Ops!K$114 -> 0 | L31: =Ops!L$114 -> 0 | ... EA31: =Ops!EA$114 -> 0
E32: [Corporate income tax expense]
E33: Cash flow available for senior debt service | G33: =SMU -> $ 000s | H33: =SUM(J33:EA33) -> 322667.04 | J33: =SUM(J30:J32) -> 0 | K33: =SUM(K30:K32) -> 0 | L33: =SUM(L30:L32) -> 0 | M33: =SUM(M30:M32) -> 1519.3516 | N33: =SUM(N30:N32) -> 5023.8866 | O33: =SUM(O30:O32) -> 4170.5296 | P33: =SUM(P30:P32) -> 2028.6153 | Q33: =SUM(Q30:Q32) -> 3006.718 | ... EA33: =SUM(EA30:EA32) -> 0
E35: =Debt!E$82 -> Senior debt interest | F35: =Debt!F$82 -> 0 | G35: =Debt!G$82 -> $ 000s | H35: =Debt!H$82 -> -26512.862 | I35: =Debt!I$82 -> 0 | J35: =Debt!J$82 -> 0 | K35: =Debt!K$82 -> 0 | L35: =Debt!L$82 -> 0 | ... EA35: =Debt!EA$82 -> 7.0333755e-12
E36: =Debt!E$69 -> Senior debt principal repayment | F36: =Debt!F$69 -> 0 | G36: =Debt!G$69 -> $ 000s | H36: =Debt!H$69 -> -78175.933 | I36: =Debt!I$69 -> 0 | J36: =Debt!J$69 -> 0 | K36: =Debt!K$69 -> 0 | L36: =Debt!L$69 -> 0 | ... EA36: =Debt!EA$69 -> -7.0333755e-12
E37: Cash flow available for refinancing facility | G37: =SMU -> $ 000s | H37: =SUM(J37:EA37) -> 217978.25 | J37: =J33 + SUM(J35:J36) -> 0 | K37: =K33 + SUM(K35:K36) -> 0 | L37: =L33 + SUM(L35:L36) -> 0 | M37: =M33 + SUM(M35:M36) -> 350.61961 | N37: =N33 + SUM(N35:N36) -> 1159.3584 | O37: =O33 + SUM(O35:O36) -> 962.4299 | P37: =P33 + SUM(P35:P36) -> 468.142 | Q37: =Q33 + SUM(Q35:Q36) -> 693.85801 | ... EA37: =EA33 + SUM(EA35:EA36) -> 0
E39: [Refi facility drawdown]
E40: [Refi facility repayment]
E41: [Refi facility interest]
E42: Cash flow available for revolving credit facility | G42: =SMU -> $ 000s | H42: =SUM(J42:EA42) -> 217978.25 | J42: =J37 + SUM(J39:J41) -> 0 | K42: =K37 + SUM(K39:K41) -> 0 | L42: =L37 + SUM(L39:L41) -> 0 | M42: =M37 + SUM(M39:M41) -> 350.61961 | N42: =N37 + SUM(N39:N41) -> 1159.3584 | O42: =O37 + SUM(O39:O41) -> 962.4299 | P42: =P37 + SUM(P39:P41) -> 468.142 | Q42: =Q37 + SUM(Q39:Q41) -> 693.85801 | ... EA42: =EA37 + SUM(EA39:EA41) -> 0
E44: [RCF drawdown]
E45: [RCF repayment]
E46: [RCF interest expense paid]
E47: Cash flow available for distribution | G47: =SMU -> $ 000s | H47: =SUM(J47:EA47) -> 217978.25 | J47: =J42 + SUM(J44:J46) -> 0 | K47: =K42 + SUM(K44:K46) -> 0 | L47: =L42 + SUM(L44:L46) -> 0 | M47: =M42 + SUM(M44:M46) -> 350.61961 | N47: =N42 + SUM(N44:N46) -> 1159.3584 | O47: =O42 + SUM(O44:O46) -> 962.4299 | P47: =P42 + SUM(P44:P46) -> 468.142 | Q47: =Q42 + SUM(Q44:Q46) -> 693.85801 | ... EA47: =EA42 + SUM(EA44:EA46) -> 0
E49: =Equity!E$19 -> Share capital redemption | F49: =Equity!F$19 -> 0 | G49: =Equity!G$19 -> $ 000s | H49: =Equity!H$19 -> -21824.067 | I49: =Equity!I$19 -> 0 | J49: =Equity!J$19 -> 0 | K49: =Equity!K$19 -> 0 | L49: =Equity!L$19 -> 0 | ... EA49: =Equity!EA$19 -> 0
E50: Cash flow available for dividends | G50: =SMU -> $ 000s | H50: =SUM(J50:EA50) -> 196154.18 | J50: =J47 + J49 -> 0 | K50: =K47 + K49 -> 0 | L50: =L47 + L49 -> 0 | M50: =M47 + M49 -> 350.61961 | N50: =N47 + N49 -> 1159.3584 | O50: =O47 + O49 -> 962.4299 | P50: =P47 + P49 -> 468.142 | Q50: =Q47 + Q49 -> 693.85801 | ... EA50: =EA47 + EA49 -> 0
E52: =Equity!E$70 -> Dividends paid | F52: =Equity!F$70 -> 0 | G52: =Equity!G$70 -> $ 000s | H52: =Equity!H$70 -> -196154.18 | I52: =Equity!I$70 -> 0 | J52: =Equity!J$70 -> 0 | K52: =Equity!K$70 -> 0 | L52: =Equity!L$70 -> 0 | ... EA52: =Equity!EA$70 -> 0
E53: Net cash flow after dividends | G53: =SMU -> $ 000s | H53: =SUM(J53:EA53) -> 0 | J53: =J50 + J52 -> 0 | K53: =K50 + K52 -> 0 | L53: =L50 + L52 -> 0 | M53: =M50 + M52 -> 0 | N53: =N50 + N52 -> 0 | O53: =O50 + O52 -> 0 | P53: =P50 + P52 -> 0 | Q53: =Q50 + Q52 -> 0 | ... EA53: =EA50 + EA52 -> 0
A56: BALANCE SHEET
...

Sheet FS Ann
A1: =RIGHT(CELL("filename", A1), LEN(CELL("filename", A1)) - SEARCH("]", CELL("filename", A1))) & " - " & InpC!F3 -> FS Ann - Base case 1
E2: =Time!E$48 -> Model period ending - annual | F2: =Check!$F$9 -> 0 | G2: Error chks | J2: =Time!J$48 -> 43921 | K2: =Time!K$48 -> 44286 | L2: =Time!L$48 -> 44651 | M2: =Time!M$48 -> 45016 | N2: =Time!N$48 -> 45382 | O2: =Time!O$48 -> 45747 | P2: =Time!P$48 -> 46112 | Q2: =Time!Q$48 -> 46477 | ... AN2: =Time!AN$48 -> 54878
E3: =Time!E$53 -> Timeline label - annual | F3: =Output!J2 -> 0 | G3: Track chgs | J3: =Time!J$53 -> Pre-fcst | K3: =Time!K$53 -> Operations | L3: =Time!L$53 -> Operations | M3: =Time!M$53 -> Operations | N3: =Time!N$53 -> Operations | O3: =Time!O$53 -> Operations | P3: =Time!P$53 -> Operations | Q3: =Time!Q$53 -> Operations | ... AN3: =Time!AN$53 -> Post ops
E4: =Time!E$42 -> Contract year | F4: =Check!$F$21 -> 0 | G4: Alerts | J4: =YEAR(J2) -> 2020 | K4: =YEAR(K2) -> 2021 | L4: =YEAR(L2) -> 2022 | M4: =YEAR(M2) -> 2023 | N4: =YEAR(N2) -> 2024 | O4: =YEAR(O2) -> 2025 | P4: =YEAR(P2) -> 2026 | Q4: =YEAR(Q2) -> 2027 | ... AN4: =YEAR(AN2) -> 2050
