Workbook
Name BaseCaseIndicator: InpC!$J$7:$S$7
Name CHK_TOL: InpC!$F$66
Name InputRowTemplate: InpC!$E$81:$S$81
Name InputStored: InpC!$J$3:$S$3
Name SMU: InpC!$F$70
Name TRK_TOL: InpC!$F$65

Sheet InpC
A1: =RIGHT(CELL("filename", A1), LEN(CELL("filename", A1)) - SEARCH("]", CELL("filename", A1))) & " - " & $F$3 -> InpC - Base case 1
K2: =IF(K4 = $F4, "q", "") -> q | L2: =IF(L4 = $F4, "q", "") | M2: =IF(M4 = $F4, "q", "") | O2: =IF(O4 = $F4, "q", "") | P2: =IF(P4 = $F4, "q", "") | Q2: =IF(Q4 = $F4, "q", "") | R2: =IF(R4 = $F4, "q", "")
F3: =INDEX(J3:S3,MATCH(F4,J4:S4)) -> Base case 1 | K3: Base case 1 | L3: Base case 2 | M3: Base case 3 | O3: Scenario 1 | P3: Scenario 2 | Q3: Scenario 3 | R3: Scenario 4
E4: Active scenario | F4: 1 | I4: =MATCH(F4, $J$4:$S$4) -> 2 | K4: 1 | L4: 2 | M4: 3 | O4: 5 | P4: 6 | Q4: 7 | R4: 8
E5: Comparison scenario | F5: 1 | I5: =MATCH(F5, $J$4:$S$4) -> 2
E6: Base case | F6: =INDEX(J6:S6,MATCH(F4,J4:S4,0)) -> 1 | I6: =MATCH(F6, $J$4:$S$4) -> 2 | K6: 1 | L6: 2 | M6: 3 | O6: 1 | P6: 1 | Q6: 2 | R6: 2
E7: Input differences | F7: =COUNTIF(I10:I63, "tu") -> 0 | K7: =IF(K6 = $F$6, "Base case", "") -> Base case | L7: =IF(L6 = $F$6, "Base case", "") | M7: =IF(M6 = $F$6, "Base case", "")
F9: Constant | G9: Unit | H9: Source
A11: TIMING ASSUMPTIONS
E13: First date of time rulers | F13: =IF( INDEX(J13:S13, $I$4) = "", INDEX(J13:R13, $I$6), INDEX(J13:S13, $I$4)) -> 44166 | G13: date | I13: {=IF( INDEX(J13:S13, I$5) = "", IF( INDEX(J13:S13, I$6) = F13, "vw", "tu"), IF(INDEX(J13:S13, I$5) = F13, "vw", "tu"))} -> vw | K13: 44166
E14: Annual year end date of first operating period | F14: =IF( INDEX(J14:S14, $I$4) = "", INDEX(J14:R14, $I$6), INDEX(J14:S14, $I$4)) -> 43921 | G14: date | I14: {=IF( INDEX(J14:S14, I$5) = "", IF( INDEX(J14:S14, I$6) = F14, "vw", "tu"), IF(INDEX(J14:S14, I$5) = F14, "vw", "tu"))} -> vw | K14: 43921
E15: Financial year end month number | F15: =IF( INDEX(J15:S15, $I$4) = "", INDEX(J15:R15, $I$6), INDEX(J15:S15, $I$4)) -> 12 | G15: month # | I15: {=IF( INDEX(J15:S15, I$5) = "", IF( INDEX(J15:S15, I$6) = F15, "vw", "tu"), IF(INDEX(J15:S15, I$5) = F15, "vw", "tu"))} -> vw | K15: 12
E16: Length of operating period | F16: =IF( INDEX(J16:S16, $I$4) = "", INDEX(J16:R16, $I$6), INDEX(J16:S16, $I$4)) -> 1 | G16: months | I16: {=IF( INDEX(J16:S16, I$5) = "", IF( INDEX(J16:S16, I$6) = F16, "vw", "tu"), IF(INDEX(J16:S16, I$5) = F16, "vw", "tu"))} -> vw | K16: 1
E18: Acquisition date | F18: =IF( INDEX(J18:S18, $I$4) = "", INDEX(J18:R18, $I$6), INDEX(J18:S18, $I$4)) -> 44286 | G18: date | I18: {=IF( INDEX(J18:S18, I$5) = "", IF( INDEX(J18:S18, I$6) = F18, "vw", "tu"), IF(INDEX(J18:S18, I$5) = F18, "vw", "tu"))} -> vw | K18: 44286
E20: Operating years remaining | F20: =IF( INDEX(J20:S20, $I$4) = "", INDEX(J20:R20, $I$6), INDEX(J20:S20, $I$4)) -> 5 | G20: years | I20: {=IF( INDEX(J20:S20, I$5) = "", IF( INDEX(J20:S20, I$6) = F20, "vw", "tu"), IF(INDEX(J20:S20, I$5) = F20, "vw", "tu"))} -> vw | K20: 5
E21: Contract extension | F21: =IF( INDEX(J21:S21, $I$4) = "", INDEX(J21:R21, $I$6), INDEX(J21:S21, $I$4)) -> 0 | G21: years | I21: {=IF( INDEX(J21:S21, I$5) = "", IF( INDEX(J21:S21, I$6) = F21, "vw", "tu"), IF(INDEX(J21:S21, I$5) = F21, "vw", "tu"))} -> vw | K21: 0
A23: REVENUE
B25: Seasonality adjustment
E26: January | F26: =IF( INDEX(J26:S26, $I$4) = "", INDEX(J26:R26, $I$6), INDEX(J26:S26, $I$4)) -> 0.035112118 | G26: % of annual yield | I26: {=IF( INDEX(J26:S26, I$5) = "", IF( INDEX(J26:S26, I$6) = F26, "vw", "tu"), IF(INDEX(J26:S26, I$5) = F26, "vw", "tu"))} -> vw | K26: 0.035112118 | L26: 0.035112118 | M26: 0.035112118
E27: February | F27: =IF( INDEX(J27:S27, $I$4) = "", INDEX(J27:R27, $I$6), INDEX(J27:S27, $I$4)) -> 0.047 | G27: % of annual yield | I27: {=IF( INDEX(J27:S27, I$5) = "", IF( INDEX(J27:S27, I$6) = F27, "vw", "tu"), IF(INDEX(J27:S27, I$5) = F27, "vw", "tu"))} -> vw | K27: 0.047 | L27: 0.047 | M27: 0.047
E28: March | F28: =IF( INDEX(J28:S28, $I$4) = "", INDEX(J28:R28, $I$6), INDEX(J28:S28, $I$4)) -> 0.052 | G28: % of annual yield | I28: {=IF( INDEX(J28:S28, I$5) = "", IF( INDEX(J28:S28, I$6) = F28, "vw", "tu"), IF(INDEX(J28:S28, I$5) = F28, "vw", "tu"))} -> vw | K28: 0.052 | L28: 0.052 | M28: 0.052
E29: April | F29: =IF( INDEX(J29:S29, $I$4) = "", INDEX(J29:R29, $I$6), INDEX(J29:S29, $I$4)) -> 0.071 | G29: % of annual yield | I29: {=IF( INDEX(J29:S29, I$5) = "", IF( INDEX(J29:S29, I$6) = F29, "vw", "tu"), IF(INDEX(J29:S29, I$5) = F29, "vw", "tu"))} -> vw | K29: 0.071 | L29: 0.071 | M29: 0.071
E30: May | F30: =IF( INDEX(J30:S30, $I$4) = "", INDEX(J30:R30, $I$6), INDEX(J30:S30, $I$4)) -> 0.091 | G30: % of annual yield | I30: {=IF( INDEX(J30:S30, I$5) = "", IF( INDEX(J30:S30, I$6) = F30, "vw", "tu"), IF(INDEX(J30:S30, I$5) = F30, "vw", "tu"))} -> vw | K30: 0.091 | L30: 0.091 | M30: 0.091
E31: June | F31: =IF( INDEX(J31:S31, $I$4) = "", INDEX(J31:R31, $I$6), INDEX(J31:S31, $I$4)) -> 0.102 | G31: % of annual yield | I31: {=IF( INDEX(J31:S31, I$5) = "", IF( INDEX(J31:S31, I$6) = F31, "vw", "tu"), IF(INDEX(J31:S31, I$5) = F31, "vw", "tu"))} -> vw | K31: 0.102 | L31: 0.102 | M31: 0.102
E32: July | F32: =IF( INDEX(J32:S32, $I$4) = "", INDEX(J32:R32, $I$6), INDEX(J32:S32, $I$4)) -> 0.12388788 | G32: % of annual yield | I32: {=IF( INDEX(J32:S32, I$5) = "", IF( INDEX(J32:S32, I$6) = F32, "vw", "tu"), IF(INDEX(J32:S32, I$5) = F32, "vw", "tu"))} -> vw | K32: 0.12388788 | L32: 0.12388788 | M32: 0.12388788
E33: August | F33: =IF( INDEX(J33:S33, $I$4) = "", INDEX(J33:R33, $I$6), INDEX(J33:S33, $I$4)) -> 0.142 | G33: % of annual yield | I33: {=IF( INDEX(J33:S33, I$5) = "", IF( INDEX(J33:S33, I$6) = F33, "vw", "tu"), IF(INDEX(J33:S33, I$5) = F33, "vw", "tu"))} -> vw | K33: 0.142 | L33: 0.142 | M33: 0.142
E34: September | F34: =IF( INDEX(J34:S34, $I$4) = "", INDEX(J34:R34, $I$6), INDEX(J34:S34, $I$4)) -> 0.132 | G34: % of annual yield | I34: {=IF( INDEX(J34:S34, I$5) = "", IF( INDEX(J34:S34, I$6) = F34, "vw", "tu"), IF(INDEX(J34:S34, I$5) = F34, "vw", "tu"))} -> vw | K34: 0.132 | L34: 0.132 | M34: 0.132
E35: October | F35: =IF( INDEX(J35:S35, $I$4) = "", INDEX(J35:R35, $I$6), INDEX(J35:S35, $I$4)) -> 0.102 | G35: % of annual yield | I35: {=IF( INDEX(J35:S35, I$5) = "", IF( INDEX(J35:S35, I$6) = F35, "vw", "tu"), IF(INDEX(J35:S35, I$5) = F35, "vw", "tu"))} -> vw | K35: 0.102 | L35: 0.102 | M35: 0.102
E36: November | F36: =IF( INDEX(J36:S36, $I$4) = "", INDEX(J36:R36, $I$6), INDEX(J36:S36, $I$4)) -> 0.061 | G36: % of annual yield | I36: {=IF( INDEX(J36:S36, I$5) = "", IF( INDEX(J36:S36, I$6) = F36, "vw", "tu"), IF(INDEX(J36:S36, I$5) = F36, "vw", "tu"))} -> vw | K36: 0.061 | L36: 0.061 | M36: 0.061
E37: December | F37: =IF( INDEX(J37:S37, $I$4) = "", INDEX(J37:R37, $I$6), INDEX(J37:S37, $I$4)) -> 0.041 | G37: % of annual yield | I37: {=IF( INDEX(J37:S37, I$5) = "", IF( INDEX(J37:S37, I$6) = F37, "vw", "tu"), IF(INDEX(J37:S37, I$5) = F37, "vw", "tu"))} -> vw | K37: 0.041 | L37: 0.041 | M37: 0.041
B39: Plant operations
E40: Annual degradation | F40: =IF( INDEX(J40:S40, $I$4) = "", INDEX(J40:R40, $I$6), INDEX(J40:S40, $I$4)) -> 0.005 | G40: % p.a. | I40: {=IF( INDEX(J40:S40, I$5) = "", IF( INDEX(J40:S40, I$6) = F40, "vw", "tu"), IF(INDEX(J40:S40, I$5) = F40, "vw", "tu"))} -> vw | K40: 0.005 | L40: 0.005 | M40: 0.005
E41: Year 1 P50 yield | F41: =IF( INDEX(J41:S41, $I$4) = "", INDEX(J41:R41, $I$6), INDEX(J41:S41, $I$4)) -> 250 | G41: GWh | I41: {=IF( INDEX(J41:S41, I$5) = "", IF( INDEX(J41:S41, I$6) = F41, "vw", "tu"), IF(INDEX(J41:S41, I$5) = F41, "vw", "tu"))} -> vw | K41: 250 | L41: 250 | M41: 250
E42: Availability | F42: =IF( INDEX(J42:S42, $I$4) = "", INDEX(J42:R42, $I$6), INDEX(J42:S42, $I$4)) -> 0.97 | G42: % | I42: {=IF( INDEX(J42:S42, I$5) = "", IF( INDEX(J42:S42, I$6) = F42, "vw", "tu"), IF(INDEX(J42:S42, I$5) = F42, "vw", "tu"))} -> vw | K42: 0.97 | L42: 0.97 | M42: 0.97
E44: Power tariff | F44: =IF( INDEX(J44:S44, $I$4) = "", INDEX(J44:R44, $I$6), INDEX(J44:S44, $I$4)) -> 0.065 | G44: USD / kWh | I44: {=IF( INDEX(J44:S44, I$5) = "", IF( INDEX(J44:S44, I$6) = F44, "vw", "tu"), IF(INDEX(J44:S44, I$5) = F44, "vw", "tu"))} -> vw | K44: 0.065 | L44: 0.065 | M44: 0.065
A46: WORKING CAPITAL
E47: Invoice payment lag | F47: =IF( INDEX(J47:S47, $I$4) = "", INDEX(J47:R47, $I$6), INDEX(J47:S47, $I$4)) -> 2 | G47: months | I47: {=IF( INDEX(J47:S47, I$5) = "", IF( INDEX(J47:S47, I$6) = F47, "vw", "tu"), IF(INDEX(J47:S47, I$5) = F47, "vw", "tu"))} -> vw | K47: 2 | L47: 2 | M47: 2
A49: OPENING BALANCES
E50: Retained earnings - initial balance | F50: =IF( INDEX(J50:S50, $I$4) = "", INDEX(J50:R50, $I$6), INDEX(J50:S50, $I$4)) -> 2608 | G50: =SMU -> $ 000s | I50: {=IF( INDEX(J50:S50, I$5) = "", IF( INDEX(J50:S50, I$6) = F50, "vw", "tu"), IF(INDEX(J50:S50, I$5) = F50, "vw", "tu"))} -> vw | K50: 2608 | L50: 0 | M50: 0
E51: Retained cash - initial balance | F51: =IF( INDEX(J51:S51, $I$4) = "", INDEX(J51:R51, $I$6), INDEX(J51:S51, $I$4)) -> 0 | G51: =SMU -> $ 000s | I51: {=IF( INDEX(J51:S51, I$5) = "", IF( INDEX(J51:S51, I$6) = F51, "vw", "tu"), IF(INDEX(J51:S51, I$5) = F51, "vw", "tu"))} -> vw | K51: 0 | L51: 0 | M51: 0
...

Sheet Time
A1: =RIGHT(CELL("filename", A1), LEN(CELL("filename", A1)) - SEARCH("]", CELL("filename", A1))) & " - " & InpC!F3 -> Time - Base case 1
E2: =Time!E$25 -> Model period ending | F2: =Check!$F$9 -> 0 | G2: Error chks | J2: =Time!J$25 -> 44196 | K2: =Time!K$25 -> 44227 | L2: =Time!L$25 -> 44255 | M2: =Time!M$25 -> 44286 | N2: =Time!N$25 -> 44316 | O2: =Time!O$25 -> 44347 | P2: =Time!P$25 -> 44377 | Q2: =Time!Q$25 -> 44408 | ... CD2: =Time!CD$25 -> 46387
E3: =Time!E$57 -> Timeline label | F3: 0 | G3: Track chgs | J3: =Time!J$57 -> Pre-fcst | K3: =Time!K$57 -> Pre-fcst | L3: =Time!L$57 -> Pre-fcst | M3: =Time!M$57 -> Fin Close | N3: =Time!N$57 -> Operations | O3: =Time!O$57 -> Operations | P3: =Time!P$57 -> Operations | Q3: =Time!Q$57 -> Operations | ... CD3: =Time!CD$57 -> Post ops
E4: =Time!E$42 -> Contract year | F4: =Check!$F$20 -> 0 | G4: Alerts | J4: =Time!J$42 -> 2020 | K4: =Time!K$42 -> 2020 | L4: =Time!L$42 -> 2020 | M4: =Time!M$42 -> 2020 | N4: =Time!N$42 -> 2021 | O4: =Time!O$42 -> 2021 | P4: =Time!P$42 -> 2021 | Q4: =Time!Q$42 -> 2021 | ... CD4: =Time!CD$42 -> 2026
E5: =Time!E$10 -> Model column counter | F5: Constant | G5: Unit | H5: Total | J5: =Time!J$10 -> 1 | K5: =Time!K$10 -> 2 | L5: =Time!L$10 -> 3 | M5: =Time!M$10 -> 4 | N5: =Time!N$10 -> 5 | O5: =Time!O$10 -> 6 | P5: =Time!P$10 -> 7 | Q5: =Time!Q$10 -> 8 | ... CD5: =Time!CD$10 -> 73
A7: TIME RULER
B9: First model column
E10: Model column counter | G10: counter | J10: =I10 + 1 -> 1 | K10: =J10 + 1 -> 2 | L10: =K10 + 1 -> 3 | M10: =L10 + 1 -> 4 | N10: =M10 + 1 -> 5 | O10: =N10 + 1 -> 6 | P10: =O10 + 1 -> 7 | Q10: =P10 + 1 -> 8 | ... CD10: =CC10 + 1 -> 73
E11: Model column total | F11: =MAX(J10:EA10) -> 73 | G11: columns
E13: =E$10 -> Model column counter | F13: =F$10 -> 0 | G13: =G$10 -> counter | H13: =H$10 -> 0 | I13: =I$10 -> 0 | J13: =J$10 -> 1 | K13: =K$10 -> 2 | L13: =L$10 -> 3 | ... CD13: =CD$10 -> 73
E14: First model column flag | G14: flag | H14: =SUM(J14:EA14) -> 1 | J14: =IF(J13 = 1, 1, 0) -> 1 | K14: =IF(K13 = 1, 1, 0) -> 0 | L14: =IF(L13 = 1, 1, 0) -> 0 | M14: =IF(M13 = 1, 1, 0) -> 0 | N14: =IF(N13 = 1, 1, 0) -> 0 | O14: =IF(O13 = 1, 1, 0) -> 0 | P14: =IF(P13 = 1, 1, 0) -> 0 | Q14: =IF(Q13 = 1, 1, 0) -> 0 | ... CD14: =IF(CD13 = 1, 1, 0) -> 0
B16: Model period beginning
E17: =InpC!E$13 -> First date of time rulers | F17: =InpC!F$13 -> 44166 | G17: =InpC!G$13 -> date
E18: =InpC!E$16 -> Length of operating period | F18: =InpC!F$16 -> 1 | G18: =InpC!G$16 -> months
E19: =E$14 -> First model column flag | F19: =F$14 -> 0 | G19: =G$14 -> flag | H19: =H$14 -> 1 | I19: =I$14 -> 0 | J19: =J$14 -> 1 | K19: =K$14 -> 0 | L19: =L$14 -> 0 | ... CD19: =CD$14 -> 0
E20: Model period beginning | G20: date | J20: =IF(J19 = 1, $F17, DATE(YEAR(I20), MONTH(I20) + $F18, DAY(1))) -> 44166 | K20: =IF(K19 = 1, $F17, DATE(YEAR(J20), MONTH(J20) + $F18, DAY(1))) -> 44197 | L20: =IF(L19 = 1, $F17, DATE(YEAR(K20), MONTH(K20) + $F18, DAY(1))) -> 44228 | M20: =IF(M19 = 1, $F17, DATE(YEAR(L20), MONTH(L20) + $F18, DAY(1))) -> 44256 | N20: =IF(N19 = 1, $F17, DATE(YEAR(M20), MONTH(M20) + $F18, DAY(1))) -> 44287 | O20: =IF(O19 = 1, $F17, DATE(YEAR(N20), MONTH(N20) + $F18, DAY(1))) -> 44317 | P20: =IF(P19 = 1, $F17, DATE(YEAR(O20), MONTH(O20) + $F18, DAY(1))) -> 44348 | Q20: =IF(Q19 = 1, $F17, DATE(YEAR(P20), MONTH(P20) + $F18, DAY(1))) -> 44378 | ... CD20: =IF(CD19 = 1, $F17, DATE(YEAR(CC20), MONTH(CC20) + $F18, DAY(1))) -> 46357
B22: Model period ending
E23: =InpC!E$16 -> Length of operating period | F23: =InpC!F$16 -> 1 | G23: =InpC!G$16 -> months
E24: =E$20 -> Model period beginning | F24: =F$20 -> 0 | G24: =G$20 -> date | H24: =H$20 -> 0 | I24: =I$20 -> 0 | J24: =J$20 -> 44166 | K24: =K$20 -> 44197 | L24: =L$20 -> 44228 | ... CD24: =CD$20 -> 46357
E25: Model period ending | G25: date | J25: =DATE(YEAR(J24), MONTH(J24) + $F23, DAY(J24) -1) -> 44196 | K25: =DATE(YEAR(K24), MONTH(K24) + $F23, DAY(K24) -1) -> 44227 | L25: =DATE(YEAR(L24), MONTH(L24) + $F23, DAY(L24) -1) -> 44255 | M25: =DATE(YEAR(M24), MONTH(M24) + $F23, DAY(M24) -1) -> 44286 | N25: =DATE(YEAR(N24), MONTH(N24) + $F23, DAY(N24) -1) -> 44316 | O25: =DATE(YEAR(O24), MONTH(O24) + $F23, DAY(O24) -1) -> 44347 | P25: =DATE(YEAR(P24), MONTH(P24) + $F23, DAY(P24) -1) -> 44377 | Q25: =DATE(YEAR(Q24), MONTH(Q24) + $F23, DAY(Q24) -1) -> 44408 | ... CD25: =DATE(YEAR(CD24), MONTH(CD24) + $F23, DAY(CD24) -1) -> 46387
B27: Contract year
E28: =InpC!E$18 -> Acquisition date | F28: =InpC!F$18 -> 44286 | G28: =InpC!G$18 -> date
E29: Contract year end month | F29: =MONTH(F28) -> 3 | G29: month
E31: =E$29 -> Contract year end month | F31: =F$29 -> 3 | G31: =G$29 -> month
E32: =E$25 -> Model period ending | F32: =F$25 -> 0 | G32: =G$25 -> date | H32: =H$25 -> 0 | I32: =I$25 -> 0 | J32: =J$25 -> 44196 | K32: =K$25 -> 44227 | L32: =L$25 -> 44255 | ... CD32: =CD$25 -> 46387
E33: End of contract year flag | J33: =IF( MONTH(J32) = $F31, 1, 0) -> 0 | K33: =IF( MONTH(K32) = $F31, 1, 0) -> 0 | L33: =IF( MONTH(L32) = $F31, 1, 0) -> 0 | M33: =IF( MONTH(M32) = $F31, 1, 0) -> 1 | N33: =IF( MONTH(N32) = $F31, 1, 0) -> 0 | O33: =IF( MONTH(O32) = $F31, 1, 0) -> 0 | P33: =IF( MONTH(P32) = $F31, 1, 0) -> 0 | Q33: =IF( MONTH(Q32) = $F31, 1, 0) -> 0 | ... CD33: =IF( MONTH(CD32) = $F31, 1, 0) -> 0
E35: =InpC!E$14 -> Annual year end date of first operating period | F35: =InpC!F$14 -> 43921 | G35: =InpC!G$14 -> date
E36: =InpC!E$67 -> Months in year | F36: =InpC!F$67 -> 12 | G36: =InpC!G$67 -> months
E37: =E$14 -> First model column flag | F37: =F$14 -> 0 | G37: =G$14 -> flag | H37: =H$14 -> 1 | I37: =I$14 -> 0 | J37: =J$14 -> 1 | K37: =K$14 -> 0 | L37: =L$14 -> 0 | ... CD37: =CD$14 -> 0
E38: =E$33 -> End of contract year flag | F38: =F$33 -> 0 | G38: =G$33 -> 0 | H38: =H$33 -> 0 | I38: =I$33 -> 0 | J38: =J$33 -> 0 | K38: =K$33 -> 0 | L38: =L$33 -> 0 | ... CD38: =CD$33 -> 0
E39: Contract year applicable to period | G39: date | J39: =IF( J37 = 1, $F35, IF( I38 = 1, EOMONTH(I39, 12), I39)) -> 43921 | K39: =IF( K37 = 1, $F35, IF( J38 = 1, EOMONTH(J39, 12), J39)) -> 43921 | L39: =IF( L37 = 1, $F35, IF( K38 = 1, EOMONTH(K39, 12), K39)) -> 43921 | M39: =IF( M37 = 1, $F35, IF( L38 = 1, EOMONTH(L39, 12), L39)) -> 43921 | N39: =IF( N37 = 1, $F35, IF( M38 = 1, EOMONTH(M39, 12), M39)) -> 44286 | O39: =IF( O37 = 1, $F35, IF( N38 = 1, EOMONTH(N39, 12), N39)) -> 44286 | P39: =IF( P37 = 1, $F35, IF( O38 = 1, EOMONTH(O39, 12), O39)) -> 44286 | Q39: =IF( Q37 = 1, $F35, IF( P38 = 1, EOMONTH(P39, 12), P39)) -> 44286 | ... CD39: =IF( CD37 = 1, $F35, IF( CC38 = 1, EOMONTH(CC39, 12), CC39)) -> 46112
E41: =E$39 -> Contract year applicable to period | F41: =F$39 -> 0 | G41: =G$39 -> date | H41: =H$39 -> 0 | I41: =I$39 -> 0 | J41: =J$39 -> 43921 | K41: =K$39 -> 43921 | L41: =L$39 -> 43921 | ... CD41: =CD$39 -> 46112
E42: Contract year | G42: year # | J42: =YEAR(J41) -> 2020 | K42: =YEAR(K41) -> 2020 | L42: =YEAR(L41) -> 2020 | M42: =YEAR(M41) -> 2020 | N42: =YEAR(N41) -> 2021 | O42: =YEAR(O41) -> 2021 | P42: =YEAR(P41) -> 2021 | Q42: =YEAR(Q41) -> 2021 | ... CD42: =YEAR(CD41) -> 2026
B45: Timeline
E46: =E$14 -> First model column flag | F46: =F$14 -> 0 | G46: =G$14 -> flag | H46: =H$14 -> 1 | I46: =I$14 -> 0 | J46: =J$14 -> 1 | K46: =K$14 -> 0 | L46: =L$14 -> 0 | ... CD46: =CD$14 -> 0
E47: =E$66 -> Financial close date flag | F47: =F$66 -> 0 | G47: =G$66 -> flag | H47: =H$66 -> 1 | I47: =I$66 -> 0 | J47: =J$66 -> 0 | K47: =K$66 -> 0 | L47: =L$66 -> 0 | ... CD47: =CD$66 -> 0
E48: =E$70 -> First operating period flag | F48: =F$70 -> 0 | G48: =G$70 -> flag | H48: =H$70 -> 1 | I48: =I$70 -> 0 | J48: =J$70 -> 0 | K48: =K$70 -> 0 | L48: =L$70 -> 0 | ... CD48: =CD$70 -> 0
E49: =E$96 -> First post operating period flag | F49: =F$96 -> 0 | G49: =G$96 -> 0 | H49: =H$96 -> 0 | I49: =I$96 -> 0 | J49: =J$96 -> 0 | K49: =K$96 -> 0 | L49: =L$96 -> 0 | ... CD49: =CD$96 -> 0
E50: Timeline label counter | G50: counter | J50: =I50 + MAX(J46:J49) -> 1 | K50: =J50 + MAX(K46:K49) -> 1 | L50: =K50 + MAX(L46:L49) -> 1 | M50: =L50 + MAX(M46:M49) -> 2 | N50: =M50 + MAX(N46:N49) -> 3 | O50: =N50 + MAX(O46:O49) -> 3 | P50: =O50 + MAX(P46:P49) -> 3 | Q50: =P50 + MAX(Q46:Q49) -> 3 | ... CD50: =CC50 + MAX(CD46:CD49) -> 4
E52: =InpC!E$76 -> Pre-forecast period | F52: =InpC!F$76 -> Pre-fcst | G52: =InpC!G$76 -> label
...

Sheet Ops
A1: =RIGHT(CELL("filename", A1), LEN(CELL("filename", A1)) - SEARCH("]", CELL("filename", A1))) & " - " & InpC!F3 -> Ops - Base case 1
E2: =Time!E$25 -> Model period ending | F2: =Check!$F$9 -> 0 | G2: Error chks | J2: =Time!J$25 -> 44196 | K2: =Time!K$25 -> 44227 | L2: =Time!L$25 -> 44255 | M2: =Time!M$25 -> 44286 | N2: =Time!N$25 -> 44316 | O2: =Time!O$25 -> 44347 | P2: =Time!P$25 -> 44377 | Q2: =Time!Q$25 -> 44408 | ... CD2: =Time!CD$25 -> 46387
E3: =Time!E$57 -> Timeline label | F3: 0 | G3: Track chgs | J3: =Time!J$57 -> Pre-fcst | K3: =Time!K$57 -> Pre-fcst | L3: =Time!L$57 -> Pre-fcst | M3: =Time!M$57 -> Fin Close | N3: =Time!N$57 -> Operations | O3: =Time!O$57 -> Operations | P3: =Time!P$57 -> Operations | Q3: =Time!Q$57 -> Operations | ... CD3: =Time!CD$57 -> Post ops
E4: =Time!E$42 -> Contract year | F4: =Check!$F$20 -> 0 | G4: Alerts | J4: =Time!J$42 -> 2020 | K4: =Time!K$42 -> 2020 | L4: =Time!L$42 -> 2020 | M4: =Time!M$42 -> 2020 | N4: =Time!N$42 -> 2021 | O4: =Time!O$42 -> 2021 | P4: =Time!P$42 -> 2021 | Q4: =Time!Q$42 -> 2021 | ... CD4: =Time!CD$42 -> 2026
E5: =Time!E$10 -> Model column counter | F5: Constant | G5: Unit | H5: Total | J5: =Time!J$10 -> 1 | K5: =Time!K$10 -> 2 | L5: =Time!L$10 -> 3 | M5: =Time!M$10 -> 4 | N5: =Time!N$10 -> 5 | O5: =Time!O$10 -> 6 | P5: =Time!P$10 -> 7 | Q5: =Time!Q$10 -> 8 | ... CD5: =Time!CD$10 -> 73
A8: REVENUE
B10: Degradation
E11: =InpC!E$40 -> Annual degradation | F11: =InpC!F$40 -> 0.005 | G11: =InpC!G$40 -> % p.a.
E12: =Time!E$115 -> Contract year number | F12: =Time!F$115 -> 0 | G12: =Time!G$115 -> counter | H12: =Time!H$115 -> 0 | I12: =Time!I$115 -> 0 | J12: =Time!J$115 -> 0 | K12: =Time!K$115 -> 0 | L12: =Time!L$115 -> 0 | ... CD12: =Time!CD$115 -> 0
E13: =Time!E$87 -> Operating period flag | F13: =Time!F$87 -> 0 | G13: =Time!G$87 -> flag | H13: =Time!H$87 -> 60 | I13: =Time!I$87 -> 0 | J13: =Time!J$87 -> 0 | K13: =Time!K$87 -> 0 | L13: =Time!L$87 -> 0 | ... CD13: =Time!CD$87 -> 0
E14: Compound degradation | G14: % | J14: =IF( J13 = 1, 1 / ((1 + $F11) ^ (J12 - 1)), 0) -> 0 | K14: =IF( K13 = 1, 1 / ((1 + $F11) ^ (K12 - 1)), 0) -> 0 | L14: =IF( L13 = 1, 1 / ((1 + $F11) ^ (L12 - 1)), 0) -> 0 | M14: =IF( M13 = 1, 1 / ((1 + $F11) ^ (M12 - 1)), 0) -> 0 | N14: =IF( N13 = 1, 1 / ((1 + $F11) ^ (N12 - 1)), 0) -> 1 | O14: =IF( O13 = 1, 1 / ((1 + $F11) ^ (O12 - 1)), 0) -> 1 | P14: =IF( P13 = 1, 1 / ((1 + $F11) ^ (P12 - 1)), 0) -> 1 | Q14: =IF( Q13 = 1, 1 / ((1 + $F11) ^ (Q12 - 1)), 0) -> 1 | ... CD14: =IF( CD13 = 1, 1 / ((1 + $F11) ^ (CD12 - 1)), 0) -> 0
B16: Seasonality adjustment
E17: =InpC!E$26 -> January | F17: =InpC!F$26 -> 0.035112118 | G17: =InpC!G$26 -> % of annual yield
E18: =InpC!E$27 -> February | F18: =InpC!F$27 -> 0.047 | G18: =InpC!G$27 -> % of annual yield
E19: =InpC!E$28 -> March | F19: =InpC!F$28 -> 0.052 | G19: =InpC!G$28 -> % of annual yield
E20: =InpC!E$29 -> April | F20: =InpC!F$29 -> 0.071 | G20: =InpC!G$29 -> % of annual yield
E21: =InpC!E$30 -> May | F21: =InpC!F$30 -> 0.091 | G21: =InpC!G$30 -> % of annual yield
E22: =InpC!E$31 -> June | F22: =InpC!F$31 -> 0.102 | G22: =InpC!G$31 -> % of annual yield
E23: =InpC!E$32 -> July | F23: =InpC!F$32 -> 0.12388788 | G23: =InpC!G$32 -> % of annual yield
E24: =InpC!E$33 -> August | F24: =InpC!F$33 -> 0.142 | G24: =InpC!G$33 -> % of annual yield
E25: =InpC!E$34 -> September | F25: =InpC!F$34 -> 0.132 | G25: =InpC!G$34 -> % of annual yield
E26: =InpC!E$35 -> October | F26: =InpC!F$35 -> 0.102 | G26: =InpC!G$35 -> % of annual yield
E27: =InpC!E$36 -> November | F27: =InpC!F$36 -> 0.061 | G27: =InpC!G$36 -> % of annual yield
E28: =InpC!E$37 -> December | F28: =InpC!F$37 -> 0.041 | G28: =InpC!G$37 -> % of annual yield
E29: =Time!E$126 -> Month number | F29: =Time!F$126 -> 0 | G29: =Time!G$126 -> month | H29: =Time!H$126 -> 0 | I29: =Time!I$126 -> 0 | J29: =Time!J$126 -> 12 | K29: =Time!K$126 -> 1 | L29: =Time!L$126 -> 2 | ... CD29: =Time!CD$126 -> 12
E30: Seasonality adjustment | G30: % | J30: =INDEX($F17:$F28, J29) -> 0.041 | K30: =INDEX($F17:$F28, K29) -> 0.035112118 | L30: =INDEX($F17:$F28, L29) -> 0.047 | M30: =INDEX($F17:$F28, M29) -> 0.052 | N30: =INDEX($F17:$F28, N29) -> 0.071 | O30: =INDEX($F17:$F28, O29) -> 0.091 | P30: =INDEX($F17:$F28, P29) -> 0.102 | Q30: =INDEX($F17:$F28, Q29) -> 0.12388788 | ... CD30: =INDEX($F17:$F28, CD29) -> 0.041
B33: Electricity generation
E34: =InpC!E$41 -> Year 1 P50 yield | F34: =InpC!F$41 -> 250 | G34: =InpC!G$41 -> GWh
E35: =InpC!E$42 -> Availability | F35: =InpC!F$42 -> 0.97 | G35: =InpC!G$42 -> %
E36: =E$14 -> Compound degradation | F36: =F$14 -> 0 | G36: =G$14 -> % | H36: =H$14 -> 0 | I36: =I$14 -> 0 | J36: =J$14 -> 0 | K36: =K$14 -> 0 | L36: =L$14 -> 0 | ... CD36: =CD$14 -> 0
E37: =E$30 -> Seasonality adjustment | F37: =F$30 -> 0 | G37: =G$30 -> % | H37: =H$30 -> 0 | I37: =I$30 -> 0 | J37: =J$30 -> 0.041 | K37: =K$30 -> 0.035112118 | L37: =L$30 -> 0.047 | ... CD37: =CD$30 -> 0.041
E38: Electricity generation | G38: GWh | H38: =SUM(J38:CD38) -> 1200.4952 | J38: =$F34 * $F35 * J36 * J37 -> 0 | K38: =$F34 * $F35 * K36 * K37 -> 0 | L38: =$F34 * $F35 * L36 * L37 -> 0 | M38: =$F34 * $F35 * M36 * M37 -> 0 | N38: =$F34 * $F35 * N36 * N37 -> 17.2175 | O38: =$F34 * $F35 * O36 * O37 -> 22.0675 | P38: =$F34 * $F35 * P36 * P37 -> 24.735 | Q38: =$F34 * $F35 * Q36 * Q37 -> 30.042811 | ... CD38: =$F34 * $F35 * CD36 * CD37 -> 0
B40: Electricity revenue
E41: =InpC!E$44 -> Power tariff | F41: =InpC!F$44 -> 0.065 | G41: =InpC!G$44 -> USD / kWh
E42: =InpC!E$72 -> GWh to kWh conversion | F42: =InpC!F$72 -> 1000000 | G42: =InpC!G$72 -> kWh / GWh
E43: =InpC!E$73 -> Units in a thousand | F43: =InpC!F$73 -> 1000 | G43: =InpC!G$73 -> units
E44: =E$38 -> Electricity generation | F44: =F$38 -> 0 | G44: =G$38 -> GWh | H44: =H$38 -> 1200.4952 | I44: =I$38 -> 0 | J44: =J$38 -> 0 | K44: =K$38 -> 0 | L44: =L$38 -> 0 | ... CD44: =CD$38 -> 0
E45: =Time!E$87 -> Operating period flag | F45: =Time!F$87 -> 0 | G45: =Time!G$87 -> flag | H45: =Time!H$87 -> 60 | I45: =Time!I$87 -> 0 | J45: =Time!J$87 -> 0 | K45: =Time!K$87 -> 0 | L45: =Time!L$87 -> 0 | ... CD45: =Time!CD$87 -> 0
E46: Electricity revenue | G46: =SMU -> $ 000s | H46: =SUM(J46:CD46) -> 78032.188 | J46: =$F41 * $F42 / $F43 * J44 * J45 -> 0 | K46: =$F41 * $F42 / $F43 * K44 * K45 -> 0 | L46: =$F41 * $F42 / $F43 * L44 * L45 -> 0 | M46: =$F41 * $F42 / $F43 * M44 * M45 -> 0 | N46: =$F41 * $F42 / $F43 * N44 * N45 -> 1119.1375 | O46: =$F41 * $F42 / $F43 * O44 * O45 -> 1434.3875 | P46: =$F41 * $F42 / $F43 * P44 * P45 -> 1607.775 | Q46: =$F41 * $F42 / $F43 * Q44 * Q45 -> 1952.7827 | ... CD46: =$F41 * $F42 / $F43 * CD44 * CD45 -> 0
A49: ACCOUNTS RECEIVABLE
...

Sheet Equity
A1: =RIGHT(CELL("filename", A1), LEN(CELL("filename", A1)) - SEARCH("]", CELL("filename", A1))) & " - " & InpC!F3 -> Equity - Base case 1
E2: =Time!E$25 -> Model period ending | F2: =Check!$F$9 -> 0 | G2: Error chks | J2: =Time!J$25 -> 44196 | K2: =Time!K$25 -> 44227 | L2: =Time!L$25 -> 44255 | M2: =Time!M$25 -> 44286 | N2: =Time!N$25 -> 44316 | O2: =Time!O$25 -> 44347 | P2: =Time!P$25 -> 44377 | Q2: =Time!Q$25 -> 44408 | ... CD2: =Time!CD$25 -> 46387
E3: =Time!E$57 -> Timeline label | F3: 0 | G3: Track chgs | J3: =Time!J$57 -> Pre-fcst | K3: =Time!K$57 -> Pre-fcst | L3: =Time!L$57 -> Pre-fcst | M3: =Time!M$57 -> Fin Close | N3: =Time!N$57 -> Operations | O3: =Time!O$57 -> Operations | P3: =Time!P$57 -> Operations | Q3: =Time!Q$57 -> Operations | ... CD3: =Time!CD$57 -> Post ops
E4: =Time!E$42 -> Contract year | F4: =Check!$F$20 -> 0 | G4: Alerts | J4: =Time!J$42 -> 2020 | K4: =Time!K$42 -> 2020 | L4: =Time!L$42 -> 2020 | M4: =Time!M$42 -> 2020 | N4: =Time!N$42 -> 2021 | O4: =Time!O$42 -> 2021 | P4: =Time!P$42 -> 2021 | Q4: =Time!Q$42 -> 2021 | ... CD4: =Time!CD$42 -> 2026
E5: =Time!E$10 -> Model column counter | F5: Constant | G5: Unit | H5: Total | J5: =Time!J$10 -> 1 | K5: =Time!K$10 -> 2 | L5: =Time!L$10 -> 3 | M5: =Time!M$10 -> 4 | N5: =Time!N$10 -> 5 | O5: =Time!O$10 -> 6 | P5: =Time!P$10 -> 7 | Q5: =Time!Q$10 -> 8 | ... CD5: =Time!CD$10 -> 73
A8: RETAINED EARNINGS
E10: =InpC!E$50 -> Retained earnings - initial balance | F10: =InpC!F$50 -> 2608 | G10: =InpC!G$50 -> $ 000s
E11: =Time!E$66 -> Financial close date flag | F11: =Time!F$66 -> 0 | G11: =Time!G$66 -> flag | H11: =Time!H$66 -> 1 | I11: =Time!I$66 -> 0 | J11: =Time!J$66 -> 0 | K11: =Time!K$66 -> 0 | L11: =Time!L$66 -> 0 | ... CD11: =Time!CD$66 -> 0
E13: Retained earnings balance BEG | G13: =SMU -> $ 000s | J13: =I16 -> 0 | K13: =J16 -> 0 | L13: =K16 -> 0 | M13: =L16 -> 0 | N13: =M16 -> 2608 | O13: =N16 -> 3727.1375 | P13: =O16 -> 5161.525 | Q13: =P16 -> 6769.3 | ... CD13: =CC16 -> 80640.188
E14: ='FS Qtr'!E$22 -> Profit after tax | F14: ='FS Qtr'!F$22 -> 0 | G14: ='FS Qtr'!G$22 -> $ 000s | H14: ='FS Qtr'!H$22 -> 78032.188 | I14: ='FS Qtr'!I$22 -> 0 | J14: ='FS Qtr'!J$22 -> 0 | K14: ='FS Qtr'!K$22 -> 0 | L14: ='FS Qtr'!L$22 -> 0 | ... CD14: ='FS Qtr'!CD$22 -> 0
E15: [dividends paid]
E16: Retained earnings balance | G16: =SMU -> $ 000s | J16: =IF( J11 = 1, $F10, J13 + J14 - J15) -> 0 | K16: =IF( K11 = 1, $F10, K13 + K14 - K15) -> 0 | L16: =IF( L11 = 1, $F10, L13 + L14 - L15) -> 0 | M16: =IF( M11 = 1, $F10, M13 + M14 - M15) -> 2608 | N16: =IF( N11 = 1, $F10, N13 + N14 - N15) -> 3727.1375 | O16: =IF( O11 = 1, $F10, O13 + O14 - O15) -> 5161.525 | P16: =IF( P11 = 1, $F10, P13 + P14 - P15) -> 6769.3 | Q16: =IF( Q11 = 1, $F10, Q13 + Q14 - Q15) -> 8722.0827 | ... CD16: =IF( CD11 = 1, $F10, CD13 + CD14 - CD15) -> 80640.188
A19: RETAINED CASH
E21: =InpC!E$51 -> Retained cash - initial balance | F21: =InpC!F$51 -> 0 | G21: =InpC!G$51 -> $ 000s
E22: =Time!E$66 -> Financial close date flag | F22: =Time!F$66 -> 0 | G22: =Time!G$66 -> flag | H22: =Time!H$66 -> 1 | I22: =Time!I$66 -> 0 | J22: =Time!J$66 -> 0 | K22: =Time!K$66 -> 0 | L22: =Time!L$66 -> 0 | ... CD22: =Time!CD$66 -> 0
E24: Retained cash balance BEG | G24: =SMU -> $ 000s | J24: =I27 -> 0 | K24: =J27 -> 0 | L24: =K27 -> 0 | M24: =L27 -> 0 | N24: =M27 -> 0 | O24: =N27 -> 1310 | P24: =O27 -> 2608 | Q24: =P27 -> 3727.1375 | ... CD24: =CC27 -> 80640.188
E25: ='FS Qtr'!E$50 -> Cash flow available for dividends | F25: ='FS Qtr'!F$50 -> 0 | G25: ='FS Qtr'!G$50 -> $ 000s | H25: ='FS Qtr'!H$50 -> 80640.188 | I25: ='FS Qtr'!I$50 -> 0 | J25: ='FS Qtr'!J$50 -> 0 | K25: ='FS Qtr'!K$50 -> 0 | L25: ='FS Qtr'!L$50 -> 0 | ... CD25: ='FS Qtr'!CD$50 -> 0
E26: [dividends paid]
E27: Retained cash balance | G27: =SMU -> $ 000s | J27: =IF( J22 = 1, $F21, J24 + J25 - J26) -> 0 | K27: =IF( K22 = 1, $F21, K24 + K25 - K26) -> 0 | L27: =IF( L22 = 1, $F21, L24 + L25 - L26) -> 0 | M27: =IF( M22 = 1, $F21, M24 + M25 - M26) -> 0 | N27: =IF( N22 = 1, $F21, N24 + N25 - N26) -> 1310 | O27: =IF( O22 = 1, $F21, O24 + O25 - O26) -> 2608 | P27: =IF( P22 = 1, $F21, P24 + P25 - P26) -> 3727.1375 | Q27: =IF( Q22 = 1, $F21, Q24 + Q25 - Q26) -> 5161.525 | ... CD27: =IF( CD22 = 1, $F21, CD24 + CD25 - CD26) -> 80640.188
E30: ='FS Qtr'!E$50 -> Cash flow available for dividends | F30: ='FS Qtr'!F$50 -> 0 | G30: ='FS Qtr'!G$50 -> $ 000s | H30: ='FS Qtr'!H$50 -> 80640.188 | I30: ='FS Qtr'!I$50 -> 0 | J30: ='FS Qtr'!J$50 -> 0 | K30: ='FS Qtr'!K$50 -> 0 | L30: ='FS Qtr'!L$50 -> 0 | ... CD30: ='FS Qtr'!CD$50 -> 0
E31: Total CFADS | F31: =SUM(J30:CD30) -> 80640.188 | G31: =SMU -> $ 000s
A34: END

Sheet FS Qtr
A1: =RIGHT(CELL("filename", A1), LEN(CELL("filename", A1)) - SEARCH("]", CELL("filename", A1))) & " - " & InpC!F3 -> FS Qtr - Base case 1
E2: =Time!E$25 -> Model period ending | F2: =Check!$F$9 -> 0 | G2: Error chks | J2: =Time!J$25 -> 44196 | K2: =Time!K$25 -> 44227 | L2: =Time!L$25 -> 44255 | M2: =Time!M$25 -> 44286 | N2: =Time!N$25 -> 44316 | O2: =Time!O$25 -> 44347 | P2: =Time!P$25 -> 44377 | Q2: =Time!Q$25 -> 44408 | ... CD2: =Time!CD$25 -> 46387
E3: =Time!E$57 -> Timeline label | F3: =#REF! -> #REF! | G3: Track chgs | J3: =Time!J$57 -> Pre-fcst | K3: =Time!K$57 -> Pre-fcst | L3: =Time!L$57 -> Pre-fcst | M3: =Time!M$57 -> Fin Close | N3: =Time!N$57 -> Operations | O3: =Time!O$57 -> Operations | P3: =Time!P$57 -> Operations | Q3: =Time!Q$57 -> Operations | ... CD3: =Time!CD$57 -> Post ops
E4: =Time!E$42 -> Contract year | F4: =Check!$F$20 -> 0 | G4: Alerts | J4: =Time!J$42 -> 2020 | K4: =Time!K$42 -> 2020 | L4: =Time!L$42 -> 2020 | M4: =Time!M$42 -> 2020 | N4: =Time!N$42 -> 2021 | O4: =Time!O$42 -> 2021 | P4: =Time!P$42 -> 2021 | Q4: =Time!Q$42 -> 2021 | ... CD4: =Time!CD$42 -> 2026
E5: =Time!E$10 -> Model column counter | F5: Constant | G5: Unit | H5: Total | J5: =Time!J$10 -> 1 | K5: =Time!K$10 -> 2 | L5: =Time!L$10 -> 3 | M5: =Time!M$10 -> 4 | N5: =Time!N$10 -> 5 | O5: =Time!O$10 -> 6 | P5: =Time!P$10 -> 7 | Q5: =Time!Q$10 -> 8 | ... CD5: =Time!CD$10 -> 73
A7: INCOME STATEMENT
E9: =Ops!E$46 -> Electricity revenue | F9: =Ops!F$46 -> 0 | G9: =Ops!G$46 -> $ 000s | H9: =Ops!H$46 -> 78032.188 | I9: =Ops!I$46 -> 0 | J9: =Ops!J$46 -> 0 | K9: =Ops!K$46 -> 0 | L9: =Ops!L$46 -> 0 | ... CD9: =Ops!CD$46 -> 0
E10: [O&M]
E11: EBITDA | G11: =SMU -> $ 000s | H11: =SUM(J11:EA11) -> 78032.188 | J11: =SUM(J9:J10) -> 0 | K11: =SUM(K9:K10) -> 0 | L11: =SUM(L9:L10) -> 0 | M11: =SUM(M9:M10) -> 0 | N11: =SUM(N9:N10) -> 1119.1375 | O11: =SUM(O9:O10) -> 1434.3875 | P11: =SUM(P9:P10) -> 1607.775 | Q11: =SUM(Q9:Q10) -> 1952.7827 | ... CD11: =SUM(CD9:CD10) -> 0
E13: [Depreciation of non current assets]
E14: EBIT | G14: =SMU -> $ 000s | H14: =SUM(J14:EA14) -> 78032.188 | J14: =J11 + SUM(J13:J13) -> 0 | K14: =K11 + SUM(K13:K13) -> 0 | L14: =L11 + SUM(L13:L13) -> 0 | M14: =M11 + SUM(M13:M13) -> 0 | N14: =N11 + SUM(N13:N13) -> 1119.1375 | O14: =O11 + SUM(O13:O13) -> 1434.3875 | P14: =P11 + SUM(P13:P13) -> 1607.775 | Q14: =Q11 + SUM(Q13:Q13) -> 1952.7827 | ... CD14: =CD11 + SUM(CD13:CD13) -> 0
E16: [Senior debt interest]
E17: [Refi facility interest]
E18: [RCF interest expense]
E19: Profit before tax | G19: =SMU -> $ 000s | H19: =SUM(J19:EA19) -> 78032.188 | J19: =J14 + SUM(J16:J18) -> 0 | K19: =K14 + SUM(K16:K18) -> 0 | L19: =L14 + SUM(L16:L18) -> 0 | M19: =M14 + SUM(M16:M18) -> 0 | N19: =N14 + SUM(N16:N18) -> 1119.1375 | O19: =O14 + SUM(O16:O18) -> 1434.3875 | P19: =P14 + SUM(P16:P18) -> 1607.775 | Q19: =Q14 + SUM(Q16:Q18) -> 1952.7827 | ... CD19: =CD14 + SUM(CD16:CD18) -> 0
E21: [Corporate income tax expense]
E22: Profit after tax | G22: =SMU -> $ 000s | H22: =SUM(J22:EA22) -> 78032.188 | J22: =J19 + J21 -> 0 | K22: =K19 + K21 -> 0 | L22: =L19 + L21 -> 0 | M22: =M19 + M21 -> 0 | N22: =N19 + N21 -> 1119.1375 | O22: =O19 + O21 -> 1434.3875 | P22: =P19 + P21 -> 1607.775 | Q22: =Q19 + Q21 -> 1952.7827 | ... CD22: =CD19 + CD21 -> 0
E24: [Dividends paid]
E25: Net income | G25: =SMU -> $ 000s | H25: =SUM(J25:EA25) -> 78032.188 | J25: =J22 + J24 -> 0 | K25: =K22 + K24 -> 0 | L25: =L22 + L24 -> 0 | M25: =M22 + M24 -> 0 | N25: =N22 + N24 -> 1119.1375 | O25: =O22 + O24 -> 1434.3875 | P25: =P22 + P24 -> 1607.775 | Q25: =Q22 + Q24 -> 1952.7827 | ... CD25: =CD22 + CD24 -> 0
A28: CASH FLOW STATEMENT
E30: =Ops!E$71 -> Cash received from invoices | F30: =Ops!F$71 -> 0 | G30: =Ops!G$71 -> $ 000s | H30: =Ops!H$71 -> 80640.188 | I30: =Ops!I$71 -> 0 | J30: =Ops!J$71 -> 0 | K30: =Ops!K$71 -> 0 | L30: =Ops!L$71 -> 0 | ... CD30: =Ops!CD$71 -> 0
E31: [Cash paid for operating costs]
E32: [Corporate income tax expense]
E33: Cash flow available for senior debt service | G33: =SMU -> $ 000s | H33: =SUM(J33:EA33) -> 80640.188 | J33: =SUM(J30:J32) -> 0 | K33: =SUM(K30:K32) -> 0 | L33: =SUM(L30:L32) -> 0 | M33: =SUM(M30:M32) -> 0 | N33: =SUM(N30:N32) -> 1310 | O33: =SUM(O30:O32) -> 1298 | P33: =SUM(P30:P32) -> 1119.1375 | Q33: =SUM(Q30:Q32) -> 1434.3875 | ... CD33: =SUM(CD30:CD32) -> 0
E35: [Senior debt interest]
E36: [Senior debt repayment]
E37: Cash flow available for refinancing facility | G37: =SMU -> $ 000s | H37: =SUM(J37:EA37) -> 80640.188 | J37: =J33 + SUM(J35:J36) -> 0 | K37: =K33 + SUM(K35:K36) -> 0 | L37: =L33 + SUM(L35:L36) -> 0 | M37: =M33 + SUM(M35:M36) -> 0 | N37: =N33 + SUM(N35:N36) -> 1310 | O37: =O33 + SUM(O35:O36) -> 1298 | P37: =P33 + SUM(P35:P36) -> 1119.1375 | Q37: =Q33 + SUM(Q35:Q36) -> 1434.3875 | ... CD37: =CD33 + SUM(CD35:CD36) -> 0
E39: [Refi facility drawdown]
E40: [Refi facility repayment]
E41: [Refi facility interest]
E42: Cash flow available for revolving credit facility | G42: =SMU -> $ 000s | H42: =SUM(J42:EA42) -> 80640.188 | J42: =J37 + SUM(J39:J41) -> 0 | K42: =K37 + SUM(K39:K41) -> 0 | L42: =L37 + SUM(L39:L41) -> 0 | M42: =M37 + SUM(M39:M41) -> 0 | N42: =N37 + SUM(N39:N41) -> 1310 | O42: =O37 + SUM(O39:O41) -> 1298 | P42: =P37 + SUM(P39:P41) -> 1119.1375 | Q42: =Q37 + SUM(Q39:Q41) -> 1434.3875 | ... CD42: =CD37 + SUM(CD39:CD41) -> 0
E44: [RCF drawdown]
E45: [RCF repayment]
E46: [RCF interest expense paid]
E47: Cash available for shareholders | G47: =SMU -> $ 000s | H47: =SUM(J47:EA47) -> 80640.188 | J47: =J42 + SUM(J44:J46) -> 0 | K47: =K42 + SUM(K44:K46) -> 0 | L47: =L42 + SUM(L44:L46) -> 0 | M47: =M42 + SUM(M44:M46) -> 0 | N47: =N42 + SUM(N44:N46) -> 1310 | O47: =O42 + SUM(O44:O46) -> 1298 | P47: =P42 + SUM(P44:P46) -> 1119.1375 | Q47: =Q42 + SUM(Q44:Q46) -> 1434.3875 | ... CD47: =CD42 + SUM(CD44:CD46) -> 0
E49: [Share capital redemption]
E50: Cash flow available for dividends | G50: =SMU -> $ 000s | H50: =SUM(J50:EA50) -> 80640.188 | J50: =J47 + J49 -> 0 | K50: =K47 + K49 -> 0 | L50: =L47 + L49 -> 0 | M50: =M47 + M49 -> 0 | N50: =N47 + N49 -> 1310 | O50: =O47 + O49 -> 1298 | P50: =P47 + P49 -> 1119.1375 | Q50: =Q47 + Q49 -> 1434.3875 | ... CD50: =CD47 + CD49 -> 0
E52: [Dividends paid]
E53: Net cash flow | G53: =SMU -> $ 000s | H53: =SUM(J53:EA53) -> 80640.188 | J53: =J50 + J52 -> 0 | K53: =K50 + K52 -> 0 | L53: =L50 + L52 -> 0 | M53: =M50 + M52 -> 0 | N53: =N50 + N52 -> 1310 | O53: =O50 + O52 -> 1298 | P53: =P50 + P52 -> 1119.1375 | Q53: =Q50 + Q52 -> 1434.3875 | ... CD53: =CD50 + CD52 -> 0
A56: BALANCE SHEET
...

Sheet Check
A1: =RIGHT(CELL("filename", A1), LEN(CELL("filename", A1)) - SEARCH("]", CELL("filename", A1))) & " - " & InpC!F3 -> Check - Base case 1
F2: =Check!$F$9 -> 0 | G2: Error chks
F3: =#REF! -> #REF! | G3: Track chgs
F4: =Check!$F$20 -> 0 | G4: Alerts
F5: Constant | G5: Unit
A7: CHECK SUMMARY
E9: Total checks | F9: =SUM(F10:F15) -> 0 | G9: check
E10: [do not delete this row] | F10: [range start]
E12: ='FS Qtr'!E$82 -> Balance sheet check | F12: ='FS Qtr'!F$82 -> 0 | G12: ='FS Qtr'!G$82 -> check
E15: [do not delete this row] | F15: [range end]
A18: ALERT SUMMARY
E20: Total alerts | F20: =SUM(F21:F30) -> 0 | G20: alert
E21: [do not delete this row] | F21: [range start]
E30: [do not delete this row] | F30: [range end]

Sheet Tmp
A1: =RIGHT(CELL("filename", A1), LEN(CELL("filename", A1)) - SEARCH("]", CELL("filename", A1))) & " - " & InpC!F3 -> Tmp - Base case 1
E2: =Time!E$25 -> Model period ending | F2: =Check!$F$9 -> 0 | G2: Error chks | J2: =Time!J$25 -> 44196 | K2: =Time!K$25 -> 44227 | L2: =Time!L$25 -> 44255 | M2: =Time!M$25 -> 44286 | N2: =Time!N$25 -> 44316 | O2: =Time!O$25 -> 44347 | P2: =Time!P$25 -> 44377 | Q2: =Time!Q$25 -> 44408 | ... CD2: =Time!CD$25 -> 46387
E3: =Time!E$57 -> Timeline label | F3: =#REF! -> #REF! | G3: Track chgs | J3: =Time!J$57 -> Pre-fcst | K3: =Time!K$57 -> Pre-fcst | L3: =Time!L$57 -> Pre-fcst | M3: =Time!M$57 -> Fin Close | N3: =Time!N$57 -> Operations | O3: =Time!O$57 -> Operations | P3: =Time!P$57 -> Operations | Q3: =Time!Q$57 -> Operations | ... CD3: =Time!CD$57 -> Post ops
E4: =Time!E$42 -> Contract year | F4: =Check!$F$20 -> 0 | G4: Alerts | J4: =Time!J$42 -> 2020 | K4: =Time!K$42 -> 2020 | L4: =Time!L$42 -> 2020 | M4: =Time!M$42 -> 2020 | N4: =Time!N$42 -> 2021 | O4: =Time!O$42 -> 2021 | P4: =Time!P$42 -> 2021 | Q4: =Time!Q$42 -> 2021 | ... CD4: =Time!CD$42 -> 2026
E5: =Time!E$10 -> Model column counter | F5: Constant | G5: Unit | H5: Total | J5: =Time!J$10 -> 1 | K5: =Time!K$10 -> 2 | L5: =Time!L$10 -> 3 | M5: =Time!M$10 -> 4 | N5: =Time!N$10 -> 5 | O5: =Time!O$10 -> 6 | P5: =Time!P$10 -> 7 | Q5: =Time!Q$10 -> 8 | ... CD5: =Time!CD$10 -> 73
E8: [xxx] balance BEG | J8: =I11 -> 0 | K8: =J11 -> 0 | L8: =K11 -> 0 | M8: =L11 -> 0 | N8: =M11 -> 0 | O8: =N11 -> 0 | P8: =O11 -> 0 | Q8: =P11 -> 0 | ... CD8: =CC11 -> 0
E9: [upward flow]
E10: [downward flow]
E11: [xxx] balance | J11: =J8 + J9 - J10 -> 0 | K11: =K8 + K9 - K10 -> 0 | L11: =L8 + L9 - L10 -> 0 | M11: =M8 + M9 - M10 -> 0 | N11: =N8 + N9 - N10 -> 0 | O11: =O8 + O9 - O10 -> 0 | P11: =P8 + P9 - P10 -> 0 | Q11: =Q8 + Q9 - Q10 -> 0 | ... CD11: =CD8 + CD9 - CD10 -> 0
E14: [xxx] - initial balance | G14: =SMU -> $ 000s
E15: =Time!E$66 -> Financial close date flag | F15: =Time!F$66 -> 0 | G15: =Time!G$66 -> flag | H15: =Time!H$66 -> 1 | I15: =Time!I$66 -> 0 | J15: =Time!J$66 -> 0 | K15: =Time!K$66 -> 0 | L15: =Time!L$66 -> 0 | ... CD15: =Time!CD$66 -> 0
E17: [xxx] balance BEG | G17: =SMU -> $ 000s | J17: =I20 -> 0 | K17: =J20 -> 0 | L17: =K20 -> 0 | M17: =L20 -> 0 | N17: =M20 -> 0 | O17: =N20 -> 0 | P17: =O20 -> 0 | Q17: =P20 -> 0 | ... CD17: =CC20 -> 0
E18: [upward flow]
E19: [downward flow]
E20: [xxx] balance | G20: =SMU -> $ 000s | J20: =IF( J15 = 1, $F14, J17 + J18 - J19) -> 0 | K20: =IF( K15 = 1, $F14, K17 + K18 - K19) -> 0 | L20: =IF( L15 = 1, $F14, L17 + L18 - L19) -> 0 | M20: =IF( M15 = 1, $F14, M17 + M18 - M19) -> 0 | N20: =IF( N15 = 1, $F14, N17 + N18 - N19) -> 0 | O20: =IF( O15 = 1, $F14, O17 + O18 - O19) -> 0 | P20: =IF( P15 = 1, $F14, P17 + P18 - P19) -> 0 | Q20: =IF( Q15 = 1, $F14, Q17 + Q18 - Q19) -> 0 | ... CD20: =IF( CD15 = 1, $F14, CD17 + CD18 - CD19) -> 0
E23: Sign switch line item POS | G23: =SMU -> $ 000s | H23: =SUM(J23:CD23) -> 7300 | J23: 100 | K23: 100 | L23: 100 | M23: 100 | N23: 100 | O23: 100 | P23: 100 | Q23: 100 | R23: 100 | S23: 100 | T23: 100 | U23: 100 | V23: 100 | W23: 100 | X23: 100 | Y23: 100 | Z23: 100 | AA23: 100 | AB23: 100 | AC23: 100 | AD23: 100 | AE23: 100 | AF23: 100 | AG23: 100 | AH23: 100 | AI23: 100 | AJ23: 100 | AK23: 100 | AL23: 100 | AM23: 100 | AN23: 100 | AO23: 100 | AP23: 100 | AQ23: 100 | AR23: 100 | AS23: 100 | AT23: 100 | AU23: 100 | AV23: 100 | AW23: 100 | AX23: 100 | AY23: 100 | AZ23: 100 | BA23: 100 | BB23: 100 | BC23: 100 | BD23: 100 | BE23: 100 | BF23: 100 | BG23: 100 | BH23: 100 | BI23: 100 | BJ23: 100 | BK23: 100 | BL23: 100 | BM23: 100 | BN23: 100 | BO23: 100 | BP23: 100 | BQ23: 100 | BR23: 100 | BS23: 100 | BT23: 100 | BU23: 100 | BV23: 100 | BW23: 100 | BX23: 100 | BY23: 100 | BZ23: 100 | CA23: 100 | CB23: 100 | CC23: 100 | CD23: 100
E24: =LEFT(E23, LEN(E23) - 4) -> Sign switch line item | G24: =SMU -> $ 000s | H24: =SUM(J24:CD24) -> -7300 | J24: =-1 * J23 -> -100 | K24: =-1 * K23 -> -100 | L24: =-1 * L23 -> -100 | M24: =-1 * M23 -> -100 | N24: =-1 * N23 -> -100 | O24: =-1 * O23 -> -100 | P24: =-1 * P23 -> -100 | Q24: =-1 * Q23 -> -100 | ... CD24: =-1 * CD23 -> -100
