Workbook

Sheet Year 1
B2: Unit Price | C2: £
B3: Events | C3: 600
B4: Membership | C4: 10
B5: Sponsorship | C5: 5000
B6: Events Small | C6: 100
B7: Events Medium | C7: 350
B8: Events Large | C8: 800
B9: Ticket Sales - Events | C9: 6
B10: VIP Tickets | C10: 10
B11: Income Line 9
B12: Income Line 10
B13: Income Line 11
B14: Income Line 12
B15: Income Line 13
B16: Income Line 14
B17: Income Line 15
B20: Month | C20: 1 | D20: 2 | E20: 3 | F20: 4 | G20: 5 | H20: 6 | I20: 7 | J20: 8 | K20: 9 | L20: 10 | M20: 11 | N20: 12 | O20: Total
B21: Unit Sales | C21: 45383 | D21: 45413 | E21: 45444 | F21: 45474 | G21: 45505 | H21: 45536 | I21: 45566 | J21: 45597 | K21: 45627 | L21: 45658 | M21: 45689 | N21: 45717
B22: =B3 -> Events | C22: 4 | D22: 5 | E22: 5 | F22: 10 | G22: 10 | H22: 20 | I22: 20 | J22: 20 | K22: 60 | L22: 60 | M22: 60 | N22: 60 | O22: =SUM(C22:N22) -> 334
B23: =B4 -> Membership | C23: 4 | D23: 5 | E23: 5 | F23: 10 | G23: 12 | H23: 40 | I23: 40 | J23: 40 | K23: 40 | L23: 40 | M23: 40 | N23: 40 | O23: =SUM(C23:N23) -> 316
B24: =B5 -> Sponsorship | D24: 2 | E24: 6 | F24: 10 | G24: 14 | H24: 14 | I24: 14 | J24: 14 | K24: 14 | L24: 14 | M24: 14 | N24: 14 | O24: =SUM(C24:N24) -> 130
B25: =B6 -> Events Small | C25: 2 | D25: =C25*1.1 -> 2.2 | E25: =D25*1.1 -> 2.42 | F25: =E25*1.1 -> 2.662 | G25: =F25*1.1 -> 2.9282 | H25: =G25*1.1 -> 3.22102 | I25: =H25*1.1 -> 3.543122 | J25: =I25*1.1 -> 3.8974342 | K25: =J25*1.1 -> 4.2871776 | ... N25: =M25*1.1 -> 5.7062334 | O25: =SUM(C25:N25) -> 42.768568
B26: =B7 -> Events Medium | O26: =SUM(C26:N26) -> 0
B27: =B8 -> Events Large | O27: =SUM(C27:N27) -> 0
B28: =B9 -> Ticket Sales - Events | D28: 100 | F28: 110 | H28: 120 | O28: =SUM(C28:N28) -> 330
B29: =B10 -> VIP Tickets | D29: 50 | F29: 55 | H29: 60 | O29: =SUM(C29:N29) -> 165
B30: =B11 -> Income Line 9 | O30: =SUM(C30:N30) -> 0
B31: =B12 -> Income Line 10 | O31: =SUM(C31:N31) -> 0
B32: =B13 -> Income Line 11 | O32: =SUM(C32:N32) -> 0
B33: =B14 -> Income Line 12 | O33: =SUM(C33:N33) -> 0
B34: =B15 -> Income Line 13 | O34: =SUM(C34:N34) -> 0
B35: =B16 -> Income Line 14 | O35: =SUM(C35:N35) -> 0
B36: =B17 -> Income Line 15 | O36: =SUM(C36:N36) -> 0
B38: Income Total | C38: =SUM(C22:C37) -> 10 | D38: =SUM(D22:D37) -> 164.2 | E38: =SUM(E22:E37) -> 18.42 | F38: =SUM(F22:F37) -> 197.662 | G38: =SUM(G22:G37) -> 38.9282 | H38: =SUM(H22:H37) -> 257.22102 | I38: =SUM(I22:I37) -> 77.543122 | J38: =SUM(J22:J37) -> 77.897434 | ... N38: =SUM(N22:N37) -> 119.70623 | O38: =SUM(C38:N38) -> 1317.7686
B41: Month | C41: 1 | D41: 2 | E41: 3 | F41: 4 | G41: 5 | H41: 6 | I41: 7 | J41: 8 | K41: 9 | L41: 10 | M41: 11 | N41: 12 | O41: Total
B42: Income | C42: 44287 | D42: 44317 | E42: 44348 | F42: 44378 | G42: 44409 | H42: 44440 | I42: 44470 | J42: 44501 | K42: 44531 | L42: 44562 | M42: 44593 | N42: 44621
B43: =B22 -> Events | C43: =C22*$C3 -> 2400 | D43: =D22*$C3 -> 3000 | E43: =E22*$C3 -> 3000 | F43: =F22*$C3 -> 6000 | G43: =G22*$C3 -> 6000 | H43: =H22*$C3 -> 12000 | I43: =I22*$C3 -> 12000 | J43: =J22*$C3 -> 12000 | ... N43: =N22*$C3 -> 36000 | O43: =SUM(C43:N43) -> 200400
B44: =B23 -> Membership | C44: =C23*$C4 -> 40 | D44: =D23*$C4 -> 50 | E44: =E23*$C4 -> 50 | F44: =F23*$C4 -> 100 | G44: =G23*$C4 -> 120 | H44: =H23*$C4 -> 400 | I44: =I23*$C4 -> 400 | J44: =J23*$C4 -> 400 | ... N44: =N23*$C4 -> 400 | O44: =SUM(C44:N44) -> 3160
B45: =B24 -> Sponsorship | C45: =C24*$C5 -> 0 | D45: =D24*$C5 -> 10000 | E45: =E24*$C5 -> 30000 | F45: =F24*$C5 -> 50000 | G45: =G24*$C5 -> 70000 | H45: =H24*$C5 -> 70000 | I45: =I24*$C5 -> 70000 | J45: =J24*$C5 -> 70000 | ... N45: =N24*$C5 -> 70000 | O45: =SUM(C45:N45) -> 650000
B46: Grants | C46: =C25*$C6 -> 200 | D46: =D25*$C6 -> 220 | E46: =E25*$C6 -> 242 | F46: =F25*$C6 -> 266.2 | G46: =G25*$C6 -> 292.82 | H46: =H25*$C6 -> 322.102 | I46: =I25*$C6 -> 354.3122 | J46: =J25*$C6 -> 389.74342 | ... N46: =N25*$C6 -> 570.62334 | O46: =SUM(C46:N46) -> 4276.8568
...

Sheet Year 2
B2: Unit Price | C2: £
B3: ='Year 1'!B3 -> Events | C3: ='Year 1'!C3 -> 600
B4: ='Year 1'!B4 -> Membership | C4: ='Year 1'!C4 -> 10
B5: ='Year 1'!B5 -> Sponsorship | C5: ='Year 1'!C5 -> 5000
B6: ='Year 1'!B6 -> Events Small | C6: ='Year 1'!C6 -> 100
B7: ='Year 1'!B7 -> Events Medium | C7: ='Year 1'!C7 -> 350
B8: ='Year 1'!B8 -> Events Large | C8: ='Year 1'!C8 -> 800
B9: ='Year 1'!B9 -> Ticket Sales - Events | C9: ='Year 1'!C9 -> 6
B10: ='Year 1'!B10 -> VIP Tickets | C10: ='Year 1'!C10 -> 10
B11: ='Year 1'!B11 -> Income Line 9 | C11: ='Year 1'!C11 -> 0
B12: ='Year 1'!B12 -> Income Line 10 | C12: ='Year 1'!C12 -> 0
B13: ='Year 1'!B13 -> Income Line 11 | C13: ='Year 1'!C13 -> 0
B14: ='Year 1'!B14 -> Income Line 12 | C14: ='Year 1'!C14 -> 0
... B17: ='Year 1'!B17 -> Income Line 15 | C17: ='Year 1'!C17 -> 0
B20: Month | C20: 13 | D20: 14 | E20: 15 | F20: 16 | G20: 17 | H20: 18 | I20: 19 | J20: 20 | K20: 21 | L20: 22 | M20: 23 | N20: 24 | O20: Total
B21: Unit Sales | C21: 45748 | D21: 45778 | E21: 45809 | F21: 45839 | G21: 45870 | H21: 45901 | I21: 45931 | J21: 45962 | K21: 45992 | L21: 46023 | M21: 46054 | N21: 46082
B22: =B3 -> Events | C22: 4 | D22: 5 | E22: 5 | F22: 10 | G22: 10 | H22: 20 | I22: 20 | J22: 20 | K22: 60 | L22: 60 | M22: 60 | N22: 60 | O22: =SUM(C22:N22) -> 334
B23: =B4 -> Membership | C23: 4 | D23: 5 | E23: 5 | F23: 10 | G23: 12 | H23: 40 | I23: 40 | J23: 40 | K23: 40 | L23: 40 | M23: 40 | N23: 40 | O23: =SUM(C23:N23) -> 316
B24: =B5 -> Sponsorship | D24: 2 | E24: 6 | F24: 10 | G24: 14 | H24: 14 | I24: 14 | J24: 14 | K24: 14 | L24: 14 | M24: 14 | N24: 14 | O24: =SUM(C24:N24) -> 130
B25: Grants | O25: =SUM(C25:N25) -> 0
B26: =B7 -> Events Medium | O26: =SUM(C26:N26) -> 0
B27: =B8 -> Events Large | O27: =SUM(C27:N27) -> 0
B28: =B9 -> Ticket Sales - Events | O28: =SUM(C28:N28) -> 0
B29: =B10 -> VIP Tickets | O29: =SUM(C29:N29) -> 0
B30: =B11 -> Income Line 9 | O30: =SUM(C30:N30) -> 0
B31: =B12 -> Income Line 10 | O31: =SUM(C31:N31) -> 0
B32: =B13 -> Income Line 11 | O32: =SUM(C32:N32) -> 0
B33: =B14 -> Income Line 12 | O33: =SUM(C33:N33) -> 0
B34: =B15 -> Income Line 13 | O34: =SUM(C34:N34) -> 0
B35: =B16 -> Income Line 14 | O35: =SUM(C35:N35) -> 0
B36: =B17 -> Income Line 15 | O36: =SUM(C36:N36) -> 0
B38: Income Total | C38: =SUM(C22:C37) -> 8 | D38: =SUM(D22:D37) -> 12 | E38: =SUM(E22:E37) -> 16 | F38: =SUM(F22:F37) -> 30 | G38: =SUM(G22:G37) -> 36 | H38: =SUM(H22:H37) -> 74 | I38: =SUM(I22:I37) -> 74 | J38: =SUM(J22:J37) -> 74 | ... N38: =SUM(N22:N37) -> 114 | O38: =SUM(C38:N38) -> 780
B41: Month | C41: 1 | D41: 2 | E41: 3 | F41: 4 | G41: 5 | H41: 6 | I41: 7 | J41: 8 | K41: 9 | L41: 10 | M41: 11 | N41: 12 | O41: Total
B42: Income | C42: =C21 -> 45748 | D42: =D21 -> 45778 | E42: =E21 -> 45809 | F42: =F21 -> 45839 | G42: =G21 -> 45870 | H42: =H21 -> 45901 | I42: =I21 -> 45931 | J42: =J21 -> 45962 | ... N42: =N21 -> 46082
B43: =B22 -> Events | C43: =C22*$C3 -> 2400 | D43: =D22*$C3 -> 3000 | E43: =E22*$C3 -> 3000 | F43: =F22*$C3 -> 6000 | G43: =G22*$C3 -> 6000 | H43: =H22*$C3 -> 12000 | I43: =I22*$C3 -> 12000 | J43: =J22*$C3 -> 12000 | ... N43: =N22*$C3 -> 36000 | O43: =SUM(C43:N43) -> 200400
B44: =B23 -> Membership | C44: =C23*$C4 -> 40 | D44: =D23*$C4 -> 50 | E44: =E23*$C4 -> 50 | F44: =F23*$C4 -> 100 | G44: =G23*$C4 -> 120 | H44: =H23*$C4 -> 400 | I44: =I23*$C4 -> 400 | J44: =J23*$C4 -> 400 | ... N44: =N23*$C4 -> 400 | O44: =SUM(C44:N44) -> 3160
B45: =B24 -> Sponsorship | C45: =C24*$C5 -> 0 | D45: =D24*$C5 -> 10000 | E45: =E24*$C5 -> 30000 | F45: =F24*$C5 -> 50000 | G45: =G24*$C5 -> 70000 | H45: =H24*$C5 -> 70000 | I45: =I24*$C5 -> 70000 | J45: =J24*$C5 -> 70000 | ... N45: =N24*$C5 -> 70000 | O45: =SUM(C45:N45) -> 650000
B46: =B25 -> Grants | C46: =C25*$C6 -> 0 | D46: =D25*$C6 -> 0 | E46: =E25*$C6 -> 0 | F46: =F25*$C6 -> 0 | G46: =G25*$C6 -> 0 | H46: =H25*$C6 -> 0 | I46: =I25*$C6 -> 0 | J46: =J25*$C6 -> 0 | ... N46: =N25*$C6 -> 0 | O46: =SUM(C46:N46) -> 0
B47: =B26 -> Events Medium | C47: =C26*$C7 -> 0 | D47: =D26*$C7 -> 0 | E47: =E26*$C7 -> 0 | F47: =F26*$C7 -> 0 | G47: =G26*$C7 -> 0 | H47: =H26*$C7 -> 0 | I47: =I26*$C7 -> 0 | J47: =J26*$C7 -> 0 | ... N47: =N26*$C7 -> 0 | O47: =SUM(C47:N47) -> 0
B48: =B27 -> Events Large | C48: =C27*$C8 -> 0 | D48: =D27*$C8 -> 0 | E48: =E27*$C8 -> 0 | F48: =F27*$C8 -> 0 | G48: =G27*$C8 -> 0 | H48: =H27*$C8 -> 0 | I48: =I27*$C8 -> 0 | J48: =J27*$C8 -> 0 | ... N48: =N27*$C8 -> 0 | O48: =SUM(C48:N48) -> 0
...

Sheet Year 3
B2: Unit Price | C2: £
B3: ='Year 2'!B3 -> Events | C3: ='Year 2'!C3 -> 600
B4: ='Year 2'!B4 -> Membership | C4: ='Year 2'!C4 -> 10
B5: ='Year 2'!B5 -> Sponsorship | C5: ='Year 2'!C5 -> 5000
B6: ='Year 2'!B6 -> Events Small | C6: ='Year 2'!C6 -> 100
B7: ='Year 2'!B7 -> Events Medium | C7: ='Year 2'!C7 -> 350
B8: ='Year 2'!B8 -> Events Large | C8: ='Year 2'!C8 -> 800
B9: ='Year 2'!B9 -> Ticket Sales - Events | C9: ='Year 2'!C9 -> 6
B10: ='Year 2'!B10 -> VIP Tickets | C10: ='Year 2'!C10 -> 10
B11: ='Year 2'!B11 -> Income Line 9 | C11: ='Year 2'!C11 -> 0
B12: ='Year 2'!B12 -> Income Line 10 | C12: ='Year 2'!C12 -> 0
B13: ='Year 2'!B13 -> Income Line 11 | C13: ='Year 2'!C13 -> 0
B14: ='Year 2'!B14 -> Income Line 12 | C14: ='Year 2'!C14 -> 0
... B17: ='Year 2'!B17 -> Income Line 15 | C17: ='Year 2'!C17 -> 0
B20: Month | C20: 25 | D20: 26 | E20: 27 | F20: 28 | G20: 29 | H20: 30 | I20: 31 | J20: 32 | K20: 33 | L20: 34 | M20: 35 | N20: 36 | O20: Total
B21: Unit Sales | C21: 46113 | D21: 46143 | E21: 46174 | F21: 46204 | G21: 46235 | H21: 46266 | I21: 46296 | J21: 46327 | K21: 46357 | L21: 46388 | M21: 46419 | N21: 46447
B22: =B3 -> Events | C22: 4 | D22: 5 | E22: 5 | F22: 10 | G22: 10 | H22: 20 | I22: 20 | J22: 20 | K22: 60 | L22: 60 | M22: 60 | N22: 60 | O22: =SUM(C22:N22) -> 334
B23: =B4 -> Membership | C23: 4 | D23: 5 | E23: 5 | F23: 10 | G23: 12 | H23: 40 | I23: 40 | J23: 40 | K23: 40 | L23: 40 | M23: 40 | N23: 40 | O23: =SUM(C23:N23) -> 316
B24: =B5 -> Sponsorship | D24: 2 | E24: 6 | F24: 10 | G24: 14 | H24: 14 | I24: 14 | J24: 14 | K24: 14 | L24: 14 | M24: 14 | N24: 14 | O24: =SUM(C24:N24) -> 130
B25: Grants | O25: =SUM(C25:N25) -> 0
B26: =B7 -> Events Medium | O26: =SUM(C26:N26) -> 0
B27: =B8 -> Events Large | O27: =SUM(C27:N27) -> 0
B28: =B9 -> Ticket Sales - Events | O28: =SUM(C28:N28) -> 0
B29: =B10 -> VIP Tickets | O29: =SUM(C29:N29) -> 0
B30: =B11 -> Income Line 9 | O30: =SUM(C30:N30) -> 0
B31: =B12 -> Income Line 10 | O31: =SUM(C31:N31) -> 0
B32: =B13 -> Income Line 11 | O32: =SUM(C32:N32) -> 0
B33: =B14 -> Income Line 12 | O33: =SUM(C33:N33) -> 0
B34: =B15 -> Income Line 13 | O34: =SUM(C34:N34) -> 0
B35: =B16 -> Income Line 14 | O35: =SUM(C35:N35) -> 0
B36: =B17 -> Income Line 15 | O36: =SUM(C36:N36) -> 0
B38: Income Total | C38: =SUM(C22:C37) -> 8 | D38: =SUM(D22:D37) -> 12 | E38: =SUM(E22:E37) -> 16 | F38: =SUM(F22:F37) -> 30 | G38: =SUM(G22:G37) -> 36 | H38: =SUM(H22:H37) -> 74 | I38: =SUM(I22:I37) -> 74 | J38: =SUM(J22:J37) -> 74 | ... N38: =SUM(N22:N37) -> 114 | O38: =SUM(C38:N38) -> 780
B41: Month | C41: 1 | D41: 2 | E41: 3 | F41: 4 | G41: 5 | H41: 6 | I41: 7 | J41: 8 | K41: 9 | L41: 10 | M41: 11 | N41: 12 | O41: Total
B42: Income | C42: =C21 -> 46113 | D42: =D21 -> 46143 | E42: =E21 -> 46174 | F42: =F21 -> 46204 | G42: =G21 -> 46235 | H42: =H21 -> 46266 | I42: =I21 -> 46296 | J42: =J21 -> 46327 | ... N42: =N21 -> 46447
B43: =B22 -> Events | C43: =C22*$C3 -> 2400 | D43: =D22*$C3 -> 3000 | E43: =E22*$C3 -> 3000 | F43: =F22*$C3 -> 6000 | G43: =G22*$C3 -> 6000 | H43: =H22*$C3 -> 12000 | I43: =I22*$C3 -> 12000 | J43: =J22*$C3 -> 12000 | ... N43: =N22*$C3 -> 36000 | O43: =SUM(C43:N43) -> 200400
B44: =B23 -> Membership | C44: =C23*$C4 -> 40 | D44: =D23*$C4 -> 50 | E44: =E23*$C4 -> 50 | F44: =F23*$C4 -> 100 | G44: =G23*$C4 -> 120 | H44: =H23*$C4 -> 400 | I44: =I23*$C4 -> 400 | J44: =J23*$C4 -> 400 | ... N44: =N23*$C4 -> 400 | O44: =SUM(C44:N44) -> 3160
B45: =B24 -> Sponsorship | C45: =C24*$C5 -> 0 | D45: =D24*$C5 -> 10000 | E45: =E24*$C5 -> 30000 | F45: =F24*$C5 -> 50000 | G45: =G24*$C5 -> 70000 | H45: =H24*$C5 -> 70000 | I45: =I24*$C5 -> 70000 | J45: =J24*$C5 -> 70000 | ... N45: =N24*$C5 -> 70000 | O45: =SUM(C45:N45) -> 650000
B46: =B25 -> Grants | C46: =C25*$C6 -> 0 | D46: =D25*$C6 -> 0 | E46: =E25*$C6 -> 0 | F46: =F25*$C6 -> 0 | G46: =G25*$C6 -> 0 | H46: =H25*$C6 -> 0 | I46: =I25*$C6 -> 0 | J46: =J25*$C6 -> 0 | ... N46: =N25*$C6 -> 0 | O46: =SUM(C46:N46) -> 0
B47: =B26 -> Events Medium | C47: =C26*$C7 -> 0 | D47: =D26*$C7 -> 0 | E47: =E26*$C7 -> 0 | F47: =F26*$C7 -> 0 | G47: =G26*$C7 -> 0 | H47: =H26*$C7 -> 0 | I47: =I26*$C7 -> 0 | J47: =J26*$C7 -> 0 | ... N47: =N26*$C7 -> 0 | O47: =SUM(C47:N47) -> 0
B48: =B27 -> Events Large | C48: =C27*$C8 -> 0 | D48: =D27*$C8 -> 0 | E48: =E27*$C8 -> 0 | F48: =F27*$C8 -> 0 | G48: =G27*$C8 -> 0 | H48: =H27*$C8 -> 0 | I48: =I27*$C8 -> 0 | J48: =J27*$C8 -> 0 | ... N48: =N27*$C8 -> 0 | O48: =SUM(C48:N48) -> 0
...

Sheet Summary
B2: ='Year 3'!B41 -> Month | C2: Year 1 | D2: Year 2 | E2: Year 3 | F2: ='Year 1'!C20 -> 1 | G2: ='Year 1'!D20 -> 2 | H2: ='Year 1'!E20 -> 3 | I2: ='Year 1'!F20 -> 4 | J2: ='Year 1'!G20 -> 5 | K2: ='Year 1'!H20 -> 6 | L2: ='Year 1'!I20 -> 7 | M2: ='Year 1'!J20 -> 8 | ... Q2: ='Year 1'!N20 -> 12 | R2: ='Year 2'!C20 -> 13 | S2: ='Year 2'!D20 -> 14 | T2: ='Year 2'!E20 -> 15 | U2: ='Year 2'!F20 -> 16 | V2: ='Year 2'!G20 -> 17 | W2: ='Year 2'!H20 -> 18 | X2: ='Year 2'!I20 -> 19 | Y2: ='Year 2'!J20 -> 20 | ... AC2: ='Year 2'!N20 -> 24 | AD2: ='Year 3'!C20 -> 25 | AE2: ='Year 3'!D20 -> 26 | AF2: ='Year 3'!E20 -> 27 | AG2: ='Year 3'!F20 -> 28 | AH2: ='Year 3'!G20 -> 29 | AI2: ='Year 3'!H20 -> 30 | AJ2: ='Year 3'!I20 -> 31 | AK2: ='Year 3'!J20 -> 32 | ... AO2: ='Year 3'!N20 -> 36
B3: ='Year 3'!B42 -> Income | F3: ='Year 1'!C21 -> 45383 | G3: ='Year 1'!D21 -> 45413 | H3: ='Year 1'!E21 -> 45444 | I3: ='Year 1'!F21 -> 45474 | J3: ='Year 1'!G21 -> 45505 | K3: ='Year 1'!H21 -> 45536 | L3: ='Year 1'!I21 -> 45566 | M3: ='Year 1'!J21 -> 45597 | ... Q3: ='Year 1'!N21 -> 45717 | R3: ='Year 2'!C21 -> 45748 | S3: ='Year 2'!D21 -> 45778 | T3: ='Year 2'!E21 -> 45809 | U3: ='Year 2'!F21 -> 45839 | V3: ='Year 2'!G21 -> 45870 | W3: ='Year 2'!H21 -> 45901 | X3: ='Year 2'!I21 -> 45931 | Y3: ='Year 2'!J21 -> 45962 | ... AC3: ='Year 2'!N21 -> 46082 | AD3: ='Year 3'!C21 -> 46113 | AE3: ='Year 3'!D21 -> 46143 | AF3: ='Year 3'!E21 -> 46174 | AG3: ='Year 3'!F21 -> 46204 | AH3: ='Year 3'!G21 -> 46235 | AI3: ='Year 3'!H21 -> 46266 | AJ3: ='Year 3'!I21 -> 46296 | AK3: ='Year 3'!J21 -> 46327 | ... AO3: ='Year 3'!N21 -> 46447
B4: ='Year 3'!B43 -> Events | C4: ='Year 1'!O43 -> 200400 | D4: ='Year 2'!O43 -> 200400 | E4: ='Year 3'!O43 -> 200400 | F4: ='Year 1'!C43 -> 2400 | G4: ='Year 1'!D43 -> 3000 | H4: ='Year 1'!E43 -> 3000 | I4: ='Year 1'!F43 -> 6000 | J4: ='Year 1'!G43 -> 6000 | K4: ='Year 1'!H43 -> 12000 | L4: ='Year 1'!I43 -> 12000 | M4: ='Year 1'!J43 -> 12000 | ... Q4: ='Year 1'!N43 -> 36000 | R4: ='Year 2'!C43 -> 2400 | S4: ='Year 2'!D43 -> 3000 | T4: ='Year 2'!E43 -> 3000 | U4: ='Year 2'!F43 -> 6000 | V4: ='Year 2'!G43 -> 6000 | W4: ='Year 2'!H43 -> 12000 | X4: ='Year 2'!I43 -> 12000 | Y4: ='Year 2'!J43 -> 12000 | ... AC4: ='Year 2'!N43 -> 36000 | AD4: ='Year 3'!C43 -> 2400 | AE4: ='Year 3'!D43 -> 3000 | AF4: ='Year 3'!E43 -> 3000 | AG4: ='Year 3'!F43 -> 6000 | AH4: ='Year 3'!G43 -> 6000 | AI4: ='Year 3'!H43 -> 12000 | AJ4: ='Year 3'!I43 -> 12000 | AK4: ='Year 3'!J43 -> 12000 | ... AO4: ='Year 3'!N43 -> 36000
B5: ='Year 3'!B44 -> Membership | C5: ='Year 1'!O44 -> 3160 | D5: ='Year 2'!O44 -> 3160 | E5: ='Year 3'!O44 -> 3160 | F5: ='Year 1'!C44 -> 40 | G5: ='Year 1'!D44 -> 50 | H5: ='Year 1'!E44 -> 50 | I5: ='Year 1'!F44 -> 100 | J5: ='Year 1'!G44 -> 120 | K5: ='Year 1'!H44 -> 400 | L5: ='Year 1'!I44 -> 400 | M5: ='Year 1'!J44 -> 400 | ... Q5: ='Year 1'!N44 -> 400 | R5: ='Year 2'!C44 -> 40 | S5: ='Year 2'!D44 -> 50 | T5: ='Year 2'!E44 -> 50 | U5: ='Year 2'!F44 -> 100 | V5: ='Year 2'!G44 -> 120 | W5: ='Year 2'!H44 -> 400 | X5: ='Year 2'!I44 -> 400 | Y5: ='Year 2'!J44 -> 400 | ... AC5: ='Year 2'!N44 -> 400 | AD5: ='Year 3'!C44 -> 40 | AE5: ='Year 3'!D44 -> 50 | AF5: ='Year 3'!E44 -> 50 | AG5: ='Year 3'!F44 -> 100 | AH5: ='Year 3'!G44 -> 120 | AI5: ='Year 3'!H44 -> 400 | AJ5: ='Year 3'!I44 -> 400 | AK5: ='Year 3'!J44 -> 400 | ... AO5: ='Year 3'!N44 -> 400
B6: ='Year 3'!B45 -> Sponsorship | C6: ='Year 1'!O45 -> 650000 | D6: ='Year 2'!O45 -> 650000 | E6: ='Year 3'!O45 -> 650000 | F6: ='Year 1'!C45 -> 0 | G6: ='Year 1'!D45 -> 10000 | H6: ='Year 1'!E45 -> 30000 | I6: ='Year 1'!F45 -> 50000 | J6: ='Year 1'!G45 -> 70000 | K6: ='Year 1'!H45 -> 70000 | L6: ='Year 1'!I45 -> 70000 | M6: ='Year 1'!J45 -> 70000 | ... Q6: ='Year 1'!N45 -> 70000 | R6: ='Year 2'!C45 -> 0 | S6: ='Year 2'!D45 -> 10000 | T6: ='Year 2'!E45 -> 30000 | U6: ='Year 2'!F45 -> 50000 | V6: ='Year 2'!G45 -> 70000 | W6: ='Year 2'!H45 -> 70000 | X6: ='Year 2'!I45 -> 70000 | Y6: ='Year 2'!J45 -> 70000 | ... AC6: ='Year 2'!N45 -> 70000 | AD6: ='Year 3'!C45 -> 0 | AE6: ='Year 3'!D45 -> 10000 | AF6: ='Year 3'!E45 -> 30000 | AG6: ='Year 3'!F45 -> 50000 | AH6: ='Year 3'!G45 -> 70000 | AI6: ='Year 3'!H45 -> 70000 | AJ6: ='Year 3'!I45 -> 70000 | AK6: ='Year 3'!J45 -> 70000 | ... AO6: ='Year 3'!N45 -> 70000
B7: ='Year 3'!B46 -> Grants | C7: ='Year 1'!O46 -> 4276.8568 | D7: ='Year 2'!O46 -> 0 | E7: ='Year 3'!O46 -> 0 | F7: ='Year 1'!C46 -> 200 | G7: ='Year 1'!D46 -> 220 | H7: ='Year 1'!E46 -> 242 | I7: ='Year 1'!F46 -> 266.2 | J7: ='Year 1'!G46 -> 292.82 | K7: ='Year 1'!H46 -> 322.102 | L7: ='Year 1'!I46 -> 354.3122 | M7: ='Year 1'!J46 -> 389.74342 | ... Q7: ='Year 1'!N46 -> 570.62334 | R7: ='Year 2'!C46 -> 0 | S7: ='Year 2'!D46 -> 0 | T7: ='Year 2'!E46 -> 0 | U7: ='Year 2'!F46 -> 0 | V7: ='Year 2'!G46 -> 0 | W7: ='Year 2'!H46 -> 0 | X7: ='Year 2'!I46 -> 0 | Y7: ='Year 2'!J46 -> 0 | ... AC7: ='Year 2'!N46 -> 0 | AD7: ='Year 3'!C46 -> 0 | AE7: ='Year 3'!D46 -> 0 | AF7: ='Year 3'!E46 -> 0 | AG7: ='Year 3'!F46 -> 0 | AH7: ='Year 3'!G46 -> 0 | AI7: ='Year 3'!H46 -> 0 | AJ7: ='Year 3'!I46 -> 0 | AK7: ='Year 3'!J46 -> 0 | ... AO7: ='Year 3'!N46 -> 0
B8: ='Year 3'!B47 -> Events Medium | C8: ='Year 1'!O47 -> 0 | D8: ='Year 2'!O47 -> 0 | E8: ='Year 3'!O47 -> 0 | F8: ='Year 1'!C47 -> 0 | G8: ='Year 1'!D47 -> 0 | H8: ='Year 1'!E47 -> 0 | I8: ='Year 1'!F47 -> 0 | J8: ='Year 1'!G47 -> 0 | K8: ='Year 1'!H47 -> 0 | L8: ='Year 1'!I47 -> 0 | M8: ='Year 1'!J47 -> 0 | ... Q8: ='Year 1'!N47 -> 0 | R8: ='Year 2'!C47 -> 0 | S8: ='Year 2'!D47 -> 0 | T8: ='Year 2'!E47 -> 0 | U8: ='Year 2'!F47 -> 0 | V8: ='Year 2'!G47 -> 0 | W8: ='Year 2'!H47 -> 0 | X8: ='Year 2'!I47 -> 0 | Y8: ='Year 2'!J47 -> 0 | ... AC8: ='Year 2'!N47 -> 0 | AD8: ='Year 3'!C47 -> 0 | AE8: ='Year 3'!D47 -> 0 | AF8: ='Year 3'!E47 -> 0 | AG8: ='Year 3'!F47 -> 0 | AH8: ='Year 3'!G47 -> 0 | AI8: ='Year 3'!H47 -> 0 | AJ8: ='Year 3'!I47 -> 0 | AK8: ='Year 3'!J47 -> 0 | ... AO8: ='Year 3'!N47 -> 0
B9: ='Year 3'!B48 -> Events Large | C9: ='Year 1'!O48 -> 0 | D9: ='Year 2'!O48 -> 0 | E9: ='Year 3'!O48 -> 0 | F9: ='Year 1'!C48 -> 0 | G9: ='Year 1'!D48 -> 0 | H9: ='Year 1'!E48 -> 0 | I9: ='Year 1'!F48 -> 0 | J9: ='Year 1'!G48 -> 0 | K9: ='Year 1'!H48 -> 0 | L9: ='Year 1'!I48 -> 0 | M9: ='Year 1'!J48 -> 0 | ... Q9: ='Year 1'!N48 -> 0 | R9: ='Year 2'!C48 -> 0 | S9: ='Year 2'!D48 -> 0 | T9: ='Year 2'!E48 -> 0 | U9: ='Year 2'!F48 -> 0 | V9: ='Year 2'!G48 -> 0 | W9: ='Year 2'!H48 -> 0 | X9: ='Year 2'!I48 -> 0 | Y9: ='Year 2'!J48 -> 0 | ... AC9: ='Year 2'!N48 -> 0 | AD9: ='Year 3'!C48 -> 0 | AE9: ='Year 3'!D48 -> 0 | AF9: ='Year 3'!E48 -> 0 | AG9: ='Year 3'!F48 -> 0 | AH9: ='Year 3'!G48 -> 0 | AI9: ='Year 3'!H48 -> 0 | AJ9: ='Year 3'!I48 -> 0 | AK9: ='Year 3'!J48 -> 0 | ... AO9: ='Year 3'!N48 -> 0
B10: ='Year 3'!B49 -> Ticket Sales - Events | C10: ='Year 1'!O49 -> 1980 | D10: ='Year 2'!O49 -> 0 | E10: ='Year 3'!O49 -> 0 | F10: ='Year 1'!C49 -> 0 | G10: ='Year 1'!D49 -> 600 | H10: ='Year 1'!E49 -> 0 | I10: ='Year 1'!F49 -> 660 | J10: ='Year 1'!G49 -> 0 | K10: ='Year 1'!H49 -> 720 | L10: ='Year 1'!I49 -> 0 | M10: ='Year 1'!J49 -> 0 | ... Q10: ='Year 1'!N49 -> 0 | R10: ='Year 2'!C49 -> 0 | S10: ='Year 2'!D49 -> 0 | T10: ='Year 2'!E49 -> 0 | U10: ='Year 2'!F49 -> 0 | V10: ='Year 2'!G49 -> 0 | W10: ='Year 2'!H49 -> 0 | X10: ='Year 2'!I49 -> 0 | Y10: ='Year 2'!J49 -> 0 | ... AC10: ='Year 2'!N49 -> 0 | AD10: ='Year 3'!C49 -> 0 | AE10: ='Year 3'!D49 -> 0 | AF10: ='Year 3'!E49 -> 0 | AG10: ='Year 3'!F49 -> 0 | AH10: ='Year 3'!G49 -> 0 | AI10: ='Year 3'!H49 -> 0 | AJ10: ='Year 3'!I49 -> 0 | AK10: ='Year 3'!J49 -> 0 | ... AO10: ='Year 3'!N49 -> 0
B11: ='Year 3'!B50 -> VIP Tickets | C11: ='Year 1'!O50 -> 1650 | D11: ='Year 2'!O50 -> 0 | E11: ='Year 3'!O50 -> 0 | F11: ='Year 1'!C50 -> 0 | G11: ='Year 1'!D50 -> 500 | H11: ='Year 1'!E50 -> 0 | I11: ='Year 1'!F50 -> 550 | J11: ='Year 1'!G50 -> 0 | K11: ='Year 1'!H50 -> 600 | L11: ='Year 1'!I50 -> 0 | M11: ='Year 1'!J50 -> 0 | ... Q11: ='Year 1'!N50 -> 0 | R11: ='Year 2'!C50 -> 0 | S11: ='Year 2'!D50 -> 0 | T11: ='Year 2'!E50 -> 0 | U11: ='Year 2'!F50 -> 0 | V11: ='Year 2'!G50 -> 0 | W11: ='Year 2'!H50 -> 0 | X11: ='Year 2'!I50 -> 0 | Y11: ='Year 2'!J50 -> 0 | ... AC11: ='Year 2'!N50 -> 0 | AD11: ='Year 3'!C50 -> 0 | AE11: ='Year 3'!D50 -> 0 | AF11: ='Year 3'!E50 -> 0 | AG11: ='Year 3'!F50 -> 0 | AH11: ='Year 3'!G50 -> 0 | AI11: ='Year 3'!H50 -> 0 | AJ11: ='Year 3'!I50 -> 0 | AK11: ='Year 3'!J50 -> 0 | ... AO11: ='Year 3'!N50 -> 0
B12: ='Year 3'!B51 -> Income Line 9 | C12: ='Year 1'!O51 -> 0 | D12: ='Year 2'!O51 -> 0 | E12: ='Year 3'!O51 -> 0 | F12: ='Year 1'!C51 -> 0 | G12: ='Year 1'!D51 -> 0 | H12: ='Year 1'!E51 -> 0 | I12: ='Year 1'!F51 -> 0 | J12: ='Year 1'!G51 -> 0 | K12: ='Year 1'!H51 -> 0 | L12: ='Year 1'!I51 -> 0 | M12: ='Year 1'!J51 -> 0 | ... Q12: ='Year 1'!N51 -> 0 | R12: ='Year 2'!C51 -> 0 | S12: ='Year 2'!D51 -> 0 | T12: ='Year 2'!E51 -> 0 | U12: ='Year 2'!F51 -> 0 | V12: ='Year 2'!G51 -> 0 | W12: ='Year 2'!H51 -> 0 | X12: ='Year 2'!I51 -> 0 | Y12: ='Year 2'!J51 -> 0 | ... AC12: ='Year 2'!N51 -> 0 | AD12: ='Year 3'!C51 -> 0 | AE12: ='Year 3'!D51 -> 0 | AF12: ='Year 3'!E51 -> 0 | AG12: ='Year 3'!F51 -> 0 | AH12: ='Year 3'!G51 -> 0 | AI12: ='Year 3'!H51 -> 0 | AJ12: ='Year 3'!I51 -> 0 | AK12: ='Year 3'!J51 -> 0 | ... AO12: ='Year 3'!N51 -> 0
B13: ='Year 3'!B52 -> Income Line 10 | C13: ='Year 1'!O52 -> 0 | D13: ='Year 2'!O52 -> 0 | E13: ='Year 3'!O52 -> 0 | F13: ='Year 1'!C52 -> 0 | G13: ='Year 1'!D52 -> 0 | H13: ='Year 1'!E52 -> 0 | I13: ='Year 1'!F52 -> 0 | J13: ='Year 1'!G52 -> 0 | K13: ='Year 1'!H52 -> 0 | L13: ='Year 1'!I52 -> 0 | M13: ='Year 1'!J52 -> 0 | ... Q13: ='Year 1'!N52 -> 0 | R13: ='Year 2'!C52 -> 0 | S13: ='Year 2'!D52 -> 0 | T13: ='Year 2'!E52 -> 0 | U13: ='Year 2'!F52 -> 0 | V13: ='Year 2'!G52 -> 0 | W13: ='Year 2'!H52 -> 0 | X13: ='Year 2'!I52 -> 0 | Y13: ='Year 2'!J52 -> 0 | ... AC13: ='Year 2'!N52 -> 0 | AD13: ='Year 3'!C52 -> 0 | AE13: ='Year 3'!D52 -> 0 | AF13: ='Year 3'!E52 -> 0 | AG13: ='Year 3'!F52 -> 0 | AH13: ='Year 3'!G52 -> 0 | AI13: ='Year 3'!H52 -> 0 | AJ13: ='Year 3'!I52 -> 0 | AK13: ='Year 3'!J52 -> 0 | ... AO13: ='Year 3'!N52 -> 0
B14: ='Year 3'!B53 -> Income Line 11 | C14: ='Year 1'!O53 -> 0 | D14: ='Year 2'!O53 -> 0 | E14: ='Year 3'!O53 -> 0 | F14: ='Year 1'!C53 -> 0 | G14: ='Year 1'!D53 -> 0 | H14: ='Year 1'!E53 -> 0 | I14: ='Year 1'!F53 -> 0 | J14: ='Year 1'!G53 -> 0 | K14: ='Year 1'!H53 -> 0 | L14: ='Year 1'!I53 -> 0 | M14: ='Year 1'!J53 -> 0 | ... Q14: ='Year 1'!N53 -> 0 | R14: ='Year 2'!C53 -> 0 | S14: ='Year 2'!D53 -> 0 | T14: ='Year 2'!E53 -> 0 | U14: ='Year 2'!F53 -> 0 | V14: ='Year 2'!G53 -> 0 | W14: ='Year 2'!H53 -> 0 | X14: ='Year 2'!I53 -> 0 | Y14: ='Year 2'!J53 -> 0 | ... AC14: ='Year 2'!N53 -> 0 | AD14: ='Year 3'!C53 -> 0 | AE14: ='Year 3'!D53 -> 0 | AF14: ='Year 3'!E53 -> 0 | AG14: ='Year 3'!F53 -> 0 | AH14: ='Year 3'!G53 -> 0 | AI14: ='Year 3'!H53 -> 0 | AJ14: ='Year 3'!I53 -> 0 | AK14: ='Year 3'!J53 -> 0 | ... AO14: ='Year 3'!N53 -> 0
B15: ='Year 3'!B54 -> Income Line 12 | C15: ='Year 1'!O54 -> 0 | D15: ='Year 2'!O54 -> 0 | E15: ='Year 3'!O54 -> 0 | F15: ='Year 1'!C54 -> 0 | G15: ='Year 1'!D54 -> 0 | H15: ='Year 1'!E54 -> 0 | I15: ='Year 1'!F54 -> 0 | J15: ='Year 1'!G54 -> 0 | K15: ='Year 1'!H54 -> 0 | L15: ='Year 1'!I54 -> 0 | M15: ='Year 1'!J54 -> 0 | ... Q15: ='Year 1'!N54 -> 0 | R15: ='Year 2'!C54 -> 0 | S15: ='Year 2'!D54 -> 0 | T15: ='Year 2'!E54 -> 0 | U15: ='Year 2'!F54 -> 0 | V15: ='Year 2'!G54 -> 0 | W15: ='Year 2'!H54 -> 0 | X15: ='Year 2'!I54 -> 0 | Y15: ='Year 2'!J54 -> 0 | ... AC15: ='Year 2'!N54 -> 0 | AD15: ='Year 3'!C54 -> 0 | AE15: ='Year 3'!D54 -> 0 | AF15: ='Year 3'!E54 -> 0 | AG15: ='Year 3'!F54 -> 0 | AH15: ='Year 3'!G54 -> 0 | AI15: ='Year 3'!H54 -> 0 | AJ15: ='Year 3'!I54 -> 0 | AK15: ='Year 3'!J54 -> 0 | ... AO15: ='Year 3'!N54 -> 0
... B20: ='Year 3'!B59 -> Income Total | C20: ='Year 1'!O59 -> 861466.86 | D20: ='Year 2'!O59 -> 853560 | E20: ='Year 3'!O59 -> 853560 | F20: ='Year 1'!C59 -> 2640 | G20: ='Year 1'!D59 -> 14370 | H20: ='Year 1'!E59 -> 33292 | I20: ='Year 1'!F59 -> 57576.2 | J20: ='Year 1'!G59 -> 76412.82 | K20: ='Year 1'!H59 -> 84042.102 | L20: ='Year 1'!I59 -> 82754.312 | M20: ='Year 1'!J59 -> 82789.743 | ... Q20: ='Year 1'!N59 -> 106970.62 | R20: ='Year 2'!C59 -> 2440 | S20: ='Year 2'!D59 -> 13050 | T20: ='Year 2'!E59 -> 33050 | U20: ='Year 2'!F59 -> 56100 | V20: ='Year 2'!G59 -> 76120 | W20: ='Year 2'!H59 -> 82400 | X20: ='Year 2'!I59 -> 82400 | Y20: ='Year 2'!J59 -> 82400 | ... AC20: ='Year 2'!N59 -> 106400 | AD20: ='Year 3'!C59 -> 2440 | AE20: ='Year 3'!D59 -> 13050 | AF20: ='Year 3'!E59 -> 33050 | AG20: ='Year 3'!F59 -> 56100 | AH20: ='Year 3'!G59 -> 76120 | AI20: ='Year 3'!H59 -> 82400 | AJ20: ='Year 3'!I59 -> 82400 | AK20: ='Year 3'!J59 -> 82400 | ... AO20: ='Year 3'!N59 -> 106400
B22: ='Year 3'!B62 -> Expenditure
B23: ='Year 3'!B63 -> Salary | C23: ='Year 1'!O63 -> 10500 | D23: ='Year 2'!O63 -> 10500 | E23: ='Year 3'!O63 -> 10500 | F23: ='Year 1'!C63 -> 0 | G23: ='Year 1'!D63 -> 0 | H23: ='Year 1'!E63 -> 0 | I23: ='Year 1'!F63 -> 500 | J23: ='Year 1'!G63 -> 500 | K23: ='Year 1'!H63 -> 500 | L23: ='Year 1'!I63 -> 1500 | M23: ='Year 1'!J63 -> 1500 | ... Q23: ='Year 1'!N63 -> 1500 | R23: ='Year 2'!C63 -> 0 | S23: ='Year 2'!D63 -> 0 | T23: ='Year 2'!E63 -> 0 | U23: ='Year 2'!F63 -> 500 | V23: ='Year 2'!G63 -> 500 | W23: ='Year 2'!H63 -> 500 | X23: ='Year 2'!I63 -> 1500 | Y23: ='Year 2'!J63 -> 1500 | ... AC23: ='Year 2'!N63 -> 1500 | AD23: ='Year 3'!C63 -> 0 | AE23: ='Year 3'!D63 -> 0 | AF23: ='Year 3'!E63 -> 0 | AG23: ='Year 3'!F63 -> 500 | AH23: ='Year 3'!G63 -> 500 | AI23: ='Year 3'!H63 -> 500 | AJ23: ='Year 3'!I63 -> 1500 | AK23: ='Year 3'!J63 -> 1500 | ... AO23: ='Year 3'!N63 -> 1500
B24: ='Year 3'!B64 -> Materials | C24: ='Year 1'!O64 -> 4372 | D24: ='Year 2'!O64 -> 4372 | E24: ='Year 3'!O64 -> 4372 | F24: ='Year 1'!C64 -> 12 | G24: ='Year 1'!D64 -> 120 | H24: ='Year 1'!E64 -> 120 | I24: ='Year 1'!F64 -> 120 | J24: ='Year 1'!G64 -> 500 | K24: ='Year 1'!H64 -> 500 | L24: ='Year 1'!I64 -> 500 | M24: ='Year 1'!J64 -> 500 | ... Q24: ='Year 1'!N64 -> 500 | R24: ='Year 2'!C64 -> 12 | S24: ='Year 2'!D64 -> 120 | T24: ='Year 2'!E64 -> 120 | U24: ='Year 2'!F64 -> 120 | V24: ='Year 2'!G64 -> 500 | W24: ='Year 2'!H64 -> 500 | X24: ='Year 2'!I64 -> 500 | Y24: ='Year 2'!J64 -> 500 | ... AC24: ='Year 2'!N64 -> 500 | AD24: ='Year 3'!C64 -> 12 | AE24: ='Year 3'!D64 -> 120 | AF24: ='Year 3'!E64 -> 120 | AG24: ='Year 3'!F64 -> 120 | AH24: ='Year 3'!G64 -> 500 | AI24: ='Year 3'!H64 -> 500 | AJ24: ='Year 3'!I64 -> 500 | AK24: ='Year 3'!J64 -> 500 | ... AO24: ='Year 3'!N64 -> 500
B25: ='Year 3'!B65 -> Website | C25: ='Year 1'!O65 -> 900 | D25: ='Year 2'!O65 -> 900 | E25: ='Year 3'!O65 -> 900 | F25: ='Year 1'!C65 -> 0 | G25: ='Year 1'!D65 -> 0 | H25: ='Year 1'!E65 -> 0 | I25: ='Year 1'!F65 -> 500 | J25: ='Year 1'!G65 -> 50 | K25: ='Year 1'!H65 -> 50 | L25: ='Year 1'!I65 -> 50 | M25: ='Year 1'!J65 -> 50 | ... Q25: ='Year 1'!N65 -> 50 | R25: ='Year 2'!C65 -> 0 | S25: ='Year 2'!D65 -> 0 | T25: ='Year 2'!E65 -> 0 | U25: ='Year 2'!F65 -> 500 | V25: ='Year 2'!G65 -> 50 | W25: ='Year 2'!H65 -> 50 | X25: ='Year 2'!I65 -> 50 | Y25: ='Year 2'!J65 -> 50 | ... AC25: ='Year 2'!N65 -> 50 | AD25: ='Year 3'!C65 -> 0 | AE25: ='Year 3'!D65 -> 0 | AF25: ='Year 3'!E65 -> 0 | AG25: ='Year 3'!F65 -> 500 | AH25: ='Year 3'!G65 -> 50 | AI25: ='Year 3'!H65 -> 50 | AJ25: ='Year 3'!I65 -> 50 | AK25: ='Year 3'!J65 -> 50 | ... AO25: ='Year 3'!N65 -> 50
B26: ='Year 3'!B66 -> Marketing | C26: ='Year 1'!O66 -> 900 | D26: ='Year 2'!O66 -> 900 | E26: ='Year 3'!O66 -> 900 | F26: ='Year 1'!C66 -> 0 | G26: ='Year 1'!D66 -> 0 | H26: ='Year 1'!E66 -> 0 | I26: ='Year 1'!F66 -> 100 | J26: ='Year 1'!G66 -> 100 | K26: ='Year 1'!H66 -> 100 | L26: ='Year 1'!I66 -> 100 | M26: ='Year 1'!J66 -> 100 | ... Q26: ='Year 1'!N66 -> 100 | R26: ='Year 2'!C66 -> 0 | S26: ='Year 2'!D66 -> 0 | T26: ='Year 2'!E66 -> 0 | U26: ='Year 2'!F66 -> 100 | V26: ='Year 2'!G66 -> 100 | W26: ='Year 2'!H66 -> 100 | X26: ='Year 2'!I66 -> 100 | Y26: ='Year 2'!J66 -> 100 | ... AC26: ='Year 2'!N66 -> 100 | AD26: ='Year 3'!C66 -> 0 | AE26: ='Year 3'!D66 -> 0 | AF26: ='Year 3'!E66 -> 0 | AG26: ='Year 3'!F66 -> 100 | AH26: ='Year 3'!G66 -> 100 | AI26: ='Year 3'!H66 -> 100 | AJ26: ='Year 3'!I66 -> 100 | AK26: ='Year 3'!J66 -> 100 | ... AO26: ='Year 3'!N66 -> 100
B27: ='Year 3'!B67 -> Business Fees | C27: ='Year 1'!O67 -> 600 | D27: ='Year 2'!O67 -> 600 | E27: ='Year 3'!O67 -> 600 | F27: ='Year 1'!C67 -> 0 | G27: ='Year 1'!D67 -> 0 | H27: ='Year 1'!E67 -> 0 | I27: ='Year 1'!F67 -> 100 | J27: ='Year 1'!G67 -> 0 | K27: ='Year 1'!H67 -> 0 | L27: ='Year 1'!I67 -> 0 | M27: ='Year 1'!J67 -> 0 | ... Q27: ='Year 1'!N67 -> 500 | R27: ='Year 2'!C67 -> 0 | S27: ='Year 2'!D67 -> 0 | T27: ='Year 2'!E67 -> 0 | U27: ='Year 2'!F67 -> 100 | V27: ='Year 2'!G67 -> 0 | W27: ='Year 2'!H67 -> 0 | X27: ='Year 2'!I67 -> 0 | Y27: ='Year 2'!J67 -> 0 | ... AC27: ='Year 2'!N67 -> 500 | AD27: ='Year 3'!C67 -> 0 | AE27: ='Year 3'!D67 -> 0 | AF27: ='Year 3'!E67 -> 0 | AG27: ='Year 3'!F67 -> 100 | AH27: ='Year 3'!G67 -> 0 | AI27: ='Year 3'!H67 -> 0 | AJ27: ='Year 3'!I67 -> 0 | AK27: ='Year 3'!J67 -> 0 | ... AO27: ='Year 3'!N67 -> 500
B28: ='Year 3'!B68 -> Expenditure Line 6 | C28: ='Year 1'!O68 -> 0 | D28: ='Year 2'!O68 -> 0 | E28: ='Year 3'!O68 -> 0 | F28: ='Year 1'!C68 -> 0 | G28: ='Year 1'!D68 -> 0 | H28: ='Year 1'!E68 -> 0 | I28: ='Year 1'!F68 -> 0 | J28: ='Year 1'!G68 -> 0 | K28: ='Year 1'!H68 -> 0 | L28: ='Year 1'!I68 -> 0 | M28: ='Year 1'!J68 -> 0 | ... Q28: ='Year 1'!N68 -> 0 | R28: ='Year 2'!C68 -> 0 | S28: ='Year 2'!D68 -> 0 | T28: ='Year 2'!E68 -> 0 | U28: ='Year 2'!F68 -> 0 | V28: ='Year 2'!G68 -> 0 | W28: ='Year 2'!H68 -> 0 | X28: ='Year 2'!I68 -> 0 | Y28: ='Year 2'!J68 -> 0 | ... AC28: ='Year 2'!N68 -> 0 | AD28: ='Year 3'!C68 -> 0 | AE28: ='Year 3'!D68 -> 0 | AF28: ='Year 3'!E68 -> 0 | AG28: ='Year 3'!F68 -> 0 | AH28: ='Year 3'!G68 -> 0 | AI28: ='Year 3'!H68 -> 0 | AJ28: ='Year 3'!I68 -> 0 | AK28: ='Year 3'!J68 -> 0 | ... AO28: ='Year 3'!N68 -> 0
B29: ='Year 3'!B69 -> Expenditure Line 7 | C29: ='Year 1'!O69 -> 0 | D29: ='Year 2'!O69 -> 0 | E29: ='Year 3'!O69 -> 0 | F29: ='Year 1'!C69 -> 0 | G29: ='Year 1'!D69 -> 0 | H29: ='Year 1'!E69 -> 0 | I29: ='Year 1'!F69 -> 0 | J29: ='Year 1'!G69 -> 0 | K29: ='Year 1'!H69 -> 0 | L29: ='Year 1'!I69 -> 0 | M29: ='Year 1'!J69 -> 0 | ... Q29: ='Year 1'!N69 -> 0 | R29: ='Year 2'!C69 -> 0 | S29: ='Year 2'!D69 -> 0 | T29: ='Year 2'!E69 -> 0 | U29: ='Year 2'!F69 -> 0 | V29: ='Year 2'!G69 -> 0 | W29: ='Year 2'!H69 -> 0 | X29: ='Year 2'!I69 -> 0 | Y29: ='Year 2'!J69 -> 0 | ... AC29: ='Year 2'!N69 -> 0 | AD29: ='Year 3'!C69 -> 0 | AE29: ='Year 3'!D69 -> 0 | AF29: ='Year 3'!E69 -> 0 | AG29: ='Year 3'!F69 -> 0 | AH29: ='Year 3'!G69 -> 0 | AI29: ='Year 3'!H69 -> 0 | AJ29: ='Year 3'!I69 -> 0 | AK29: ='Year 3'!J69 -> 0 | ... AO29: ='Year 3'!N69 -> 0
B30: ='Year 3'!B70 -> Expenditure Line 8 | C30: ='Year 1'!O70 -> 0 | D30: ='Year 2'!O70 -> 0 | E30: ='Year 3'!O70 -> 0 | F30: ='Year 1'!C70 -> 0 | G30: ='Year 1'!D70 -> 0 | H30: ='Year 1'!E70 -> 0 | I30: ='Year 1'!F70 -> 0 | J30: ='Year 1'!G70 -> 0 | K30: ='Year 1'!H70 -> 0 | L30: ='Year 1'!I70 -> 0 | M30: ='Year 1'!J70 -> 0 | ... Q30: ='Year 1'!N70 -> 0 | R30: ='Year 2'!C70 -> 0 | S30: ='Year 2'!D70 -> 0 | T30: ='Year 2'!E70 -> 0 | U30: ='Year 2'!F70 -> 0 | V30: ='Year 2'!G70 -> 0 | W30: ='Year 2'!H70 -> 0 | X30: ='Year 2'!I70 -> 0 | Y30: ='Year 2'!J70 -> 0 | ... AC30: ='Year 2'!N70 -> 0 | AD30: ='Year 3'!C70 -> 0 | AE30: ='Year 3'!D70 -> 0 | AF30: ='Year 3'!E70 -> 0 | AG30: ='Year 3'!F70 -> 0 | AH30: ='Year 3'!G70 -> 0 | AI30: ='Year 3'!H70 -> 0 | AJ30: ='Year 3'!I70 -> 0 | AK30: ='Year 3'!J70 -> 0 | ... AO30: ='Year 3'!N70 -> 0
B31: ='Year 3'!B71 -> Expenditure Line 9 | C31: ='Year 1'!O71 -> 0 | D31: ='Year 2'!O71 -> 0 | E31: ='Year 3'!O71 -> 0 | F31: ='Year 1'!C71 -> 0 | G31: ='Year 1'!D71 -> 0 | H31: ='Year 1'!E71 -> 0 | I31: ='Year 1'!F71 -> 0 | J31: ='Year 1'!G71 -> 0 | K31: ='Year 1'!H71 -> 0 | L31: ='Year 1'!I71 -> 0 | M31: ='Year 1'!J71 -> 0 | ... Q31: ='Year 1'!N71 -> 0 | R31: ='Year 2'!C71 -> 0 | S31: ='Year 2'!D71 -> 0 | T31: ='Year 2'!E71 -> 0 | U31: ='Year 2'!F71 -> 0 | V31: ='Year 2'!G71 -> 0 | W31: ='Year 2'!H71 -> 0 | X31: ='Year 2'!I71 -> 0 | Y31: ='Year 2'!J71 -> 0 | ... AC31: ='Year 2'!N71 -> 0 | AD31: ='Year 3'!C71 -> 0 | AE31: ='Year 3'!D71 -> 0 | AF31: ='Year 3'!E71 -> 0 | AG31: ='Year 3'!F71 -> 0 | AH31: ='Year 3'!G71 -> 0 | AI31: ='Year 3'!H71 -> 0 | AJ31: ='Year 3'!I71 -> 0 | AK31: ='Year 3'!J71 -> 0 | ... AO31: ='Year 3'!N71 -> 0
B32: ='Year 3'!B72 -> Expenditure Line 10 | C32: ='Year 1'!O72 -> 0 | D32: ='Year 2'!O72 -> 0 | E32: ='Year 3'!O72 -> 0 | F32: ='Year 1'!C72 -> 0 | G32: ='Year 1'!D72 -> 0 | H32: ='Year 1'!E72 -> 0 | I32: ='Year 1'!F72 -> 0 | J32: ='Year 1'!G72 -> 0 | K32: ='Year 1'!H72 -> 0 | L32: ='Year 1'!I72 -> 0 | M32: ='Year 1'!J72 -> 0 | ... Q32: ='Year 1'!N72 -> 0 | R32: ='Year 2'!C72 -> 0 | S32: ='Year 2'!D72 -> 0 | T32: ='Year 2'!E72 -> 0 | U32: ='Year 2'!F72 -> 0 | V32: ='Year 2'!G72 -> 0 | W32: ='Year 2'!H72 -> 0 | X32: ='Year 2'!I72 -> 0 | Y32: ='Year 2'!J72 -> 0 | ... AC32: ='Year 2'!N72 -> 0 | AD32: ='Year 3'!C72 -> 0 | AE32: ='Year 3'!D72 -> 0 | AF32: ='Year 3'!E72 -> 0 | AG32: ='Year 3'!F72 -> 0 | AH32: ='Year 3'!G72 -> 0 | AI32: ='Year 3'!H72 -> 0 | AJ32: ='Year 3'!I72 -> 0 | AK32: ='Year 3'!J72 -> 0 | ... AO32: ='Year 3'!N72 -> 0
B33: ='Year 3'!B73 -> Expenditure Line 11 | C33: ='Year 1'!O73 -> 0 | D33: ='Year 2'!O73 -> 0 | E33: ='Year 3'!O73 -> 0 | F33: ='Year 1'!C73 -> 0 | G33: ='Year 1'!D73 -> 0 | H33: ='Year 1'!E73 -> 0 | I33: ='Year 1'!F73 -> 0 | J33: ='Year 1'!G73 -> 0 | K33: ='Year 1'!H73 -> 0 | L33: ='Year 1'!I73 -> 0 | M33: ='Year 1'!J73 -> 0 | ... Q33: ='Year 1'!N73 -> 0 | R33: ='Year 2'!C73 -> 0 | S33: ='Year 2'!D73 -> 0 | T33: ='Year 2'!E73 -> 0 | U33: ='Year 2'!F73 -> 0 | V33: ='Year 2'!G73 -> 0 | W33: ='Year 2'!H73 -> 0 | X33: ='Year 2'!I73 -> 0 | Y33: ='Year 2'!J73 -> 0 | ... AC33: ='Year 2'!N73 -> 0 | AD33: ='Year 3'!C73 -> 0 | AE33: ='Year 3'!D73 -> 0 | AF33: ='Year 3'!E73 -> 0 | AG33: ='Year 3'!F73 -> 0 | AH33: ='Year 3'!G73 -> 0 | AI33: ='Year 3'!H73 -> 0 | AJ33: ='Year 3'!I73 -> 0 | AK33: ='Year 3'!J73 -> 0 | ... AO33: ='Year 3'!N73 -> 0
B34: ='Year 3'!B74 -> Expenditure Line 12 | C34: ='Year 1'!O74 -> 0 | D34: ='Year 2'!O74 -> 0 | E34: ='Year 3'!O74 -> 0 | F34: ='Year 1'!C74 -> 0 | G34: ='Year 1'!D74 -> 0 | H34: ='Year 1'!E74 -> 0 | I34: ='Year 1'!F74 -> 0 | J34: ='Year 1'!G74 -> 0 | K34: ='Year 1'!H74 -> 0 | L34: ='Year 1'!I74 -> 0 | M34: ='Year 1'!J74 -> 0 | ... Q34: ='Year 1'!N74 -> 0 | R34: ='Year 2'!C74 -> 0 | S34: ='Year 2'!D74 -> 0 | T34: ='Year 2'!E74 -> 0 | U34: ='Year 2'!F74 -> 0 | V34: ='Year 2'!G74 -> 0 | W34: ='Year 2'!H74 -> 0 | X34: ='Year 2'!I74 -> 0 | Y34: ='Year 2'!J74 -> 0 | ... AC34: ='Year 2'!N74 -> 0 | AD34: ='Year 3'!C74 -> 0 | AE34: ='Year 3'!D74 -> 0 | AF34: ='Year 3'!E74 -> 0 | AG34: ='Year 3'!F74 -> 0 | AH34: ='Year 3'!G74 -> 0 | AI34: ='Year 3'!H74 -> 0 | AJ34: ='Year 3'!I74 -> 0 | AK34: ='Year 3'!J74 -> 0 | ... AO34: ='Year 3'!N74 -> 0
... B44: ='Year 3'!B84 -> Expenditure Total | C44: ='Year 1'!O84 -> 17272 | D44: ='Year 2'!O84 -> 17272 | E44: ='Year 3'!O84 -> 17272 | F44: ='Year 1'!C84 -> 12 | G44: ='Year 1'!D84 -> 120 | H44: ='Year 1'!E84 -> 120 | I44: ='Year 1'!F84 -> 1320 | J44: ='Year 1'!G84 -> 1150 | K44: ='Year 1'!H84 -> 1150 | L44: ='Year 1'!I84 -> 2150 | M44: ='Year 1'!J84 -> 2150 | ... Q44: ='Year 1'!N84 -> 2650 | R44: ='Year 2'!C84 -> 12 | S44: ='Year 2'!D84 -> 120 | T44: ='Year 2'!E84 -> 120 | U44: ='Year 2'!F84 -> 1320 | V44: ='Year 2'!G84 -> 1150 | W44: ='Year 2'!H84 -> 1150 | X44: ='Year 2'!I84 -> 2150 | Y44: ='Year 2'!J84 -> 2150 | ... AC44: ='Year 2'!N84 -> 2650 | AD44: ='Year 3'!C84 -> 12 | AE44: ='Year 3'!D84 -> 120 | AF44: ='Year 3'!E84 -> 120 | AG44: ='Year 3'!F84 -> 1320 | AH44: ='Year 3'!G84 -> 1150 | AI44: ='Year 3'!H84 -> 1150 | AJ44: ='Year 3'!I84 -> 2150 | AK44: ='Year 3'!J84 -> 2150 | ... AO44: ='Year 3'!N84 -> 2650
B46: NET CASH FLOW | C46: =C20-C44 -> 844194.86 | D46: =D20-D44 -> 836288 | E46: =E20-E44 -> 836288 | F46: =F20-F44 -> 2628 | G46: =G20-G44 -> 14250 | H46: =H20-H44 -> 33172 | I46: =I20-I44 -> 56256.2 | J46: =J20-J44 -> 75262.82 | ... AO46: =AO20-AO44 -> 103750
B47: CASH B/F | C47: =F47 -> 0 | D47: =C48 -> 844194.86 | E47: =D48 -> 1680482.9 | F47: ='Year 1'!C87 -> 0 | G47: =F48 -> 2628 | H47: =G48 -> 16878 | I47: =H48 -> 50050 | J47: =I48 -> 106306.2 | K47: =J48 -> 181569.02 | L47: =K48 -> 264461.12 | M47: =L48 -> 345065.43 | N47: =M48 -> 425705.18 | ... AO47: =AN48 -> 2413020.9
B48: CASH C/F | C48: =Q48 -> 844194.86 | D48: =AC48 -> 1680482.9 | E48: =AO48 -> 2516770.9 | F48: =F47+F46 -> 2628 | G48: =G47+G46 -> 16878 | H48: =H47+H46 -> 50050 | I48: =I47+I46 -> 106306.2 | J48: =J47+J46 -> 181569.02 | K48: =K47+K46 -> 264461.12 | L48: =L47+L46 -> 345065.43 | M48: =M47+M46 -> 425705.18 | ... AO48: =AO47+AO46 -> 2516770.9
