Workbook

Sheet Year 1
B2: Month | C2: 1 | D2: 2 | E2: 3 | F2: 4 | G2: 5 | H2: 6 | I2: 7 | J2: 8 | K2: 9 | L2: 10 | M2: 11 | N2: 12 | O2: Total
B3: Income | C3: 44287 | D3: 44317 | E3: 44348 | F3: 44378 | G3: 44409 | H3: 44440 | I3: 44470 | J3: 44501 | K3: 44531 | L3: 44562 | M3: 44593 | N3: 44621
B4: App Sales | D4: 50 | O4: =SUM(C4:N4) -> 50
B5: Income Line 2 | O5: =SUM(C5:N5) -> 0
B6: Income Line 3 | O6: =SUM(C6:N6) -> 0
B7: Income Line 4 | O7: =SUM(C7:N7) -> 0
B8: Income Line 5 | O8: =SUM(C8:N8) -> 0
B9: Income Line 6 | O9: =SUM(C9:N9) -> 0
B10: Income Line 7 | O10: =SUM(C10:N10) -> 0
B11: Income Line 8 | O11: =SUM(C11:N11) -> 0
B12: Income Line 9 | O12: =SUM(C12:N12) -> 0
B13: Income Line 10 | O13: =SUM(C13:N13) -> 0
B14: Income Line 11 | O14: =SUM(C14:N14) -> 0
B15: Income Line 12 | O15: =SUM(C15:N15) -> 0
B16: Income Line 13 | O16: =SUM(C16:N16) -> 0
... B18: Income Line 15 | O18: =SUM(C18:N18) -> 0
B20: Income Total | C20: =SUM(C4:C19) -> 0 | D20: =SUM(D4:D19) -> 50 | E20: =SUM(E4:E19) -> 0 | F20: =SUM(F4:F19) -> 0 | G20: =SUM(G4:G19) -> 0 | H20: =SUM(H4:H19) -> 0 | I20: =SUM(I4:I19) -> 0 | J20: =SUM(J4:J19) -> 0 | ... N20: =SUM(N4:N19) -> 0 | O20: =SUM(C20:N20) -> 50
B22: Month | C22: =C2 -> 1 | D22: =D2 -> 2 | E22: =E2 -> 3 | F22: =F2 -> 4 | G22: =G2 -> 5 | H22: =H2 -> 6 | I22: =I2 -> 7 | J22: =J2 -> 8 | ... N22: =N2 -> 12 | O22: Total
B23: Expenditure | C23: =C3 -> 44287 | D23: =D3 -> 44317 | E23: =E3 -> 44348 | F23: =F3 -> 44378 | G23: =G3 -> 44409 | H23: =H3 -> 44440 | I23: =I3 -> 44470 | J23: =J3 -> 44501 | ... N23: =N3 -> 44621
B24: Marketing | D24: 45 | O24: =SUM(C24:N24) -> 45
B25: Expenditure Line 2 | O25: =SUM(C25:N25) -> 0
B26: Expenditure Line 3 | O26: =SUM(C26:N26) -> 0
B27: Expenditure Line 4 | O27: =SUM(C27:N27) -> 0
B28: Expenditure Line 5 | O28: =SUM(C28:N28) -> 0
B29: Expenditure Line 6 | O29: =SUM(C29:N29) -> 0
B30: Expenditure Line 7 | O30: =SUM(C30:N30) -> 0
B31: Expenditure Line 8 | O31: =SUM(C31:N31) -> 0
B32: Expenditure Line 9 | O32: =SUM(C32:N32) -> 0
B33: Expenditure Line 10 | O33: =SUM(C33:N33) -> 0
B34: Expenditure Line 11 | O34: =SUM(C34:N34) -> 0
B35: Expenditure Line 12 | O35: =SUM(C35:N35) -> 0
B36: Expenditure Line 13 | O36: =SUM(C36:N36) -> 0
... B43: Expenditure Line 20 | O43: =SUM(C43:N43) -> 0
B45: Expenditure Total | C45: =SUM(C24:C43) -> 0 | D45: =SUM(D24:D43) -> 45 | E45: =SUM(E24:E43) -> 0 | F45: =SUM(F24:F43) -> 0 | G45: =SUM(G24:G43) -> 0 | H45: =SUM(H24:H43) -> 0 | I45: =SUM(I24:I43) -> 0 | J45: =SUM(J24:J43) -> 0 | ... N45: =SUM(N24:N43) -> 0 | O45: =SUM(C45:N45) -> 45
B47: Retained Earnings/Losses | C47: =C20-C45 -> 0 | D47: =D20-D45 -> 5 | E47: =E20-E45 -> 0 | F47: =F20-F45 -> 0 | G47: =G20-G45 -> 0 | H47: =H20-H45 -> 0 | I47: =I20-I45 -> 0 | J47: =J20-J45 -> 0 | ... N47: =N20-N45 -> 0 | O47: =SUM(C47:N47) -> 5
B48: Cash B/F | C48: 0 | D48: =C49 -> 0 | E48: =D49 -> 5 | F48: =E49 -> 5 | G48: =F49 -> 5 | H48: =G49 -> 5 | I48: =H49 -> 5 | J48: =I49 -> 5 | K48: =J49 -> 5 | ... N48: =M49 -> 5 | O48: =C48 -> 0
B49: Cash C/F | C49: =C47+C48 -> 0 | D49: =D47+D48 -> 5 | E49: =E47+E48 -> 5 | F49: =F47+F48 -> 5 | G49: =G47+G48 -> 5 | H49: =H47+H48 -> 5 | I49: =I47+I48 -> 5 | J49: =J47+J48 -> 5 | ... N49: =N47+N48 -> 5 | O49: =N49 -> 5

Sheet Year 2
B2: Month | C2: 13 | D2: 14 | E2: 15 | F2: 16 | G2: 17 | H2: 18 | I2: 19 | J2: 20 | K2: 21 | L2: 22 | M2: 23 | N2: 24 | O2: Total
B3: Income | C3: 44652 | D3: 44682 | E3: 44713 | F3: 44743 | G3: 44774 | H3: 44805 | I3: 44835 | J3: 44866 | K3: 44896 | L3: 44927 | M3: 44958 | N3: 44986
B4: Income Line 1 | O4: =SUM(C4:N4) -> 0
B5: Income Line 2 | O5: =SUM(C5:N5) -> 0
B6: Income Line 3 | O6: =SUM(C6:N6) -> 0
B7: Income Line 4 | O7: =SUM(C7:N7) -> 0
B8: Income Line 5 | O8: =SUM(C8:N8) -> 0
B9: Income Line 6 | O9: =SUM(C9:N9) -> 0
B10: Income Line 7 | O10: =SUM(C10:N10) -> 0
B11: Income Line 8 | O11: =SUM(C11:N11) -> 0
B12: Income Line 9 | O12: =SUM(C12:N12) -> 0
B13: Income Line 10 | O13: =SUM(C13:N13) -> 0
B14: Income Line 11 | O14: =SUM(C14:N14) -> 0
B15: Income Line 12 | O15: =SUM(C15:N15) -> 0
... B18: Income Line 15 | O18: =SUM(C18:N18) -> 0
B20: Income Total | C20: =SUM(C4:C19) -> 0 | D20: =SUM(D4:D19) -> 0 | E20: =SUM(E4:E19) -> 0 | F20: =SUM(F4:F19) -> 0 | G20: =SUM(G4:G19) -> 0 | H20: =SUM(H4:H19) -> 0 | I20: =SUM(I4:I19) -> 0 | J20: =SUM(J4:J19) -> 0 | ... N20: =SUM(N4:N19) -> 0 | O20: =SUM(C20:N20) -> 0
B22: Month | C22: =C2 -> 13 | D22: =D2 -> 14 | E22: =E2 -> 15 | F22: =F2 -> 16 | G22: =G2 -> 17 | H22: =H2 -> 18 | I22: =I2 -> 19 | J22: =J2 -> 20 | ... N22: =N2 -> 24 | O22: Total
B23: Expenditure | C23: =C3 -> 44652 | D23: =D3 -> 44682 | E23: =E3 -> 44713 | F23: =F3 -> 44743 | G23: =G3 -> 44774 | H23: =H3 -> 44805 | I23: =I3 -> 44835 | J23: =J3 -> 44866 | ... N23: =N3 -> 44986
B24: Expenditure Line 1 | O24: =SUM(C24:N24) -> 0
B25: Expenditure Line 2 | O25: =SUM(C25:N25) -> 0
B26: Expenditure Line 3 | O26: =SUM(C26:N26) -> 0
B27: Expenditure Line 4 | O27: =SUM(C27:N27) -> 0
B28: Expenditure Line 5 | O28: =SUM(C28:N28) -> 0
B29: Expenditure Line 6 | O29: =SUM(C29:N29) -> 0
B30: Expenditure Line 7 | O30: =SUM(C30:N30) -> 0
B31: Expenditure Line 8 | O31: =SUM(C31:N31) -> 0
B32: Expenditure Line 9 | O32: =SUM(C32:N32) -> 0
B33: Expenditure Line 10 | O33: =SUM(C33:N33) -> 0
B34: Expenditure Line 11 | O34: =SUM(C34:N34) -> 0
B35: Expenditure Line 12 | O35: =SUM(C35:N35) -> 0
... B43: Expenditure Line 20 | O43: =SUM(C43:N43) -> 0
B45: Expenditure Total | C45: =SUM(C24:C43) -> 0 | D45: =SUM(D24:D43) -> 0 | E45: =SUM(E24:E43) -> 0 | F45: =SUM(F24:F43) -> 0 | G45: =SUM(G24:G43) -> 0 | H45: =SUM(H24:H43) -> 0 | I45: =SUM(I24:I43) -> 0 | J45: =SUM(J24:J43) -> 0 | ... N45: =SUM(N24:N43) -> 0 | O45: =SUM(C45:N45) -> 0
B47: Retained Earnings/Losses | C47: =C20-C45 -> 0 | D47: =D20-D45 -> 0 | E47: =E20-E45 -> 0 | F47: =F20-F45 -> 0 | G47: =G20-G45 -> 0 | H47: =H20-H45 -> 0 | I47: =I20-I45 -> 0 | J47: =J20-J45 -> 0 | ... N47: =N20-N45 -> 0 | O47: =SUM(C47:N47) -> 0
B48: Cash B/F | C48: ='Year 1'!N49 -> 5 | D48: =C49 -> 5 | E48: =D49 -> 5 | F48: =E49 -> 5 | G48: =F49 -> 5 | H48: =G49 -> 5 | I48: =H49 -> 5 | J48: =I49 -> 5 | K48: =J49 -> 5 | ... N48: =M49 -> 5 | O48: ='Year 1'!N49 -> 5
B49: Cash C/F | C49: =C47+C48 -> 5 | D49: =D47+D48 -> 5 | E49: =E47+E48 -> 5 | F49: =F47+F48 -> 5 | G49: =G47+G48 -> 5 | H49: =H47+H48 -> 5 | I49: =I47+I48 -> 5 | J49: =J47+J48 -> 5 | ... N49: =N47+N48 -> 5 | O49: =N49 -> 5

Sheet Year 3
B2: Month | C2: 25 | D2: 26 | E2: 27 | F2: 28 | G2: 29 | H2: 30 | I2: 31 | J2: 32 | K2: 33 | L2: 34 | M2: 35 | N2: 36 | O2: Total
B3: Income | C3: 45017 | D3: 45047 | E3: 45078 | F3: 45108 | G3: 45139 | H3: 45170 | I3: 45200 | J3: 45231 | K3: 45261 | L3: 45292 | M3: 45323 | N3: 45352
B4: Income Line 1 | O4: =SUM(C4:N4) -> 0
B5: Income Line 2 | O5: =SUM(C5:N5) -> 0
B6: Income Line 3 | O6: =SUM(C6:N6) -> 0
B7: Income Line 4 | O7: =SUM(C7:N7) -> 0
B8: Income Line 5 | O8: =SUM(C8:N8) -> 0
B9: Income Line 6 | O9: =SUM(C9:N9) -> 0
B10: Income Line 7 | O10: =SUM(C10:N10) -> 0
B11: Income Line 8 | O11: =SUM(C11:N11) -> 0
B12: Income Line 9 | O12: =SUM(C12:N12) -> 0
B13: Income Line 10 | O13: =SUM(C13:N13) -> 0
B14: Income Line 11 | O14: =SUM(C14:N14) -> 0
B15: Income Line 12 | O15: =SUM(C15:N15) -> 0
... B18: Income Line 15 | O18: =SUM(C18:N18) -> 0
B20: Income Total | C20: =SUM(C4:C19) -> 0 | D20: =SUM(D4:D19) -> 0 | E20: =SUM(E4:E19) -> 0 | F20: =SUM(F4:F19) -> 0 | G20: =SUM(G4:G19) -> 0 | H20: =SUM(H4:H19) -> 0 | I20: =SUM(I4:I19) -> 0 | J20: =SUM(J4:J19) -> 0 | ... N20: =SUM(N4:N19) -> 0 | O20: =SUM(C20:N20) -> 0
B22: Month | C22: =C2 -> 25 | D22: =D2 -> 26 | E22: =E2 -> 27 | F22: =F2 -> 28 | G22: =G2 -> 29 | H22: =H2 -> 30 | I22: =I2 -> 31 | J22: =J2 -> 32 | ... N22: =N2 -> 36 | O22: Total
B23: Expenditure | C23: =C3 -> 45017 | D23: =D3 -> 45047 | E23: =E3 -> 45078 | F23: =F3 -> 45108 | G23: =G3 -> 45139 | H23: =H3 -> 45170 | I23: =I3 -> 45200 | J23: =J3 -> 45231 | ... N23: =N3 -> 45352
B24: Expenditure Line 1 | O24: =SUM(C24:N24) -> 0
B25: Expenditure Line 2 | O25: =SUM(C25:N25) -> 0
B26: Expenditure Line 3 | O26: =SUM(C26:N26) -> 0
B27: Expenditure Line 4 | O27: =SUM(C27:N27) -> 0
B28: Expenditure Line 5 | O28: =SUM(C28:N28) -> 0
B29: Expenditure Line 6 | O29: =SUM(C29:N29) -> 0
B30: Expenditure Line 7 | O30: =SUM(C30:N30) -> 0
B31: Expenditure Line 8 | O31: =SUM(C31:N31) -> 0
B32: Expenditure Line 9 | O32: =SUM(C32:N32) -> 0
B33: Expenditure Line 10 | O33: =SUM(C33:N33) -> 0
B34: Expenditure Line 11 | O34: =SUM(C34:N34) -> 0
B35: Expenditure Line 12 | O35: =SUM(C35:N35) -> 0
... B43: Expenditure Line 20 | O43: =SUM(C43:N43) -> 0
B45: Expenditure Total | C45: =SUM(C24:C43) -> 0 | D45: =SUM(D24:D43) -> 0 | E45: =SUM(E24:E43) -> 0 | F45: =SUM(F24:F43) -> 0 | G45: =SUM(G24:G43) -> 0 | H45: =SUM(H24:H43) -> 0 | I45: =SUM(I24:I43) -> 0 | J45: =SUM(J24:J43) -> 0 | ... N45: =SUM(N24:N43) -> 0 | O45: =SUM(C45:N45) -> 0
B47: Retained Earnings/Losses | C47: =C20-C45 -> 0 | D47: =D20-D45 -> 0 | E47: =E20-E45 -> 0 | F47: =F20-F45 -> 0 | G47: =G20-G45 -> 0 | H47: =H20-H45 -> 0 | I47: =I20-I45 -> 0 | J47: =J20-J45 -> 0 | ... N47: =N20-N45 -> 0 | O47: =SUM(C47:N47) -> 0
B48: Cash B/F | C48: ='Year 2'!N49 -> 5 | D48: =C49 -> 5 | E48: =D49 -> 5 | F48: =E49 -> 5 | G48: =F49 -> 5 | H48: =G49 -> 5 | I48: =H49 -> 5 | J48: =I49 -> 5 | K48: =J49 -> 5 | ... N48: =M49 -> 5 | O48: ='Year 2'!N49 -> 5
B49: Cash C/F | C49: =C47+C48 -> 5 | D49: =D47+D48 -> 5 | E49: =E47+E48 -> 5 | F49: =F47+F48 -> 5 | G49: =G47+G48 -> 5 | H49: =H47+H48 -> 5 | I49: =I47+I48 -> 5 | J49: =J47+J48 -> 5 | ... N49: =N47+N48 -> 5 | O49: =N49 -> 5

Sheet Summary
B2: ='Year 1'!B2 -> Month | C2: Year 1 | D2: Year 2 | E2: Year 3 | F2: ='Year 1'!C2 -> 1 | G2: ='Year 1'!D2 -> 2 | H2: ='Year 1'!E2 -> 3 | I2: ='Year 1'!F2 -> 4 | J2: ='Year 1'!G2 -> 5 | K2: ='Year 1'!H2 -> 6 | L2: ='Year 1'!I2 -> 7 | M2: ='Year 1'!J2 -> 8 | ... Q2: ='Year 1'!N2 -> 12 | R2: ='Year 2'!C2 -> 13 | S2: ='Year 2'!D2 -> 14 | T2: ='Year 2'!E2 -> 15 | U2: ='Year 2'!F2 -> 16 | V2: ='Year 2'!G2 -> 17 | W2: ='Year 2'!H2 -> 18 | X2: ='Year 2'!I2 -> 19 | Y2: ='Year 2'!J2 -> 20 | ... AC2: ='Year 2'!N2 -> 24 | AD2: ='Year 3'!C2 -> 25 | AE2: ='Year 3'!D2 -> 26 | AF2: ='Year 3'!E2 -> 27 | AG2: ='Year 3'!F2 -> 28 | AH2: ='Year 3'!G2 -> 29 | AI2: ='Year 3'!H2 -> 30 | AJ2: ='Year 3'!I2 -> 31 | AK2: ='Year 3'!J2 -> 32 | ... AO2: ='Year 3'!N2 -> 36
B3: ='Year 1'!B3 -> Income | F3: ='Year 1'!C3 -> 44287 | G3: ='Year 1'!D3 -> 44317 | H3: ='Year 1'!E3 -> 44348 | I3: ='Year 1'!F3 -> 44378 | J3: ='Year 1'!G3 -> 44409 | K3: ='Year 1'!H3 -> 44440 | L3: ='Year 1'!I3 -> 44470 | M3: ='Year 1'!J3 -> 44501 | ... Q3: ='Year 1'!N3 -> 44621 | R3: ='Year 2'!C3 -> 44652 | S3: ='Year 2'!D3 -> 44682 | T3: ='Year 2'!E3 -> 44713 | U3: ='Year 2'!F3 -> 44743 | V3: ='Year 2'!G3 -> 44774 | W3: ='Year 2'!H3 -> 44805 | X3: ='Year 2'!I3 -> 44835 | Y3: ='Year 2'!J3 -> 44866 | ... AC3: ='Year 2'!N3 -> 44986 | AD3: ='Year 3'!C3 -> 45017 | AE3: ='Year 3'!D3 -> 45047 | AF3: ='Year 3'!E3 -> 45078 | AG3: ='Year 3'!F3 -> 45108 | AH3: ='Year 3'!G3 -> 45139 | AI3: ='Year 3'!H3 -> 45170 | AJ3: ='Year 3'!I3 -> 45200 | AK3: ='Year 3'!J3 -> 45231 | ... AO3: ='Year 3'!N3 -> 45352
B4: ='Year 1'!B4 -> App Sales | C4: ='Year 1'!O4 -> 50 | D4: ='Year 2'!O4 -> 0 | E4: ='Year 3'!O4 -> 0 | F4: ='Year 1'!C4 -> 0 | G4: ='Year 1'!D4 -> 50 | H4: ='Year 1'!E4 -> 0 | I4: ='Year 1'!F4 -> 0 | J4: ='Year 1'!G4 -> 0 | K4: ='Year 1'!H4 -> 0 | L4: ='Year 1'!I4 -> 0 | M4: ='Year 1'!J4 -> 0 | ... Q4: ='Year 1'!N4 -> 0 | R4: ='Year 2'!C4 -> 0 | S4: ='Year 2'!D4 -> 0 | T4: ='Year 2'!E4 -> 0 | U4: ='Year 2'!F4 -> 0 | V4: ='Year 2'!G4 -> 0 | W4: ='Year 2'!H4 -> 0 | X4: ='Year 2'!I4 -> 0 | Y4: ='Year 2'!J4 -> 0 | ... AC4: ='Year 2'!N4 -> 0 | AD4: ='Year 3'!C4 -> 0 | AE4: ='Year 3'!D4 -> 0 | AF4: ='Year 3'!E4 -> 0 | AG4: ='Year 3'!F4 -> 0 | AH4: ='Year 3'!G4 -> 0 | AI4: ='Year 3'!H4 -> 0 | AJ4: ='Year 3'!I4 -> 0 | AK4: ='Year 3'!J4 -> 0 | ... AO4: ='Year 3'!N4 -> 0
B5: ='Year 1'!B5 -> Income Line 2 | C5: ='Year 1'!O5 -> 0 | D5: ='Year 2'!O5 -> 0 | E5: ='Year 3'!O5 -> 0 | F5: ='Year 1'!C5 -> 0 | G5: ='Year 1'!D5 -> 0 | H5: ='Year 1'!E5 -> 0 | I5: ='Year 1'!F5 -> 0 | J5: ='Year 1'!G5 -> 0 | K5: ='Year 1'!H5 -> 0 | L5: ='Year 1'!I5 -> 0 | M5: ='Year 1'!J5 -> 0 | ... Q5: ='Year 1'!N5 -> 0 | R5: ='Year 2'!C5 -> 0 | S5: ='Year 2'!D5 -> 0 | T5: ='Year 2'!E5 -> 0 | U5: ='Year 2'!F5 -> 0 | V5: ='Year 2'!G5 -> 0 | W5: ='Year 2'!H5 -> 0 | X5: ='Year 2'!I5 -> 0 | Y5: ='Year 2'!J5 -> 0 | ... AC5: ='Year 2'!N5 -> 0 | AD5: ='Year 3'!C5 -> 0 | AE5: ='Year 3'!D5 -> 0 | AF5: ='Year 3'!E5 -> 0 | AG5: ='Year 3'!F5 -> 0 | AH5: ='Year 3'!G5 -> 0 | AI5: ='Year 3'!H5 -> 0 | AJ5: ='Year 3'!I5 -> 0 | AK5: ='Year 3'!J5 -> 0 | ... AO5: ='Year 3'!N5 -> 0
B6: ='Year 1'!B6 -> Income Line 3 | C6: ='Year 1'!O6 -> 0 | D6: ='Year 2'!O6 -> 0 | E6: ='Year 3'!O6 -> 0 | F6: ='Year 1'!C6 -> 0 | G6: ='Year 1'!D6 -> 0 | H6: ='Year 1'!E6 -> 0 | I6: ='Year 1'!F6 -> 0 | J6: ='Year 1'!G6 -> 0 | K6: ='Year 1'!H6 -> 0 | L6: ='Year 1'!I6 -> 0 | M6: ='Year 1'!J6 -> 0 | ... Q6: ='Year 1'!N6 -> 0 | R6: ='Year 2'!C6 -> 0 | S6: ='Year 2'!D6 -> 0 | T6: ='Year 2'!E6 -> 0 | U6: ='Year 2'!F6 -> 0 | V6: ='Year 2'!G6 -> 0 | W6: ='Year 2'!H6 -> 0 | X6: ='Year 2'!I6 -> 0 | Y6: ='Year 2'!J6 -> 0 | ... AC6: ='Year 2'!N6 -> 0 | AD6: ='Year 3'!C6 -> 0 | AE6: ='Year 3'!D6 -> 0 | AF6: ='Year 3'!E6 -> 0 | AG6: ='Year 3'!F6 -> 0 | AH6: ='Year 3'!G6 -> 0 | AI6: ='Year 3'!H6 -> 0 | AJ6: ='Year 3'!I6 -> 0 | AK6: ='Year 3'!J6 -> 0 | ... AO6: ='Year 3'!N6 -> 0
B7: ='Year 1'!B7 -> Income Line 4 | C7: ='Year 1'!O7 -> 0 | D7: ='Year 2'!O7 -> 0 | E7: ='Year 3'!O7 -> 0 | F7: ='Year 1'!C7 -> 0 | G7: ='Year 1'!D7 -> 0 | H7: ='Year 1'!E7 -> 0 | I7: ='Year 1'!F7 -> 0 | J7: ='Year 1'!G7 -> 0 | K7: ='Year 1'!H7 -> 0 | L7: ='Year 1'!I7 -> 0 | M7: ='Year 1'!J7 -> 0 | ... Q7: ='Year 1'!N7 -> 0 | R7: ='Year 2'!C7 -> 0 | S7: ='Year 2'!D7 -> 0 | T7: ='Year 2'!E7 -> 0 | U7: ='Year 2'!F7 -> 0 | V7: ='Year 2'!G7 -> 0 | W7: ='Year 2'!H7 -> 0 | X7: ='Year 2'!I7 -> 0 | Y7: ='Year 2'!J7 -> 0 | ... AC7: ='Year 2'!N7 -> 0 | AD7: ='Year 3'!C7 -> 0 | AE7: ='Year 3'!D7 -> 0 | AF7: ='Year 3'!E7 -> 0 | AG7: ='Year 3'!F7 -> 0 | AH7: ='Year 3'!G7 -> 0 | AI7: ='Year 3'!H7 -> 0 | AJ7: ='Year 3'!I7 -> 0 | AK7: ='Year 3'!J7 -> 0 | ... AO7: ='Year 3'!N7 -> 0
B8: ='Year 1'!B8 -> Income Line 5 | C8: ='Year 1'!O8 -> 0 | D8: ='Year 2'!O8 -> 0 | E8: ='Year 3'!O8 -> 0 | F8: ='Year 1'!C8 -> 0 | G8: ='Year 1'!D8 -> 0 | H8: ='Year 1'!E8 -> 0 | I8: ='Year 1'!F8 -> 0 | J8: ='Year 1'!G8 -> 0 | K8: ='Year 1'!H8 -> 0 | L8: ='Year 1'!I8 -> 0 | M8: ='Year 1'!J8 -> 0 | ... Q8: ='Year 1'!N8 -> 0 | R8: ='Year 2'!C8 -> 0 | S8: ='Year 2'!D8 -> 0 | T8: ='Year 2'!E8 -> 0 | U8: ='Year 2'!F8 -> 0 | V8: ='Year 2'!G8 -> 0 | W8: ='Year 2'!H8 -> 0 | X8: ='Year 2'!I8 -> 0 | Y8: ='Year 2'!J8 -> 0 | ... AC8: ='Year 2'!N8 -> 0 | AD8: ='Year 3'!C8 -> 0 | AE8: ='Year 3'!D8 -> 0 | AF8: ='Year 3'!E8 -> 0 | AG8: ='Year 3'!F8 -> 0 | AH8: ='Year 3'!G8 -> 0 | AI8: ='Year 3'!H8 -> 0 | AJ8: ='Year 3'!I8 -> 0 | AK8: ='Year 3'!J8 -> 0 | ... AO8: ='Year 3'!N8 -> 0
B9: ='Year 1'!B9 -> Income Line 6 | C9: ='Year 1'!O9 -> 0 | D9: ='Year 2'!O9 -> 0 | E9: ='Year 3'!O9 -> 0 | F9: ='Year 1'!C9 -> 0 | G9: ='Year 1'!D9 -> 0 | H9: ='Year 1'!E9 -> 0 | I9: ='Year 1'!F9 -> 0 | J9: ='Year 1'!G9 -> 0 | K9: ='Year 1'!H9 -> 0 | L9: ='Year 1'!I9 -> 0 | M9: ='Year 1'!J9 -> 0 | ... Q9: ='Year 1'!N9 -> 0 | R9: ='Year 2'!C9 -> 0 | S9: ='Year 2'!D9 -> 0 | T9: ='Year 2'!E9 -> 0 | U9: ='Year 2'!F9 -> 0 | V9: ='Year 2'!G9 -> 0 | W9: ='Year 2'!H9 -> 0 | X9: ='Year 2'!I9 -> 0 | Y9: ='Year 2'!J9 -> 0 | ... AC9: ='Year 2'!N9 -> 0 | AD9: ='Year 3'!C9 -> 0 | AE9: ='Year 3'!D9 -> 0 | AF9: ='Year 3'!E9 -> 0 | AG9: ='Year 3'!F9 -> 0 | AH9: ='Year 3'!G9 -> 0 | AI9: ='Year 3'!H9 -> 0 | AJ9: ='Year 3'!I9 -> 0 | AK9: ='Year 3'!J9 -> 0 | ... AO9: ='Year 3'!N9 -> 0
B10: ='Year 1'!B10 -> Income Line 7 | C10: ='Year 1'!O10 -> 0 | D10: ='Year 2'!O10 -> 0 | E10: ='Year 3'!O10 -> 0 | F10: ='Year 1'!C10 -> 0 | G10: ='Year 1'!D10 -> 0 | H10: ='Year 1'!E10 -> 0 | I10: ='Year 1'!F10 -> 0 | J10: ='Year 1'!G10 -> 0 | K10: ='Year 1'!H10 -> 0 | L10: ='Year 1'!I10 -> 0 | M10: ='Year 1'!J10 -> 0 | ... Q10: ='Year 1'!N10 -> 0 | R10: ='Year 2'!C10 -> 0 | S10: ='Year 2'!D10 -> 0 | T10: ='Year 2'!E10 -> 0 | U10: ='Year 2'!F10 -> 0 | V10: ='Year 2'!G10 -> 0 | W10: ='Year 2'!H10 -> 0 | X10: ='Year 2'!I10 -> 0 | Y10: ='Year 2'!J10 -> 0 | ... AC10: ='Year 2'!N10 -> 0 | AD10: ='Year 3'!C10 -> 0 | AE10: ='Year 3'!D10 -> 0 | AF10: ='Year 3'!E10 -> 0 | AG10: ='Year 3'!F10 -> 0 | AH10: ='Year 3'!G10 -> 0 | AI10: ='Year 3'!H10 -> 0 | AJ10: ='Year 3'!I10 -> 0 | AK10: ='Year 3'!J10 -> 0 | ... AO10: ='Year 3'!N10 -> 0
B11: ='Year 1'!B11 -> Income Line 8 | C11: ='Year 1'!O11 -> 0 | D11: ='Year 2'!O11 -> 0 | E11: ='Year 3'!O11 -> 0 | F11: ='Year 1'!C11 -> 0 | G11: ='Year 1'!D11 -> 0 | H11: ='Year 1'!E11 -> 0 | I11: ='Year 1'!F11 -> 0 | J11: ='Year 1'!G11 -> 0 | K11: ='Year 1'!H11 -> 0 | L11: ='Year 1'!I11 -> 0 | M11: ='Year 1'!J11 -> 0 | ... Q11: ='Year 1'!N11 -> 0 | R11: ='Year 2'!C11 -> 0 | S11: ='Year 2'!D11 -> 0 | T11: ='Year 2'!E11 -> 0 | U11: ='Year 2'!F11 -> 0 | V11: ='Year 2'!G11 -> 0 | W11: ='Year 2'!H11 -> 0 | X11: ='Year 2'!I11 -> 0 | Y11: ='Year 2'!J11 -> 0 | ... AC11: ='Year 2'!N11 -> 0 | AD11: ='Year 3'!C11 -> 0 | AE11: ='Year 3'!D11 -> 0 | AF11: ='Year 3'!E11 -> 0 | AG11: ='Year 3'!F11 -> 0 | AH11: ='Year 3'!G11 -> 0 | AI11: ='Year 3'!H11 -> 0 | AJ11: ='Year 3'!I11 -> 0 | AK11: ='Year 3'!J11 -> 0 | ... AO11: ='Year 3'!N11 -> 0
B12: ='Year 1'!B12 -> Income Line 9 | C12: ='Year 1'!O12 -> 0 | D12: ='Year 2'!O12 -> 0 | E12: ='Year 3'!O12 -> 0 | F12: ='Year 1'!C12 -> 0 | G12: ='Year 1'!D12 -> 0 | H12: ='Year 1'!E12 -> 0 | I12: ='Year 1'!F12 -> 0 | J12: ='Year 1'!G12 -> 0 | K12: ='Year 1'!H12 -> 0 | L12: ='Year 1'!I12 -> 0 | M12: ='Year 1'!J12 -> 0 | ... Q12: ='Year 1'!N12 -> 0 | R12: ='Year 2'!C12 -> 0 | S12: ='Year 2'!D12 -> 0 | T12: ='Year 2'!E12 -> 0 | U12: ='Year 2'!F12 -> 0 | V12: ='Year 2'!G12 -> 0 | W12: ='Year 2'!H12 -> 0 | X12: ='Year 2'!I12 -> 0 | Y12: ='Year 2'!J12 -> 0 | ... AC12: ='Year 2'!N12 -> 0 | AD12: ='Year 3'!C12 -> 0 | AE12: ='Year 3'!D12 -> 0 | AF12: ='Year 3'!E12 -> 0 | AG12: ='Year 3'!F12 -> 0 | AH12: ='Year 3'!G12 -> 0 | AI12: ='Year 3'!H12 -> 0 | AJ12: ='Year 3'!I12 -> 0 | AK12: ='Year 3'!J12 -> 0 | ... AO12: ='Year 3'!N12 -> 0
B13: ='Year 1'!B13 -> Income Line 10 | C13: ='Year 1'!O13 -> 0 | D13: ='Year 2'!O13 -> 0 | E13: ='Year 3'!O13 -> 0 | F13: ='Year 1'!C13 -> 0 | G13: ='Year 1'!D13 -> 0 | H13: ='Year 1'!E13 -> 0 | I13: ='Year 1'!F13 -> 0 | J13: ='Year 1'!G13 -> 0 | K13: ='Year 1'!H13 -> 0 | L13: ='Year 1'!I13 -> 0 | M13: ='Year 1'!J13 -> 0 | ... Q13: ='Year 1'!N13 -> 0 | R13: ='Year 2'!C13 -> 0 | S13: ='Year 2'!D13 -> 0 | T13: ='Year 2'!E13 -> 0 | U13: ='Year 2'!F13 -> 0 | V13: ='Year 2'!G13 -> 0 | W13: ='Year 2'!H13 -> 0 | X13: ='Year 2'!I13 -> 0 | Y13: ='Year 2'!J13 -> 0 | ... AC13: ='Year 2'!N13 -> 0 | AD13: ='Year 3'!C13 -> 0 | AE13: ='Year 3'!D13 -> 0 | AF13: ='Year 3'!E13 -> 0 | AG13: ='Year 3'!F13 -> 0 | AH13: ='Year 3'!G13 -> 0 | AI13: ='Year 3'!H13 -> 0 | AJ13: ='Year 3'!I13 -> 0 | AK13: ='Year 3'!J13 -> 0 | ... AO13: ='Year 3'!N13 -> 0
B14: ='Year 1'!B14 -> Income Line 11 | C14: ='Year 1'!O14 -> 0 | D14: ='Year 2'!O14 -> 0 | E14: ='Year 3'!O14 -> 0 | F14: ='Year 1'!C14 -> 0 | G14: ='Year 1'!D14 -> 0 | H14: ='Year 1'!E14 -> 0 | I14: ='Year 1'!F14 -> 0 | J14: ='Year 1'!G14 -> 0 | K14: ='Year 1'!H14 -> 0 | L14: ='Year 1'!I14 -> 0 | M14: ='Year 1'!J14 -> 0 | ... Q14: ='Year 1'!N14 -> 0 | R14: ='Year 2'!C14 -> 0 | S14: ='Year 2'!D14 -> 0 | T14: ='Year 2'!E14 -> 0 | U14: ='Year 2'!F14 -> 0 | V14: ='Year 2'!G14 -> 0 | W14: ='Year 2'!H14 -> 0 | X14: ='Year 2'!I14 -> 0 | Y14: ='Year 2'!J14 -> 0 | ... AC14: ='Year 2'!N14 -> 0 | AD14: ='Year 3'!C14 -> 0 | AE14: ='Year 3'!D14 -> 0 | AF14: ='Year 3'!E14 -> 0 | AG14: ='Year 3'!F14 -> 0 | AH14: ='Year 3'!G14 -> 0 | AI14: ='Year 3'!H14 -> 0 | AJ14: ='Year 3'!I14 -> 0 | AK14: ='Year 3'!J14 -> 0 | ... AO14: ='Year 3'!N14 -> 0
B15: ='Year 1'!B15 -> Income Line 12 | C15: ='Year 1'!O15 -> 0 | D15: ='Year 2'!O15 -> 0 | E15: ='Year 3'!O15 -> 0 | F15: ='Year 1'!C15 -> 0 | G15: ='Year 1'!D15 -> 0 | H15: ='Year 1'!E15 -> 0 | I15: ='Year 1'!F15 -> 0 | J15: ='Year 1'!G15 -> 0 | K15: ='Year 1'!H15 -> 0 | L15: ='Year 1'!I15 -> 0 | M15: ='Year 1'!J15 -> 0 | ... Q15: ='Year 1'!N15 -> 0 | R15: ='Year 2'!C15 -> 0 | S15: ='Year 2'!D15 -> 0 | T15: ='Year 2'!E15 -> 0 | U15: ='Year 2'!F15 -> 0 | V15: ='Year 2'!G15 -> 0 | W15: ='Year 2'!H15 -> 0 | X15: ='Year 2'!I15 -> 0 | Y15: ='Year 2'!J15 -> 0 | ... AC15: ='Year 2'!N15 -> 0 | AD15: ='Year 3'!C15 -> 0 | AE15: ='Year 3'!D15 -> 0 | AF15: ='Year 3'!E15 -> 0 | AG15: ='Year 3'!F15 -> 0 | AH15: ='Year 3'!G15 -> 0 | AI15: ='Year 3'!H15 -> 0 | AJ15: ='Year 3'!I15 -> 0 | AK15: ='Year 3'!J15 -> 0 | ... AO15: ='Year 3'!N15 -> 0
... B20: ='Year 1'!B20 -> Income Total | C20: ='Year 1'!O20 -> 50 | D20: ='Year 2'!O20 -> 0 | E20: ='Year 3'!O20 -> 0 | F20: ='Year 1'!C20 -> 0 | G20: ='Year 1'!D20 -> 50 | H20: ='Year 1'!E20 -> 0 | I20: ='Year 1'!F20 -> 0 | J20: ='Year 1'!G20 -> 0 | K20: ='Year 1'!H20 -> 0 | L20: ='Year 1'!I20 -> 0 | M20: ='Year 1'!J20 -> 0 | ... Q20: ='Year 1'!N20 -> 0 | R20: ='Year 2'!C20 -> 0 | S20: ='Year 2'!D20 -> 0 | T20: ='Year 2'!E20 -> 0 | U20: ='Year 2'!F20 -> 0 | V20: ='Year 2'!G20 -> 0 | W20: ='Year 2'!H20 -> 0 | X20: ='Year 2'!I20 -> 0 | Y20: ='Year 2'!J20 -> 0 | ... AC20: ='Year 2'!N20 -> 0 | AD20: ='Year 3'!C20 -> 0 | AE20: ='Year 3'!D20 -> 0 | AF20: ='Year 3'!E20 -> 0 | AG20: ='Year 3'!F20 -> 0 | AH20: ='Year 3'!G20 -> 0 | AI20: ='Year 3'!H20 -> 0 | AJ20: ='Year 3'!I20 -> 0 | AK20: ='Year 3'!J20 -> 0 | ... AO20: ='Year 3'!N20 -> 0
B22: ='Year 1'!B23 -> Expenditure
B23: ='Year 1'!B24 -> Marketing | C23: ='Year 1'!O24 -> 45 | D23: ='Year 2'!O24 -> 0 | E23: ='Year 3'!O24 -> 0 | F23: ='Year 1'!C24 -> 0 | G23: ='Year 1'!D24 -> 45 | H23: ='Year 1'!E24 -> 0 | I23: ='Year 1'!F24 -> 0 | J23: ='Year 1'!G24 -> 0 | K23: ='Year 1'!H24 -> 0 | L23: ='Year 1'!I24 -> 0 | M23: ='Year 1'!J24 -> 0 | ... Q23: ='Year 1'!N24 -> 0 | R23: ='Year 2'!C24 -> 0 | S23: ='Year 2'!D24 -> 0 | T23: ='Year 2'!E24 -> 0 | U23: ='Year 2'!F24 -> 0 | V23: ='Year 2'!G24 -> 0 | W23: ='Year 2'!H24 -> 0 | X23: ='Year 2'!I24 -> 0 | Y23: ='Year 2'!J24 -> 0 | ... AC23: ='Year 2'!N24 -> 0 | AD23: ='Year 3'!C24 -> 0 | AE23: ='Year 3'!D24 -> 0 | AF23: ='Year 3'!E24 -> 0 | AG23: ='Year 3'!F24 -> 0 | AH23: ='Year 3'!G24 -> 0 | AI23: ='Year 3'!H24 -> 0 | AJ23: ='Year 3'!I24 -> 0 | AK23: ='Year 3'!J24 -> 0 | ... AO23: ='Year 3'!N24 -> 0
B24: ='Year 1'!B25 -> Expenditure Line 2 | C24: ='Year 1'!O25 -> 0 | D24: ='Year 2'!O25 -> 0 | E24: ='Year 3'!O25 -> 0 | F24: ='Year 1'!C25 -> 0 | G24: ='Year 1'!D25 -> 0 | H24: ='Year 1'!E25 -> 0 | I24: ='Year 1'!F25 -> 0 | J24: ='Year 1'!G25 -> 0 | K24: ='Year 1'!H25 -> 0 | L24: ='Year 1'!I25 -> 0 | M24: ='Year 1'!J25 -> 0 | ... Q24: ='Year 1'!N25 -> 0 | R24: ='Year 2'!C25 -> 0 | S24: ='Year 2'!D25 -> 0 | T24: ='Year 2'!E25 -> 0 | U24: ='Year 2'!F25 -> 0 | V24: ='Year 2'!G25 -> 0 | W24: ='Year 2'!H25 -> 0 | X24: ='Year 2'!I25 -> 0 | Y24: ='Year 2'!J25 -> 0 | ... AC24: ='Year 2'!N25 -> 0 | AD24: ='Year 3'!C25 -> 0 | AE24: ='Year 3'!D25 -> 0 | AF24: ='Year 3'!E25 -> 0 | AG24: ='Year 3'!F25 -> 0 | AH24: ='Year 3'!G25 -> 0 | AI24: ='Year 3'!H25 -> 0 | AJ24: ='Year 3'!I25 -> 0 | AK24: ='Year 3'!J25 -> 0 | ... AO24: ='Year 3'!N25 -> 0
B25: ='Year 1'!B26 -> Expenditure Line 3 | C25: ='Year 1'!O26 -> 0 | D25: ='Year 2'!O26 -> 0 | E25: ='Year 3'!O26 -> 0 | F25: ='Year 1'!C26 -> 0 | G25: ='Year 1'!D26 -> 0 | H25: ='Year 1'!E26 -> 0 | I25: ='Year 1'!F26 -> 0 | J25: ='Year 1'!G26 -> 0 | K25: ='Year 1'!H26 -> 0 | L25: ='Year 1'!I26 -> 0 | M25: ='Year 1'!J26 -> 0 | ... Q25: ='Year 1'!N26 -> 0 | R25: ='Year 2'!C26 -> 0 | S25: ='Year 2'!D26 -> 0 | T25: ='Year 2'!E26 -> 0 | U25: ='Year 2'!F26 -> 0 | V25: ='Year 2'!G26 -> 0 | W25: ='Year 2'!H26 -> 0 | X25: ='Year 2'!I26 -> 0 | Y25: ='Year 2'!J26 -> 0 | ... AC25: ='Year 2'!N26 -> 0 | AD25: ='Year 3'!C26 -> 0 | AE25: ='Year 3'!D26 -> 0 | AF25: ='Year 3'!E26 -> 0 | AG25: ='Year 3'!F26 -> 0 | AH25: ='Year 3'!G26 -> 0 | AI25: ='Year 3'!H26 -> 0 | AJ25: ='Year 3'!I26 -> 0 | AK25: ='Year 3'!J26 -> 0 | ... AO25: ='Year 3'!N26 -> 0
B26: ='Year 1'!B27 -> Expenditure Line 4 | C26: ='Year 1'!O27 -> 0 | D26: ='Year 2'!O27 -> 0 | E26: ='Year 3'!O27 -> 0 | F26: ='Year 1'!C27 -> 0 | G26: ='Year 1'!D27 -> 0 | H26: ='Year 1'!E27 -> 0 | I26: ='Year 1'!F27 -> 0 | J26: ='Year 1'!G27 -> 0 | K26: ='Year 1'!H27 -> 0 | L26: ='Year 1'!I27 -> 0 | M26: ='Year 1'!J27 -> 0 | ... Q26: ='Year 1'!N27 -> 0 | R26: ='Year 2'!C27 -> 0 | S26: ='Year 2'!D27 -> 0 | T26: ='Year 2'!E27 -> 0 | U26: ='Year 2'!F27 -> 0 | V26: ='Year 2'!G27 -> 0 | W26: ='Year 2'!H27 -> 0 | X26: ='Year 2'!I27 -> 0 | Y26: ='Year 2'!J27 -> 0 | ... AC26: ='Year 2'!N27 -> 0 | AD26: ='Year 3'!C27 -> 0 | AE26: ='Year 3'!D27 -> 0 | AF26: ='Year 3'!E27 -> 0 | AG26: ='Year 3'!F27 -> 0 | AH26: ='Year 3'!G27 -> 0 | AI26: ='Year 3'!H27 -> 0 | AJ26: ='Year 3'!I27 -> 0 | AK26: ='Year 3'!J27 -> 0 | ... AO26: ='Year 3'!N27 -> 0
B27: ='Year 1'!B28 -> Expenditure Line 5 | C27: ='Year 1'!O28 -> 0 | D27: ='Year 2'!O28 -> 0 | E27: ='Year 3'!O28 -> 0 | F27: ='Year 1'!C28 -> 0 | G27: ='Year 1'!D28 -> 0 | H27: ='Year 1'!E28 -> 0 | I27: ='Year 1'!F28 -> 0 | J27: ='Year 1'!G28 -> 0 | K27: ='Year 1'!H28 -> 0 | L27: ='Year 1'!I28 -> 0 | M27: ='Year 1'!J28 -> 0 | ... Q27: ='Year 1'!N28 -> 0 | R27: ='Year 2'!C28 -> 0 | S27: ='Year 2'!D28 -> 0 | T27: ='Year 2'!E28 -> 0 | U27: ='Year 2'!F28 -> 0 | V27: ='Year 2'!G28 -> 0 | W27: ='Year 2'!H28 -> 0 | X27: ='Year 2'!I28 -> 0 | Y27: ='Year 2'!J28 -> 0 | ... AC27: ='Year 2'!N28 -> 0 | AD27: ='Year 3'!C28 -> 0 | AE27: ='Year 3'!D28 -> 0 | AF27: ='Year 3'!E28 -> 0 | AG27: ='Year 3'!F28 -> 0 | AH27: ='Year 3'!G28 -> 0 | AI27: ='Year 3'!H28 -> 0 | AJ27: ='Year 3'!I28 -> 0 | AK27: ='Year 3'!J28 -> 0 | ... AO27: ='Year 3'!N28 -> 0
B28: ='Year 1'!B29 -> Expenditure Line 6 | C28: ='Year 1'!O29 -> 0 | D28: ='Year 2'!O29 -> 0 | E28: ='Year 3'!O29 -> 0 | F28: ='Year 1'!C29 -> 0 | G28: ='Year 1'!D29 -> 0 | H28: ='Year 1'!E29 -> 0 | I28: ='Year 1'!F29 -> 0 | J28: ='Year 1'!G29 -> 0 | K28: ='Year 1'!H29 -> 0 | L28: ='Year 1'!I29 -> 0 | M28: ='Year 1'!J29 -> 0 | ... Q28: ='Year 1'!N29 -> 0 | R28: ='Year 2'!C29 -> 0 | S28: ='Year 2'!D29 -> 0 | T28: ='Year 2'!E29 -> 0 | U28: ='Year 2'!F29 -> 0 | V28: ='Year 2'!G29 -> 0 | W28: ='Year 2'!H29 -> 0 | X28: ='Year 2'!I29 -> 0 | Y28: ='Year 2'!J29 -> 0 | ... AC28: ='Year 2'!N29 -> 0 | AD28: ='Year 3'!C29 -> 0 | AE28: ='Year 3'!D29 -> 0 | AF28: ='Year 3'!E29 -> 0 | AG28: ='Year 3'!F29 -> 0 | AH28: ='Year 3'!G29 -> 0 | AI28: ='Year 3'!H29 -> 0 | AJ28: ='Year 3'!I29 -> 0 | AK28: ='Year 3'!J29 -> 0 | ... AO28: ='Year 3'!N29 -> 0
B29: ='Year 1'!B30 -> Expenditure Line 7 | C29: ='Year 1'!O30 -> 0 | D29: ='Year 2'!O30 -> 0 | E29: ='Year 3'!O30 -> 0 | F29: ='Year 1'!C30 -> 0 | G29: ='Year 1'!D30 -> 0 | H29: ='Year 1'!E30 -> 0 | I29: ='Year 1'!F30 -> 0 | J29: ='Year 1'!G30 -> 0 | K29: ='Year 1'!H30 -> 0 | L29: ='Year 1'!I30 -> 0 | M29: ='Year 1'!J30 -> 0 | ... Q29: ='Year 1'!N30 -> 0 | R29: ='Year 2'!C30 -> 0 | S29: ='Year 2'!D30 -> 0 | T29: ='Year 2'!E30 -> 0 | U29: ='Year 2'!F30 -> 0 | V29: ='Year 2'!G30 -> 0 | W29: ='Year 2'!H30 -> 0 | X29: ='Year 2'!I30 -> 0 | Y29: ='Year 2'!J30 -> 0 | ... AC29: ='Year 2'!N30 -> 0 | AD29: ='Year 3'!C30 -> 0 | AE29: ='Year 3'!D30 -> 0 | AF29: ='Year 3'!E30 -> 0 | AG29: ='Year 3'!F30 -> 0 | AH29: ='Year 3'!G30 -> 0 | AI29: ='Year 3'!H30 -> 0 | AJ29: ='Year 3'!I30 -> 0 | AK29: ='Year 3'!J30 -> 0 | ... AO29: ='Year 3'!N30 -> 0
B30: ='Year 1'!B31 -> Expenditure Line 8 | C30: ='Year 1'!O31 -> 0 | D30: ='Year 2'!O31 -> 0 | E30: ='Year 3'!O31 -> 0 | F30: ='Year 1'!C31 -> 0 | G30: ='Year 1'!D31 -> 0 | H30: ='Year 1'!E31 -> 0 | I30: ='Year 1'!F31 -> 0 | J30: ='Year 1'!G31 -> 0 | K30: ='Year 1'!H31 -> 0 | L30: ='Year 1'!I31 -> 0 | M30: ='Year 1'!J31 -> 0 | ... Q30: ='Year 1'!N31 -> 0 | R30: ='Year 2'!C31 -> 0 | S30: ='Year 2'!D31 -> 0 | T30: ='Year 2'!E31 -> 0 | U30: ='Year 2'!F31 -> 0 | V30: ='Year 2'!G31 -> 0 | W30: ='Year 2'!H31 -> 0 | X30: ='Year 2'!I31 -> 0 | Y30: ='Year 2'!J31 -> 0 | ... AC30: ='Year 2'!N31 -> 0 | AD30: ='Year 3'!C31 -> 0 | AE30: ='Year 3'!D31 -> 0 | AF30: ='Year 3'!E31 -> 0 | AG30: ='Year 3'!F31 -> 0 | AH30: ='Year 3'!G31 -> 0 | AI30: ='Year 3'!H31 -> 0 | AJ30: ='Year 3'!I31 -> 0 | AK30: ='Year 3'!J31 -> 0 | ... AO30: ='Year 3'!N31 -> 0
B31: ='Year 1'!B32 -> Expenditure Line 9 | C31: ='Year 1'!O32 -> 0 | D31: ='Year 2'!O32 -> 0 | E31: ='Year 3'!O32 -> 0 | F31: ='Year 1'!C32 -> 0 | G31: ='Year 1'!D32 -> 0 | H31: ='Year 1'!E32 -> 0 | I31: ='Year 1'!F32 -> 0 | J31: ='Year 1'!G32 -> 0 | K31: ='Year 1'!H32 -> 0 | L31: ='Year 1'!I32 -> 0 | M31: ='Year 1'!J32 -> 0 | ... Q31: ='Year 1'!N32 -> 0 | R31: ='Year 2'!C32 -> 0 | S31: ='Year 2'!D32 -> 0 | T31: ='Year 2'!E32 -> 0 | U31: ='Year 2'!F32 -> 0 | V31: ='Year 2'!G32 -> 0 | W31: ='Year 2'!H32 -> 0 | X31: ='Year 2'!I32 -> 0 | Y31: ='Year 2'!J32 -> 0 | ... AC31: ='Year 2'!N32 -> 0 | AD31: ='Year 3'!C32 -> 0 | AE31: ='Year 3'!D32 -> 0 | AF31: ='Year 3'!E32 -> 0 | AG31: ='Year 3'!F32 -> 0 | AH31: ='Year 3'!G32 -> 0 | AI31: ='Year 3'!H32 -> 0 | AJ31: ='Year 3'!I32 -> 0 | AK31: ='Year 3'!J32 -> 0 | ... AO31: ='Year 3'!N32 -> 0
B32: ='Year 1'!B33 -> Expenditure Line 10 | C32: ='Year 1'!O33 -> 0 | D32: ='Year 2'!O33 -> 0 | E32: ='Year 3'!O33 -> 0 | F32: ='Year 1'!C33 -> 0 | G32: ='Year 1'!D33 -> 0 | H32: ='Year 1'!E33 -> 0 | I32: ='Year 1'!F33 -> 0 | J32: ='Year 1'!G33 -> 0 | K32: ='Year 1'!H33 -> 0 | L32: ='Year 1'!I33 -> 0 | M32: ='Year 1'!J33 -> 0 | ... Q32: ='Year 1'!N33 -> 0 | R32: ='Year 2'!C33 -> 0 | S32: ='Year 2'!D33 -> 0 | T32: ='Year 2'!E33 -> 0 | U32: ='Year 2'!F33 -> 0 | V32: ='Year 2'!G33 -> 0 | W32: ='Year 2'!H33 -> 0 | X32: ='Year 2'!I33 -> 0 | Y32: ='Year 2'!J33 -> 0 | ... AC32: ='Year 2'!N33 -> 0 | AD32: ='Year 3'!C33 -> 0 | AE32: ='Year 3'!D33 -> 0 | AF32: ='Year 3'!E33 -> 0 | AG32: ='Year 3'!F33 -> 0 | AH32: ='Year 3'!G33 -> 0 | AI32: ='Year 3'!H33 -> 0 | AJ32: ='Year 3'!I33 -> 0 | AK32: ='Year 3'!J33 -> 0 | ... AO32: ='Year 3'!N33 -> 0
B33: ='Year 1'!B34 -> Expenditure Line 11 | C33: ='Year 1'!O34 -> 0 | D33: ='Year 2'!O34 -> 0 | E33: ='Year 3'!O34 -> 0 | F33: ='Year 1'!C34 -> 0 | G33: ='Year 1'!D34 -> 0 | H33: ='Year 1'!E34 -> 0 | I33: ='Year 1'!F34 -> 0 | J33: ='Year 1'!G34 -> 0 | K33: ='Year 1'!H34 -> 0 | L33: ='Year 1'!I34 -> 0 | M33: ='Year 1'!J34 -> 0 | ... Q33: ='Year 1'!N34 -> 0 | R33: ='Year 2'!C34 -> 0 | S33: ='Year 2'!D34 -> 0 | T33: ='Year 2'!E34 -> 0 | U33: ='Year 2'!F34 -> 0 | V33: ='Year 2'!G34 -> 0 | W33: ='Year 2'!H34 -> 0 | X33: ='Year 2'!I34 -> 0 | Y33: ='Year 2'!J34 -> 0 | ... AC33: ='Year 2'!N34 -> 0 | AD33: ='Year 3'!C34 -> 0 | AE33: ='Year 3'!D34 -> 0 | AF33: ='Year 3'!E34 -> 0 | AG33: ='Year 3'!F34 -> 0 | AH33: ='Year 3'!G34 -> 0 | AI33: ='Year 3'!H34 -> 0 | AJ33: ='Year 3'!I34 -> 0 | AK33: ='Year 3'!J34 -> 0 | ... AO33: ='Year 3'!N34 -> 0
B34: ='Year 1'!B35 -> Expenditure Line 12 | C34: ='Year 1'!O35 -> 0 | D34: ='Year 2'!O35 -> 0 | E34: ='Year 3'!O35 -> 0 | F34: ='Year 1'!C35 -> 0 | G34: ='Year 1'!D35 -> 0 | H34: ='Year 1'!E35 -> 0 | I34: ='Year 1'!F35 -> 0 | J34: ='Year 1'!G35 -> 0 | K34: ='Year 1'!H35 -> 0 | L34: ='Year 1'!I35 -> 0 | M34: ='Year 1'!J35 -> 0 | ... Q34: ='Year 1'!N35 -> 0 | R34: ='Year 2'!C35 -> 0 | S34: ='Year 2'!D35 -> 0 | T34: ='Year 2'!E35 -> 0 | U34: ='Year 2'!F35 -> 0 | V34: ='Year 2'!G35 -> 0 | W34: ='Year 2'!H35 -> 0 | X34: ='Year 2'!I35 -> 0 | Y34: ='Year 2'!J35 -> 0 | ... AC34: ='Year 2'!N35 -> 0 | AD34: ='Year 3'!C35 -> 0 | AE34: ='Year 3'!D35 -> 0 | AF34: ='Year 3'!E35 -> 0 | AG34: ='Year 3'!F35 -> 0 | AH34: ='Year 3'!G35 -> 0 | AI34: ='Year 3'!H35 -> 0 | AJ34: ='Year 3'!I35 -> 0 | AK34: ='Year 3'!J35 -> 0 | ... AO34: ='Year 3'!N35 -> 0
... B44: ='Year 1'!B45 -> Expenditure Total | C44: ='Year 1'!O45 -> 45 | D44: ='Year 2'!O45 -> 0 | E44: ='Year 3'!O45 -> 0 | F44: ='Year 1'!C45 -> 0 | G44: ='Year 1'!D45 -> 45 | H44: ='Year 1'!E45 -> 0 | I44: ='Year 1'!F45 -> 0 | J44: ='Year 1'!G45 -> 0 | K44: ='Year 1'!H45 -> 0 | L44: ='Year 1'!I45 -> 0 | M44: ='Year 1'!J45 -> 0 | ... Q44: ='Year 1'!N45 -> 0 | R44: ='Year 2'!C45 -> 0 | S44: ='Year 2'!D45 -> 0 | T44: ='Year 2'!E45 -> 0 | U44: ='Year 2'!F45 -> 0 | V44: ='Year 2'!G45 -> 0 | W44: ='Year 2'!H45 -> 0 | X44: ='Year 2'!I45 -> 0 | Y44: ='Year 2'!J45 -> 0 | ... AC44: ='Year 2'!N45 -> 0 | AD44: ='Year 3'!C45 -> 0 | AE44: ='Year 3'!D45 -> 0 | AF44: ='Year 3'!E45 -> 0 | AG44: ='Year 3'!F45 -> 0 | AH44: ='Year 3'!G45 -> 0 | AI44: ='Year 3'!H45 -> 0 | AJ44: ='Year 3'!I45 -> 0 | AK44: ='Year 3'!J45 -> 0 | ... AO44: ='Year 3'!N45 -> 0
B46: ='Year 1'!B47 -> Retained Earnings/Losses | C46: =C20-C44 -> 5 | D46: =D20-D44 -> 0 | E46: =E20-E44 -> 0 | F46: ='Year 1'!C47 -> 0 | G46: ='Year 1'!D47 -> 5 | H46: ='Year 1'!E47 -> 0 | I46: ='Year 1'!F47 -> 0 | J46: ='Year 1'!G47 -> 0 | K46: ='Year 1'!H47 -> 0 | L46: ='Year 1'!I47 -> 0 | M46: ='Year 1'!J47 -> 0 | ... Q46: ='Year 1'!N47 -> 0 | R46: ='Year 2'!C47 -> 0 | S46: ='Year 2'!D47 -> 0 | T46: ='Year 2'!E47 -> 0 | U46: ='Year 2'!F47 -> 0 | V46: ='Year 2'!G47 -> 0 | W46: ='Year 2'!H47 -> 0 | X46: ='Year 2'!I47 -> 0 | Y46: ='Year 2'!J47 -> 0 | ... AC46: ='Year 2'!N47 -> 0 | AD46: ='Year 3'!C47 -> 0 | AE46: ='Year 3'!D47 -> 0 | AF46: ='Year 3'!E47 -> 0 | AG46: ='Year 3'!F47 -> 0 | AH46: ='Year 3'!G47 -> 0 | AI46: ='Year 3'!H47 -> 0 | AJ46: ='Year 3'!I47 -> 0 | AK46: ='Year 3'!J47 -> 0 | ... AO46: ='Year 3'!N47 -> 0
B47: ='Year 1'!B48 -> Cash B/F | C47: =F47 -> 0 | D47: =C48 -> 5 | E47: =D48 -> 5 | F47: ='Year 1'!C48 -> 0 | G47: ='Year 1'!D48 -> 0 | H47: ='Year 1'!E48 -> 5 | I47: ='Year 1'!F48 -> 5 | J47: ='Year 1'!G48 -> 5 | K47: ='Year 1'!H48 -> 5 | L47: ='Year 1'!I48 -> 5 | M47: ='Year 1'!J48 -> 5 | ... Q47: ='Year 1'!N48 -> 5 | R47: ='Year 2'!C48 -> 5 | S47: ='Year 2'!D48 -> 5 | T47: ='Year 2'!E48 -> 5 | U47: ='Year 2'!F48 -> 5 | V47: ='Year 2'!G48 -> 5 | W47: ='Year 2'!H48 -> 5 | X47: ='Year 2'!I48 -> 5 | Y47: ='Year 2'!J48 -> 5 | ... AC47: ='Year 2'!N48 -> 5 | AD47: ='Year 3'!C48 -> 5 | AE47: ='Year 3'!D48 -> 5 | AF47: ='Year 3'!E48 -> 5 | AG47: ='Year 3'!F48 -> 5 | AH47: ='Year 3'!G48 -> 5 | AI47: ='Year 3'!H48 -> 5 | AJ47: ='Year 3'!I48 -> 5 | AK47: ='Year 3'!J48 -> 5 | ... AO47: ='Year 3'!N48 -> 5
B48: ='Year 1'!B49 -> Cash C/F | C48: =Q48 -> 5 | D48: =AC48 -> 5 | E48: =AO48 -> 5 | F48: ='Year 1'!C49 -> 0 | G48: ='Year 1'!D49 -> 5 | H48: ='Year 1'!E49 -> 5 | I48: ='Year 1'!F49 -> 5 | J48: ='Year 1'!G49 -> 5 | K48: ='Year 1'!H49 -> 5 | L48: ='Year 1'!I49 -> 5 | M48: ='Year 1'!J49 -> 5 | ... Q48: ='Year 1'!N49 -> 5 | R48: ='Year 2'!C49 -> 5 | S48: ='Year 2'!D49 -> 5 | T48: ='Year 2'!E49 -> 5 | U48: ='Year 2'!F49 -> 5 | V48: ='Year 2'!G49 -> 5 | W48: ='Year 2'!H49 -> 5 | X48: ='Year 2'!I49 -> 5 | Y48: ='Year 2'!J49 -> 5 | ... AC48: ='Year 2'!N49 -> 5 | AD48: ='Year 3'!C49 -> 5 | AE48: ='Year 3'!D49 -> 5 | AF48: ='Year 3'!E49 -> 5 | AG48: ='Year 3'!F49 -> 5 | AH48: ='Year 3'!G49 -> 5 | AI48: ='Year 3'!H49 -> 5 | AJ48: ='Year 3'!I49 -> 5 | AK48: ='Year 3'!J49 -> 5 | ... AO48: ='Year 3'!N49 -> 5

Sheet Year 1 UNIT PRICING
B2: Unit Price | C2: £
B3: Job Placement | C3: 3000
B4: Graduate Placement | C4: 3000
B5: Workshops | C5: 1000
B6: Consultancy | C6: 500
B7: Internship Placements | C7: 2000
B8: Courses | C8: 10000
B9: Income Line 7 | C9: 0
B10: Income Line 8 | C10: 0
B11: Income Line 9
B12: Income Line 10
B13: Income Line 11
B14: Income Line 12
B15: Income Line 13
B16: Income Line 14
B17: Income Line 15
B20: Month | C20: 1 | D20: 2 | E20: 3 | F20: 4 | G20: 5 | H20: 6 | I20: 7 | J20: 8 | K20: 9 | L20: 10 | M20: 11 | N20: 12 | O20: Total
B21: Unit Sales | C21: 44287 | D21: 44317 | E21: 44348 | F21: 44378 | G21: 44409 | H21: 44440 | I21: 44470 | J21: 44501 | K21: 44531 | L21: 44562 | M21: 44593 | N21: 44621
B22: =B3 -> Job Placement | C22: 4 | D22: 5 | E22: 5 | F22: 10 | G22: 10 | H22: 20 | I22: 20 | J22: 20 | K22: 60 | L22: 60 | M22: 60 | N22: 60 | O22: =SUM(C22:N22) -> 334
B23: =B4 -> Graduate Placement | C23: 4 | D23: 5 | E23: 5 | F23: 10 | G23: 12 | H23: 40 | I23: 40 | J23: 40 | K23: 40 | L23: 40 | M23: 40 | N23: 40 | O23: =SUM(C23:N23) -> 316
B24: =B5 -> Workshops | D24: 2 | E24: 6 | F24: 10 | G24: 14 | H24: 14 | I24: 14 | J24: 14 | K24: 14 | L24: 14 | M24: 14 | N24: 14 | O24: =SUM(C24:N24) -> 130
B25: Grants | O25: =SUM(C25:N25) -> 0
B26: =B7 -> Internship Placements | C26: 1 | E26: 1 | G26: 1 | I26: 1 | K26: 2 | M26: 2 | O26: =SUM(C26:N26) -> 8
B27: =B8 -> Courses | O27: =SUM(C27:N27) -> 0
B28: =B9 -> Income Line 7 | O28: =SUM(C28:N28) -> 0
B29: =B10 -> Income Line 8 | O29: =SUM(C29:N29) -> 0
B30: =B11 -> Income Line 9 | O30: =SUM(C30:N30) -> 0
B31: =B12 -> Income Line 10 | O31: =SUM(C31:N31) -> 0
B32: =B13 -> Income Line 11 | O32: =SUM(C32:N32) -> 0
B33: =B14 -> Income Line 12 | O33: =SUM(C33:N33) -> 0
B34: =B15 -> Income Line 13 | O34: =SUM(C34:N34) -> 0
B35: =B16 -> Income Line 14 | O35: =SUM(C35:N35) -> 0
B36: =B17 -> Income Line 15 | O36: =SUM(C36:N36) -> 0
B38: Income Total | C38: =SUM(C22:C37) -> 9 | D38: =SUM(D22:D37) -> 12 | E38: =SUM(E22:E37) -> 17 | F38: =SUM(F22:F37) -> 30 | G38: =SUM(G22:G37) -> 37 | H38: =SUM(H22:H37) -> 74 | I38: =SUM(I22:I37) -> 75 | J38: =SUM(J22:J37) -> 74 | ... N38: =SUM(N22:N37) -> 114 | O38: =SUM(C38:N38) -> 788
B41: Month | C41: 1 | D41: 2 | E41: 3 | F41: 4 | G41: 5 | H41: 6 | I41: 7 | J41: 8 | K41: 9 | L41: 10 | M41: 11 | N41: 12 | O41: Total
B42: Income | C42: 44287 | D42: 44317 | E42: 44348 | F42: 44378 | G42: 44409 | H42: 44440 | I42: 44470 | J42: 44501 | K42: 44531 | L42: 44562 | M42: 44593 | N42: 44621
B43: =B22 -> Job Placement | C43: =C22*$C$3 -> 12000 | D43: =D22*$C$3 -> 15000 | E43: =E22*$C$3 -> 15000 | F43: =F22*$C$3 -> 30000 | G43: =G22*$C$3 -> 30000 | H43: =H22*$C$3 -> 60000 | I43: =I22*$C$3 -> 60000 | J43: =J22*$C$3 -> 60000 | ... N43: =N22*$C$3 -> 180000 | O43: =SUM(C43:N43) -> 1002000
B44: =B23 -> Graduate Placement | C44: =C23*$C$4 -> 12000 | D44: =D23*$C$4 -> 15000 | E44: =E23*$C$4 -> 15000 | F44: =F23*$C$4 -> 30000 | G44: =G23*$C$4 -> 36000 | H44: =H23*$C$4 -> 120000 | I44: =I23*$C$4 -> 120000 | J44: =J23*$C$4 -> 120000 | ... N44: =N23*$C$4 -> 120000 | O44: =SUM(C44:N44) -> 948000
B45: =B24 -> Workshops | C45: =C24*$C$5 -> 0 | D45: =D24*$C5 -> 2000 | E45: =E24*$C$5 -> 6000 | F45: =F24*$C$5 -> 10000 | G45: =G24*$C$5 -> 14000 | H45: =H24*$C$5 -> 14000 | I45: =I24*$C$5 -> 14000 | J45: =J24*$C$5 -> 14000 | K45: =K24*$C$5 -> 14000 | L45: =L24*$C$5 -> 14000 | ... N45: =N24*$C$5 -> 14000 | O45: =SUM(C45:N45) -> 130000
B46: Grants | D46: =D25*$C6 -> 0 | E46: =E25*$C6 -> 0 | F46: =F25*$C6 -> 0 | G46: =G25*$C6 -> 0 | H46: =H25*$C6 -> 0 | I46: =I25*$C6 -> 0 | J46: =J25*$C6 -> 0 | K46: 2500 | O46: =SUM(C46:N46) -> 2500
...

Sheet Year 2 UNIT PRICING
B2: Unit Price | C2: £
B3: Customer | C3: 5500
B4: NHS | C4: 1000
B5: Physio | C5: 2000
B6: Income Line 4
B7: Income Line 5
B8: Income Line 6
B9: Income Line 7
B10: Income Line 8
B11: Income Line 9
B12: Income Line 10
B13: Income Line 11
B14: Income Line 12
B15: Income Line 13
B16: Income Line 14
B17: Income Line 15
B20: Month | C20: 1 | D20: 2 | E20: 3 | F20: 4 | G20: 5 | H20: 6 | I20: 7 | J20: 8 | K20: 9 | L20: 10 | M20: 11 | N20: 12 | O20: Total
B21: Unit Sales | C21: 44652 | D21: 44682 | E21: 44713 | F21: 44743 | G21: 44774 | H21: 44805 | I21: 44835 | J21: 44866 | K21: 44896 | L21: 44927 | M21: 44958 | N21: 44986
B22: =B3 -> Customer | C22: 4 | D22: 5 | E22: 5 | F22: 10 | G22: 10 | H22: 20 | I22: 20 | J22: 20 | K22: 60 | L22: 60 | M22: 60 | N22: 60 | O22: =SUM(C22:N22) -> 334
B23: =B4 -> NHS | C23: 4 | D23: 5 | E23: 5 | F23: 10 | G23: 12 | H23: 40 | I23: 40 | J23: 40 | K23: 40 | L23: 40 | M23: 40 | N23: 40 | O23: =SUM(C23:N23) -> 316
B24: =B5 -> Physio | D24: 2 | E24: 6 | F24: 10 | G24: 14 | H24: 14 | I24: 14 | J24: 14 | K24: 14 | L24: 14 | M24: 14 | N24: 14 | O24: =SUM(C24:N24) -> 130
B25: Grants | O25: =SUM(C25:N25) -> 0
B26: =B7 -> Income Line 5 | O26: =SUM(C26:N26) -> 0
B27: =B8 -> Income Line 6 | O27: =SUM(C27:N27) -> 0
B28: =B9 -> Income Line 7 | O28: =SUM(C28:N28) -> 0
B29: =B10 -> Income Line 8 | O29: =SUM(C29:N29) -> 0
B30: =B11 -> Income Line 9 | O30: =SUM(C30:N30) -> 0
B31: =B12 -> Income Line 10 | O31: =SUM(C31:N31) -> 0
B32: =B13 -> Income Line 11 | O32: =SUM(C32:N32) -> 0
B33: =B14 -> Income Line 12 | O33: =SUM(C33:N33) -> 0
B34: =B15 -> Income Line 13 | O34: =SUM(C34:N34) -> 0
B35: =B16 -> Income Line 14 | O35: =SUM(C35:N35) -> 0
B36: =B17 -> Income Line 15 | O36: =SUM(C36:N36) -> 0
B38: Income Total | C38: =SUM(C22:C37) -> 8 | D38: =SUM(D22:D37) -> 12 | E38: =SUM(E22:E37) -> 16 | F38: =SUM(F22:F37) -> 30 | G38: =SUM(G22:G37) -> 36 | H38: =SUM(H22:H37) -> 74 | I38: =SUM(I22:I37) -> 74 | J38: =SUM(J22:J37) -> 74 | ... N38: =SUM(N22:N37) -> 114 | O38: =SUM(C38:N38) -> 780
B41: Month | C41: 1 | D41: 2 | E41: 3 | F41: 4 | G41: 5 | H41: 6 | I41: 7 | J41: 8 | K41: 9 | L41: 10 | M41: 11 | N41: 12 | O41: Total
B42: Income | C42: =C21 -> 44652 | D42: =D21 -> 44682 | E42: =E21 -> 44713 | F42: =F21 -> 44743 | G42: =G21 -> 44774 | H42: =H21 -> 44805 | I42: =I21 -> 44835 | J42: =J21 -> 44866 | ... N42: =N21 -> 44986
B43: Cake sales to businesses | C43: =C22*$C$3 -> 22000 | D43: =D22*$C$3 -> 27500 | E43: =E22*$C$3 -> 27500 | F43: =F22*$C$3 -> 55000 | G43: =G22*$C$3 -> 55000 | H43: =H22*$C$3 -> 110000 | I43: =I22*$C$3 -> 110000 | J43: =J22*$C$3 -> 110000 | ... N43: =N22*$C$3 -> 330000 | O43: =SUM(C43:N43) -> 1837000
B44: Cake sales to customers | C44: =C23*$C$4 -> 4000 | D44: =D23*$C$4 -> 5000 | E44: =E23*$C$4 -> 5000 | F44: =F23*$C$4 -> 10000 | G44: =G23*$C$4 -> 12000 | H44: =H23*$C$4 -> 40000 | I44: =I23*$C$4 -> 40000 | J44: =J23*$C$4 -> 40000 | ... N44: =N23*$C$4 -> 40000 | O44: =SUM(C44:N44) -> 316000
B45: Bespoke Catering orders | C45: =C24*$C$5 -> 0 | D45: =D24*$C$5 -> 4000 | E45: =E24*$C$5 -> 12000 | F45: =F24*$C$5 -> 20000 | G45: =G24*$C$5 -> 28000 | H45: =H24*$C$5 -> 28000 | I45: =I24*$C$5 -> 28000 | J45: =J24*$C$5 -> 28000 | ... N45: =N24*$C$5 -> 28000 | O45: =SUM(C45:N45) -> 260000
B46: Grants | H46: 2500 | K46: 2500 | O46: =SUM(C46:N46) -> 5000
...

Sheet Year 3 UNIT PRICING
B2: Unit Price | C2: £
B3: Customer | C3: 5000
B4: NHS | C4: 1000
B5: Physio | C5: 2000
B6: Income Line 4
B7: Income Line 5
B8: Income Line 6
B9: Income Line 7
B10: Income Line 8
B11: Income Line 9
B12: Income Line 10
B13: Income Line 11
B14: Income Line 12
B15: Income Line 13
B16: Income Line 14
B17: Income Line 15
B20: Month | C20: 1 | D20: 2 | E20: 3 | F20: 4 | G20: 5 | H20: 6 | I20: 7 | J20: 8 | K20: 9 | L20: 10 | M20: 11 | N20: 12 | O20: Total
B21: Unit Sales | C21: 45017 | D21: 45047 | E21: 45078 | F21: 45108 | G21: 45139 | H21: 45170 | I21: 45200 | J21: 45231 | K21: 45261 | L21: 45292 | M21: 45323 | N21: 45352
B22: =B3 -> Customer | C22: 4 | D22: 5 | E22: 5 | F22: 10 | G22: 10 | H22: 20 | I22: 20 | J22: 20 | K22: 60 | L22: 60 | M22: 60 | N22: 60 | O22: =SUM(C22:N22) -> 334
B23: =B4 -> NHS | C23: 4 | D23: 5 | E23: 5 | F23: 10 | G23: 12 | H23: 40 | I23: 40 | J23: 40 | K23: 40 | L23: 40 | M23: 40 | N23: 40 | O23: =SUM(C23:N23) -> 316
B24: =B5 -> Physio | D24: 2 | E24: 6 | F24: 10 | G24: 14 | H24: 14 | I24: 14 | J24: 14 | K24: 14 | L24: 14 | M24: 14 | N24: 14 | O24: =SUM(C24:N24) -> 130
B25: Grants | O25: =SUM(C25:N25) -> 0
B26: =B7 -> Income Line 5 | O26: =SUM(C26:N26) -> 0
B27: =B8 -> Income Line 6 | O27: =SUM(C27:N27) -> 0
B28: =B9 -> Income Line 7 | O28: =SUM(C28:N28) -> 0
B29: =B10 -> Income Line 8 | O29: =SUM(C29:N29) -> 0
B30: =B11 -> Income Line 9 | O30: =SUM(C30:N30) -> 0
B31: =B12 -> Income Line 10 | O31: =SUM(C31:N31) -> 0
B32: =B13 -> Income Line 11 | O32: =SUM(C32:N32) -> 0
B33: =B14 -> Income Line 12 | O33: =SUM(C33:N33) -> 0
B34: =B15 -> Income Line 13 | O34: =SUM(C34:N34) -> 0
B35: =B16 -> Income Line 14 | O35: =SUM(C35:N35) -> 0
B36: =B17 -> Income Line 15 | O36: =SUM(C36:N36) -> 0
B38: Income Total | C38: =SUM(C22:C37) -> 8 | D38: =SUM(D22:D37) -> 12 | E38: =SUM(E22:E37) -> 16 | F38: =SUM(F22:F37) -> 30 | G38: =SUM(G22:G37) -> 36 | H38: =SUM(H22:H37) -> 74 | I38: =SUM(I22:I37) -> 74 | J38: =SUM(J22:J37) -> 74 | ... N38: =SUM(N22:N37) -> 114 | O38: =SUM(C38:N38) -> 780
B41: Month | C41: 1 | D41: 2 | E41: 3 | F41: 4 | G41: 5 | H41: 6 | I41: 7 | J41: 8 | K41: 9 | L41: 10 | M41: 11 | N41: 12 | O41: Total
B42: Income | C42: =C21 -> 45017 | D42: =D21 -> 45047 | E42: =E21 -> 45078 | F42: =F21 -> 45108 | G42: =G21 -> 45139 | H42: =H21 -> 45170 | I42: =I21 -> 45200 | J42: =J21 -> 45231 | ... N42: =N21 -> 45352
B43: Cake sales to businesses | C43: =C22*$C$3 -> 20000 | D43: =D22*$C$3 -> 25000 | E43: =E22*$C$3 -> 25000 | F43: =F22*$C$3 -> 50000 | G43: =G22*$C$3 -> 50000 | H43: =H22*$C$3 -> 100000 | I43: =I22*$C$3 -> 100000 | J43: =J22*$C$3 -> 100000 | ... N43: =N22*$C$3 -> 300000 | O43: =SUM(C43:N43) -> 1670000
B44: Cake sales to customers | C44: =C23*$C$4 -> 4000 | D44: =D23*$C$4 -> 5000 | E44: =E23*$C$4 -> 5000 | F44: =F23*$C$4 -> 10000 | G44: =G23*$C$4 -> 12000 | H44: =H23*$C$4 -> 40000 | I44: =I23*$C$4 -> 40000 | J44: =J23*$C$4 -> 40000 | ... N44: =N23*$C$4 -> 40000 | O44: =SUM(C44:N44) -> 316000
B45: Bespoke Catering orders | C45: =C24*$C$5 -> 0 | D45: =D24*$C$5 -> 4000 | E45: =E24*$C$5 -> 12000 | F45: =F24*$C$5 -> 20000 | G45: =G24*$C$5 -> 28000 | H45: =H24*$C$5 -> 28000 | I45: =I24*$C$5 -> 28000 | J45: =J24*$C$5 -> 28000 | ... N45: =N24*$C$5 -> 28000 | O45: =SUM(C45:N45) -> 260000
B46: Grants | H46: 2500 | K46: 2500 | O46: =SUM(C46:N46) -> 5000
...

Sheet Summary UNIT PRICING
B2: ='Year 1'!B2 -> Month | C2: Year 1 | D2: Year 2 | E2: Year 3 | F2: ='Year 1'!C2 -> 1 | G2: ='Year 1'!D2 -> 2 | H2: ='Year 1'!E2 -> 3 | I2: ='Year 1'!F2 -> 4 | J2: ='Year 1'!G2 -> 5 | K2: ='Year 1'!H2 -> 6 | L2: ='Year 1'!I2 -> 7 | M2: ='Year 1'!J2 -> 8 | ... Q2: ='Year 1'!N2 -> 12 | R2: ='Year 2'!C2 -> 13 | S2: ='Year 2'!D2 -> 14 | T2: ='Year 2'!E2 -> 15 | U2: ='Year 2'!F2 -> 16 | V2: ='Year 2'!G2 -> 17 | W2: ='Year 2'!H2 -> 18 | X2: ='Year 2'!I2 -> 19 | Y2: ='Year 2'!J2 -> 20 | ... AC2: ='Year 2'!N2 -> 24 | AD2: ='Year 3'!C2 -> 25 | AE2: ='Year 3'!D2 -> 26 | AF2: ='Year 3'!E2 -> 27 | AG2: ='Year 3'!F2 -> 28 | AH2: ='Year 3'!G2 -> 29 | AI2: ='Year 3'!H2 -> 30 | AJ2: ='Year 3'!I2 -> 31 | AK2: ='Year 3'!J2 -> 32 | ... AO2: ='Year 3'!N2 -> 36
B3: ='Year 1'!B3 -> Income | F3: ='Year 1'!C3 -> 44287 | G3: ='Year 1'!D3 -> 44317 | H3: ='Year 1'!E3 -> 44348 | I3: ='Year 1'!F3 -> 44378 | J3: ='Year 1'!G3 -> 44409 | K3: ='Year 1'!H3 -> 44440 | L3: ='Year 1'!I3 -> 44470 | M3: ='Year 1'!J3 -> 44501 | ... Q3: ='Year 1'!N3 -> 44621 | R3: ='Year 2'!C3 -> 44652 | S3: ='Year 2'!D3 -> 44682 | T3: ='Year 2'!E3 -> 44713 | U3: ='Year 2'!F3 -> 44743 | V3: ='Year 2'!G3 -> 44774 | W3: ='Year 2'!H3 -> 44805 | X3: ='Year 2'!I3 -> 44835 | Y3: ='Year 2'!J3 -> 44866 | ... AC3: ='Year 2'!N3 -> 44986 | AD3: ='Year 3'!C3 -> 45017 | AE3: ='Year 3'!D3 -> 45047 | AF3: ='Year 3'!E3 -> 45078 | AG3: ='Year 3'!F3 -> 45108 | AH3: ='Year 3'!G3 -> 45139 | AI3: ='Year 3'!H3 -> 45170 | AJ3: ='Year 3'!I3 -> 45200 | AK3: ='Year 3'!J3 -> 45231 | ... AO3: ='Year 3'!N3 -> 45352
B4: ='Year 1'!B4 -> App Sales | C4: ='Year 1 UNIT PRICING'!O43 -> 1002000 | D4: ='Year 2 UNIT PRICING'!O43 -> 1837000 | E4: ='Year 3 UNIT PRICING'!O43 -> 1670000 | F4: ='Year 1 UNIT PRICING'!C43 -> 12000 | G4: ='Year 1 UNIT PRICING'!D43 -> 15000 | H4: ='Year 1 UNIT PRICING'!E43 -> 15000 | I4: ='Year 1 UNIT PRICING'!F43 -> 30000 | J4: ='Year 1 UNIT PRICING'!G43 -> 30000 | K4: ='Year 1 UNIT PRICING'!H43 -> 60000 | L4: ='Year 1 UNIT PRICING'!I43 -> 60000 | M4: ='Year 1 UNIT PRICING'!J43 -> 60000 | ... Q4: ='Year 1 UNIT PRICING'!N43 -> 180000 | R4: ='Year 2 UNIT PRICING'!C43 -> 22000 | S4: ='Year 2 UNIT PRICING'!D43 -> 27500 | T4: ='Year 2 UNIT PRICING'!E43 -> 27500 | U4: ='Year 2 UNIT PRICING'!F43 -> 55000 | V4: ='Year 2 UNIT PRICING'!G43 -> 55000 | W4: ='Year 2 UNIT PRICING'!H43 -> 110000 | X4: ='Year 2 UNIT PRICING'!I43 -> 110000 | Y4: ='Year 2 UNIT PRICING'!J43 -> 110000 | ... AC4: ='Year 2 UNIT PRICING'!N43 -> 330000 | AD4: ='Year 3 UNIT PRICING'!C43 -> 20000 | AE4: ='Year 3 UNIT PRICING'!D43 -> 25000 | AF4: ='Year 3 UNIT PRICING'!E43 -> 25000 | AG4: ='Year 3 UNIT PRICING'!F43 -> 50000 | AH4: ='Year 3 UNIT PRICING'!G43 -> 50000 | AI4: ='Year 3 UNIT PRICING'!H43 -> 100000 | AJ4: ='Year 3 UNIT PRICING'!I43 -> 100000 | AK4: ='Year 3 UNIT PRICING'!J43 -> 100000 | ... AO4: ='Year 3 UNIT PRICING'!N43 -> 300000
B5: ='Year 1'!B5 -> Income Line 2 | C5: ='Year 1 UNIT PRICING'!O44 -> 948000 | D5: ='Year 2 UNIT PRICING'!O44 -> 316000 | E5: ='Year 3 UNIT PRICING'!O44 -> 316000 | F5: ='Year 1 UNIT PRICING'!C44 -> 12000 | G5: ='Year 1 UNIT PRICING'!D44 -> 15000 | H5: ='Year 1 UNIT PRICING'!E44 -> 15000 | I5: ='Year 1 UNIT PRICING'!F44 -> 30000 | J5: ='Year 1 UNIT PRICING'!G44 -> 36000 | K5: ='Year 1 UNIT PRICING'!H44 -> 120000 | L5: ='Year 1 UNIT PRICING'!I44 -> 120000 | M5: ='Year 1 UNIT PRICING'!J44 -> 120000 | ... Q5: ='Year 1 UNIT PRICING'!N44 -> 120000 | R5: ='Year 2 UNIT PRICING'!C44 -> 4000 | S5: ='Year 2 UNIT PRICING'!D44 -> 5000 | T5: ='Year 2 UNIT PRICING'!E44 -> 5000 | U5: ='Year 2 UNIT PRICING'!F44 -> 10000 | V5: ='Year 2 UNIT PRICING'!G44 -> 12000 | W5: ='Year 2 UNIT PRICING'!H44 -> 40000 | X5: ='Year 2 UNIT PRICING'!I44 -> 40000 | Y5: ='Year 2 UNIT PRICING'!J44 -> 40000 | ... AC5: ='Year 2 UNIT PRICING'!N44 -> 40000 | AD5: ='Year 3 UNIT PRICING'!C44 -> 4000 | AE5: ='Year 3 UNIT PRICING'!D44 -> 5000 | AF5: ='Year 3 UNIT PRICING'!E44 -> 5000 | AG5: ='Year 3 UNIT PRICING'!F44 -> 10000 | AH5: ='Year 3 UNIT PRICING'!G44 -> 12000 | AI5: ='Year 3 UNIT PRICING'!H44 -> 40000 | AJ5: ='Year 3 UNIT PRICING'!I44 -> 40000 | AK5: ='Year 3 UNIT PRICING'!J44 -> 40000 | ... AO5: ='Year 3 UNIT PRICING'!N44 -> 40000
B6: ='Year 1'!B6 -> Income Line 3 | C6: ='Year 1 UNIT PRICING'!O45 -> 130000 | D6: ='Year 2 UNIT PRICING'!O45 -> 260000 | E6: ='Year 3 UNIT PRICING'!O45 -> 260000 | F6: ='Year 1 UNIT PRICING'!C45 -> 0 | G6: ='Year 1 UNIT PRICING'!D45 -> 2000 | H6: ='Year 1 UNIT PRICING'!E45 -> 6000 | I6: ='Year 1 UNIT PRICING'!F45 -> 10000 | J6: ='Year 1 UNIT PRICING'!G45 -> 14000 | K6: ='Year 1 UNIT PRICING'!H45 -> 14000 | L6: ='Year 1 UNIT PRICING'!I45 -> 14000 | M6: ='Year 1 UNIT PRICING'!J45 -> 14000 | ... Q6: ='Year 1 UNIT PRICING'!N45 -> 14000 | R6: ='Year 2 UNIT PRICING'!C45 -> 0 | S6: ='Year 2 UNIT PRICING'!D45 -> 4000 | T6: ='Year 2 UNIT PRICING'!E45 -> 12000 | U6: ='Year 2 UNIT PRICING'!F45 -> 20000 | V6: ='Year 2 UNIT PRICING'!G45 -> 28000 | W6: ='Year 2 UNIT PRICING'!H45 -> 28000 | X6: ='Year 2 UNIT PRICING'!I45 -> 28000 | Y6: ='Year 2 UNIT PRICING'!J45 -> 28000 | ... AC6: ='Year 2 UNIT PRICING'!N45 -> 28000 | AD6: ='Year 3 UNIT PRICING'!C45 -> 0 | AE6: ='Year 3 UNIT PRICING'!D45 -> 4000 | AF6: ='Year 3 UNIT PRICING'!E45 -> 12000 | AG6: ='Year 3 UNIT PRICING'!F45 -> 20000 | AH6: ='Year 3 UNIT PRICING'!G45 -> 28000 | AI6: ='Year 3 UNIT PRICING'!H45 -> 28000 | AJ6: ='Year 3 UNIT PRICING'!I45 -> 28000 | AK6: ='Year 3 UNIT PRICING'!J45 -> 28000 | ... AO6: ='Year 3 UNIT PRICING'!N45 -> 28000
B7: ='Year 1'!B7 -> Income Line 4 | C7: ='Year 1 UNIT PRICING'!O46 -> 2500 | D7: ='Year 2 UNIT PRICING'!O46 -> 5000 | E7: ='Year 3 UNIT PRICING'!O46 -> 5000 | F7: ='Year 1 UNIT PRICING'!C46 -> 0 | G7: ='Year 1 UNIT PRICING'!D46 -> 0 | H7: ='Year 1 UNIT PRICING'!E46 -> 0 | I7: ='Year 1 UNIT PRICING'!F46 -> 0 | J7: ='Year 1 UNIT PRICING'!G46 -> 0 | K7: ='Year 1 UNIT PRICING'!H46 -> 0 | L7: ='Year 1 UNIT PRICING'!I46 -> 0 | M7: ='Year 1 UNIT PRICING'!J46 -> 0 | ... Q7: ='Year 1 UNIT PRICING'!N46 -> 0 | R7: ='Year 2 UNIT PRICING'!C46 -> 0 | S7: ='Year 2 UNIT PRICING'!D46 -> 0 | T7: ='Year 2 UNIT PRICING'!E46 -> 0 | U7: ='Year 2 UNIT PRICING'!F46 -> 0 | V7: ='Year 2 UNIT PRICING'!G46 -> 0 | W7: ='Year 2 UNIT PRICING'!H46 -> 2500 | X7: ='Year 2 UNIT PRICING'!I46 -> 0 | Y7: ='Year 2 UNIT PRICING'!J46 -> 0 | ... AC7: ='Year 2 UNIT PRICING'!N46 -> 0 | AD7: ='Year 3 UNIT PRICING'!C46 -> 0 | AE7: ='Year 3 UNIT PRICING'!D46 -> 0 | AF7: ='Year 3 UNIT PRICING'!E46 -> 0 | AG7: ='Year 3 UNIT PRICING'!F46 -> 0 | AH7: ='Year 3 UNIT PRICING'!G46 -> 0 | AI7: ='Year 3 UNIT PRICING'!H46 -> 2500 | AJ7: ='Year 3 UNIT PRICING'!I46 -> 0 | AK7: ='Year 3 UNIT PRICING'!J46 -> 0 | ... AO7: ='Year 3 UNIT PRICING'!N46 -> 0
B8: ='Year 1'!B8 -> Income Line 5 | C8: ='Year 1 UNIT PRICING'!O47 -> 6000 | D8: ='Year 2 UNIT PRICING'!O47 -> 0 | E8: ='Year 3 UNIT PRICING'!O47 -> 0 | F8: ='Year 1 UNIT PRICING'!C47 -> 0 | G8: ='Year 1 UNIT PRICING'!D47 -> 0 | H8: ='Year 1 UNIT PRICING'!E47 -> 2000 | I8: ='Year 1 UNIT PRICING'!F47 -> 0 | J8: ='Year 1 UNIT PRICING'!G47 -> 2000 | K8: ='Year 1 UNIT PRICING'!H47 -> 0 | L8: ='Year 1 UNIT PRICING'!I47 -> 2000 | M8: ='Year 1 UNIT PRICING'!J47 -> 0 | ... Q8: ='Year 1 UNIT PRICING'!N47 -> 0 | R8: ='Year 2 UNIT PRICING'!C47 -> 0 | S8: ='Year 2 UNIT PRICING'!D47 -> 0 | T8: ='Year 2 UNIT PRICING'!E47 -> 0 | U8: ='Year 2 UNIT PRICING'!F47 -> 0 | V8: ='Year 2 UNIT PRICING'!G47 -> 0 | W8: ='Year 2 UNIT PRICING'!H47 -> 0 | X8: ='Year 2 UNIT PRICING'!I47 -> 0 | Y8: ='Year 2 UNIT PRICING'!J47 -> 0 | ... AC8: ='Year 2 UNIT PRICING'!N47 -> 0 | AD8: ='Year 3 UNIT PRICING'!C47 -> 0 | AE8: ='Year 3 UNIT PRICING'!D47 -> 0 | AF8: ='Year 3 UNIT PRICING'!E47 -> 0 | AG8: ='Year 3 UNIT PRICING'!F47 -> 0 | AH8: ='Year 3 UNIT PRICING'!G47 -> 0 | AI8: ='Year 3 UNIT PRICING'!H47 -> 0 | AJ8: ='Year 3 UNIT PRICING'!I47 -> 0 | AK8: ='Year 3 UNIT PRICING'!J47 -> 0 | ... AO8: ='Year 3 UNIT PRICING'!N47 -> 0
B9: ='Year 1'!B9 -> Income Line 6 | C9: ='Year 1 UNIT PRICING'!O48 -> 0 | D9: ='Year 2 UNIT PRICING'!O48 -> 0 | E9: ='Year 3 UNIT PRICING'!O48 -> 0 | F9: ='Year 1 UNIT PRICING'!C48 -> 0 | G9: ='Year 1 UNIT PRICING'!D48 -> 0 | H9: ='Year 1 UNIT PRICING'!E48 -> 0 | I9: ='Year 1 UNIT PRICING'!F48 -> 0 | J9: ='Year 1 UNIT PRICING'!G48 -> 0 | K9: ='Year 1 UNIT PRICING'!H48 -> 0 | L9: ='Year 1 UNIT PRICING'!I48 -> 0 | M9: ='Year 1 UNIT PRICING'!J48 -> 0 | ... Q9: ='Year 1 UNIT PRICING'!N48 -> 0 | R9: ='Year 2 UNIT PRICING'!C48 -> 0 | S9: ='Year 2 UNIT PRICING'!D48 -> 0 | T9: ='Year 2 UNIT PRICING'!E48 -> 0 | U9: ='Year 2 UNIT PRICING'!F48 -> 0 | V9: ='Year 2 UNIT PRICING'!G48 -> 0 | W9: ='Year 2 UNIT PRICING'!H48 -> 0 | X9: ='Year 2 UNIT PRICING'!I48 -> 0 | Y9: ='Year 2 UNIT PRICING'!J48 -> 0 | ... AC9: ='Year 2 UNIT PRICING'!N48 -> 0 | AD9: ='Year 3 UNIT PRICING'!C48 -> 0 | AE9: ='Year 3 UNIT PRICING'!D48 -> 0 | AF9: ='Year 3 UNIT PRICING'!E48 -> 0 | AG9: ='Year 3 UNIT PRICING'!F48 -> 0 | AH9: ='Year 3 UNIT PRICING'!G48 -> 0 | AI9: ='Year 3 UNIT PRICING'!H48 -> 0 | AJ9: ='Year 3 UNIT PRICING'!I48 -> 0 | AK9: ='Year 3 UNIT PRICING'!J48 -> 0 | ... AO9: ='Year 3 UNIT PRICING'!N48 -> 0
B10: ='Year 1'!B10 -> Income Line 7 | C10: ='Year 1 UNIT PRICING'!O49 -> 0 | D10: ='Year 2 UNIT PRICING'!O49 -> 0 | E10: ='Year 3 UNIT PRICING'!O49 -> 0 | F10: ='Year 1 UNIT PRICING'!C49 -> 0 | G10: ='Year 1 UNIT PRICING'!D49 -> 0 | H10: ='Year 1 UNIT PRICING'!E49 -> 0 | I10: ='Year 1 UNIT PRICING'!F49 -> 0 | J10: ='Year 1 UNIT PRICING'!G49 -> 0 | K10: ='Year 1 UNIT PRICING'!H49 -> 0 | L10: ='Year 1 UNIT PRICING'!I49 -> 0 | M10: ='Year 1 UNIT PRICING'!J49 -> 0 | ... Q10: ='Year 1 UNIT PRICING'!N49 -> 0 | R10: ='Year 2 UNIT PRICING'!C49 -> 0 | S10: ='Year 2 UNIT PRICING'!D49 -> 0 | T10: ='Year 2 UNIT PRICING'!E49 -> 0 | U10: ='Year 2 UNIT PRICING'!F49 -> 0 | V10: ='Year 2 UNIT PRICING'!G49 -> 0 | W10: ='Year 2 UNIT PRICING'!H49 -> 0 | X10: ='Year 2 UNIT PRICING'!I49 -> 0 | Y10: ='Year 2 UNIT PRICING'!J49 -> 0 | ... AC10: ='Year 2 UNIT PRICING'!N49 -> 0 | AD10: ='Year 3 UNIT PRICING'!C49 -> 0 | AE10: ='Year 3 UNIT PRICING'!D49 -> 0 | AF10: ='Year 3 UNIT PRICING'!E49 -> 0 | AG10: ='Year 3 UNIT PRICING'!F49 -> 0 | AH10: ='Year 3 UNIT PRICING'!G49 -> 0 | AI10: ='Year 3 UNIT PRICING'!H49 -> 0 | AJ10: ='Year 3 UNIT PRICING'!I49 -> 0 | AK10: ='Year 3 UNIT PRICING'!J49 -> 0 | ... AO10: ='Year 3 UNIT PRICING'!N49 -> 0
B11: ='Year 1'!B11 -> Income Line 8 | C11: ='Year 1 UNIT PRICING'!O50 -> 0 | D11: ='Year 2 UNIT PRICING'!O50 -> 0 | E11: ='Year 3 UNIT PRICING'!O50 -> 0 | F11: ='Year 1 UNIT PRICING'!C50 -> 0 | G11: ='Year 1 UNIT PRICING'!D50 -> 0 | H11: ='Year 1 UNIT PRICING'!E50 -> 0 | I11: ='Year 1 UNIT PRICING'!F50 -> 0 | J11: ='Year 1 UNIT PRICING'!G50 -> 0 | K11: ='Year 1 UNIT PRICING'!H50 -> 0 | L11: ='Year 1 UNIT PRICING'!I50 -> 0 | M11: ='Year 1 UNIT PRICING'!J50 -> 0 | ... Q11: ='Year 1 UNIT PRICING'!N50 -> 0 | R11: ='Year 2 UNIT PRICING'!C50 -> 0 | S11: ='Year 2 UNIT PRICING'!D50 -> 0 | T11: ='Year 2 UNIT PRICING'!E50 -> 0 | U11: ='Year 2 UNIT PRICING'!F50 -> 0 | V11: ='Year 2 UNIT PRICING'!G50 -> 0 | W11: ='Year 2 UNIT PRICING'!H50 -> 0 | X11: ='Year 2 UNIT PRICING'!I50 -> 0 | Y11: ='Year 2 UNIT PRICING'!J50 -> 0 | ... AC11: ='Year 2 UNIT PRICING'!N50 -> 0 | AD11: ='Year 3 UNIT PRICING'!C50 -> 0 | AE11: ='Year 3 UNIT PRICING'!D50 -> 0 | AF11: ='Year 3 UNIT PRICING'!E50 -> 0 | AG11: ='Year 3 UNIT PRICING'!F50 -> 0 | AH11: ='Year 3 UNIT PRICING'!G50 -> 0 | AI11: ='Year 3 UNIT PRICING'!H50 -> 0 | AJ11: ='Year 3 UNIT PRICING'!I50 -> 0 | AK11: ='Year 3 UNIT PRICING'!J50 -> 0 | ... AO11: ='Year 3 UNIT PRICING'!N50 -> 0
B12: ='Year 1'!B12 -> Income Line 9 | C12: ='Year 1 UNIT PRICING'!O51 -> 0 | D12: ='Year 2 UNIT PRICING'!O51 -> 0 | E12: ='Year 3 UNIT PRICING'!O51 -> 0 | F12: ='Year 1 UNIT PRICING'!C51 -> 0 | G12: ='Year 1 UNIT PRICING'!D51 -> 0 | H12: ='Year 1 UNIT PRICING'!E51 -> 0 | I12: ='Year 1 UNIT PRICING'!F51 -> 0 | J12: ='Year 1 UNIT PRICING'!G51 -> 0 | K12: ='Year 1 UNIT PRICING'!H51 -> 0 | L12: ='Year 1 UNIT PRICING'!I51 -> 0 | M12: ='Year 1 UNIT PRICING'!J51 -> 0 | ... Q12: ='Year 1 UNIT PRICING'!N51 -> 0 | R12: ='Year 2 UNIT PRICING'!C51 -> 0 | S12: ='Year 2 UNIT PRICING'!D51 -> 0 | T12: ='Year 2 UNIT PRICING'!E51 -> 0 | U12: ='Year 2 UNIT PRICING'!F51 -> 0 | V12: ='Year 2 UNIT PRICING'!G51 -> 0 | W12: ='Year 2 UNIT PRICING'!H51 -> 0 | X12: ='Year 2 UNIT PRICING'!I51 -> 0 | Y12: ='Year 2 UNIT PRICING'!J51 -> 0 | ... AC12: ='Year 2 UNIT PRICING'!N51 -> 0 | AD12: ='Year 3 UNIT PRICING'!C51 -> 0 | AE12: ='Year 3 UNIT PRICING'!D51 -> 0 | AF12: ='Year 3 UNIT PRICING'!E51 -> 0 | AG12: ='Year 3 UNIT PRICING'!F51 -> 0 | AH12: ='Year 3 UNIT PRICING'!G51 -> 0 | AI12: ='Year 3 UNIT PRICING'!H51 -> 0 | AJ12: ='Year 3 UNIT PRICING'!I51 -> 0 | AK12: ='Year 3 UNIT PRICING'!J51 -> 0 | ... AO12: ='Year 3 UNIT PRICING'!N51 -> 0
B13: ='Year 1'!B13 -> Income Line 10 | C13: ='Year 1 UNIT PRICING'!O52 -> 0 | D13: ='Year 2 UNIT PRICING'!O52 -> 0 | E13: ='Year 3 UNIT PRICING'!O52 -> 0 | F13: ='Year 1 UNIT PRICING'!C52 -> 0 | G13: ='Year 1 UNIT PRICING'!D52 -> 0 | H13: ='Year 1 UNIT PRICING'!E52 -> 0 | I13: ='Year 1 UNIT PRICING'!F52 -> 0 | J13: ='Year 1 UNIT PRICING'!G52 -> 0 | K13: ='Year 1 UNIT PRICING'!H52 -> 0 | L13: ='Year 1 UNIT PRICING'!I52 -> 0 | M13: ='Year 1 UNIT PRICING'!J52 -> 0 | ... Q13: ='Year 1 UNIT PRICING'!N52 -> 0 | R13: ='Year 2 UNIT PRICING'!C52 -> 0 | S13: ='Year 2 UNIT PRICING'!D52 -> 0 | T13: ='Year 2 UNIT PRICING'!E52 -> 0 | U13: ='Year 2 UNIT PRICING'!F52 -> 0 | V13: ='Year 2 UNIT PRICING'!G52 -> 0 | W13: ='Year 2 UNIT PRICING'!H52 -> 0 | X13: ='Year 2 UNIT PRICING'!I52 -> 0 | Y13: ='Year 2 UNIT PRICING'!J52 -> 0 | ... AC13: ='Year 2 UNIT PRICING'!N52 -> 0 | AD13: ='Year 3 UNIT PRICING'!C52 -> 0 | AE13: ='Year 3 UNIT PRICING'!D52 -> 0 | AF13: ='Year 3 UNIT PRICING'!E52 -> 0 | AG13: ='Year 3 UNIT PRICING'!F52 -> 0 | AH13: ='Year 3 UNIT PRICING'!G52 -> 0 | AI13: ='Year 3 UNIT PRICING'!H52 -> 0 | AJ13: ='Year 3 UNIT PRICING'!I52 -> 0 | AK13: ='Year 3 UNIT PRICING'!J52 -> 0 | ... AO13: ='Year 3 UNIT PRICING'!N52 -> 0
