Workbook
Name BSCheck: #REF!
Name BSCheck: #REF!
Name BSCheck: #REF!
Name BSCheck: #REF!
Name BSCheck: #REF!
Name BSCheck: #REF!
Name BSCheck: #REF!
Name BSCheck: #REF!
Name BSCheck: #REF!
Name CentralCosts: 'Other income'!$K$32:$BS$32
Name CentralCosts: CentralCosts!$K$32:$BS$32
Name CentralStaff: StaffCosts!$K$15:$BS$15
Name Creditors: #REF!
Name Creditors: #REF!
Name Creditors: #REF!
Name Creditors: #REF!
Name Creditors: #REF!
Name Creditors: #REF!
Name Creditors: #REF!
Name Creditors: #REF!
Name Creditors: #REF!
Name DebtIssued: [1]Input!$E$33
Name Debtors: #REF!
Name Debtors: #REF!
Name Debtors: #REF!
Name Debtors: #REF!
Name Debtors: #REF!
Name Debtors: #REF!
Name Debtors: #REF!
Name Debtors: #REF!
Name Debtors: #REF!
Name DebtRec: DebtFinancing!#REF!
Name DebtRec: DebtFinancing!#REF!
Name DebtRec: GrantIncome!#REF!
Name DebtRec: DebtFinancing!#REF!
Name DebtRec: DebtFinancing!#REF!
Name DebtRec: DebtFinancing!#REF!
Name DebtRec: DebtFinancing!#REF!
Name DebtRec: DebtFinancing!#REF!
Name DebtRec: DebtFinancing!#REF!
Name DebtTerm: [1]Input!$E$36
Name Depreciation: Capex!#REF!
Name Depreciation: Capex!#REF!
Name Depreciation: Capex!#REF!
Name Depreciation: Capex!#REF!
Name Depreciation: Capex!#REF!
Name Depreciation: Capex!#REF!
Name Depreciation: Capex!#REF!
Name Depreciation: Capex!#REF!
Name Depreciation: Capex!#REF!
Name EquityVal: [2]DCF!$E$20
Name GrantRec: EquityFinancing!$K$22:$BS$22
Name GrantRec: #REF!
Name GrantRec: #REF!
Name IntRate: [1]Input!$E$35
Name Months1: Worksheet!$A$1:$A$12
Name RevBusLine1: Revenue!$K$16:$BS$16
Name RevBusLine2: Revenue!$K$22:$BS$22
Name RevBusLine3: Revenue!$K$28:$BS$28
Name StaffCosts: StaffCosts!$K$116:$BS$116

Sheet Key Inputs
D2: Started | E2: Completed
C4: General Assumptions
C6: Volume Sales
C8: Pricing
C10: Variable Costs
C12: Staff Costs
C14: Central Costs
C16: Stock Orders
C18: Capital Expenditure
C20: Grant Income
C22: Investment Income
B24: Yes
B25: No

Sheet Disclaimer
A1: Disclaimer

Sheet Outputs - Summary
A3: =IF(KeyInputs!$F$14=0,"Company Name",KeyInputs!$F$14) -> Company Name
A4: Outputs summary
A5: =KeyInputs!C5 -> 0 | D5: =KeyInputs!D5 -> Year | E5: =KeyInputs!E5 -> 2012 | F5: =KeyInputs!F5 -> 2013 | G5: =KeyInputs!G5 -> 2014 | H5: =KeyInputs!H5 -> 2015 | I5: =KeyInputs!I5 -> 2016 | J5: =KeyInputs!J5 -> 2017 | K5: =KeyInputs!K5 -> 2018 | L5: =KeyInputs!L5 -> 2019
D6: =KeyInputs!D6 -> Period number | E6: =KeyInputs!E6 -> -2 | F6: =KeyInputs!F6 -> -1 | G6: =KeyInputs!G6 -> 0 | H6: =KeyInputs!H6 -> 1 | I6: =KeyInputs!I6 -> 2 | J6: =KeyInputs!J6 -> 3 | K6: =KeyInputs!K6 -> 4 | L6: =KeyInputs!L6 -> 5
D7: =KeyInputs!D7 -> Period starts | E7: =KeyInputs!E7 -> 40909 | F7: =KeyInputs!F7 -> 41275 | G7: =KeyInputs!G7 -> 41640 | H7: =KeyInputs!H7 -> 42005 | I7: =KeyInputs!I7 -> 42370 | J7: =KeyInputs!J7 -> 42736 | K7: =KeyInputs!K7 -> 43101 | L7: =KeyInputs!L7 -> 43466
B8: =IF(Check!$C$12=0,"All checks are OK","There are "&Check!$C$12&" error/errors") -> All checks are OK | D8: =KeyInputs!D8 -> Period ends | E8: =KeyInputs!E8 -> 41274 | F8: =KeyInputs!F8 -> 41639 | G8: =KeyInputs!G8 -> 42004 | H8: =KeyInputs!H8 -> 42369 | I8: =KeyInputs!I8 -> 42735 | J8: =KeyInputs!J8 -> 43100 | K8: =KeyInputs!K8 -> 43465 | L8: =KeyInputs!L8 -> 43830
A10: =Header1 -> 1 | B10: Profit & Loss Account
B12: Sales | D12: =unit -> £ | E12: =SUM(E13:E15) -> 0 | F12: =SUM(F13:F15) -> 0 | G12: =SUM(G13:G15) -> 0 | H12: =SUM(H13:H15) -> 0 | I12: =SUM(I13:I15) -> 0 | J12: =SUM(J13:J15) -> 0 | K12: =SUM(K13:K15) -> 0 | L12: =SUM(L13:L15) -> 0
B13: =KeyInputs!F21 -> Test | D13: =unit -> £ | E13: =KeyInputs!E156 -> 0 | F13: =KeyInputs!F156 -> 0 | G13: =KeyInputs!G156 -> 0 | H13: ='Outputs - P&L'!E13 -> 0 | I13: ='Outputs - P&L'!F13 -> 0 | J13: ='Outputs - P&L'!G13 -> 0 | K13: ='Outputs - P&L'!H13 -> 0 | L13: ='Outputs - P&L'!I13 -> 0
B14: =KeyInputs!F26 -> Insert Business Line2 | D14: =unit -> £ | E14: =KeyInputs!E157 -> 0 | F14: =KeyInputs!F157 -> 0 | G14: =KeyInputs!G157 -> 0 | H14: ='Outputs - P&L'!E14 -> 0 | I14: ='Outputs - P&L'!F14 -> 0 | J14: ='Outputs - P&L'!G14 -> 0 | K14: ='Outputs - P&L'!H14 -> 0 | L14: ='Outputs - P&L'!I14 -> 0
B15: =KeyInputs!F31 -> Insert Business Line3 | D15: =unit -> £ | E15: =KeyInputs!E158 -> 0 | F15: =KeyInputs!F158 -> 0 | G15: =KeyInputs!G158 -> 0 | H15: ='Outputs - P&L'!E15 -> 0 | I15: ='Outputs - P&L'!F15 -> 0 | J15: ='Outputs - P&L'!G15 -> 0 | K15: ='Outputs - P&L'!H15 -> 0 | L15: ='Outputs - P&L'!I15 -> 0
B17: Variable costs | D17: =unit -> £ | E17: =SUM(E18:E20) -> 0 | F17: =SUM(F18:F20) -> 0 | G17: =SUM(G18:G20) -> 0 | H17: =SUM(H18:H20) -> 0 | I17: =SUM(I18:I20) -> 0 | J17: =SUM(J18:J20) -> 0 | K17: =SUM(K18:K20) -> 0 | L17: =SUM(L18:L20) -> 0
B18: =B13 -> Test | D18: =unit -> £ | E18: =KeyInputs!E161 -> 0 | F18: =KeyInputs!F161 -> 0 | G18: =KeyInputs!G161 -> 0 | H18: ='Outputs - P&L'!E18 -> 0 | I18: ='Outputs - P&L'!F18 -> 0 | J18: ='Outputs - P&L'!G18 -> 0 | K18: ='Outputs - P&L'!H18 -> 0 | L18: ='Outputs - P&L'!I18 -> 0 | O18: =IFERROR(F18/F$17,"-") -> - | P18: =IFERROR(G18/G$17,"-") -> - | Q18: =IFERROR(H18/H$17,"-") -> - | R18: =IFERROR(I18/I$17,"-") -> - | S18: =IFERROR(J18/J$17,"-") -> - | T18: =IFERROR(K18/K$17,"-") -> - | U18: =IFERROR(L18/L$17,"-") -> -
B19: =B14 -> Insert Business Line2 | D19: =unit -> £ | E19: =KeyInputs!E162 -> 0 | F19: =KeyInputs!F162 -> 0 | G19: =KeyInputs!G162 -> 0 | H19: ='Outputs - P&L'!E19 -> 0 | I19: ='Outputs - P&L'!F19 -> 0 | J19: ='Outputs - P&L'!G19 -> 0 | K19: ='Outputs - P&L'!H19 -> 0 | L19: ='Outputs - P&L'!I19 -> 0 | O19: =IFERROR(F19/F$17,"-") -> - | P19: =IFERROR(G19/G$17,"-") -> - | Q19: =IFERROR(H19/H$17,"-") -> - | R19: =IFERROR(I19/I$17,"-") -> - | S19: =IFERROR(J19/J$17,"-") -> - | T19: =IFERROR(K19/K$17,"-") -> - | U19: =IFERROR(L19/L$17,"-") -> -
B20: =B15 -> Insert Business Line3 | D20: =unit -> £ | E20: =KeyInputs!E163 -> 0 | F20: =KeyInputs!F163 -> 0 | G20: =KeyInputs!G163 -> 0 | H20: ='Outputs - P&L'!E20 -> 0 | I20: ='Outputs - P&L'!F20 -> 0 | J20: ='Outputs - P&L'!G20 -> 0 | K20: ='Outputs - P&L'!H20 -> 0 | L20: ='Outputs - P&L'!I20 -> 0 | O20: =IFERROR(F20/F$17,"-") -> - | P20: =IFERROR(G20/G$17,"-") -> - | Q20: =IFERROR(H20/H$17,"-") -> - | R20: =IFERROR(I20/I$17,"-") -> - | S20: =IFERROR(J20/J$17,"-") -> - | T20: =IFERROR(K20/K$17,"-") -> - | U20: =IFERROR(L20/L$17,"-") -> -
B22: Direct staff costs | D22: =unit -> £ | E22: =SUM(E23:E25) -> 0 | F22: =SUM(F23:F25) -> 0 | G22: =SUM(G23:G25) -> 0 | H22: =SUM(H23:H25) -> 0 | I22: =SUM(I23:I25) -> 0 | J22: =SUM(J23:J25) -> 0 | K22: =SUM(K23:K25) -> 0 | L22: =SUM(L23:L25) -> 0
B23: =B13 -> Test | D23: =unit -> £ | E23: =KeyInputs!E166 -> 0 | F23: =KeyInputs!F166 -> 0 | G23: =KeyInputs!G166 -> 0 | H23: ='Outputs - P&L'!E23 -> 0 | I23: ='Outputs - P&L'!F23 -> 0 | J23: ='Outputs - P&L'!G23 -> 0 | K23: ='Outputs - P&L'!H23 -> 0 | L23: ='Outputs - P&L'!I23 -> 0 | O23: =IFERROR(F23/F$22,"-") -> - | P23: =IFERROR(G23/G$22,"-") -> - | Q23: =IFERROR(H23/H$22,"-") -> - | R23: =IFERROR(I23/I$22,"-") -> - | S23: =IFERROR(J23/J$22,"-") -> - | T23: =IFERROR(K23/K$22,"-") -> - | U23: =IFERROR(L23/L$22,"-") -> -
B24: =B14 -> Insert Business Line2 | D24: =unit -> £ | E24: =KeyInputs!E167 -> 0 | F24: =KeyInputs!F167 -> 0 | G24: =KeyInputs!G167 -> 0 | H24: ='Outputs - P&L'!E24 -> 0 | I24: ='Outputs - P&L'!F24 -> 0 | J24: ='Outputs - P&L'!G24 -> 0 | K24: ='Outputs - P&L'!H24 -> 0 | L24: ='Outputs - P&L'!I24 -> 0 | O24: =IFERROR(F24/F$22,"-") -> - | P24: =IFERROR(G24/G$22,"-") -> - | Q24: =IFERROR(H24/H$22,"-") -> - | R24: =IFERROR(I24/I$22,"-") -> - | S24: =IFERROR(J24/J$22,"-") -> - | T24: =IFERROR(K24/K$22,"-") -> - | U24: =IFERROR(L24/L$22,"-") -> -
B25: =B15 -> Insert Business Line3 | D25: =unit -> £ | E25: =KeyInputs!E168 -> 0 | F25: =KeyInputs!F168 -> 0 | G25: =KeyInputs!G168 -> 0 | H25: ='Outputs - P&L'!E25 -> 0 | I25: ='Outputs - P&L'!F25 -> 0 | J25: ='Outputs - P&L'!G25 -> 0 | K25: ='Outputs - P&L'!H25 -> 0 | L25: ='Outputs - P&L'!I25 -> 0 | O25: =IFERROR(F25/F$22,"-") -> - | P25: =IFERROR(G25/G$22,"-") -> - | Q25: =IFERROR(H25/H$22,"-") -> - | R25: =IFERROR(I25/I$22,"-") -> - | S25: =IFERROR(J25/J$22,"-") -> - | T25: =IFERROR(K25/K$22,"-") -> - | U25: =IFERROR(L25/L$22,"-") -> -
B27: Gross profit | D27: =unit -> £ | E27: =SUM(E12,E17,E22) -> 0 | F27: =SUM(F12,F17,F22) -> 0 | G27: =SUM(G12,G17,G22) -> 0 | H27: =SUM(H12,H17,H22) -> 0 | I27: =SUM(I12,I17,I22) -> 0 | J27: =SUM(J12,J17,J22) -> 0 | K27: =SUM(K12,K17,K22) -> 0 | L27: =SUM(L12,L17,L22) -> 0
B29: Central staff costs | D29: =unit -> £ | E29: =KeyInputs!E172 -> 0 | F29: =KeyInputs!F172 -> 0 | G29: =KeyInputs!G172 -> 0 | H29: ='Outputs - P&L'!E29 -> 0 | I29: ='Outputs - P&L'!F29 -> 0 | J29: ='Outputs - P&L'!G29 -> 0 | K29: ='Outputs - P&L'!H29 -> 0 | L29: ='Outputs - P&L'!I29 -> 0
B30: Central costs | D30: =unit -> £ | E30: =KeyInputs!E173 -> 0 | F30: =KeyInputs!F173 -> 0 | G30: =KeyInputs!G173 -> 0 | H30: ='Outputs - P&L'!E30 -> 0 | I30: ='Outputs - P&L'!F30 -> 0 | J30: ='Outputs - P&L'!G30 -> 0 | K30: ='Outputs - P&L'!H30 -> 0 | L30: ='Outputs - P&L'!I30 -> 0
B31: Depreciation | D31: =unit -> £ | E31: =KeyInputs!E174 -> 0 | F31: =KeyInputs!F174 -> 0 | G31: =KeyInputs!G174 -> 0 | H31: ='Outputs - P&L'!E31 -> 0 | I31: ='Outputs - P&L'!F31 -> 0 | J31: ='Outputs - P&L'!G31 -> 0 | K31: ='Outputs - P&L'!H31 -> 0 | L31: ='Outputs - P&L'!I31 -> 0
B32: Operating profit | D32: =unit -> £ | E32: =SUM(E27:E31) -> 0 | F32: =SUM(F27:F31) -> 0 | G32: =SUM(G27:G31) -> 0 | H32: =SUM(H27:H31) -> 0 | I32: =SUM(I27:I31) -> 0 | J32: =SUM(J27:J31) -> 0 | K32: =SUM(K27:K31) -> 0 | L32: =SUM(L27:L31) -> 0
B34: Grant income | D34: =unit -> £ | E34: =KeyInputs!E177 -> 0 | F34: =KeyInputs!F177 -> 0 | G34: =KeyInputs!G177 -> 0 | H34: ='Outputs - P&L'!E34 -> 0 | I34: ='Outputs - P&L'!F34 -> 0 | J34: ='Outputs - P&L'!G34 -> 0 | K34: ='Outputs - P&L'!H34 -> 0 | L34: ='Outputs - P&L'!I34 -> 0
B35: Other income | D35: =unit -> £ | E35: =KeyInputs!E178 -> 0 | F35: =KeyInputs!F178 -> 0 | G35: =KeyInputs!G178 -> 0 | H35: ='Outputs - P&L'!E35 -> 0 | I35: ='Outputs - P&L'!F35 -> 0 | J35: ='Outputs - P&L'!G35 -> 0 | K35: ='Outputs - P&L'!H35 -> 0 | L35: ='Outputs - P&L'!I35 -> 0
B36: Interest on debt | D36: =unit -> £ | E36: =KeyInputs!E179 -> 0 | F36: =KeyInputs!F179 -> 0 | G36: =KeyInputs!G179 -> 0 | H36: ='Outputs - P&L'!E36 -> 0 | I36: ='Outputs - P&L'!F36 -> 0 | J36: ='Outputs - P&L'!G36 -> 0 | K36: ='Outputs - P&L'!H36 -> 0 | L36: ='Outputs - P&L'!I36 -> 0
B37: Overdraft interest | E37: =KeyInputs!E180 -> 0 | F37: =KeyInputs!F180 -> 0 | G37: =KeyInputs!G180 -> 0 | H37: ='Outputs - P&L'!E37 -> 0 | I37: ='Outputs - P&L'!F37 -> 0 | J37: ='Outputs - P&L'!G37 -> 0 | K37: ='Outputs - P&L'!H37 -> 0 | L37: ='Outputs - P&L'!I37 -> 0
B38: PBT | D38: =unit -> £ | E38: =SUM(E32:E37) -> 0 | F38: =SUM(F32:F37) -> 0 | G38: =SUM(G32:G37) -> 0 | H38: =SUM(H32:H37) -> 0 | I38: =SUM(I32:I37) -> 0 | J38: =SUM(J32:J37) -> 0 | K38: =SUM(K32:K37) -> 0 | L38: =SUM(L32:L37) -> 0
B40: Current tax | D40: =unit -> £ | E40: =KeyInputs!E183 -> 0 | F40: =KeyInputs!F183 -> 0 | G40: =KeyInputs!G183 -> 0 | H40: ='Outputs - P&L'!E40 -> 0 | I40: ='Outputs - P&L'!F40 -> 0 | J40: ='Outputs - P&L'!G40 -> 0 | K40: ='Outputs - P&L'!H40 -> 0 | L40: ='Outputs - P&L'!I40 -> 0
B41: PAT | D41: =unit -> £ | E41: =SUM(E38:E40) -> 0 | F41: =SUM(F38:F40) -> 0 | G41: =SUM(G38:G40) -> 0 | H41: =SUM(H38:H40) -> 0 | I41: =SUM(I38:I40) -> 0 | J41: =SUM(J38:J40) -> 0 | K41: =SUM(K38:K40) -> 0 | L41: =SUM(L38:L40) -> 0
B43: Dividends Payable | D43: =unit -> £ | E43: =KeyInputs!E186 -> 0 | F43: =KeyInputs!F186 -> 0 | G43: =KeyInputs!G186 -> 0 | H43: ='Outputs - P&L'!E43 -> 0 | I43: ='Outputs - P&L'!F43 -> 0 | J43: ='Outputs - P&L'!G43 -> 0 | K43: ='Outputs - P&L'!H43 -> 0 | L43: ='Outputs - P&L'!I43 -> 0
B45: Retained profit | D45: =unit -> £ | E45: =SUM(E41:E43) -> 0 | F45: =SUM(F41:F43) -> 0 | G45: =SUM(G41:G43) -> 0 | H45: =SUM(H41:H43) -> 0 | I45: =SUM(I41:I43) -> 0 | J45: =SUM(J41:J43) -> 0 | K45: =SUM(K41:K43) -> 0 | L45: =SUM(L41:L43) -> 0
B47: EBITDA | E47: =E32+E34-E31 -> 0 | F47: =F32+F34-F31 -> 0 | G47: =G32+G34-G31 -> 0 | H47: =H32+H34-H31 -> 0 | I47: =I32+I34-I31 -> 0 | J47: =J32+J34-J31 -> 0 | K47: =K32+K34-K31 -> 0 | L47: =L32+L34-L31 -> 0
B49: KPI's
B50: Revenue growth | D50: % | E50: na | F50: =(F12-E12)/E12*100 -> #DIV/0! | G50: =(G12-F12)/F12*100 -> #DIV/0! | H50: =(H12-G12)/G12*100 -> #DIV/0! | I50: =(I12-H12)/H12*100 -> #DIV/0! | J50: =(J12-I12)/I12*100 -> #DIV/0! | K50: =(K12-J12)/J12*100 -> #DIV/0! | L50: =(L12-K12)/K12*100 -> #DIV/0!
B51: Gross margin | D51: % | E51: =E27/E12*100 -> #DIV/0! | F51: =F27/F12*100 -> #DIV/0! | G51: =G27/G12*100 -> #DIV/0! | H51: =H27/H12*100 -> #DIV/0! | I51: =I27/I12*100 -> #DIV/0! | J51: =J27/J12*100 -> #DIV/0! | K51: =K27/K12*100 -> #DIV/0! | L51: =L27/L12*100 -> #DIV/0!
B52: Gross profit growth | D52: % | E52: na | F52: =(F27-E27)/E27*100 -> #DIV/0! | G52: =(G27-F27)/F27*100 -> #DIV/0! | H52: =(H27-G27)/G27*100 -> #DIV/0! | I52: =(I27-H27)/H27*100 -> #DIV/0! | J52: =(J27-I27)/I27*100 -> #DIV/0! | K52: =(K27-J27)/J27*100 -> #DIV/0! | L52: =(L27-K27)/K27*100 -> #DIV/0!
B53: Operating margin | D53: % | E53: =E32/E12*100 -> #DIV/0! | F53: =F32/F12*100 -> #DIV/0! | G53: =G32/G12*100 -> #DIV/0! | H53: =H32/H12*100 -> #DIV/0! | I53: =I32/I12*100 -> #DIV/0! | J53: =J32/J12*100 -> #DIV/0! | K53: =K32/K12*100 -> #DIV/0! | L53: =L32/L12*100 -> #DIV/0!
B54: Sales volumes
...

Sheet Outputs - P&L
A3: =IF(KeyInputs!$F$14=0,"Company Name",KeyInputs!$F$14) -> Company Name
A4: Profit and Loss Account
D5: =KeyInputs!D5 -> Year | E5: =KeyInputs!H5 -> 2015 | F5: =KeyInputs!I5 -> 2016 | G5: =KeyInputs!J5 -> 2017 | H5: =KeyInputs!K5 -> 2018 | I5: =KeyInputs!L5 -> 2019 | K5: =KeyInputs!N5 -> 2015 | L5: =KeyInputs!O5 -> 2015 | M5: =KeyInputs!P5 -> 2015 | N5: =KeyInputs!Q5 -> 2015 | O5: =KeyInputs!R5 -> 2015 | P5: =KeyInputs!S5 -> 2015 | Q5: =KeyInputs!T5 -> 2015 | R5: =KeyInputs!U5 -> 2015 | ... BR5: =KeyInputs!BU5 -> 2019
D6: =KeyInputs!D6 -> Period number | E6: =KeyInputs!H6 -> 1 | F6: =KeyInputs!I6 -> 2 | G6: =KeyInputs!J6 -> 3 | H6: =KeyInputs!K6 -> 4 | I6: =KeyInputs!L6 -> 5 | K6: =KeyInputs!N6 -> 1 | L6: =KeyInputs!O6 -> 2 | M6: =KeyInputs!P6 -> 3 | N6: =KeyInputs!Q6 -> 4 | O6: =KeyInputs!R6 -> 5 | P6: =KeyInputs!S6 -> 6 | Q6: =KeyInputs!T6 -> 7 | R6: =KeyInputs!U6 -> 8 | ... BR6: =KeyInputs!BU6 -> 60
D7: =KeyInputs!D7 -> Period starts | E7: =KeyInputs!H7 -> 42005 | F7: =KeyInputs!I7 -> 42370 | G7: =KeyInputs!J7 -> 42736 | H7: =KeyInputs!K7 -> 43101 | I7: =KeyInputs!L7 -> 43466 | K7: =KeyInputs!N7 -> 42005 | L7: =KeyInputs!O7 -> 42036 | M7: =KeyInputs!P7 -> 42064 | N7: =KeyInputs!Q7 -> 42095 | O7: =KeyInputs!R7 -> 42125 | P7: =KeyInputs!S7 -> 42156 | Q7: =KeyInputs!T7 -> 42186 | R7: =KeyInputs!U7 -> 42217 | ... BR7: =KeyInputs!BU7 -> 43800
B8: =IF(Check!$C$12=0,"All checks are OK","There are "&Check!$C$12&" error/errors") -> All checks are OK | D8: =KeyInputs!D8 -> Period ends | E8: =KeyInputs!H8 -> 42369 | F8: =KeyInputs!I8 -> 42735 | G8: =KeyInputs!J8 -> 43100 | H8: =KeyInputs!K8 -> 43465 | I8: =KeyInputs!L8 -> 43830 | K8: =KeyInputs!N8 -> 42035 | L8: =KeyInputs!O8 -> 42063 | M8: =KeyInputs!P8 -> 42094 | N8: =KeyInputs!Q8 -> 42124 | O8: =KeyInputs!R8 -> 42155 | P8: =KeyInputs!S8 -> 42185 | Q8: =KeyInputs!T8 -> 42216 | R8: =KeyInputs!U8 -> 42247 | ... BR8: =KeyInputs!BU8 -> 43830
A10: =Header1 -> 1 | B10: Profit & Loss Account
B12: Sales | D12: =unit -> £ | E12: =SUMIF($K$5:$BR$5,E$5,$K12:$BR12) -> 0 | F12: =SUMIF($K$5:$BR$5,F$5,$K12:$BR12) -> 0 | G12: =SUMIF($K$5:$BR$5,G$5,$K12:$BR12) -> 0 | H12: =SUMIF($K$5:$BR$5,H$5,$K12:$BR12) -> 0 | I12: =SUMIF($K$5:$BR$5,I$5,$K12:$BR12) -> 0 | K12: =SUM(K13:K15) -> 0 | L12: =SUM(L13:L15) -> 0 | M12: =SUM(M13:M15) -> 0 | N12: =SUM(N13:N15) -> 0 | O12: =SUM(O13:O15) -> 0 | P12: =SUM(P13:P15) -> 0 | Q12: =SUM(Q13:Q15) -> 0 | R12: =SUM(R13:R15) -> 0 | ... BR12: =SUM(BR13:BR15) -> 0
B13: =KeyInputs!F21 -> Test | D13: =unit -> £ | E13: =SUMIF($K$5:$BR$5,E$5,$K13:$BR13) -> 0 | F13: =SUMIF($K$5:$BR$5,F$5,$K13:$BR13) -> 0 | G13: =SUMIF($K$5:$BR$5,G$5,$K13:$BR13) -> 0 | H13: =SUMIF($K$5:$BR$5,H$5,$K13:$BR13) -> 0 | I13: =SUMIF($K$5:$BR$5,I$5,$K13:$BR13) -> 0 | K13: =Revenue!K16 -> 0 | L13: =Revenue!L16 -> 0 | M13: =Revenue!M16 -> 0 | N13: =Revenue!N16 -> 0 | O13: =Revenue!O16 -> 0 | P13: =Revenue!P16 -> 0 | Q13: =Revenue!Q16 -> 0 | R13: =Revenue!R16 -> 0 | ... BR13: =Revenue!BR16 -> 0
B14: =KeyInputs!F26 -> Insert Business Line2 | D14: =unit -> £ | E14: =SUMIF($K$5:$BR$5,E$5,$K14:$BR14) -> 0 | F14: =SUMIF($K$5:$BR$5,F$5,$K14:$BR14) -> 0 | G14: =SUMIF($K$5:$BR$5,G$5,$K14:$BR14) -> 0 | H14: =SUMIF($K$5:$BR$5,H$5,$K14:$BR14) -> 0 | I14: =SUMIF($K$5:$BR$5,I$5,$K14:$BR14) -> 0 | K14: =Revenue!K22 -> 0 | L14: =Revenue!L22 -> 0 | M14: =Revenue!M22 -> 0 | N14: =Revenue!N22 -> 0 | O14: =Revenue!O22 -> 0 | P14: =Revenue!P22 -> 0 | Q14: =Revenue!Q22 -> 0 | R14: =Revenue!R22 -> 0 | ... BR14: =Revenue!BR22 -> 0
B15: =KeyInputs!F31 -> Insert Business Line3 | D15: =unit -> £ | E15: =SUMIF($K$5:$BR$5,E$5,$K15:$BR15) -> 0 | F15: =SUMIF($K$5:$BR$5,F$5,$K15:$BR15) -> 0 | G15: =SUMIF($K$5:$BR$5,G$5,$K15:$BR15) -> 0 | H15: =SUMIF($K$5:$BR$5,H$5,$K15:$BR15) -> 0 | I15: =SUMIF($K$5:$BR$5,I$5,$K15:$BR15) -> 0 | K15: =Revenue!K28 -> 0 | L15: =Revenue!L28 -> 0 | M15: =Revenue!M28 -> 0 | N15: =Revenue!N28 -> 0 | O15: =Revenue!O28 -> 0 | P15: =Revenue!P28 -> 0 | Q15: =Revenue!Q28 -> 0 | R15: =Revenue!R28 -> 0 | ... BR15: =Revenue!BR28 -> 0
B17: Variable costs | D17: =unit -> £ | E17: =SUMIF($K$5:$BR$5,E$5,$K17:$BR17) -> 0 | F17: =SUMIF($K$5:$BR$5,F$5,$K17:$BR17) -> 0 | G17: =SUMIF($K$5:$BR$5,G$5,$K17:$BR17) -> 0 | H17: =SUMIF($K$5:$BR$5,H$5,$K17:$BR17) -> 0 | I17: =SUMIF($K$5:$BR$5,I$5,$K17:$BR17) -> 0 | K17: =SUM(K18:K20) -> 0 | L17: =SUM(L18:L20) -> 0 | M17: =SUM(M18:M20) -> 0 | N17: =SUM(N18:N20) -> 0 | O17: =SUM(O18:O20) -> 0 | P17: =SUM(P18:P20) -> 0 | Q17: =SUM(Q18:Q20) -> 0 | R17: =SUM(R18:R20) -> 0 | ... BR17: =SUM(BR18:BR20) -> 0
B18: =B13 -> Test | D18: =unit -> £ | E18: =SUMIF($K$5:$BR$5,E$5,$K18:$BR18) -> 0 | F18: =SUMIF($K$5:$BR$5,F$5,$K18:$BR18) -> 0 | G18: =SUMIF($K$5:$BR$5,G$5,$K18:$BR18) -> 0 | H18: =SUMIF($K$5:$BR$5,H$5,$K18:$BR18) -> 0 | I18: =SUMIF($K$5:$BR$5,I$5,$K18:$BR18) -> 0 | K18: =VariableCosts!K16 -> 0 | L18: =VariableCosts!L16 -> 0 | M18: =VariableCosts!M16 -> 0 | N18: =VariableCosts!N16 -> 0 | O18: =VariableCosts!O16 -> 0 | P18: =VariableCosts!P16 -> 0 | Q18: =VariableCosts!Q16 -> 0 | R18: =VariableCosts!R16 -> 0 | ... BR18: =VariableCosts!BR16 -> 0
B19: =B14 -> Insert Business Line2 | D19: =unit -> £ | E19: =SUMIF($K$5:$BR$5,E$5,$K19:$BR19) -> 0 | F19: =SUMIF($K$5:$BR$5,F$5,$K19:$BR19) -> 0 | G19: =SUMIF($K$5:$BR$5,G$5,$K19:$BR19) -> 0 | H19: =SUMIF($K$5:$BR$5,H$5,$K19:$BR19) -> 0 | I19: =SUMIF($K$5:$BR$5,I$5,$K19:$BR19) -> 0 | K19: =VariableCosts!K22 -> 0 | L19: =VariableCosts!L22 -> 0 | M19: =VariableCosts!M22 -> 0 | N19: =VariableCosts!N22 -> 0 | O19: =VariableCosts!O22 -> 0 | P19: =VariableCosts!P22 -> 0 | Q19: =VariableCosts!Q22 -> 0 | R19: =VariableCosts!R22 -> 0 | ... BR19: =VariableCosts!BR22 -> 0
B20: =B15 -> Insert Business Line3 | D20: =unit -> £ | E20: =SUMIF($K$5:$BR$5,E$5,$K20:$BR20) -> 0 | F20: =SUMIF($K$5:$BR$5,F$5,$K20:$BR20) -> 0 | G20: =SUMIF($K$5:$BR$5,G$5,$K20:$BR20) -> 0 | H20: =SUMIF($K$5:$BR$5,H$5,$K20:$BR20) -> 0 | I20: =SUMIF($K$5:$BR$5,I$5,$K20:$BR20) -> 0 | K20: =VariableCosts!K27 -> 0 | L20: =VariableCosts!L27 -> 0 | M20: =VariableCosts!M27 -> 0 | N20: =VariableCosts!N27 -> 0 | O20: =VariableCosts!O27 -> 0 | P20: =VariableCosts!P27 -> 0 | Q20: =VariableCosts!Q27 -> 0 | R20: =VariableCosts!R27 -> 0 | ... BR20: =VariableCosts!BR27 -> 0
B22: Direct staff costs | D22: =unit -> £ | E22: =SUMIF($K$5:$BR$5,E$5,$K22:$BR22) -> 0 | F22: =SUMIF($K$5:$BR$5,F$5,$K22:$BR22) -> 0 | G22: =SUMIF($K$5:$BR$5,G$5,$K22:$BR22) -> 0 | H22: =SUMIF($K$5:$BR$5,H$5,$K22:$BR22) -> 0 | I22: =SUMIF($K$5:$BR$5,I$5,$K22:$BR22) -> 0 | K22: =SUM(K23:K25) -> 0 | L22: =SUM(L23:L25) -> 0 | M22: =SUM(M23:M25) -> 0 | N22: =SUM(N23:N25) -> 0 | O22: =SUM(O23:O25) -> 0 | P22: =SUM(P23:P25) -> 0 | Q22: =SUM(Q23:Q25) -> 0 | R22: =SUM(R23:R25) -> 0 | ... BR22: =SUM(BR23:BR25) -> 0
B23: =B13 -> Test | D23: =unit -> £ | E23: =SUMIF($K$5:$BR$5,E$5,$K23:$BR23) -> 0 | F23: =SUMIF($K$5:$BR$5,F$5,$K23:$BR23) -> 0 | G23: =SUMIF($K$5:$BR$5,G$5,$K23:$BR23) -> 0 | H23: =SUMIF($K$5:$BR$5,H$5,$K23:$BR23) -> 0 | I23: =SUMIF($K$5:$BR$5,I$5,$K23:$BR23) -> 0 | K23: =StaffCosts!K12 -> 0 | L23: =StaffCosts!L12 -> 0 | M23: =StaffCosts!M12 -> 0 | N23: =StaffCosts!N12 -> 0 | O23: =StaffCosts!O12 -> 0 | P23: =StaffCosts!P12 -> 0 | Q23: =StaffCosts!Q12 -> 0 | R23: =StaffCosts!R12 -> 0 | ... BR23: =StaffCosts!BR12 -> 0
B24: =B14 -> Insert Business Line2 | D24: =unit -> £ | E24: =SUMIF($K$5:$BR$5,E$5,$K24:$BR24) -> 0 | F24: =SUMIF($K$5:$BR$5,F$5,$K24:$BR24) -> 0 | G24: =SUMIF($K$5:$BR$5,G$5,$K24:$BR24) -> 0 | H24: =SUMIF($K$5:$BR$5,H$5,$K24:$BR24) -> 0 | I24: =SUMIF($K$5:$BR$5,I$5,$K24:$BR24) -> 0 | K24: =StaffCosts!K13 -> 0 | L24: =StaffCosts!L13 -> 0 | M24: =StaffCosts!M13 -> 0 | N24: =StaffCosts!N13 -> 0 | O24: =StaffCosts!O13 -> 0 | P24: =StaffCosts!P13 -> 0 | Q24: =StaffCosts!Q13 -> 0 | R24: =StaffCosts!R13 -> 0 | ... BR24: =StaffCosts!BR13 -> 0
B25: =B15 -> Insert Business Line3 | D25: =unit -> £ | E25: =SUMIF($K$5:$BR$5,E$5,$K25:$BR25) -> 0 | F25: =SUMIF($K$5:$BR$5,F$5,$K25:$BR25) -> 0 | G25: =SUMIF($K$5:$BR$5,G$5,$K25:$BR25) -> 0 | H25: =SUMIF($K$5:$BR$5,H$5,$K25:$BR25) -> 0 | I25: =SUMIF($K$5:$BR$5,I$5,$K25:$BR25) -> 0 | K25: =StaffCosts!K14 -> 0 | L25: =StaffCosts!L14 -> 0 | M25: =StaffCosts!M14 -> 0 | N25: =StaffCosts!N14 -> 0 | O25: =StaffCosts!O14 -> 0 | P25: =StaffCosts!P14 -> 0 | Q25: =StaffCosts!Q14 -> 0 | R25: =StaffCosts!R14 -> 0 | ... BR25: =StaffCosts!BR14 -> 0
B27: Gross profit | D27: =unit -> £ | E27: =SUM(E12,E17,E22) -> 0 | F27: =SUM(F12,F17,F22) -> 0 | G27: =SUM(G12,G17,G22) -> 0 | H27: =SUM(H12,H17,H22) -> 0 | I27: =SUM(I12,I17,I22) -> 0 | K27: =SUM(K12,K17,K22) -> 0 | L27: =SUM(L12,L17,L22) -> 0 | M27: =SUM(M12,M17,M22) -> 0 | N27: =SUM(N12,N17,N22) -> 0 | O27: =SUM(O12,O17,O22) -> 0 | P27: =SUM(P12,P17,P22) -> 0 | Q27: =SUM(Q12,Q17,Q22) -> 0 | R27: =SUM(R12,R17,R22) -> 0 | ... BR27: =SUM(BR12,BR17,BR22) -> 0
B29: Central staff costs | D29: =unit -> £ | E29: =SUMIF($K$5:$BR$5,E$5,$K29:$BR29) -> 0 | F29: =SUMIF($K$5:$BR$5,F$5,$K29:$BR29) -> 0 | G29: =SUMIF($K$5:$BR$5,G$5,$K29:$BR29) -> 0 | H29: =SUMIF($K$5:$BR$5,H$5,$K29:$BR29) -> 0 | I29: =SUMIF($K$5:$BR$5,I$5,$K29:$BR29) -> 0 | K29: =StaffCosts!K15 -> 0 | L29: =StaffCosts!L15 -> 0 | M29: =StaffCosts!M15 -> 0 | N29: =StaffCosts!N15 -> 0 | O29: =StaffCosts!O15 -> 0 | P29: =StaffCosts!P15 -> 0 | Q29: =StaffCosts!Q15 -> 0 | R29: =StaffCosts!R15 -> 0 | ... BR29: =StaffCosts!BR15 -> 0
B30: Central costs | D30: =unit -> £ | E30: =SUMIF($K$5:$BR$5,E$5,$K30:$BR30) -> 0 | F30: =SUMIF($K$5:$BR$5,F$5,$K30:$BR30) -> 0 | G30: =SUMIF($K$5:$BR$5,G$5,$K30:$BR30) -> 0 | H30: =SUMIF($K$5:$BR$5,H$5,$K30:$BR30) -> 0 | I30: =SUMIF($K$5:$BR$5,I$5,$K30:$BR30) -> 0 | K30: =-CentralCosts!K32 -> 0 | L30: =-CentralCosts!L32 -> 0 | M30: =-CentralCosts!M32 -> 0 | N30: =-CentralCosts!N32 -> 0 | O30: =-CentralCosts!O32 -> 0 | P30: =-CentralCosts!P32 -> 0 | Q30: =-CentralCosts!Q32 -> 0 | R30: =-CentralCosts!R32 -> 0 | ... BR30: =-CentralCosts!BR32 -> 0
B31: Depreciation | D31: =unit -> £ | E31: =SUMIF($K$5:$BR$5,E$5,$K31:$BR31) -> 0 | F31: =SUMIF($K$5:$BR$5,F$5,$K31:$BR31) -> 0 | G31: =SUMIF($K$5:$BR$5,G$5,$K31:$BR31) -> 0 | H31: =SUMIF($K$5:$BR$5,H$5,$K31:$BR31) -> 0 | I31: =SUMIF($K$5:$BR$5,I$5,$K31:$BR31) -> 0 | K31: =SUM(Capex!K35,Capex!K45,Capex!K55,Capex!K65,Capex!K75) -> 0 | L31: =SUM(Capex!L35,Capex!L45,Capex!L55,Capex!L65,Capex!L75) -> 0 | M31: =SUM(Capex!M35,Capex!M45,Capex!M55,Capex!M65,Capex!M75) -> 0 | N31: =SUM(Capex!N35,Capex!N45,Capex!N55,Capex!N65,Capex!N75) -> 0 | O31: =SUM(Capex!O35,Capex!O45,Capex!O55,Capex!O65,Capex!O75) -> 0 | P31: =SUM(Capex!P35,Capex!P45,Capex!P55,Capex!P65,Capex!P75) -> 0 | Q31: =SUM(Capex!Q35,Capex!Q45,Capex!Q55,Capex!Q65,Capex!Q75) -> 0 | R31: =SUM(Capex!R35,Capex!R45,Capex!R55,Capex!R65,Capex!R75) -> 0 | ... BR31: =SUM(Capex!BR35,Capex!BR45,Capex!BR55,Capex!BR65,Capex!BR75) -> 0
B32: Operating profit | D32: =unit -> £ | E32: =SUM(E27:E31) -> 0 | F32: =SUM(F27:F31) -> 0 | G32: =SUM(G27:G31) -> 0 | H32: =SUM(H27:H31) -> 0 | I32: =SUM(I27:I31) -> 0 | K32: =SUM(K27:K31) -> 0 | L32: =SUM(L27:L31) -> 0 | M32: =SUM(M27:M31) -> 0 | N32: =SUM(N27:N31) -> 0 | O32: =SUM(O27:O31) -> 0 | P32: =SUM(P27:P31) -> 0 | Q32: =SUM(Q27:Q31) -> 0 | R32: =SUM(R27:R31) -> 0 | ... BR32: =SUM(BR27:BR31) -> 0
B34: Grant income | D34: =unit -> £ | E34: =SUMIF($K$5:$BR$5,E$5,$K34:$BR34) -> 0 | F34: =SUMIF($K$5:$BR$5,F$5,$K34:$BR34) -> 0 | G34: =SUMIF($K$5:$BR$5,G$5,$K34:$BR34) -> 0 | H34: =SUMIF($K$5:$BR$5,H$5,$K34:$BR34) -> 0 | I34: =SUMIF($K$5:$BR$5,I$5,$K34:$BR34) -> 0 | K34: =GrantIncome!K16 -> 0 | L34: =GrantIncome!L16 -> 0 | M34: =GrantIncome!M16 -> 0 | N34: =GrantIncome!N16 -> 0 | O34: =GrantIncome!O16 -> 0 | P34: =GrantIncome!P16 -> 0 | Q34: =GrantIncome!Q16 -> 0 | R34: =GrantIncome!R16 -> 0 | ... BR34: =GrantIncome!BR16 -> 0
B35: Other income | D35: =unit -> £ | E35: =SUMIF($K$5:$BR$5,E$5,$K35:$BR35) -> 0 | F35: =SUMIF($K$5:$BR$5,F$5,$K35:$BR35) -> 0 | G35: =SUMIF($K$5:$BR$5,G$5,$K35:$BR35) -> 0 | H35: =SUMIF($K$5:$BR$5,H$5,$K35:$BR35) -> 0 | I35: =SUMIF($K$5:$BR$5,I$5,$K35:$BR35) -> 0 | K35: ='Other income'!K32 -> 0 | L35: ='Other income'!L32 -> 0 | M35: ='Other income'!M32 -> 0 | N35: ='Other income'!N32 -> 0 | O35: ='Other income'!O32 -> 0 | P35: ='Other income'!P32 -> 0 | Q35: ='Other income'!Q32 -> 0 | R35: ='Other income'!R32 -> 0 | ... BR35: ='Other income'!BR32 -> 0
B36: Interest on debt | D36: =unit -> £ | E36: =SUMIF($K$5:$BR$5,E$5,$K36:$BR36) -> 0 | F36: =SUMIF($K$5:$BR$5,F$5,$K36:$BR36) -> 0 | G36: =SUMIF($K$5:$BR$5,G$5,$K36:$BR36) -> 0 | H36: =SUMIF($K$5:$BR$5,H$5,$K36:$BR36) -> 0 | I36: =SUMIF($K$5:$BR$5,I$5,$K36:$BR36) -> 0 | K36: =DebtFinancing!K22 -> 0 | L36: =DebtFinancing!L22 -> 0 | M36: =DebtFinancing!M22 -> 0 | N36: =DebtFinancing!N22 -> 0 | O36: =DebtFinancing!O22 -> 0 | P36: =DebtFinancing!P22 -> 0 | Q36: =DebtFinancing!Q22 -> 0 | R36: =DebtFinancing!R22 -> 0 | ... BR36: =DebtFinancing!BR22 -> 0
B37: Overdraft interest | E37: =SUMIF($K$5:$BR$5,E$5,$K37:$BR37) -> 0 | F37: =SUMIF($K$5:$BR$5,F$5,$K37:$BR37) -> 0 | G37: =SUMIF($K$5:$BR$5,G$5,$K37:$BR37) -> 0 | H37: =SUMIF($K$5:$BR$5,H$5,$K37:$BR37) -> 0 | I37: =SUMIF($K$5:$BR$5,I$5,$K37:$BR37) -> 0 | K37: ='Outputs - Cashflow'!K40 -> 0 | L37: ='Outputs - Cashflow'!L40 -> 0 | M37: ='Outputs - Cashflow'!M40 -> 0 | N37: ='Outputs - Cashflow'!N40 -> 0 | O37: ='Outputs - Cashflow'!O40 -> 0 | P37: ='Outputs - Cashflow'!P40 -> 0 | Q37: ='Outputs - Cashflow'!Q40 -> 0 | R37: ='Outputs - Cashflow'!R40 -> 0 | ... BR37: ='Outputs - Cashflow'!BR40 -> 0
B38: PBT | D38: =unit -> £ | E38: =SUM(E32:E37) -> 0 | F38: =SUM(F32:F37) -> 0 | G38: =SUM(G32:G37) -> 0 | H38: =SUM(H32:H37) -> 0 | I38: =SUM(I32:I37) -> 0 | K38: =SUM(K32:K37) -> 0 | L38: =SUM(L32:L37) -> 0 | M38: =SUM(M32:M37) -> 0 | N38: =SUM(N32:N37) -> 0 | O38: =SUM(O32:O37) -> 0 | P38: =SUM(P32:P37) -> 0 | Q38: =SUM(Q32:Q37) -> 0 | R38: =SUM(R32:R37) -> 0 | ... BR38: =SUM(BR32:BR37) -> 0
B40: Current tax | D40: =unit -> £ | E40: =SUMIF($K$5:$BR$5,E$5,$K40:$BR40) -> 0 | F40: =SUMIF($K$5:$BR$5,F$5,$K40:$BR40) -> 0 | G40: =SUMIF($K$5:$BR$5,G$5,$K40:$BR40) -> 0 | H40: =SUMIF($K$5:$BR$5,H$5,$K40:$BR40) -> 0 | I40: =SUMIF($K$5:$BR$5,I$5,$K40:$BR40) -> 0 | K40: =TAX!K30 -> 0 | L40: =TAX!L30 -> 0 | M40: =TAX!M30 -> 0 | N40: =TAX!N30 -> 0 | O40: =TAX!O30 -> 0 | P40: =TAX!P30 -> 0 | Q40: =TAX!Q30 -> 0 | R40: =TAX!R30 -> 0 | ... BR40: =TAX!BR30 -> 0
B41: PAT | D41: =unit -> £ | E41: =SUM(E38:E40) -> 0 | F41: =SUM(F38:F40) -> 0 | G41: =SUM(G38:G40) -> 0 | H41: =SUM(H38:H40) -> 0 | I41: =SUM(I38:I40) -> 0 | K41: =SUM(K38:K40) -> 0 | L41: =SUM(L38:L40) -> 0 | M41: =SUM(M38:M40) -> 0 | N41: =SUM(N38:N40) -> 0 | O41: =SUM(O38:O40) -> 0 | P41: =SUM(P38:P40) -> 0 | Q41: =SUM(Q38:Q40) -> 0 | R41: =SUM(R38:R40) -> 0 | ... BR41: =SUM(BR38:BR40) -> 0
B43: Dividends Payable | D43: =unit -> £ | E43: =SUMIF($K$5:$BR$5,E$5,$K43:$BR43) -> 0 | F43: =SUMIF($K$5:$BR$5,F$5,$K43:$BR43) -> 0 | G43: =SUMIF($K$5:$BR$5,G$5,$K43:$BR43) -> 0 | H43: =SUMIF($K$5:$BR$5,H$5,$K43:$BR43) -> 0 | I43: =SUMIF($K$5:$BR$5,I$5,$K43:$BR43) -> 0 | K43: =Dividends!K14 -> 0 | L43: =Dividends!L14 -> 0 | M43: =Dividends!M14 -> 0 | N43: =Dividends!N14 -> 0 | O43: =Dividends!O14 -> 0 | P43: =Dividends!P14 -> 0 | Q43: =Dividends!Q14 -> 0 | R43: =Dividends!R14 -> 0 | ... BR43: =Dividends!BR14 -> 0
B45: Retained profit | D45: =unit -> £ | E45: =SUM(E41:E43) -> 0 | F45: =SUM(F41:F43) -> 0 | G45: =SUM(G41:G43) -> 0 | H45: =SUM(H41:H43) -> 0 | I45: =SUM(I41:I43) -> 0 | K45: =SUM(K41:K43) -> 0 | L45: =SUM(L41:L43) -> 0 | M45: =SUM(M41:M43) -> 0 | N45: =SUM(N41:N43) -> 0 | O45: =SUM(O41:O43) -> 0 | P45: =SUM(P41:P43) -> 0 | Q45: =SUM(Q41:Q43) -> 0 | R45: =SUM(R41:R43) -> 0 | ... BR45: =SUM(BR41:BR43) -> 0
B47: P&L reserve BF | D47: =unit -> £ | E47: =D48 -> 0 | F47: =E48 -> 0 | G47: =F48 -> 0 | H47: =G48 -> 0 | I47: =H48 -> 0 | K47: =J48 -> 0 | L47: =K48 -> 0 | M47: =L48 -> 0 | N47: =M48 -> 0 | O47: =N48 -> 0 | P47: =O48 -> 0 | Q47: =P48 -> 0 | R47: =Q48 -> 0 | ... BR47: =BQ48 -> 0
B48: P&L reserve CF | D48: =KeyInputs!G141 -> 0 | E48: =SUM(E45:E47) -> 0 | F48: =SUM(F45:F47) -> 0 | G48: =SUM(G45:G47) -> 0 | H48: =SUM(H45:H47) -> 0 | I48: =SUM(I45:I47) -> 0 | J48: =D48 -> 0 | K48: =SUM(K45:K47) -> 0 | L48: =SUM(L45:L47) -> 0 | M48: =SUM(M45:M47) -> 0 | N48: =SUM(N45:N47) -> 0 | O48: =SUM(O45:O47) -> 0 | P48: =SUM(P45:P47) -> 0 | Q48: =SUM(Q45:Q47) -> 0 | R48: =SUM(R45:R47) -> 0 | ... BR48: =SUM(BR45:BR47) -> 0
A51: End of sheet

Sheet Outputs - BalanceSheet
A3: =IF(KeyInputs!$F$14=0,"Company Name",KeyInputs!$F$14) -> Company Name
A4: Balance Sheet
D5: =KeyInputs!D5 -> Year | E5: =KeyInputs!H5 -> 2015 | F5: =KeyInputs!I5 -> 2016 | G5: =KeyInputs!J5 -> 2017 | H5: =KeyInputs!K5 -> 2018 | I5: =KeyInputs!L5 -> 2019 | K5: =KeyInputs!N5 -> 2015 | L5: =KeyInputs!O5 -> 2015 | M5: =KeyInputs!P5 -> 2015 | N5: =KeyInputs!Q5 -> 2015 | O5: =KeyInputs!R5 -> 2015 | P5: =KeyInputs!S5 -> 2015 | Q5: =KeyInputs!T5 -> 2015 | R5: =KeyInputs!U5 -> 2015 | ... BR5: =KeyInputs!BU5 -> 2019
D6: =KeyInputs!D6 -> Period number | E6: =KeyInputs!H6 -> 1 | F6: =KeyInputs!I6 -> 2 | G6: =KeyInputs!J6 -> 3 | H6: =KeyInputs!K6 -> 4 | I6: =KeyInputs!L6 -> 5 | K6: =KeyInputs!N6 -> 1 | L6: =KeyInputs!O6 -> 2 | M6: =KeyInputs!P6 -> 3 | N6: =KeyInputs!Q6 -> 4 | O6: =KeyInputs!R6 -> 5 | P6: =KeyInputs!S6 -> 6 | Q6: =KeyInputs!T6 -> 7 | R6: =KeyInputs!U6 -> 8 | ... BR6: =KeyInputs!BU6 -> 60
D7: =KeyInputs!D7 -> Period starts | E7: =KeyInputs!H7 -> 42005 | F7: =KeyInputs!I7 -> 42370 | G7: =KeyInputs!J7 -> 42736 | H7: =KeyInputs!K7 -> 43101 | I7: =KeyInputs!L7 -> 43466 | K7: =KeyInputs!N7 -> 42005 | L7: =KeyInputs!O7 -> 42036 | M7: =KeyInputs!P7 -> 42064 | N7: =KeyInputs!Q7 -> 42095 | O7: =KeyInputs!R7 -> 42125 | P7: =KeyInputs!S7 -> 42156 | Q7: =KeyInputs!T7 -> 42186 | R7: =KeyInputs!U7 -> 42217 | ... BR7: =KeyInputs!BU7 -> 43800
B8: =IF(Check!$C$12=0,"All checks are OK","There are "&Check!$C$12&" error/errors") -> All checks are OK | D8: =KeyInputs!D8 -> Period ends | E8: =KeyInputs!H8 -> 42369 | F8: =KeyInputs!I8 -> 42735 | G8: =KeyInputs!J8 -> 43100 | H8: =KeyInputs!K8 -> 43465 | I8: =KeyInputs!L8 -> 43830 | K8: =KeyInputs!N8 -> 42035 | L8: =KeyInputs!O8 -> 42063 | M8: =KeyInputs!P8 -> 42094 | N8: =KeyInputs!Q8 -> 42124 | O8: =KeyInputs!R8 -> 42155 | P8: =KeyInputs!S8 -> 42185 | Q8: =KeyInputs!T8 -> 42216 | R8: =KeyInputs!U8 -> 42247 | ... BR8: =KeyInputs!BU8 -> 43830
A10: =Header1 -> 1 | B10: Balance Sheet
B12: Fixed assets | D12: =unit -> £ | E12: =INDEX($K12:$BR12,0,MATCH(E$8,$K$8:$BR$8,0)) -> 0 | F12: =INDEX($K12:$BR12,0,MATCH(F$8,$K$8:$BR$8,0)) -> 0 | G12: =INDEX($K12:$BR12,0,MATCH(G$8,$K$8:$BR$8,0)) -> 0 | H12: =INDEX($K12:$BR12,0,MATCH(H$8,$K$8:$BR$8,0)) -> 0 | I12: =INDEX($K12:$BR12,0,MATCH(I$8,$K$8:$BR$8,0)) -> 0 | K12: =SUM(K13:K17) -> 0 | L12: =SUM(L13:L17) -> 0 | M12: =SUM(M13:M17) -> 0 | N12: =SUM(N13:N17) -> 0 | O12: =SUM(O13:O17) -> 0 | P12: =SUM(P13:P17) -> 0 | Q12: =SUM(Q13:Q17) -> 0 | R12: =SUM(R13:R17) -> 0 | ... BR12: =SUM(BR13:BR17) -> 0
B13: =KeyInputs!F61 -> ICT equipement | D13: =unit -> £ | E13: =INDEX($K13:$BR13,0,MATCH(E$8,$K$8:$BR$8,0)) -> 0 | F13: =INDEX($K13:$BR13,0,MATCH(F$8,$K$8:$BR$8,0)) -> 0 | G13: =INDEX($K13:$BR13,0,MATCH(G$8,$K$8:$BR$8,0)) -> 0 | H13: =INDEX($K13:$BR13,0,MATCH(H$8,$K$8:$BR$8,0)) -> 0 | I13: =INDEX($K13:$BR13,0,MATCH(I$8,$K$8:$BR$8,0)) -> 0 | K13: =Capex!K37 -> 0 | L13: =Capex!L37 -> 0 | M13: =Capex!M37 -> 0 | N13: =Capex!N37 -> 0 | O13: =Capex!O37 -> 0 | P13: =Capex!P37 -> 0 | Q13: =Capex!Q37 -> 0 | R13: =Capex!R37 -> 0 | ... BR13: =Capex!BR37 -> 0
B14: =KeyInputs!F62 -> F&F | D14: =unit -> £ | E14: =INDEX($K14:$BR14,0,MATCH(E$8,$K$8:$BR$8,0)) -> 0 | F14: =INDEX($K14:$BR14,0,MATCH(F$8,$K$8:$BR$8,0)) -> 0 | G14: =INDEX($K14:$BR14,0,MATCH(G$8,$K$8:$BR$8,0)) -> 0 | H14: =INDEX($K14:$BR14,0,MATCH(H$8,$K$8:$BR$8,0)) -> 0 | I14: =INDEX($K14:$BR14,0,MATCH(I$8,$K$8:$BR$8,0)) -> 0 | K14: =Capex!K47 -> 0 | L14: =Capex!L47 -> 0 | M14: =Capex!M47 -> 0 | N14: =Capex!N47 -> 0 | O14: =Capex!O47 -> 0 | P14: =Capex!P47 -> 0 | Q14: =Capex!Q47 -> 0 | R14: =Capex!R47 -> 0 | ... BR14: =Capex!BR47 -> 0
B15: =KeyInputs!F63 -> Property | D15: =unit -> £ | E15: =INDEX($K15:$BR15,0,MATCH(E$8,$K$8:$BR$8,0)) -> 0 | F15: =INDEX($K15:$BR15,0,MATCH(F$8,$K$8:$BR$8,0)) -> 0 | G15: =INDEX($K15:$BR15,0,MATCH(G$8,$K$8:$BR$8,0)) -> 0 | H15: =INDEX($K15:$BR15,0,MATCH(H$8,$K$8:$BR$8,0)) -> 0 | I15: =INDEX($K15:$BR15,0,MATCH(I$8,$K$8:$BR$8,0)) -> 0 | K15: =Capex!K57 -> 0 | L15: =Capex!L57 -> 0 | M15: =Capex!M57 -> 0 | N15: =Capex!N57 -> 0 | O15: =Capex!O57 -> 0 | P15: =Capex!P57 -> 0 | Q15: =Capex!Q57 -> 0 | R15: =Capex!R57 -> 0 | ... BR15: =Capex!BR57 -> 0
B16: =KeyInputs!F64 -> Vehicles | D16: =unit -> £ | E16: =INDEX($K16:$BR16,0,MATCH(E$8,$K$8:$BR$8,0)) -> 0 | F16: =INDEX($K16:$BR16,0,MATCH(F$8,$K$8:$BR$8,0)) -> 0 | G16: =INDEX($K16:$BR16,0,MATCH(G$8,$K$8:$BR$8,0)) -> 0 | H16: =INDEX($K16:$BR16,0,MATCH(H$8,$K$8:$BR$8,0)) -> 0 | I16: =INDEX($K16:$BR16,0,MATCH(I$8,$K$8:$BR$8,0)) -> 0 | K16: =Capex!K67 -> 0 | L16: =Capex!L67 -> 0 | M16: =Capex!M67 -> 0 | N16: =Capex!N67 -> 0 | O16: =Capex!O67 -> 0 | P16: =Capex!P67 -> 0 | Q16: =Capex!Q67 -> 0 | R16: =Capex!R67 -> 0 | ... BR16: =Capex!BR67 -> 0
B17: =KeyInputs!F65 -> n/a | D17: =unit -> £ | E17: =INDEX($K17:$BR17,0,MATCH(E$8,$K$8:$BR$8,0)) -> 0 | F17: =INDEX($K17:$BR17,0,MATCH(F$8,$K$8:$BR$8,0)) -> 0 | G17: =INDEX($K17:$BR17,0,MATCH(G$8,$K$8:$BR$8,0)) -> 0 | H17: =INDEX($K17:$BR17,0,MATCH(H$8,$K$8:$BR$8,0)) -> 0 | I17: =INDEX($K17:$BR17,0,MATCH(I$8,$K$8:$BR$8,0)) -> 0 | K17: =Capex!K77 -> 0 | L17: =Capex!L77 -> 0 | M17: =Capex!M77 -> 0 | N17: =Capex!N77 -> 0 | O17: =Capex!O77 -> 0 | P17: =Capex!P77 -> 0 | Q17: =Capex!Q77 -> 0 | R17: =Capex!R77 -> 0 | ... BR17: =Capex!BR77 -> 0
B19: Trade debtors | D19: =unit -> £ | E19: =INDEX($K19:$BR19,0,MATCH(E$8,$K$8:$BR$8,0)) -> 0 | F19: =INDEX($K19:$BR19,0,MATCH(F$8,$K$8:$BR$8,0)) -> 0 | G19: =INDEX($K19:$BR19,0,MATCH(G$8,$K$8:$BR$8,0)) -> 0 | H19: =INDEX($K19:$BR19,0,MATCH(H$8,$K$8:$BR$8,0)) -> 0 | I19: =INDEX($K19:$BR19,0,MATCH(I$8,$K$8:$BR$8,0)) -> 0 | K19: =SUM(K20:K22) -> 0 | L19: =SUM(L20:L22) -> 0 | M19: =SUM(M20:M22) -> 0 | N19: =SUM(N20:N22) -> 0 | O19: =SUM(O20:O22) -> 0 | P19: =SUM(P20:P22) -> 0 | Q19: =SUM(Q20:Q22) -> 0 | R19: =SUM(R20:R22) -> 0 | ... BR19: =SUM(BR20:BR22) -> 0
B20: =KeyInputs!F21 -> Test | D20: =unit -> £ | E20: =INDEX($K20:$BR20,0,MATCH(E$8,$K$8:$BR$8,0)) -> 0 | F20: =INDEX($K20:$BR20,0,MATCH(F$8,$K$8:$BR$8,0)) -> 0 | G20: =INDEX($K20:$BR20,0,MATCH(G$8,$K$8:$BR$8,0)) -> 0 | H20: =INDEX($K20:$BR20,0,MATCH(H$8,$K$8:$BR$8,0)) -> 0 | I20: =INDEX($K20:$BR20,0,MATCH(I$8,$K$8:$BR$8,0)) -> 0 | K20: =WorkingCapital!K21 -> 0 | L20: =WorkingCapital!L21 -> 0 | M20: =WorkingCapital!M21 -> 0 | N20: =WorkingCapital!N21 -> 0 | O20: =WorkingCapital!O21 -> 0 | P20: =WorkingCapital!P21 -> 0 | Q20: =WorkingCapital!Q21 -> 0 | R20: =WorkingCapital!R21 -> 0 | ... BR20: =WorkingCapital!BR21 -> 0
B21: =KeyInputs!F26 -> Insert Business Line2 | D21: =unit -> £ | E21: =INDEX($K21:$BR21,0,MATCH(E$8,$K$8:$BR$8,0)) -> 0 | F21: =INDEX($K21:$BR21,0,MATCH(F$8,$K$8:$BR$8,0)) -> 0 | G21: =INDEX($K21:$BR21,0,MATCH(G$8,$K$8:$BR$8,0)) -> 0 | H21: =INDEX($K21:$BR21,0,MATCH(H$8,$K$8:$BR$8,0)) -> 0 | I21: =INDEX($K21:$BR21,0,MATCH(I$8,$K$8:$BR$8,0)) -> 0 | K21: =WorkingCapital!K32 -> 0 | L21: =WorkingCapital!L32 -> 0 | M21: =WorkingCapital!M32 -> 0 | N21: =WorkingCapital!N32 -> 0 | O21: =WorkingCapital!O32 -> 0 | P21: =WorkingCapital!P32 -> 0 | Q21: =WorkingCapital!Q32 -> 0 | R21: =WorkingCapital!R32 -> 0 | ... BR21: =WorkingCapital!BR32 -> 0
B22: =KeyInputs!F31 -> Insert Business Line3 | D22: =unit -> £ | E22: =INDEX($K22:$BR22,0,MATCH(E$8,$K$8:$BR$8,0)) -> 0 | F22: =INDEX($K22:$BR22,0,MATCH(F$8,$K$8:$BR$8,0)) -> 0 | G22: =INDEX($K22:$BR22,0,MATCH(G$8,$K$8:$BR$8,0)) -> 0 | H22: =INDEX($K22:$BR22,0,MATCH(H$8,$K$8:$BR$8,0)) -> 0 | I22: =INDEX($K22:$BR22,0,MATCH(I$8,$K$8:$BR$8,0)) -> 0 | K22: =WorkingCapital!K43 -> 0 | L22: =WorkingCapital!L43 -> 0 | M22: =WorkingCapital!M43 -> 0 | N22: =WorkingCapital!N43 -> 0 | O22: =WorkingCapital!O43 -> 0 | P22: =WorkingCapital!P43 -> 0 | Q22: =WorkingCapital!Q43 -> 0 | R22: =WorkingCapital!R43 -> 0 | ... BR22: =WorkingCapital!BR43 -> 0
B24: Stocks | D24: =unit -> £ | E24: =INDEX($K24:$BR24,0,MATCH(E$8,$K$8:$BR$8,0)) -> 0 | F24: =INDEX($K24:$BR24,0,MATCH(F$8,$K$8:$BR$8,0)) -> 0 | G24: =INDEX($K24:$BR24,0,MATCH(G$8,$K$8:$BR$8,0)) -> 0 | H24: =INDEX($K24:$BR24,0,MATCH(H$8,$K$8:$BR$8,0)) -> 0 | I24: =INDEX($K24:$BR24,0,MATCH(I$8,$K$8:$BR$8,0)) -> 0 | K24: =SUM(K25:K27) -> 0 | L24: =SUM(L25:L27) -> 0 | M24: =SUM(M25:M27) -> 0 | N24: =SUM(N25:N27) -> 0 | O24: =SUM(O25:O27) -> 0 | P24: =SUM(P25:P27) -> 0 | Q24: =SUM(Q25:Q27) -> 0 | R24: =SUM(R25:R27) -> 0 | ... BR24: =SUM(BR25:BR27) -> 0
B25: =B20 -> Test | D25: =unit -> £ | E25: =INDEX($K25:$BR25,0,MATCH(E$8,$K$8:$BR$8,0)) -> 0 | F25: =INDEX($K25:$BR25,0,MATCH(F$8,$K$8:$BR$8,0)) -> 0 | G25: =INDEX($K25:$BR25,0,MATCH(G$8,$K$8:$BR$8,0)) -> 0 | H25: =INDEX($K25:$BR25,0,MATCH(H$8,$K$8:$BR$8,0)) -> 0 | I25: =INDEX($K25:$BR25,0,MATCH(I$8,$K$8:$BR$8,0)) -> 0 | K25: =WorkingCapital!K56 -> 0 | L25: =WorkingCapital!L56 -> 0 | M25: =WorkingCapital!M56 -> 0 | N25: =WorkingCapital!N56 -> 0 | O25: =WorkingCapital!O56 -> 0 | P25: =WorkingCapital!P56 -> 0 | Q25: =WorkingCapital!Q56 -> 0 | R25: =WorkingCapital!R56 -> 0 | ... BR25: =WorkingCapital!BR56 -> 0
B26: =B21 -> Insert Business Line2 | D26: =unit -> £ | E26: =INDEX($K26:$BR26,0,MATCH(E$8,$K$8:$BR$8,0)) -> 0 | F26: =INDEX($K26:$BR26,0,MATCH(F$8,$K$8:$BR$8,0)) -> 0 | G26: =INDEX($K26:$BR26,0,MATCH(G$8,$K$8:$BR$8,0)) -> 0 | H26: =INDEX($K26:$BR26,0,MATCH(H$8,$K$8:$BR$8,0)) -> 0 | I26: =INDEX($K26:$BR26,0,MATCH(I$8,$K$8:$BR$8,0)) -> 0 | K26: =WorkingCapital!K67 -> 0 | L26: =WorkingCapital!L67 -> 0 | M26: =WorkingCapital!M67 -> 0 | N26: =WorkingCapital!N67 -> 0 | O26: =WorkingCapital!O67 -> 0 | P26: =WorkingCapital!P67 -> 0 | Q26: =WorkingCapital!Q67 -> 0 | R26: =WorkingCapital!R67 -> 0 | ... BR26: =WorkingCapital!BR67 -> 0
B27: =B22 -> Insert Business Line3 | D27: =unit -> £ | E27: =INDEX($K27:$BR27,0,MATCH(E$8,$K$8:$BR$8,0)) -> 0 | F27: =INDEX($K27:$BR27,0,MATCH(F$8,$K$8:$BR$8,0)) -> 0 | G27: =INDEX($K27:$BR27,0,MATCH(G$8,$K$8:$BR$8,0)) -> 0 | H27: =INDEX($K27:$BR27,0,MATCH(H$8,$K$8:$BR$8,0)) -> 0 | I27: =INDEX($K27:$BR27,0,MATCH(I$8,$K$8:$BR$8,0)) -> 0 | K27: =WorkingCapital!K78 -> 0 | L27: =WorkingCapital!L78 -> 0 | M27: =WorkingCapital!M78 -> 0 | N27: =WorkingCapital!N78 -> 0 | O27: =WorkingCapital!O78 -> 0 | P27: =WorkingCapital!P78 -> 0 | Q27: =WorkingCapital!Q78 -> 0 | R27: =WorkingCapital!R78 -> 0 | ... BR27: =WorkingCapital!BR78 -> 0
B29: Cash at bank | D29: =unit -> £ | E29: =INDEX($K29:$BR29,0,MATCH(E$8,$K$8:$BR$8,0)) -> 0 | F29: =INDEX($K29:$BR29,0,MATCH(F$8,$K$8:$BR$8,0)) -> 0 | G29: =INDEX($K29:$BR29,0,MATCH(G$8,$K$8:$BR$8,0)) -> 0 | H29: =INDEX($K29:$BR29,0,MATCH(H$8,$K$8:$BR$8,0)) -> 0 | I29: =INDEX($K29:$BR29,0,MATCH(I$8,$K$8:$BR$8,0)) -> 0 | K29: =MAX('Outputs - Cashflow'!K$41,0) -> 0 | L29: =MAX('Outputs - Cashflow'!L$41,0) -> 0 | M29: =MAX('Outputs - Cashflow'!M$41,0) -> 0 | N29: =MAX('Outputs - Cashflow'!N$41,0) -> 0 | O29: =MAX('Outputs - Cashflow'!O$41,0) -> 0 | P29: =MAX('Outputs - Cashflow'!P$41,0) -> 0 | Q29: =MAX('Outputs - Cashflow'!Q$41,0) -> 0 | R29: =MAX('Outputs - Cashflow'!R$41,0) -> 0 | ... BR29: =MAX('Outputs - Cashflow'!BR$41,0) -> 0
B31: Overdraft | D31: =unit -> £ | E31: =INDEX($K31:$BR31,0,MATCH(E$8,$K$8:$BR$8,0)) -> 0 | F31: =INDEX($K31:$BR31,0,MATCH(F$8,$K$8:$BR$8,0)) -> 0 | G31: =INDEX($K31:$BR31,0,MATCH(G$8,$K$8:$BR$8,0)) -> 0 | H31: =INDEX($K31:$BR31,0,MATCH(H$8,$K$8:$BR$8,0)) -> 0 | I31: =INDEX($K31:$BR31,0,MATCH(I$8,$K$8:$BR$8,0)) -> 0 | K31: =MIN('Outputs - Cashflow'!K$41,0) -> 0 | L31: =MIN('Outputs - Cashflow'!L$41,0) -> 0 | M31: =MIN('Outputs - Cashflow'!M$41,0) -> 0 | N31: =MIN('Outputs - Cashflow'!N$41,0) -> 0 | O31: =MIN('Outputs - Cashflow'!O$41,0) -> 0 | P31: =MIN('Outputs - Cashflow'!P$41,0) -> 0 | Q31: =MIN('Outputs - Cashflow'!Q$41,0) -> 0 | R31: =MIN('Outputs - Cashflow'!R$41,0) -> 0 | ... BR31: =MIN('Outputs - Cashflow'!BR$41,0) -> 0
B32: Trade creditors | D32: =unit -> £ | E32: =INDEX($K32:$BR32,0,MATCH(E$8,$K$8:$BR$8,0)) -> 0 | F32: =INDEX($K32:$BR32,0,MATCH(F$8,$K$8:$BR$8,0)) -> 0 | G32: =INDEX($K32:$BR32,0,MATCH(G$8,$K$8:$BR$8,0)) -> 0 | H32: =INDEX($K32:$BR32,0,MATCH(H$8,$K$8:$BR$8,0)) -> 0 | I32: =INDEX($K32:$BR32,0,MATCH(I$8,$K$8:$BR$8,0)) -> 0 | K32: =WorkingCapital!K$91 -> 0 | L32: =WorkingCapital!L$91 -> 0 | M32: =WorkingCapital!M$91 -> 0 | N32: =WorkingCapital!N$91 -> 0 | O32: =WorkingCapital!O$91 -> 0 | P32: =WorkingCapital!P$91 -> 0 | Q32: =WorkingCapital!Q$91 -> 0 | R32: =WorkingCapital!R$91 -> 0 | ... BR32: =WorkingCapital!BR$91 -> 0
B33: VAT CHANGED | D33: =unit -> £ | E33: =INDEX($K33:$BR33,0,MATCH(E$8,$K$8:$BR$8,0)) -> 0 | F33: =INDEX($K33:$BR33,0,MATCH(F$8,$K$8:$BR$8,0)) -> 0 | G33: =INDEX($K33:$BR33,0,MATCH(G$8,$K$8:$BR$8,0)) -> 0 | H33: =INDEX($K33:$BR33,0,MATCH(H$8,$K$8:$BR$8,0)) -> 0 | I33: =INDEX($K33:$BR33,0,MATCH(I$8,$K$8:$BR$8,0)) -> 0 | K33: =WorkingCapital!K108*-1 -> 0 | L33: =WorkingCapital!L108*-1 -> 0 | M33: =WorkingCapital!M108*-1 -> 0 | N33: =WorkingCapital!N108*-1 -> 0 | O33: =WorkingCapital!O108*-1 -> 0 | P33: =WorkingCapital!P108*-1 -> 0 | Q33: =WorkingCapital!Q108*-1 -> 0 | R33: =WorkingCapital!R108*-1 -> 0 | ... BR33: =WorkingCapital!BR108*-1 -> 0
B34: Interest on debt payable | D34: =unit -> £ | E34: =INDEX($K34:$BR34,0,MATCH(E$8,$K$8:$BR$8,0)) -> 0 | F34: =INDEX($K34:$BR34,0,MATCH(F$8,$K$8:$BR$8,0)) -> 0 | G34: =INDEX($K34:$BR34,0,MATCH(G$8,$K$8:$BR$8,0)) -> 0 | H34: =INDEX($K34:$BR34,0,MATCH(H$8,$K$8:$BR$8,0)) -> 0 | I34: =INDEX($K34:$BR34,0,MATCH(I$8,$K$8:$BR$8,0)) -> 0 | K34: =DebtFinancing!K$24 -> 0 | L34: =DebtFinancing!L$24 -> 0 | M34: =DebtFinancing!M$24 -> 0 | N34: =DebtFinancing!N$24 -> 0 | O34: =DebtFinancing!O$24 -> 0 | P34: =DebtFinancing!P$24 -> 0 | Q34: =DebtFinancing!Q$24 -> 0 | R34: =DebtFinancing!R$24 -> 0 | ... BR34: =DebtFinancing!BR$24 -> 0
B35: Term debt | D35: =unit -> £ | E35: =INDEX($K35:$BR35,0,MATCH(E$8,$K$8:$BR$8,0)) -> 0 | F35: =INDEX($K35:$BR35,0,MATCH(F$8,$K$8:$BR$8,0)) -> 0 | G35: =INDEX($K35:$BR35,0,MATCH(G$8,$K$8:$BR$8,0)) -> 0 | H35: =INDEX($K35:$BR35,0,MATCH(H$8,$K$8:$BR$8,0)) -> 0 | I35: =INDEX($K35:$BR35,0,MATCH(I$8,$K$8:$BR$8,0)) -> 0 | K35: =DebtFinancing!K$17 -> 0 | L35: =DebtFinancing!L$17 -> 0 | M35: =DebtFinancing!M$17 -> 0 | N35: =DebtFinancing!N$17 -> 0 | O35: =DebtFinancing!O$17 -> 0 | P35: =DebtFinancing!P$17 -> 0 | Q35: =DebtFinancing!Q$17 -> 0 | R35: =DebtFinancing!R$17 -> 0 | ... BR35: =DebtFinancing!BR$17 -> 0
B36: Grant deferred income | D36: =unit -> £ | E36: =INDEX($K36:$BR36,0,MATCH(E$8,$K$8:$BR$8,0)) -> 0 | F36: =INDEX($K36:$BR36,0,MATCH(F$8,$K$8:$BR$8,0)) -> 0 | G36: =INDEX($K36:$BR36,0,MATCH(G$8,$K$8:$BR$8,0)) -> 0 | H36: =INDEX($K36:$BR36,0,MATCH(H$8,$K$8:$BR$8,0)) -> 0 | I36: =INDEX($K36:$BR36,0,MATCH(I$8,$K$8:$BR$8,0)) -> 0 | K36: =GrantIncome!K17 -> 0 | L36: =GrantIncome!L17 -> 0 | M36: =GrantIncome!M17 -> 0 | N36: =GrantIncome!N17 -> 0 | O36: =GrantIncome!O17 -> 0 | P36: =GrantIncome!P17 -> 0 | Q36: =GrantIncome!Q17 -> 0 | R36: =GrantIncome!R17 -> 0 | ... BR36: =GrantIncome!BR17 -> 0
B37: Current tax | D37: =unit -> £ | E37: =INDEX($K37:$BR37,0,MATCH(E$8,$K$8:$BR$8,0)) -> 0 | F37: =INDEX($K37:$BR37,0,MATCH(F$8,$K$8:$BR$8,0)) -> 0 | G37: =INDEX($K37:$BR37,0,MATCH(G$8,$K$8:$BR$8,0)) -> 0 | H37: =INDEX($K37:$BR37,0,MATCH(H$8,$K$8:$BR$8,0)) -> 0 | I37: =INDEX($K37:$BR37,0,MATCH(I$8,$K$8:$BR$8,0)) -> 0 | K37: =TAX!K$44 -> 0 | L37: =TAX!L$44 -> 0 | M37: =TAX!M$44 -> 0 | N37: =TAX!N$44 -> 0 | O37: =TAX!O$44 -> 0 | P37: =TAX!P$44 -> 0 | Q37: =TAX!Q$44 -> 0 | R37: =TAX!R$44 -> 0 | ... BR37: =TAX!BR$44 -> 0
B39: Net assets | D39: =unit -> £ | E39: =SUM(E12,E19,E24,E29,E31:E37) -> 0 | F39: =SUM(F12,F19,F24,F29,F31:F37) -> 0 | G39: =SUM(G12,G19,G24,G29,G31:G37) -> 0 | H39: =SUM(H12,H19,H24,H29,H31:H37) -> 0 | I39: =SUM(I12,I19,I24,I29,I31:I37) -> 0 | K39: =SUM(K12,K19,K24,K29,K31:K37) -> 0 | L39: =SUM(L12,L19,L24,L29,L31:L37) -> 0 | M39: =SUM(M12,M19,M24,M29,M31:M37) -> 0 | N39: =SUM(N12,N19,N24,N29,N31:N37) -> 0 | O39: =SUM(O12,O19,O24,O29,O31:O37) -> 0 | P39: =SUM(P12,P19,P24,P29,P31:P37) -> 0 | Q39: =SUM(Q12,Q19,Q24,Q29,Q31:Q37) -> 0 | R39: =SUM(R12,R19,R24,R29,R31:R37) -> 0 | ... BR39: =SUM(BR12,BR19,BR24,BR29,BR31:BR37) -> 0
B41: Share capital | D41: =unit -> £ | E41: =INDEX($K41:$BR41,0,MATCH(E$8,$K$8:$BR$8,0)) -> 0 | F41: =INDEX($K41:$BR41,0,MATCH(F$8,$K$8:$BR$8,0)) -> 0 | G41: =INDEX($K41:$BR41,0,MATCH(G$8,$K$8:$BR$8,0)) -> 0 | H41: =INDEX($K41:$BR41,0,MATCH(H$8,$K$8:$BR$8,0)) -> 0 | I41: =INDEX($K41:$BR41,0,MATCH(I$8,$K$8:$BR$8,0)) -> 0 | K41: =KeyInputs!G140+EquityFinancing!K22 -> 0 | L41: =K41+EquityFinancing!L22 -> 0 | M41: =L41+EquityFinancing!M22 -> 0 | N41: =M41+EquityFinancing!N22 -> 0 | O41: =N41+EquityFinancing!O22 -> 0 | P41: =O41+EquityFinancing!P22 -> 0 | Q41: =P41+EquityFinancing!Q22 -> 0 | R41: =Q41+EquityFinancing!R22 -> 0 | S41: =R41+EquityFinancing!S22 -> 0 | ... BR41: =BQ41+EquityFinancing!BR22 -> 0
B42: P&L reserve | D42: =unit -> £ | E42: =INDEX($K42:$BR42,0,MATCH(E$8,$K$8:$BR$8,0)) -> 0 | F42: =INDEX($K42:$BR42,0,MATCH(F$8,$K$8:$BR$8,0)) -> 0 | G42: =INDEX($K42:$BR42,0,MATCH(G$8,$K$8:$BR$8,0)) -> 0 | H42: =INDEX($K42:$BR42,0,MATCH(H$8,$K$8:$BR$8,0)) -> 0 | I42: =INDEX($K42:$BR42,0,MATCH(I$8,$K$8:$BR$8,0)) -> 0 | K42: ='Outputs - P&L'!K48 -> 0 | L42: ='Outputs - P&L'!L48 -> 0 | M42: ='Outputs - P&L'!M48 -> 0 | N42: ='Outputs - P&L'!N48 -> 0 | O42: ='Outputs - P&L'!O48 -> 0 | P42: ='Outputs - P&L'!P48 -> 0 | Q42: ='Outputs - P&L'!Q48 -> 0 | R42: ='Outputs - P&L'!R48 -> 0 | ... BR42: ='Outputs - P&L'!BR48 -> 0
B44: Shareholders' funds | D44: =unit -> £ | E44: =SUM(E41:E43) -> 0 | F44: =SUM(F41:F43) -> 0 | G44: =SUM(G41:G43) -> 0 | H44: =SUM(H41:H43) -> 0 | I44: =SUM(I41:I43) -> 0 | K44: =SUM(K41:K43) -> 0 | L44: =SUM(L41:L43) -> 0 | M44: =SUM(M41:M43) -> 0 | N44: =SUM(N41:N43) -> 0 | O44: =SUM(O41:O43) -> 0 | P44: =SUM(P41:P43) -> 0 | Q44: =SUM(Q41:Q43) -> 0 | R44: =SUM(R41:R43) -> 0 | ... BR44: =SUM(BR41:BR43) -> 0
B46: Check | E46: =IF(ABS(E44-E39)>Tolerance,1,0) -> 0 | F46: =IF(ABS(F44-F39)>Tolerance,1,0) -> 0 | G46: =IF(ABS(G44-G39)>Tolerance,1,0) -> 0 | H46: =IF(ABS(H44-H39)>Tolerance,1,0) -> 0 | I46: =IF(ABS(I44-I39)>Tolerance,1,0) -> 0 | K46: =IF(ABS(K44-K39)>Tolerance,1,0) -> 0 | L46: =IF(ABS(L44-L39)>Tolerance,1,0) -> 0 | M46: =IF(ABS(M44-M39)>Tolerance,1,0) -> 0 | N46: =IF(ABS(N44-N39)>Tolerance,1,0) -> 0 | O46: =IF(ABS(O44-O39)>Tolerance,1,0) -> 0 | P46: =IF(ABS(P44-P39)>Tolerance,1,0) -> 0 | Q46: =IF(ABS(Q44-Q39)>Tolerance,1,0) -> 0 | R46: =IF(ABS(R44-R39)>Tolerance,1,0) -> 0 | ... BR46: =IF(ABS(BR44-BR39)>Tolerance,1,0) -> 0
A48: End of sheet

Sheet Outputs - Cashflow
A3: =IF(KeyInputs!$F$14=0,"Company Name",KeyInputs!$F$14) -> Company Name
A4: Cash Flow Statement
D5: =KeyInputs!D5 -> Year | E5: =KeyInputs!H5 -> 2015 | F5: =KeyInputs!I5 -> 2016 | G5: =KeyInputs!J5 -> 2017 | H5: =KeyInputs!K5 -> 2018 | I5: =KeyInputs!L5 -> 2019 | K5: =KeyInputs!N5 -> 2015 | L5: =KeyInputs!O5 -> 2015 | M5: =KeyInputs!P5 -> 2015 | N5: =KeyInputs!Q5 -> 2015 | O5: =KeyInputs!R5 -> 2015 | P5: =KeyInputs!S5 -> 2015 | Q5: =KeyInputs!T5 -> 2015 | R5: =KeyInputs!U5 -> 2015 | ... BR5: =KeyInputs!BU5 -> 2019
D6: =KeyInputs!D6 -> Period number | E6: =KeyInputs!H6 -> 1 | F6: =KeyInputs!I6 -> 2 | G6: =KeyInputs!J6 -> 3 | H6: =KeyInputs!K6 -> 4 | I6: =KeyInputs!L6 -> 5 | K6: =KeyInputs!N6 -> 1 | L6: =KeyInputs!O6 -> 2 | M6: =KeyInputs!P6 -> 3 | N6: =KeyInputs!Q6 -> 4 | O6: =KeyInputs!R6 -> 5 | P6: =KeyInputs!S6 -> 6 | Q6: =KeyInputs!T6 -> 7 | R6: =KeyInputs!U6 -> 8 | ... BR6: =KeyInputs!BU6 -> 60
D7: =KeyInputs!D7 -> Period starts | E7: =KeyInputs!H7 -> 42005 | F7: =KeyInputs!I7 -> 42370 | G7: =KeyInputs!J7 -> 42736 | H7: =KeyInputs!K7 -> 43101 | I7: =KeyInputs!L7 -> 43466 | K7: =KeyInputs!N7 -> 42005 | L7: =KeyInputs!O7 -> 42036 | M7: =KeyInputs!P7 -> 42064 | N7: =KeyInputs!Q7 -> 42095 | O7: =KeyInputs!R7 -> 42125 | P7: =KeyInputs!S7 -> 42156 | Q7: =KeyInputs!T7 -> 42186 | R7: =KeyInputs!U7 -> 42217 | ... BR7: =KeyInputs!BU7 -> 43800
B8: =IF(Check!$C$12=0,"All checks are OK","There are "&Check!$C$12&" error/errors") -> All checks are OK | D8: =KeyInputs!D8 -> Period ends | E8: =KeyInputs!H8 -> 42369 | F8: =KeyInputs!I8 -> 42735 | G8: =KeyInputs!J8 -> 43100 | H8: =KeyInputs!K8 -> 43465 | I8: =KeyInputs!L8 -> 43830 | K8: =KeyInputs!N8 -> 42035 | L8: =KeyInputs!O8 -> 42063 | M8: =KeyInputs!P8 -> 42094 | N8: =KeyInputs!Q8 -> 42124 | O8: =KeyInputs!R8 -> 42155 | P8: =KeyInputs!S8 -> 42185 | Q8: =KeyInputs!T8 -> 42216 | R8: =KeyInputs!U8 -> 42247 | ... BR8: =KeyInputs!BU8 -> 43830
A10: =Header1 -> 1 | B10: Cash Flow Statement
B12: Operating profit | D12: =unit -> £ | E12: =SUMIF($K$5:$BR$5,E$5,$K12:$BR12) -> 0 | F12: =SUMIF($K$5:$BR$5,F$5,$K12:$BR12) -> 0 | G12: =SUMIF($K$5:$BR$5,G$5,$K12:$BR12) -> 0 | H12: =SUMIF($K$5:$BR$5,H$5,$K12:$BR12) -> 0 | I12: =SUMIF($K$5:$BR$5,I$5,$K12:$BR12) -> 0 | K12: ='Outputs - P&L'!K$32 -> 0 | L12: ='Outputs - P&L'!L$32 -> 0 | M12: ='Outputs - P&L'!M$32 -> 0 | N12: ='Outputs - P&L'!N$32 -> 0 | O12: ='Outputs - P&L'!O$32 -> 0 | P12: ='Outputs - P&L'!P$32 -> 0 | Q12: ='Outputs - P&L'!Q$32 -> 0 | R12: ='Outputs - P&L'!R$32 -> 0 | ... BR12: ='Outputs - P&L'!BR$32 -> 0
B14: add back depreciation | D14: =unit -> £ | E14: =SUMIF($K$5:$BR$5,E$5,$K14:$BR14) -> 0 | F14: =SUMIF($K$5:$BR$5,F$5,$K14:$BR14) -> 0 | G14: =SUMIF($K$5:$BR$5,G$5,$K14:$BR14) -> 0 | H14: =SUMIF($K$5:$BR$5,H$5,$K14:$BR14) -> 0 | I14: =SUMIF($K$5:$BR$5,I$5,$K14:$BR14) -> 0 | K14: =-'Outputs - P&L'!K$31 -> 0 | L14: =-'Outputs - P&L'!L$31 -> 0 | M14: =-'Outputs - P&L'!M$31 -> 0 | N14: =-'Outputs - P&L'!N$31 -> 0 | O14: =-'Outputs - P&L'!O$31 -> 0 | P14: =-'Outputs - P&L'!P$31 -> 0 | Q14: =-'Outputs - P&L'!Q$31 -> 0 | R14: =-'Outputs - P&L'!R$31 -> 0 | ... BR14: =-'Outputs - P&L'!BR$31 -> 0
B15: movement in trade debtors | D15: =unit -> £ | E15: =SUMIF($K$5:$BR$5,E$5,$K15:$BR15) -> 0 | F15: =SUMIF($K$5:$BR$5,F$5,$K15:$BR15) -> 0 | G15: =SUMIF($K$5:$BR$5,G$5,$K15:$BR15) -> 0 | H15: =SUMIF($K$5:$BR$5,H$5,$K15:$BR15) -> 0 | I15: =SUMIF($K$5:$BR$5,I$5,$K15:$BR15) -> 0 | K15: =WorkingCapital!K23+WorkingCapital!K34+WorkingCapital!K45 -> 0 | L15: =WorkingCapital!L23+WorkingCapital!L34+WorkingCapital!L45 -> 0 | M15: =WorkingCapital!M23+WorkingCapital!M34+WorkingCapital!M45 -> 0 | N15: =WorkingCapital!N23+WorkingCapital!N34+WorkingCapital!N45 -> 0 | O15: =WorkingCapital!O23+WorkingCapital!O34+WorkingCapital!O45 -> 0 | P15: =WorkingCapital!P23+WorkingCapital!P34+WorkingCapital!P45 -> 0 | Q15: =WorkingCapital!Q23+WorkingCapital!Q34+WorkingCapital!Q45 -> 0 | R15: =WorkingCapital!R23+WorkingCapital!R34+WorkingCapital!R45 -> 0 | ... BR15: =WorkingCapital!BR23+WorkingCapital!BR34+WorkingCapital!BR45 -> 0
B16: movement in stocks | D16: =unit -> £ | E16: =SUMIF($K$5:$BR$5,E$5,$K16:$BR16) -> 0 | F16: =SUMIF($K$5:$BR$5,F$5,$K16:$BR16) -> 0 | G16: =SUMIF($K$5:$BR$5,G$5,$K16:$BR16) -> 0 | H16: =SUMIF($K$5:$BR$5,H$5,$K16:$BR16) -> 0 | I16: =SUMIF($K$5:$BR$5,I$5,$K16:$BR16) -> 0 | K16: =WorkingCapital!K58+WorkingCapital!K69+WorkingCapital!K80 -> 0 | L16: =WorkingCapital!L58+WorkingCapital!L69+WorkingCapital!L80 -> 0 | M16: =WorkingCapital!M58+WorkingCapital!M69+WorkingCapital!M80 -> 0 | N16: =WorkingCapital!N58+WorkingCapital!N69+WorkingCapital!N80 -> 0 | O16: =WorkingCapital!O58+WorkingCapital!O69+WorkingCapital!O80 -> 0 | P16: =WorkingCapital!P58+WorkingCapital!P69+WorkingCapital!P80 -> 0 | Q16: =WorkingCapital!Q58+WorkingCapital!Q69+WorkingCapital!Q80 -> 0 | R16: =WorkingCapital!R58+WorkingCapital!R69+WorkingCapital!R80 -> 0 | ... BR16: =WorkingCapital!BR58+WorkingCapital!BR69+WorkingCapital!BR80 -> 0
B17: movement in trade creditors | D17: =unit -> £ | E17: =SUMIF($K$5:$BR$5,E$5,$K17:$BR17) -> 0 | F17: =SUMIF($K$5:$BR$5,F$5,$K17:$BR17) -> 0 | G17: =SUMIF($K$5:$BR$5,G$5,$K17:$BR17) -> 0 | H17: =SUMIF($K$5:$BR$5,H$5,$K17:$BR17) -> 0 | I17: =SUMIF($K$5:$BR$5,I$5,$K17:$BR17) -> 0 | K17: =WorkingCapital!K93 -> 0 | L17: =WorkingCapital!L93 -> 0 | M17: =WorkingCapital!M93 -> 0 | N17: =WorkingCapital!N93 -> 0 | O17: =WorkingCapital!O93 -> 0 | P17: =WorkingCapital!P93 -> 0 | Q17: =WorkingCapital!Q93 -> 0 | R17: =WorkingCapital!R93 -> 0 | ... BR17: =WorkingCapital!BR93 -> 0
B18: movement in VAT | D18: =unit -> £ | E18: =SUMIF($K$5:$BR$5,E$5,$K18:$BR18) -> 0 | F18: =SUMIF($K$5:$BR$5,F$5,$K18:$BR18) -> 0 | G18: =SUMIF($K$5:$BR$5,G$5,$K18:$BR18) -> 0 | H18: =SUMIF($K$5:$BR$5,H$5,$K18:$BR18) -> 0 | I18: =SUMIF($K$5:$BR$5,I$5,$K18:$BR18) -> 0 | K18: =WorkingCapital!K110 -> 0 | L18: =WorkingCapital!L110 -> 0 | M18: =WorkingCapital!M110 -> 0 | N18: =WorkingCapital!N110 -> 0 | O18: =WorkingCapital!O110 -> 0 | P18: =WorkingCapital!P110 -> 0 | Q18: =WorkingCapital!Q110 -> 0 | R18: =WorkingCapital!R110 -> 0 | ... BR18: =WorkingCapital!BR110 -> 0
B19: Operating cash flow | D19: =unit -> £ | E19: =SUM(E12:E18) -> 0 | F19: =SUM(F12:F18) -> 0 | G19: =SUM(G12:G18) -> 0 | H19: =SUM(H12:H18) -> 0 | I19: =SUM(I12:I18) -> 0 | K19: =SUM(K12:K18) -> 0 | L19: =SUM(L12:L18) -> 0 | M19: =SUM(M12:M18) -> 0 | N19: =SUM(N12:N18) -> 0 | O19: =SUM(O12:O18) -> 0 | P19: =SUM(P12:P18) -> 0 | Q19: =SUM(Q12:Q18) -> 0 | R19: =SUM(R12:R18) -> 0 | ... BR19: =SUM(BR12:BR18) -> 0
B21: Capital expenditure | D21: =unit -> £ | E21: =SUMIF($K$5:$BR$5,E$5,$K21:$BR21) -> 0 | F21: =SUMIF($K$5:$BR$5,F$5,$K21:$BR21) -> 0 | G21: =SUMIF($K$5:$BR$5,G$5,$K21:$BR21) -> 0 | H21: =SUMIF($K$5:$BR$5,H$5,$K21:$BR21) -> 0 | I21: =SUMIF($K$5:$BR$5,I$5,$K21:$BR21) -> 0 | K21: =-SUM(Capex!K13:K17) -> 0 | L21: =-SUM(Capex!L13:L17) -> 0 | M21: =-SUM(Capex!M13:M17) -> 0 | N21: =-SUM(Capex!N13:N17) -> 0 | O21: =-SUM(Capex!O13:O17) -> 0 | P21: =-SUM(Capex!P13:P17) -> 0 | Q21: =-SUM(Capex!Q13:Q17) -> 0 | R21: =-SUM(Capex!R13:R17) -> 0 | ... BR21: =-SUM(Capex!BR13:BR17) -> 0
B22: Proceeds of disposals | D22: =unit -> £ | E22: =SUMIF($K$5:$BR$5,E$5,$K22:$BR22) -> 0 | F22: =SUMIF($K$5:$BR$5,F$5,$K22:$BR22) -> 0 | G22: =SUMIF($K$5:$BR$5,G$5,$K22:$BR22) -> 0 | H22: =SUMIF($K$5:$BR$5,H$5,$K22:$BR22) -> 0 | I22: =SUMIF($K$5:$BR$5,I$5,$K22:$BR22) -> 0 | K22: =-SUM(Capex!K21:K25) -> 0 | L22: =-SUM(Capex!L21:L25) -> 0 | M22: =-SUM(Capex!M21:M25) -> 0 | N22: =-SUM(Capex!N21:N25) -> 0 | O22: =-SUM(Capex!O21:O25) -> 0 | P22: =-SUM(Capex!P21:P25) -> 0 | Q22: =-SUM(Capex!Q21:Q25) -> 0 | R22: =-SUM(Capex!R21:R25) -> 0 | ... BR22: =-SUM(Capex!BR21:BR25) -> 0
B24: Grant received | D24: =unit -> £ | E24: =SUMIF($K$5:$BR$5,E$5,$K24:$BR24) -> 0 | F24: =SUMIF($K$5:$BR$5,F$5,$K24:$BR24) -> 0 | G24: =SUMIF($K$5:$BR$5,G$5,$K24:$BR24) -> 0 | H24: =SUMIF($K$5:$BR$5,H$5,$K24:$BR24) -> 0 | I24: =SUMIF($K$5:$BR$5,I$5,$K24:$BR24) -> 0 | K24: =-GrantIncome!K15 -> 0 | L24: =-GrantIncome!L15 -> 0 | M24: =-GrantIncome!M15 -> 0 | N24: =-GrantIncome!N15 -> 0 | O24: =-GrantIncome!O15 -> 0 | P24: =-GrantIncome!P15 -> 0 | Q24: =-GrantIncome!Q15 -> 0 | R24: =-GrantIncome!R15 -> 0 | ... BR24: =-GrantIncome!BR15 -> 0
B25: Other income | D25: =unit -> £ | E25: =SUMIF($K$5:$BR$5,E$5,$K25:$BR25) -> 0 | F25: =SUMIF($K$5:$BR$5,F$5,$K25:$BR25) -> 0 | G25: =SUMIF($K$5:$BR$5,G$5,$K25:$BR25) -> 0 | H25: =SUMIF($K$5:$BR$5,H$5,$K25:$BR25) -> 0 | I25: =SUMIF($K$5:$BR$5,I$5,$K25:$BR25) -> 0 | K25: ='Other income'!K32 -> 0 | L25: ='Other income'!L32 -> 0 | M25: ='Other income'!M32 -> 0 | N25: ='Other income'!N32 -> 0 | O25: ='Other income'!O32 -> 0 | P25: ='Other income'!P32 -> 0 | Q25: ='Other income'!Q32 -> 0 | R25: ='Other income'!R32 -> 0 | ... BR25: ='Other income'!BR32 -> 0
B26: Equity finance received | D26: =unit -> £ | E26: =SUMIF($K$5:$BR$5,E$5,$K26:$BR26) -> 0 | F26: =SUMIF($K$5:$BR$5,F$5,$K26:$BR26) -> 0 | G26: =SUMIF($K$5:$BR$5,G$5,$K26:$BR26) -> 0 | H26: =SUMIF($K$5:$BR$5,H$5,$K26:$BR26) -> 0 | I26: =SUMIF($K$5:$BR$5,I$5,$K26:$BR26) -> 0 | K26: =EquityFinancing!K22 -> 0 | L26: =EquityFinancing!L22 -> 0 | M26: =EquityFinancing!M22 -> 0 | N26: =EquityFinancing!N22 -> 0 | O26: =EquityFinancing!O22 -> 0 | P26: =EquityFinancing!P22 -> 0 | Q26: =EquityFinancing!Q22 -> 0 | R26: =EquityFinancing!R22 -> 0 | ... BR26: =EquityFinancing!BR22 -> 0
B27: Drawings on debt | D27: =unit -> £ | E27: =SUMIF($K$5:$BR$5,E$5,$K27:$BR27) -> 0 | F27: =SUMIF($K$5:$BR$5,F$5,$K27:$BR27) -> 0 | G27: =SUMIF($K$5:$BR$5,G$5,$K27:$BR27) -> 0 | H27: =SUMIF($K$5:$BR$5,H$5,$K27:$BR27) -> 0 | I27: =SUMIF($K$5:$BR$5,I$5,$K27:$BR27) -> 0 | K27: =-DebtFinancing!K15 -> 0 | L27: =-DebtFinancing!L15 -> 0 | M27: =-DebtFinancing!M15 -> 0 | N27: =-DebtFinancing!N15 -> 0 | O27: =-DebtFinancing!O15 -> 0 | P27: =-DebtFinancing!P15 -> 0 | Q27: =-DebtFinancing!Q15 -> 0 | R27: =-DebtFinancing!R15 -> 0 | ... BR27: =-DebtFinancing!BR15 -> 0
B28: Repayments of debt | D28: =unit -> £ | E28: =SUMIF($K$5:$BR$5,E$5,$K28:$BR28) -> 0 | F28: =SUMIF($K$5:$BR$5,F$5,$K28:$BR28) -> 0 | G28: =SUMIF($K$5:$BR$5,G$5,$K28:$BR28) -> 0 | H28: =SUMIF($K$5:$BR$5,H$5,$K28:$BR28) -> 0 | I28: =SUMIF($K$5:$BR$5,I$5,$K28:$BR28) -> 0 | K28: =-DebtFinancing!K16 -> 0 | L28: =-DebtFinancing!L16 -> 0 | M28: =-DebtFinancing!M16 -> 0 | N28: =-DebtFinancing!N16 -> 0 | O28: =-DebtFinancing!O16 -> 0 | P28: =-DebtFinancing!P16 -> 0 | Q28: =-DebtFinancing!Q16 -> 0 | R28: =-DebtFinancing!R16 -> 0 | ... BR28: =-DebtFinancing!BR16 -> 0
B30: Interest on debt | D30: =unit -> £ | E30: =SUMIF($K$5:$BR$5,E$5,$K30:$BR30) -> 0 | F30: =SUMIF($K$5:$BR$5,F$5,$K30:$BR30) -> 0 | G30: =SUMIF($K$5:$BR$5,G$5,$K30:$BR30) -> 0 | H30: =SUMIF($K$5:$BR$5,H$5,$K30:$BR30) -> 0 | I30: =SUMIF($K$5:$BR$5,I$5,$K30:$BR30) -> 0 | K30: =-DebtFinancing!K23 -> 0 | L30: =-DebtFinancing!L23 -> 0 | M30: =-DebtFinancing!M23 -> 0 | N30: =-DebtFinancing!N23 -> 0 | O30: =-DebtFinancing!O23 -> 0 | P30: =-DebtFinancing!P23 -> 0 | Q30: =-DebtFinancing!Q23 -> 0 | R30: =-DebtFinancing!R23 -> 0 | ... BR30: =-DebtFinancing!BR23 -> 0
B32: Taxation | D32: =unit -> £ | E32: =SUMIF($K$5:$BR$5,E$5,$K32:$BR32) -> 0 | F32: =SUMIF($K$5:$BR$5,F$5,$K32:$BR32) -> 0 | G32: =SUMIF($K$5:$BR$5,G$5,$K32:$BR32) -> 0 | H32: =SUMIF($K$5:$BR$5,H$5,$K32:$BR32) -> 0 | I32: =SUMIF($K$5:$BR$5,I$5,$K32:$BR32) -> 0 | K32: =-TAX!K43 -> 0 | L32: =-TAX!L43 -> 0 | M32: =-TAX!M43 -> 0 | N32: =-TAX!N43 -> 0 | O32: =-TAX!O43 -> 0 | P32: =-TAX!P43 -> 0 | Q32: =-TAX!Q43 -> 0 | R32: =-TAX!R43 -> 0 | ... BR32: =-TAX!BR43 -> 0
