Workbook

Sheet Dashboard

Sheet Assumptions
B2: Year (units) | F2: 1 | G2: 2 | H2: 3 | I2: 4 | J2: 5
B3: Start Date | F3: =D13 -> 45748 | G3: =EDATE(F3,12) -> 46113 | H3: =EDATE(G3,12) -> 46478 | I3: =EDATE(H3,12) -> 46844 | J3: =EDATE(I3,12) -> 47209
B4: End Date | F4: =EDATE(D13,11) -> 46082 | G4: =EDATE(F4,12) -> 46447 | H4: =EDATE(G4,12) -> 46813 | I4: =EDATE(H4,12) -> 47178 | J4: =EDATE(I4,12) -> 47543
B5: Fiscal Year Label | F5: 25/26 | G5: 26/27 | H5: 27/28 | I5: 28/29 | J5: 29/30
L8: Comments
B10: 1. General Assumptions | C10: Comments
B13: Model Start Date | D13: 45748
B14: Model Duration (in months) | D14: 60
B15: Model Duration (in years) | D15: 5
B16: Fiscal Year | D16: April 1st- 31st March
B18: Price Inflation | F18: 0 | G18: 0.03 | H18: 0.03 | I18: 0.03 | J18: 0.03 | L18: [Assumption made on inflation]
B19: Cost Inflation | F19: 0 | G19: 0.05 | H19: 0.05 | I19: 0.05 | J19: 0.05
B24: 2. Revenue Assumptions
B27: Revenue Stream One
B29: Pipeline Assumptions | L29: [Reasoning]
B30: Conversion Rates % | L30: [Reasoning]
B31: # customers won | F31: =F29*F30 -> 0 | G31: =G29*G30 -> 0 | H31: =H29*H30 -> 0 | I31: =I29*I30 -> 0 | J31: =J29*J30 -> 0 | L31: [Reasoning]
B32: # Previous Year Contracts | L32: [Reasoning]
B33: # Total Contracts | F33: =E33+F31 -> 0 | G33: =SUM(G31:G32) -> 0 | H33: =H32+G33 -> 0 | I33: =I32+H33 -> 0 | J33: =J32+I33 -> 0 | L33: [Reasoning]
B35: % of Contracts by Tier | L35: [Reasoning]
B36: Tier 1 | L36: [Reasoning]
B37: Tier 2 | L37: [Reasoning]
B38: Tier 3 | L38: [Reasoning]
B39: check | F39: =100%-SUM(F36:F38) -> 1 | G39: =100%-SUM(G36:G38) -> 1 | H39: =100%-SUM(H36:H38) -> 1 | I39: =100%-SUM(I36:I38) -> 1 | J39: =100%-SUM(J36:J38) -> 1
B40: # of Contracts | L40: [Reasoning]
B41: Tier 1 | F41: =F$33*(1/3) -> 0 | G41: =G$33*(1/3) -> 0 | H41: =H$33*(1/3) -> 0 | I41: =I$33*(1/3) -> 0 | J41: =J$33*(1/3) -> 0 | L41: [Reasoning]
B42: Tier 2 | F42: =F$33*(1/3) -> 0 | G42: =G$33*(1/3) -> 0 | H42: =H$33*(1/3) -> 0 | I42: =I$33*(1/3) -> 0 | J42: =J$33*(1/3) -> 0 | L42: [Reasoning]
B43: Tier 3 | F43: =F$33*(1/3) -> 0 | G43: =G$33*(1/3) -> 0 | H43: =H$33*(1/3) -> 0 | I43: =I$33*(1/3) -> 0 | J43: =J$33*(1/3) -> 0 | L43: [Reasoning]
B45: £ of Contracts | L45: [Reasoning]
B46: Tier 1 | L46: [Reasoning]
B47: Tier 2 | L47: [Reasoning]
B48: Tier 3 | L48: [Reasoning]
B50: Income
B51: Tier 1 | F51: =F46*F41 -> 0 | G51: =G46*G41 -> 0 | H51: =H46*H41 -> 0 | I51: =I46*I41 -> 0 | J51: =J46*J41 -> 0
B52: Tier 2 | F52: =F47*F42 -> 0 | G52: =G47*G42 -> 0 | H52: =H47*H42 -> 0 | I52: =I47*I42 -> 0 | J52: =J47*J42 -> 0
B53: Tier 3 | F53: =F48*F43 -> 0 | G53: =G48*G43 -> 0 | H53: =H48*H43 -> 0 | I53: =I48*I43 -> 0 | J53: =J48*J43 -> 0
B55: Total Income Revenue Stream One | F55: =SUM(F51:F53) -> 0 | G55: =SUM(G51:G53) -> 0 | H55: =SUM(H51:H53) -> 0 | I55: =SUM(I51:I53) -> 0 | J55: =SUM(J51:J53) -> 0
B57: Revenue Stream Two
B59: Number of Contracts
B60: Total contracts | L60: [Reasoning]
...

Sheet Monthly Cashflow 
B2: Year (units) | F2: 1 | G2: 1 | H2: 1 | I2: 1 | J2: 1 | K2: 1 | L2: 1 | M2: 1 | N2: 1 | O2: 1 | P2: 1 | Q2: 1 | R2: 2 | S2: 2 | T2: 2 | U2: 2 | V2: 2 | W2: 2 | X2: 2 | Y2: 2 | Z2: 2 | AA2: 2 | AB2: 2 | AC2: 2 | AD2: 3 | AE2: 3 | AF2: 3 | AG2: 3 | AH2: 3 | AI2: 3 | AJ2: 3 | AK2: 3 | AL2: 3 | AM2: 3 | AN2: 3 | AO2: 3 | AP2: 4 | AQ2: 4 | AR2: 4 | AS2: 4 | AT2: 4 | AU2: 4 | AV2: 4 | AW2: 4 | AX2: 4 | AY2: 4 | AZ2: 4 | BA2: 4 | BB2: 5 | BC2: 5 | BD2: 5 | BE2: 5 | BF2: 5 | BG2: 5 | BH2: 5 | BI2: 5 | BJ2: 5 | BK2: 5 | BL2: 5 | BM2: 5
B3: Date | F3: =Assumptions!D13 -> 45748 | G3: =EDATE(F3,1) -> 45778 | H3: =EDATE(G3,1) -> 45809 | I3: =EDATE(H3,1) -> 45839 | J3: =EDATE(I3,1) -> 45870 | K3: =EDATE(J3,1) -> 45901 | L3: =EDATE(K3,1) -> 45931 | M3: =EDATE(L3,1) -> 45962 | N3: =EDATE(M3,1) -> 45992 | ... BM3: =EDATE(BL3,1) -> 47543
B8: Revenue | C8: Comments
B9: Seasonality adjustment
B10: Revenue Stream 1 | C10: Add in seasonality assumptions here | F10: =1/12 -> 0.083333333 | G10: =F10 -> 0.083333333 | H10: =G10 -> 0.083333333 | I10: =H10 -> 0.083333333 | J10: =I10 -> 0.083333333 | K10: =J10 -> 0.083333333 | L10: =K10 -> 0.083333333 | M10: =L10 -> 0.083333333 | N10: =M10 -> 0.083333333 | ... BM10: =BL10 -> 0.083333333
B11: Revenue Stream 2 | F11: =1/4 -> 0.25 | G11: 0 | H11: 0 | I11: 0.25 | J11: 0 | K11: =J11 -> 0 | L11: 0.25 | M11: 0 | N11: =M11 -> 0 | O11: 0.25 | P11: 0 | Q11: 0 | R11: =1/4 -> 0.25 | S11: 0 | T11: 0 | U11: 0.25 | V11: 0 | W11: =V11 -> 0 | X11: 0.25 | Y11: 0 | Z11: =Y11 -> 0 | AA11: 0.25 | AB11: 0 | AC11: 0 | AD11: =1/4 -> 0.25 | AE11: 0 | AF11: 0 | AG11: 0.25 | AH11: 0.0033333333 | AI11: =AH11 -> 0.0033333333 | AJ11: 0.25 | AK11: 0 | AL11: =AK11 -> 0 | AM11: 0.25 | AN11: 0 | AO11: 0 | AP11: =1/4 -> 0.25 | AQ11: 0 | AR11: 0 | AS11: 0.25 | AT11: 0 | AU11: =AT11 -> 0 | AV11: 0.25 | AW11: 0 | AX11: =AW11 -> 0 | AY11: 0.25 | AZ11: =AY11 -> 0.25 | BA11: =AZ11 -> 0.25 | BB11: =1/4 -> 0.25 | BC11: 0 | BD11: 0 | BE11: 0.25 | BF11: 0 | BG11: =BF11 -> 0 | BH11: 0.25 | BI11: 0 | BJ11: =BI11 -> 0 | BK11: 0.25 | BL11: 0 | BM11: 0
B13: Revenue Stream 1 | C13: Best Case Scenario | F13: =SUMIF(Assumptions!$2:$2,'Monthly Cashflow '!F$2,Assumptions!55:55)*F10 -> 0 | G13: =SUMIF(Assumptions!$2:$2,'Monthly Cashflow '!G$2,Assumptions!55:55)*G10 -> 0 | H13: =SUMIF(Assumptions!$2:$2,'Monthly Cashflow '!H$2,Assumptions!55:55)*H10 -> 0 | I13: =SUMIF(Assumptions!$2:$2,'Monthly Cashflow '!I$2,Assumptions!55:55)*I10 -> 0 | J13: =SUMIF(Assumptions!$2:$2,'Monthly Cashflow '!J$2,Assumptions!55:55)*J10 -> 0 | K13: =SUMIF(Assumptions!$2:$2,'Monthly Cashflow '!K$2,Assumptions!55:55)*K10 -> 0 | L13: =SUMIF(Assumptions!$2:$2,'Monthly Cashflow '!L$2,Assumptions!55:55)*L10 -> 0 | M13: =SUMIF(Assumptions!$2:$2,'Monthly Cashflow '!M$2,Assumptions!55:55)*M10 -> 0 | ... BM13: =SUMIF(Assumptions!$2:$2,'Monthly Cashflow '!BM$2,Assumptions!55:55)*BM10 -> 0
B14: Revenue Stream 2 | F14: =SUMIF(Assumptions!$2:$2,'Monthly Cashflow '!F$2,Assumptions!76:76)*F11 -> 0 | G14: =SUMIF(Assumptions!$2:$2,'Monthly Cashflow '!G$2,Assumptions!76:76)*G11 -> 0 | H14: =SUMIF(Assumptions!$2:$2,'Monthly Cashflow '!H$2,Assumptions!76:76)*H11 -> 0 | I14: =SUMIF(Assumptions!$2:$2,'Monthly Cashflow '!I$2,Assumptions!76:76)*I11 -> 0 | J14: =SUMIF(Assumptions!$2:$2,'Monthly Cashflow '!J$2,Assumptions!76:76)*J11 -> 0 | K14: =SUMIF(Assumptions!$2:$2,'Monthly Cashflow '!K$2,Assumptions!76:76)*K11 -> 0 | L14: =SUMIF(Assumptions!$2:$2,'Monthly Cashflow '!L$2,Assumptions!76:76)*L11 -> 0 | M14: =SUMIF(Assumptions!$2:$2,'Monthly Cashflow '!M$2,Assumptions!76:76)*M11 -> 0 | ... BM14: =SUMIF(Assumptions!$2:$2,'Monthly Cashflow '!BM$2,Assumptions!76:76)*BM11 -> 0
B15: Total Revenue | F15: =SUM(F13:F14) -> 0 | G15: =SUM(G13:G14) -> 0 | H15: =SUM(H13:H14) -> 0 | I15: =SUM(I13:I14) -> 0 | J15: =SUM(J13:J14) -> 0 | K15: =SUM(K13:K14) -> 0 | L15: =SUM(L13:L14) -> 0 | M15: =SUM(M13:M14) -> 0 | ... BM15: =SUM(BM13:BM14) -> 0
B19: Cost of Sales | C19: Comments
B21: Cost of Sales 1 | F21: =SUMIF(Assumptions!$2:$2,'Monthly Cashflow '!F$2,Assumptions!87:87)/12 -> 0 | G21: =SUMIF(Assumptions!$2:$2,'Monthly Cashflow '!G$2,Assumptions!87:87)/12 -> 0 | H21: =SUMIF(Assumptions!$2:$2,'Monthly Cashflow '!H$2,Assumptions!87:87)/12 -> 0 | I21: =SUMIF(Assumptions!$2:$2,'Monthly Cashflow '!I$2,Assumptions!87:87)/12 -> 0 | J21: =SUMIF(Assumptions!$2:$2,'Monthly Cashflow '!J$2,Assumptions!87:87)/12 -> 0 | K21: =SUMIF(Assumptions!$2:$2,'Monthly Cashflow '!K$2,Assumptions!87:87)/12 -> 0 | L21: =SUMIF(Assumptions!$2:$2,'Monthly Cashflow '!L$2,Assumptions!87:87)/12 -> 0 | M21: =SUMIF(Assumptions!$2:$2,'Monthly Cashflow '!M$2,Assumptions!87:87)/12 -> 0 | ... BM21: =SUMIF(Assumptions!$2:$2,'Monthly Cashflow '!BM$2,Assumptions!87:87)/12 -> 0
B22: Cost of Sales 2 | F22: =SUMIF(Assumptions!$2:$2,'Monthly Cashflow '!F$2,Assumptions!96:96)/12 -> #DIV/0! | G22: =SUMIF(Assumptions!$2:$2,'Monthly Cashflow '!G$2,Assumptions!96:96)/12 -> #DIV/0! | H22: =SUMIF(Assumptions!$2:$2,'Monthly Cashflow '!H$2,Assumptions!96:96)/12 -> #DIV/0! | I22: =SUMIF(Assumptions!$2:$2,'Monthly Cashflow '!I$2,Assumptions!96:96)/12 -> #DIV/0! | J22: =SUMIF(Assumptions!$2:$2,'Monthly Cashflow '!J$2,Assumptions!96:96)/12 -> #DIV/0! | K22: =SUMIF(Assumptions!$2:$2,'Monthly Cashflow '!K$2,Assumptions!96:96)/12 -> #DIV/0! | L22: =SUMIF(Assumptions!$2:$2,'Monthly Cashflow '!L$2,Assumptions!96:96)/12 -> #DIV/0! | M22: =SUMIF(Assumptions!$2:$2,'Monthly Cashflow '!M$2,Assumptions!96:96)/12 -> #DIV/0! | ... BM22: =SUMIF(Assumptions!$2:$2,'Monthly Cashflow '!BM$2,Assumptions!96:96)/12 -> #DIV/0!
B23: Total Cost of Sales | F23: =SUM(F21:F22) -> #DIV/0! | G23: =SUM(G21:G22) -> #DIV/0! | H23: =SUM(H21:H22) -> #DIV/0! | I23: =SUM(I21:I22) -> #DIV/0! | J23: =SUM(J21:J22) -> #DIV/0! | K23: =SUM(K21:K22) -> #DIV/0! | L23: =SUM(L21:L22) -> #DIV/0! | M23: =SUM(M21:M22) -> #DIV/0! | ... BM23: =SUM(BM21:BM22) -> #DIV/0!
B25: Overhead Costs | C25: Comments
B27: Additional Staff Costs | F27: =Assumptions!$F$118/12 -> 0 | G27: =Assumptions!$F$118/12 -> 0 | H27: =Assumptions!$F$118/12 -> 0 | I27: =Assumptions!$F$118/12 -> 0 | J27: =Assumptions!$F$118/12 -> 0 | K27: =Assumptions!$F$118/12 -> 0 | L27: =Assumptions!$F$118/12 -> 0 | M27: =Assumptions!$F$118/12 -> 0 | ... Q27: =Assumptions!$F$118/12 -> 0 | R27: =Assumptions!$G$118/12 -> 0 | S27: =Assumptions!$G$118/12 -> 0 | T27: =Assumptions!$G$118/12 -> 0 | U27: =Assumptions!$G$118/12 -> 0 | V27: =Assumptions!$G$118/12 -> 0 | W27: =Assumptions!$G$118/12 -> 0 | X27: =Assumptions!$G$118/12 -> 0 | Y27: =Assumptions!$G$118/12 -> 0 | ... AC27: =Assumptions!$G$118/12 -> 0 | AD27: =Assumptions!$H$118/12 -> 0 | AE27: =Assumptions!$H$118/12 -> 0 | AF27: =Assumptions!$H$118/12 -> 0 | AG27: =Assumptions!$H$118/12 -> 0 | AH27: =Assumptions!$H$118/12 -> 0 | AI27: =Assumptions!$H$118/12 -> 0 | AJ27: =Assumptions!$H$118/12 -> 0 | AK27: =Assumptions!$H$118/12 -> 0 | ... AO27: =Assumptions!$H$118/12 -> 0 | AP27: =Assumptions!$I$118/12 -> 0 | AQ27: =Assumptions!$I$118/12 -> 0 | AR27: =Assumptions!$I$118/12 -> 0 | AS27: =Assumptions!$I$118/12 -> 0 | AT27: =Assumptions!$I$118/12 -> 0 | AU27: =Assumptions!$I$118/12 -> 0 | AV27: =Assumptions!$I$118/12 -> 0 | AW27: =Assumptions!$I$118/12 -> 0 | ... BA27: =Assumptions!$I$118/12 -> 0 | BB27: =Assumptions!$J$118/12 -> 0 | BC27: =Assumptions!$J$118/12 -> 0 | BD27: =Assumptions!$J$118/12 -> 0 | BE27: =Assumptions!$J$118/12 -> 0 | BF27: =Assumptions!$J$118/12 -> 0 | BG27: =Assumptions!$J$118/12 -> 0 | BH27: =Assumptions!$J$118/12 -> 0 | BI27: =Assumptions!$J$118/12 -> 0 | ... BM27: =Assumptions!$J$118/12 -> 0
B28: Additional Costs | F28: =SUM(Assumptions!$F$105,Assumptions!$F$121,Assumptions!$F$122,Assumptions!$F$123)/12 -> 0 | G28: =SUM(Assumptions!$F$105,Assumptions!$F$121,Assumptions!$F$122,Assumptions!$F$123)/12 -> 0 | H28: =SUM(Assumptions!$F$105,Assumptions!$F$121,Assumptions!$F$122,Assumptions!$F$123)/12 -> 0 | I28: =SUM(Assumptions!$F$105,Assumptions!$F$121,Assumptions!$F$122,Assumptions!$F$123)/12 -> 0 | J28: =SUM(Assumptions!$F$105,Assumptions!$F$121,Assumptions!$F$122,Assumptions!$F$123)/12 -> 0 | K28: =SUM(Assumptions!$F$105,Assumptions!$F$121,Assumptions!$F$122,Assumptions!$F$123)/12 -> 0 | L28: =SUM(Assumptions!$F$105,Assumptions!$F$121,Assumptions!$F$122,Assumptions!$F$123)/12 -> 0 | M28: =SUM(Assumptions!$F$105,Assumptions!$F$121,Assumptions!$F$122,Assumptions!$F$123)/12 -> 0 | ... Q28: =SUM(Assumptions!$F$105,Assumptions!$F$121,Assumptions!$F$122,Assumptions!$F$123)/12 -> 0 | R28: =SUM(Assumptions!$G$105,Assumptions!$G$121,Assumptions!$G$122,Assumptions!$G$123)/12 -> 0 | S28: =SUM(Assumptions!$G$105,Assumptions!$G$121,Assumptions!$G$122,Assumptions!$G$123)/12 -> 0 | T28: =SUM(Assumptions!$G$105,Assumptions!$G$121,Assumptions!$G$122,Assumptions!$G$123)/12 -> 0 | U28: =SUM(Assumptions!$G$105,Assumptions!$G$121,Assumptions!$G$122,Assumptions!$G$123)/12 -> 0 | V28: =SUM(Assumptions!$G$105,Assumptions!$G$121,Assumptions!$G$122,Assumptions!$G$123)/12 -> 0 | W28: =SUM(Assumptions!$G$105,Assumptions!$G$121,Assumptions!$G$122,Assumptions!$G$123)/12 -> 0 | X28: =SUM(Assumptions!$G$105,Assumptions!$G$121,Assumptions!$G$122,Assumptions!$G$123)/12 -> 0 | Y28: =SUM(Assumptions!$G$105,Assumptions!$G$121,Assumptions!$G$122,Assumptions!$G$123)/12 -> 0 | ... AC28: =SUM(Assumptions!$G$105,Assumptions!$G$121,Assumptions!$G$122,Assumptions!$G$123)/12 -> 0 | AD28: =SUM(Assumptions!$H$105,Assumptions!$H$121,Assumptions!$H$122,Assumptions!$H$123)/12 -> 0 | AE28: =SUM(Assumptions!$H$105,Assumptions!$H$121,Assumptions!$H$122,Assumptions!$H$123)/12 -> 0 | AF28: =SUM(Assumptions!$H$105,Assumptions!$H$121,Assumptions!$H$122,Assumptions!$H$123)/12 -> 0 | AG28: =SUM(Assumptions!$H$105,Assumptions!$H$121,Assumptions!$H$122,Assumptions!$H$123)/12 -> 0 | AH28: =SUM(Assumptions!$H$105,Assumptions!$H$121,Assumptions!$H$122,Assumptions!$H$123)/12 -> 0 | AI28: =SUM(Assumptions!$H$105,Assumptions!$H$121,Assumptions!$H$122,Assumptions!$H$123)/12 -> 0 | AJ28: =SUM(Assumptions!$H$105,Assumptions!$H$121,Assumptions!$H$122,Assumptions!$H$123)/12 -> 0 | AK28: =SUM(Assumptions!$H$105,Assumptions!$H$121,Assumptions!$H$122,Assumptions!$H$123)/12 -> 0 | ... AO28: =SUM(Assumptions!$H$105,Assumptions!$H$121,Assumptions!$H$122,Assumptions!$H$123)/12 -> 0 | AP28: =SUM(Assumptions!$I$105,Assumptions!$I$121,Assumptions!$I$122,Assumptions!$I$123)/12 -> 0 | AQ28: =SUM(Assumptions!$I$105,Assumptions!$I$121,Assumptions!$I$122,Assumptions!$I$123)/12 -> 0 | AR28: =SUM(Assumptions!$I$105,Assumptions!$I$121,Assumptions!$I$122,Assumptions!$I$123)/12 -> 0 | AS28: =SUM(Assumptions!$I$105,Assumptions!$I$121,Assumptions!$I$122,Assumptions!$I$123)/12 -> 0 | AT28: =SUM(Assumptions!$I$105,Assumptions!$I$121,Assumptions!$I$122,Assumptions!$I$123)/12 -> 0 | AU28: =SUM(Assumptions!$I$105,Assumptions!$I$121,Assumptions!$I$122,Assumptions!$I$123)/12 -> 0 | AV28: =SUM(Assumptions!$I$105,Assumptions!$I$121,Assumptions!$I$122,Assumptions!$I$123)/12 -> 0 | AW28: =SUM(Assumptions!$I$105,Assumptions!$I$121,Assumptions!$I$122,Assumptions!$I$123)/12 -> 0 | ... BA28: =SUM(Assumptions!$I$105,Assumptions!$I$121,Assumptions!$I$122,Assumptions!$I$123)/12 -> 0 | BB28: =SUM(Assumptions!$J$105,Assumptions!$J$121,Assumptions!$J$122,Assumptions!$J$123)/12 -> 0 | BC28: =SUM(Assumptions!$J$105,Assumptions!$J$121,Assumptions!$J$122,Assumptions!$J$123)/12 -> 0 | BD28: =SUM(Assumptions!$J$105,Assumptions!$J$121,Assumptions!$J$122,Assumptions!$J$123)/12 -> 0 | BE28: =SUM(Assumptions!$J$105,Assumptions!$J$121,Assumptions!$J$122,Assumptions!$J$123)/12 -> 0 | BF28: =SUM(Assumptions!$J$105,Assumptions!$J$121,Assumptions!$J$122,Assumptions!$J$123)/12 -> 0 | BG28: =SUM(Assumptions!$J$105,Assumptions!$J$121,Assumptions!$J$122,Assumptions!$J$123)/12 -> 0 | BH28: =SUM(Assumptions!$J$105,Assumptions!$J$121,Assumptions!$J$122,Assumptions!$J$123)/12 -> 0 | BI28: =SUM(Assumptions!$J$105,Assumptions!$J$121,Assumptions!$J$122,Assumptions!$J$123)/12 -> 0 | ... BM28: =SUM(Assumptions!$J$105,Assumptions!$J$121,Assumptions!$J$122,Assumptions!$J$123)/12 -> 0
B30: EBITDA | F30: =F15-F23-F27-F28 -> #DIV/0! | G30: =G15-G23-G27-G28 -> #DIV/0! | H30: =H15-H23-H27-H28 -> #DIV/0! | I30: =I15-I23-I27-I28 -> #DIV/0! | J30: =J15-J23-J27-J28 -> #DIV/0! | K30: =K15-K23-K27-K28 -> #DIV/0! | L30: =L15-L23-L27-L28 -> #DIV/0! | M30: =M15-M23-M27-M28 -> #DIV/0! | ... BM30: =BM15-BM23-BM27-BM28 -> #DIV/0!
B32: Beginning Cash | F32: 0 | G32: =F35 -> #DIV/0! | H32: =G35 -> #DIV/0! | I32: =H35 -> #DIV/0! | J32: =I35 -> #DIV/0! | K32: =J35 -> #DIV/0! | L32: =K35 -> #DIV/0! | M32: =L35 -> #DIV/0! | N32: =M35 -> #DIV/0! | ... BM32: =BL35 -> #DIV/0!
B33: Cash from Operations | F33: =F30 -> #DIV/0! | G33: =G30 -> #DIV/0! | H33: =H30 -> #DIV/0! | I33: =I30 -> #DIV/0! | J33: =J30 -> #DIV/0! | K33: =K30 -> #DIV/0! | L33: =L30 -> #DIV/0! | M33: =M30 -> #DIV/0! | ... BM33: =BM30 -> #DIV/0!
B34: Cash from Investments | F34: 0
B35: Closing Cash | F35: =SUM(F32:F34) -> #DIV/0! | G35: =SUM(G32:G34) -> #DIV/0! | H35: =SUM(H32:H34) -> #DIV/0! | I35: =SUM(I32:I34) -> #DIV/0! | J35: =SUM(J32:J34) -> #DIV/0! | K35: =SUM(K32:K34) -> #DIV/0! | L35: =SUM(L32:L34) -> #DIV/0! | M35: =SUM(M32:M34) -> #DIV/0! | ... BM35: =SUM(BM32:BM34) -> #DIV/0!
B37: Without Grant Financing
B38: Beginning Cash | F38: =F32 -> 0 | G38: =F41 -> #DIV/0! | H38: =G41 -> #DIV/0! | I38: =H41 -> #DIV/0! | J38: =I41 -> #DIV/0! | K38: =J41 -> #DIV/0! | L38: =K41 -> #DIV/0! | M38: =L41 -> #DIV/0! | N38: =M41 -> #DIV/0! | ... BM38: =BL41 -> #DIV/0!
B39: Cash from Operations | F39: =F33 -> #DIV/0! | G39: =G33 -> #DIV/0! | H39: =H33 -> #DIV/0! | I39: =I33 -> #DIV/0! | J39: =J33 -> #DIV/0! | K39: =K33 -> #DIV/0! | L39: =L33 -> #DIV/0! | M39: =M33 -> #DIV/0! | ... BM39: =BM33 -> #DIV/0!
B40: Cash from Investments | F40: =F34 -> 0 | G40: =G34 -> 0 | H40: =H34 -> 0 | I40: =I34 -> 0 | J40: =J34 -> 0 | K40: =K34 -> 0 | L40: =L34 -> 0 | M40: =M34 -> 0 | ... BM40: =BM34 -> 0
B41: Closing Cash | F41: =SUM(F38:F40) -> #DIV/0! | G41: =SUM(G38:G40) -> #DIV/0! | H41: =SUM(H38:H40) -> #DIV/0! | I41: =SUM(I38:I40) -> #DIV/0! | J41: =SUM(J38:J40) -> #DIV/0! | K41: =SUM(K38:K40) -> #DIV/0! | L41: =SUM(L38:L40) -> #DIV/0! | M41: =SUM(M38:M40) -> #DIV/0! | ... BM41: =SUM(BM38:BM40) -> #DIV/0!

Sheet Monthly Cashflow Worst Case
B2: Year (units) | F2: 1 | G2: 1 | H2: 1 | I2: 1 | J2: 1 | K2: 1 | L2: 1 | M2: 1 | N2: 1 | O2: 1 | P2: 1 | Q2: 1 | R2: 2 | S2: 2 | T2: 2 | U2: 2 | V2: 2 | W2: 2 | X2: 2 | Y2: 2 | Z2: 2 | AA2: 2 | AB2: 2 | AC2: 2 | AD2: 3 | AE2: 3 | AF2: 3 | AG2: 3 | AH2: 3 | AI2: 3 | AJ2: 3 | AK2: 3 | AL2: 3 | AM2: 3 | AN2: 3 | AO2: 3 | AP2: 4 | AQ2: 4 | AR2: 4 | AS2: 4 | AT2: 4 | AU2: 4 | AV2: 4 | AW2: 4 | AX2: 4 | AY2: 4 | AZ2: 4 | BA2: 4 | BB2: 5 | BC2: 5 | BD2: 5 | BE2: 5 | BF2: 5 | BG2: 5 | BH2: 5 | BI2: 5 | BJ2: 5 | BK2: 5 | BL2: 5 | BM2: 5
B3: Date | F3: =Assumptions!D13 -> 45748 | G3: =EDATE(F3,1) -> 45778 | H3: =EDATE(G3,1) -> 45809 | I3: =EDATE(H3,1) -> 45839 | J3: =EDATE(I3,1) -> 45870 | K3: =EDATE(J3,1) -> 45901 | L3: =EDATE(K3,1) -> 45931 | M3: =EDATE(L3,1) -> 45962 | N3: =EDATE(M3,1) -> 45992 | ... BM3: =EDATE(BL3,1) -> 47543
B8: Revenue | C8: Comments
B10: ='Monthly Cashflow '!B13 -> Revenue Stream 1 | C10: Worst Case Scenario | F10: =SUMIF(Assumptions!$2:$2,'Monthly Cashflow Worst Case'!F$2,Assumptions!55:55)/12 -> 0 | G10: =SUMIF(Assumptions!$2:$2,'Monthly Cashflow Worst Case'!G$2,Assumptions!55:55)/12 -> 0 | H10: =SUMIF(Assumptions!$2:$2,'Monthly Cashflow Worst Case'!H$2,Assumptions!55:55)/12 -> 0 | I10: =SUMIF(Assumptions!$2:$2,'Monthly Cashflow Worst Case'!I$2,Assumptions!55:55)/12 -> 0 | J10: =SUMIF(Assumptions!$2:$2,'Monthly Cashflow Worst Case'!J$2,Assumptions!55:55)/12 -> 0 | K10: =SUMIF(Assumptions!$2:$2,'Monthly Cashflow Worst Case'!K$2,Assumptions!55:55)/12 -> 0 | L10: =SUMIF(Assumptions!$2:$2,'Monthly Cashflow Worst Case'!L$2,Assumptions!55:55)/12 -> 0 | M10: =SUMIF(Assumptions!$2:$2,'Monthly Cashflow Worst Case'!M$2,Assumptions!55:55)/12 -> 0 | ... BM10: =SUMIF(Assumptions!$2:$2,'Monthly Cashflow Worst Case'!BM$2,Assumptions!55:55)/12 -> 0
B11: ='Monthly Cashflow '!B14 -> Revenue Stream 2 | F11: =SUMIF(Assumptions!$2:$2,'Monthly Cashflow Worst Case'!F$2,Assumptions!76:76)/3 -> 0 | J11: =SUMIF(Assumptions!$2:$2,'Monthly Cashflow Worst Case'!J$2,Assumptions!76:76)/3 -> 0 | M11: =SUMIF(Assumptions!$2:$2,'Monthly Cashflow Worst Case'!M$2,Assumptions!76:76)/3 -> 0 | R11: =SUMIF(Assumptions!$2:$2,'Monthly Cashflow Worst Case'!R$2,Assumptions!76:76)/3 -> 0 | V11: =SUMIF(Assumptions!$2:$2,'Monthly Cashflow Worst Case'!V$2,Assumptions!76:76)/3 -> 0 | Y11: =SUMIF(Assumptions!$2:$2,'Monthly Cashflow Worst Case'!Y$2,Assumptions!76:76)/3 -> 0 | AD11: =SUMIF(Assumptions!$2:$2,'Monthly Cashflow Worst Case'!AD$2,Assumptions!76:76)/3 -> 0 | AH11: =SUMIF(Assumptions!$2:$2,'Monthly Cashflow Worst Case'!AH$2,Assumptions!76:76)/3 -> 0 | AK11: =SUMIF(Assumptions!$2:$2,'Monthly Cashflow Worst Case'!AK$2,Assumptions!76:76)/3 -> 0 | AP11: =SUMIF(Assumptions!$2:$2,'Monthly Cashflow Worst Case'!AP$2,Assumptions!76:76)/3 -> 0 | AT11: =SUMIF(Assumptions!$2:$2,'Monthly Cashflow Worst Case'!AT$2,Assumptions!76:76)/3 -> 0 | AW11: =SUMIF(Assumptions!$2:$2,'Monthly Cashflow Worst Case'!AW$2,Assumptions!76:76)/3 -> 0 | BB11: =SUMIF(Assumptions!$2:$2,'Monthly Cashflow Worst Case'!BB$2,Assumptions!76:76)/3 -> 0 | BF11: =SUMIF(Assumptions!$2:$2,'Monthly Cashflow Worst Case'!BF$2,Assumptions!76:76)/3 -> 0 | BI11: =SUMIF(Assumptions!$2:$2,'Monthly Cashflow Worst Case'!BI$2,Assumptions!76:76)/3 -> 0
B12: Total Revenue | F12: =SUM(F10:F11) -> 0 | G12: =SUM(G10:G11) -> 0 | H12: =SUM(H10:H11) -> 0 | I12: =SUM(I10:I11) -> 0 | J12: =SUM(J10:J11) -> 0 | K12: =SUM(K10:K11) -> 0 | L12: =SUM(L10:L11) -> 0 | M12: =SUM(M10:M11) -> 0 | ... BM12: =SUM(BM10:BM11) -> 0
B15: Cost of Sales | C15: Comments
B17: ='Monthly Cashflow '!B21 -> Cost of Sales 1 | F17: =SUMIF(Assumptions!$2:$2,'Monthly Cashflow Worst Case'!F$2,Assumptions!87:87)/12 -> 0 | G17: =SUMIF(Assumptions!$2:$2,'Monthly Cashflow Worst Case'!G$2,Assumptions!87:87)/12 -> 0 | H17: =SUMIF(Assumptions!$2:$2,'Monthly Cashflow Worst Case'!H$2,Assumptions!87:87)/12 -> 0 | I17: =SUMIF(Assumptions!$2:$2,'Monthly Cashflow Worst Case'!I$2,Assumptions!87:87)/12 -> 0 | J17: =SUMIF(Assumptions!$2:$2,'Monthly Cashflow Worst Case'!J$2,Assumptions!87:87)/12 -> 0 | K17: =SUMIF(Assumptions!$2:$2,'Monthly Cashflow Worst Case'!K$2,Assumptions!87:87)/12 -> 0 | L17: =SUMIF(Assumptions!$2:$2,'Monthly Cashflow Worst Case'!L$2,Assumptions!87:87)/12 -> 0 | M17: =SUMIF(Assumptions!$2:$2,'Monthly Cashflow Worst Case'!M$2,Assumptions!87:87)/12 -> 0 | ... BM17: =SUMIF(Assumptions!$2:$2,'Monthly Cashflow Worst Case'!BM$2,Assumptions!87:87)/12 -> 0
B18: ='Monthly Cashflow '!B22 -> Cost of Sales 2 | F18: =SUMIF(Assumptions!$2:$2,'Monthly Cashflow Worst Case'!F$2,Assumptions!#REF!)/12 -> #REF! | G18: =SUMIF(Assumptions!$2:$2,'Monthly Cashflow Worst Case'!G$2,Assumptions!#REF!)/12 -> #REF! | H18: =SUMIF(Assumptions!$2:$2,'Monthly Cashflow Worst Case'!H$2,Assumptions!#REF!)/12 -> #REF! | I18: =SUMIF(Assumptions!$2:$2,'Monthly Cashflow Worst Case'!I$2,Assumptions!#REF!)/12 -> #REF! | J18: =SUMIF(Assumptions!$2:$2,'Monthly Cashflow Worst Case'!J$2,Assumptions!#REF!)/12 -> #REF! | K18: =SUMIF(Assumptions!$2:$2,'Monthly Cashflow Worst Case'!K$2,Assumptions!#REF!)/12 -> #REF! | L18: =SUMIF(Assumptions!$2:$2,'Monthly Cashflow Worst Case'!L$2,Assumptions!#REF!)/12 -> #REF! | M18: =SUMIF(Assumptions!$2:$2,'Monthly Cashflow Worst Case'!M$2,Assumptions!#REF!)/12 -> #REF! | ... BM18: =SUMIF(Assumptions!$2:$2,'Monthly Cashflow Worst Case'!BM$2,Assumptions!#REF!)/12 -> #REF!
B19: Total Cost of Sales | F19: =SUM(F17:F18) -> #REF! | G19: =SUM(G17:G18) -> #REF! | H19: =SUM(H17:H18) -> #REF! | I19: =SUM(I17:I18) -> #REF! | J19: =SUM(J17:J18) -> #REF! | K19: =SUM(K17:K18) -> #REF! | L19: =SUM(L17:L18) -> #REF! | M19: =SUM(M17:M18) -> #REF! | ... BM19: =SUM(BM17:BM18) -> #REF!
B22: Overhead Costs | C22: Comments
B24: Additional Staff Costs | F24: =Assumptions!$F$118/12 -> 0 | G24: =Assumptions!$F$118/12 -> 0 | H24: =Assumptions!$F$118/12 -> 0 | I24: =Assumptions!$F$118/12 -> 0 | J24: =Assumptions!$F$118/12 -> 0 | K24: =Assumptions!$F$118/12 -> 0 | L24: =Assumptions!$F$118/12 -> 0 | M24: =Assumptions!$F$118/12 -> 0 | ... Q24: =Assumptions!$F$118/12 -> 0 | R24: =Assumptions!$G$118/12 -> 0 | S24: =Assumptions!$G$118/12 -> 0 | T24: =Assumptions!$G$118/12 -> 0 | U24: =Assumptions!$G$118/12 -> 0 | V24: =Assumptions!$G$118/12 -> 0 | W24: =Assumptions!$G$118/12 -> 0 | X24: =Assumptions!$G$118/12 -> 0 | Y24: =Assumptions!$G$118/12 -> 0 | ... AC24: =Assumptions!$G$118/12 -> 0 | AD24: =Assumptions!$H$118/12 -> 0 | AE24: =Assumptions!$H$118/12 -> 0 | AF24: =Assumptions!$H$118/12 -> 0 | AG24: =Assumptions!$H$118/12 -> 0 | AH24: =Assumptions!$H$118/12 -> 0 | AI24: =Assumptions!$H$118/12 -> 0 | AJ24: =Assumptions!$H$118/12 -> 0 | AK24: =Assumptions!$H$118/12 -> 0 | ... AO24: =Assumptions!$H$118/12 -> 0 | AP24: =Assumptions!$I$118/12 -> 0 | AQ24: =Assumptions!$I$118/12 -> 0 | AR24: =Assumptions!$I$118/12 -> 0 | AS24: =Assumptions!$I$118/12 -> 0 | AT24: =Assumptions!$I$118/12 -> 0 | AU24: =Assumptions!$I$118/12 -> 0 | AV24: =Assumptions!$I$118/12 -> 0 | AW24: =Assumptions!$I$118/12 -> 0 | ... BA24: =Assumptions!$I$118/12 -> 0 | BB24: =Assumptions!$J$118/12 -> 0 | BC24: =Assumptions!$J$118/12 -> 0 | BD24: =Assumptions!$J$118/12 -> 0 | BE24: =Assumptions!$J$118/12 -> 0 | BF24: =Assumptions!$J$118/12 -> 0 | BG24: =Assumptions!$J$118/12 -> 0 | BH24: =Assumptions!$J$118/12 -> 0 | BI24: =Assumptions!$J$118/12 -> 0 | ... BM24: =Assumptions!$J$118/12 -> 0
B25: Additional Costs | F25: =SUM(Assumptions!$F$121,Assumptions!$F$122,Assumptions!$F$123)/12 -> 0 | G25: =SUM(Assumptions!$F$121,Assumptions!$F$122,Assumptions!$F$123)/12 -> 0 | H25: =SUM(Assumptions!$F$121,Assumptions!$F$122,Assumptions!$F$123)/12 -> 0 | I25: =SUM(Assumptions!$F$121,Assumptions!$F$122,Assumptions!$F$123)/12 -> 0 | J25: =SUM(Assumptions!$F$121,Assumptions!$F$122,Assumptions!$F$123)/12 -> 0 | K25: =SUM(Assumptions!$F$121,Assumptions!$F$122,Assumptions!$F$123)/12 -> 0 | L25: =SUM(Assumptions!$F$121,Assumptions!$F$122,Assumptions!$F$123)/12 -> 0 | M25: =SUM(Assumptions!$F$121,Assumptions!$F$122,Assumptions!$F$123)/12 -> 0 | ... Q25: =SUM(Assumptions!$F$121,Assumptions!$F$122,Assumptions!$F$123)/12 -> 0 | R25: =SUM(Assumptions!$G$121,Assumptions!$G$122,Assumptions!$G$123)/12 -> 0 | S25: =SUM(Assumptions!$G$121,Assumptions!$G$122,Assumptions!$G$123)/12 -> 0 | T25: =SUM(Assumptions!$G$121,Assumptions!$G$122,Assumptions!$G$123)/12 -> 0 | U25: =SUM(Assumptions!$G$121,Assumptions!$G$122,Assumptions!$G$123)/12 -> 0 | V25: =SUM(Assumptions!$G$121,Assumptions!$G$122,Assumptions!$G$123)/12 -> 0 | W25: =SUM(Assumptions!$G$121,Assumptions!$G$122,Assumptions!$G$123)/12 -> 0 | X25: =SUM(Assumptions!$G$121,Assumptions!$G$122,Assumptions!$G$123)/12 -> 0 | Y25: =SUM(Assumptions!$G$121,Assumptions!$G$122,Assumptions!$G$123)/12 -> 0 | ... AC25: =SUM(Assumptions!$G$121,Assumptions!$G$122,Assumptions!$G$123)/12 -> 0 | AD25: =SUM(Assumptions!$H$121,Assumptions!$H$122,Assumptions!$H$123)/12 -> 0 | AE25: =SUM(Assumptions!$H$121,Assumptions!$H$122,Assumptions!$H$123)/12 -> 0 | AF25: =SUM(Assumptions!$H$121,Assumptions!$H$122,Assumptions!$H$123)/12 -> 0 | AG25: =SUM(Assumptions!$H$121,Assumptions!$H$122,Assumptions!$H$123)/12 -> 0 | AH25: =SUM(Assumptions!$H$121,Assumptions!$H$122,Assumptions!$H$123)/12 -> 0 | AI25: =SUM(Assumptions!$H$121,Assumptions!$H$122,Assumptions!$H$123)/12 -> 0 | AJ25: =SUM(Assumptions!$H$121,Assumptions!$H$122,Assumptions!$H$123)/12 -> 0 | AK25: =SUM(Assumptions!$H$121,Assumptions!$H$122,Assumptions!$H$123)/12 -> 0 | ... AO25: =SUM(Assumptions!$H$121,Assumptions!$H$122,Assumptions!$H$123)/12 -> 0 | AP25: =SUM(Assumptions!$I$121,Assumptions!$I$122,Assumptions!$I$123)/12 -> 0 | AQ25: =SUM(Assumptions!$I$121,Assumptions!$I$122,Assumptions!$I$123)/12 -> 0 | AR25: =SUM(Assumptions!$I$121,Assumptions!$I$122,Assumptions!$I$123)/12 -> 0 | AS25: =SUM(Assumptions!$I$121,Assumptions!$I$122,Assumptions!$I$123)/12 -> 0 | AT25: =SUM(Assumptions!$I$121,Assumptions!$I$122,Assumptions!$I$123)/12 -> 0 | AU25: =SUM(Assumptions!$I$121,Assumptions!$I$122,Assumptions!$I$123)/12 -> 0 | AV25: =SUM(Assumptions!$I$121,Assumptions!$I$122,Assumptions!$I$123)/12 -> 0 | AW25: =SUM(Assumptions!$I$121,Assumptions!$I$122,Assumptions!$I$123)/12 -> 0 | ... BA25: =SUM(Assumptions!$I$121,Assumptions!$I$122,Assumptions!$I$123)/12 -> 0 | BB25: =SUM(Assumptions!$J$121,Assumptions!$J$122,Assumptions!$J$123)/12 -> 0 | BC25: =SUM(Assumptions!$J$121,Assumptions!$J$122,Assumptions!$J$123)/12 -> 0 | BD25: =SUM(Assumptions!$J$121,Assumptions!$J$122,Assumptions!$J$123)/12 -> 0 | BE25: =SUM(Assumptions!$J$121,Assumptions!$J$122,Assumptions!$J$123)/12 -> 0 | BF25: =SUM(Assumptions!$J$121,Assumptions!$J$122,Assumptions!$J$123)/12 -> 0 | BG25: =SUM(Assumptions!$J$121,Assumptions!$J$122,Assumptions!$J$123)/12 -> 0 | BH25: =SUM(Assumptions!$J$121,Assumptions!$J$122,Assumptions!$J$123)/12 -> 0 | BI25: =SUM(Assumptions!$J$121,Assumptions!$J$122,Assumptions!$J$123)/12 -> 0 | ... BM25: =SUM(Assumptions!$J$121,Assumptions!$J$122,Assumptions!$J$123)/12 -> 0
B26: Worst Case | F26: =SUM(F24:F25) -> 0 | G26: =SUM(G24:G25) -> 0 | H26: =SUM(H24:H25) -> 0 | I26: =SUM(I24:I25) -> 0 | J26: =SUM(J24:J25) -> 0 | K26: =SUM(K24:K25) -> 0 | L26: =SUM(L24:L25) -> 0 | M26: =SUM(M24:M25) -> 0 | ... AC26: =SUM(AC24:AC25) -> 0 | AD26: 11365 | AE26: 11365 | AF26: 11365 | AG26: 11365 | AH26: 11365 | AI26: 11365 | AJ26: 11365 | AK26: 11365 | AL26: 11365 | AM26: 11365 | AN26: 11365 | AO26: 11365 | AP26: 17430 | AQ26: 17430 | AR26: 17430 | AS26: 17430 | AT26: 17430 | AU26: 17430 | AV26: 17430 | AW26: 17430 | AX26: 17430 | AY26: 17430 | AZ26: 17430 | BA26: 17430 | BB26: 17430 | BC26: 17430 | BD26: 17430 | BE26: 17430 | BF26: 17430 | BG26: 17430 | BH26: 17430 | BI26: 17430 | BJ26: 17430 | BK26: 17430 | BL26: 17430 | BM26: 17430
B29: EBITDA | F29: =F12-F19-F26 -> #REF! | G29: =G12-G19-G26 -> #REF! | H29: =H12-H19-H26 -> #REF! | I29: =I12-I19-I26 -> #REF! | J29: =J12-J19-J26 -> #REF! | K29: =K12-K19-K26 -> #REF! | L29: =L12-L19-L26 -> #REF! | M29: =M12-M19-M26 -> #REF! | ... BM29: =BM12-BM19-BM26 -> #REF!
B31: Beginning Cash | F31: 35470 | G31: =F34 -> #REF! | H31: =G34 -> #REF! | I31: =H34 -> #REF! | J31: =I34 -> #REF! | K31: =J34 -> #REF! | L31: =K34 -> #REF! | M31: =L34 -> #REF! | N31: =M34 -> #REF! | ... BM31: =BL34 -> #REF!
B32: Cash from Operations | F32: =F29 -> #REF! | G32: =G29 -> #REF! | H32: =H29 -> #REF! | I32: =I29 -> #REF! | J32: =J29 -> #REF! | K32: =K29 -> #REF! | L32: =L29 -> #REF! | M32: =M29 -> #REF! | ... BM32: =BM29 -> #REF!
B33: Cash from Investments | F33: 0
B34: Closing Cash | F34: =SUM(F31:F33) -> #REF! | G34: =SUM(G31:G33) -> #REF! | H34: =SUM(H31:H33) -> #REF! | I34: =SUM(I31:I33) -> #REF! | J34: =SUM(J31:J33) -> #REF! | K34: =SUM(K31:K33) -> #REF! | L34: =SUM(L31:L33) -> #REF! | M34: =SUM(M31:M33) -> #REF! | ... BM34: =SUM(BM31:BM33) -> #REF!
B36: Without Grant Financing
B37: Beginning Cash | F37: =F31 -> 35470 | G37: =F40 -> #REF! | H37: =G40 -> #REF! | I37: =H40 -> #REF! | J37: =I40 -> #REF! | K37: =J40 -> #REF! | L37: =K40 -> #REF! | M37: =L40 -> #REF! | N37: =M40 -> #REF! | ... BM37: =BL40 -> #REF!
B38: =B32 -> Cash from Operations | F38: =F32 -> #REF! | G38: =G32 -> #REF! | H38: =H32 -> #REF! | I38: =I32 -> #REF! | J38: =J32 -> #REF! | K38: =K32 -> #REF! | L38: =L32 -> #REF! | M38: =M32 -> #REF! | ... BM38: =BM32 -> #REF!
B39: =B33 -> Cash from Investments | F39: =F33 -> 0 | G39: =G33 -> 0 | H39: =H33 -> 0 | I39: =I33 -> 0 | J39: =J33 -> 0 | K39: =K33 -> 0 | L39: =L33 -> 0 | M39: =M33 -> 0 | ... BM39: =BM33 -> 0
B40: =B34 -> Closing Cash | F40: =SUM(F37:F39) -> #REF! | G40: =SUM(G37:G39) -> #REF! | H40: =SUM(H37:H39) -> #REF! | I40: =SUM(I37:I39) -> #REF! | J40: =SUM(J37:J39) -> #REF! | K40: =SUM(K37:K39) -> #REF! | L40: =SUM(L37:L39) -> #REF! | M40: =SUM(M37:M39) -> #REF! | ... BM40: =SUM(BM37:BM39) -> #REF!
B42: With Investment
B43: Beginning Cash | F43: =F37 -> 35470 | G43: =F46 -> #REF! | H43: =G46 -> #REF! | I43: =H46 -> #REF! | J43: =I46 -> #REF! | K43: =J46 -> #REF! | L43: =K46 -> #REF! | M43: =L46 -> #REF! | N43: =M46 -> #REF! | ... BM43: =BL46 -> #REF!
B44: =B38 -> Cash from Operations | F44: =F32 -> #REF! | G44: =G38 -> #REF! | H44: =H38 -> #REF! | I44: =I38 -> #REF! | J44: =J38 -> #REF! | K44: =K38 -> #REF! | L44: =L38 -> #REF! | M44: =M38 -> #REF! | N44: =N38 -> #REF! | ... BM44: =BM38 -> #REF!
B45: =B39 -> Cash from Investments | F45: 0 | G45: 0 | H45: 0
B46: =B40 -> Closing Cash | F46: =SUM(F43:F45) -> #REF! | G46: =SUM(G43:G45) -> #REF! | H46: =SUM(H43:H45) -> #REF! | I46: =SUM(I43:I45) -> #REF! | J46: =SUM(J43:J45) -> #REF! | K46: =SUM(K43:K45) -> #REF! | L46: =SUM(L43:L45) -> #REF! | M46: =SUM(M43:M45) -> #REF! | ... BM46: =SUM(BM43:BM45) -> #REF!

Sheet Annual Summary 
E1: Historic | F1: Budget (Present) | G1: Forecast | H1: Forecast | I1: Forecast | J1: Forecast | K1: Forecast
B2: Year (units) | E2: -1 | F2: 0 | G2: 1 | H2: 2 | I2: 3 | J2: 4 | K2: 5
B3: Start Date | E3: 45039 | F3: 45405 | G3: =EDATE(F3,12) -> 45770 | H3: =EDATE(G3,12) -> 46135 | I3: =EDATE(H3,12) -> 46500 | J3: =EDATE(I3,12) -> 46866 | K3: =EDATE(J3,12) -> 47231
B4: End Date | E4: 45374 | F4: =EDATE(F3,11) -> 45739 | G4: =EDATE(F4,12) -> 46104 | H4: =EDATE(G4,12) -> 46469 | I4: =EDATE(H4,12) -> 46835 | J4: =EDATE(I4,12) -> 47200 | K4: =EDATE(J4,12) -> 47565
B5: Fiscal Year Label | F5: 24/25 | G5: 25/26 | H5: 26/27 | I5: 27/28 | J5: 28/29 | K5: 28/29
B10: Revenue | C10: Comments
E11: (enter historic/budget figures here)
B12: ='Monthly Cashflow '!B13 -> Revenue Stream 1 | G12: =SUMIF('Monthly Cashflow '!$F$2:$BM$2,$G$2,'Monthly Cashflow '!$F$13:$BM$13) -> 0 | H12: =SUMIF('Monthly Cashflow '!$F$2:$BM$2,$H$2,'Monthly Cashflow '!$F$13:$BM$13) -> 0 | I12: =SUMIF('Monthly Cashflow '!$F$2:$BM$2,$I$2,'Monthly Cashflow '!$F$13:$BM$13) -> 0 | J12: =SUMIF('Monthly Cashflow '!$F$2:$BM$2,$J$2,'Monthly Cashflow '!$F$13:$BM$13) -> 0 | K12: =SUMIF('Monthly Cashflow '!$F$2:$BM$2,$K$2,'Monthly Cashflow '!$F$13:$BM$13) -> 0
B13: ='Monthly Cashflow '!B14 -> Revenue Stream 2 | G13: =SUMIF('Monthly Cashflow '!$F$2:$BM$2,$G$2,'Monthly Cashflow '!$F$14:$BM$14) -> 0 | H13: =SUMIF('Monthly Cashflow '!$F$2:$BM$2,$H$2,'Monthly Cashflow '!$F$14:$BM$14) -> 0 | I13: =SUMIF('Monthly Cashflow '!$F$2:$BM$2,$I$2,'Monthly Cashflow '!$F$14:$BM$14) -> 0 | J13: =SUMIF('Monthly Cashflow '!$F$2:$BM$2,$J$2,'Monthly Cashflow '!$F$14:$BM$14) -> 0 | K13: =SUMIF('Monthly Cashflow '!$F$2:$BM$2,$K$2,'Monthly Cashflow '!$F$14:$BM$14) -> 0
B14: Total Revenue | E14: =SUM(E12:E13) -> 0 | F14: =SUM(F12:F13) -> 0 | G14: =SUM(G12:G13) -> 0 | H14: =SUM(H12:H13) -> 0 | I14: =SUM(I12:I13) -> 0 | J14: =SUM(J12:J13) -> 0 | K14: =SUM(K12:K13) -> 0
B15: Growth Rate | C15: [Reasoning] | H15: =(H14-G14)/G14 -> #DIV/0! | I15: =(I14-H14)/H14 -> #DIV/0! | J15: =(J14-I14)/I14 -> #DIV/0! | K15: =(K14-J14)/J14 -> #DIV/0!
B19: Costs of Sales | C19: Comments
B21: ='Monthly Cashflow '!B21 -> Cost of Sales 1 | G21: =SUMIF('Monthly Cashflow '!$F$2:$BM$2,$G$2,'Monthly Cashflow '!$F$21:$BM$21) -> 0 | H21: =SUMIF('Monthly Cashflow '!$F$2:$BM$2,$H$2,'Monthly Cashflow '!$F$21:$BM$21) -> 0 | I21: =SUMIF('Monthly Cashflow '!$F$2:$BM$2,$I$2,'Monthly Cashflow '!$F$21:$BM$21) -> 0 | J21: =SUMIF('Monthly Cashflow '!$F$2:$BM$2,$J$2,'Monthly Cashflow '!$F$21:$BM$21) -> 0 | K21: =SUMIF('Monthly Cashflow '!$F$2:$BM$2,$K$2,'Monthly Cashflow '!$F$21:$BM$21) -> 0
B22: ='Monthly Cashflow '!B22 -> Cost of Sales 2 | G22: =SUMIF('Monthly Cashflow '!$F$2:$BM$2,$G$2,'Monthly Cashflow '!$F$22:$BM$22) -> #DIV/0! | H22: =SUMIF('Monthly Cashflow '!$F$2:$BM$2,$H$2,'Monthly Cashflow '!$F$22:$BM$22) -> #DIV/0! | I22: =SUMIF('Monthly Cashflow '!$F$2:$BM$2,$I$2,'Monthly Cashflow '!$F$22:$BM$22) -> #DIV/0! | J22: =SUMIF('Monthly Cashflow '!$F$2:$BM$2,$J$2,'Monthly Cashflow '!$F$22:$BM$22) -> #DIV/0! | K22: =SUMIF('Monthly Cashflow '!$F$2:$BM$2,$K$2,'Monthly Cashflow '!$F$22:$BM$22) -> #DIV/0!
B23: Total Cost | E23: =SUM(E21:E22) -> 0 | F23: =SUM(F21:F22) -> 0 | G23: =SUM(G21:G22) -> #DIV/0! | H23: =SUM(H21:H22) -> #DIV/0! | I23: =SUM(I21:I22) -> #DIV/0! | J23: =SUM(J21:J22) -> #DIV/0! | K23: =SUM(K21:K22) -> #DIV/0!
B24: Growth Rate | H24: =(H23-G23)/G23 -> #DIV/0! | I24: =(I23-H23)/H23 -> #DIV/0! | J24: =(J23-I23)/I23 -> #DIV/0! | K24: =(K23-J23)/J23 -> #DIV/0!
B26: Key Metrics
B28: Gross Profit | E28: =E14-E23 -> 0 | F28: =F14-F23 -> 0 | G28: =G14-G23 -> #DIV/0! | H28: =H14-H23 -> #DIV/0! | I28: =I14-I23 -> #DIV/0! | J28: =J14-J23 -> #DIV/0! | K28: =K14-K23 -> #DIV/0!
B29: Margin | E29: =E28/E14 -> #DIV/0! | F29: =F28/F14 -> #DIV/0! | G29: =G28/G14 -> #DIV/0! | H29: =H28/H14 -> #DIV/0! | I29: =I28/I14 -> #DIV/0! | J29: =J28/J14 -> #DIV/0! | K29: =K28/K14 -> #DIV/0!
B31: Other Costs | C31: Comments
B33: Other Staff Costs | G33: =Assumptions!F118 -> 0 | H33: =Assumptions!G118 -> 0 | I33: =Assumptions!H118 -> 0 | J33: =Assumptions!I118 -> 0 | K33: =Assumptions!J118 -> 0
B34: =Assumptions!B121 -> Accounting | G34: =Assumptions!F121 -> 0 | H34: =Assumptions!G121 -> 0 | I34: =Assumptions!H121 -> 0 | J34: =Assumptions!I121 -> 0 | K34: =Assumptions!J121 -> 0
B35: =Assumptions!B122 -> DBS/Ancillary Costs | G35: =Assumptions!F122 -> 0 | H35: =Assumptions!G122 -> 0 | I35: =Assumptions!H122 -> 0 | J35: =Assumptions!I122 -> 0 | K35: =Assumptions!J122 -> 0
B36: =Assumptions!B123 -> IT costs | G36: =Assumptions!F123 -> 0 | H36: =Assumptions!G123 -> 0 | I36: =Assumptions!H123 -> 0 | J36: =Assumptions!I123 -> 0 | K36: =Assumptions!J123 -> 0
B37: Office Costs | G37: =Assumptions!F105 -> 0 | H37: =Assumptions!G105 -> 0 | I37: =Assumptions!H105 -> 0 | J37: =Assumptions!I105 -> 0 | K37: =Assumptions!J105 -> 0
B39: Total Other Costs | E39: =SUM(E33:E37) -> 0 | F39: =SUM(F33:F37) -> 0 | G39: =SUM(G33:G37) -> 0 | H39: =SUM(H33:H37) -> 0 | I39: =SUM(I33:I37) -> 0 | J39: =SUM(J33:J37) -> 0 | K39: =SUM(K33:K37) -> 0
B41: EBITDA | E41: =E28-E39 -> 0 | F41: =F28-F39 -> 0 | G41: =G28-G39 -> #DIV/0! | H41: =H28-H39 -> #DIV/0! | I41: =I28-I39 -> #DIV/0! | J41: =J28-J39 -> #DIV/0! | K41: =K28-K39 -> #DIV/0!
B42: Margin | E42: =E41/E14 -> #DIV/0! | F42: =F41/F14 -> #DIV/0! | G42: =G41/G14 -> #DIV/0! | H42: =H41/H14 -> #DIV/0! | I42: =I41/I14 -> #DIV/0! | J42: =J41/J14 -> #DIV/0! | K42: =K41/K14 -> #DIV/0!
B45: Cashflow Statement
B47: ='Monthly Cashflow '!B32 -> Beginning Cash | G47: ='Monthly Cashflow '!F32 -> 0 | H47: =G50 -> #DIV/0! | I47: =H50 -> #DIV/0! | J47: =I50 -> #DIV/0! | K47: =J50 -> #DIV/0!
B48: ='Monthly Cashflow '!B33 -> Cash from Operations | G48: =G41 -> #DIV/0! | H48: =H41 -> #DIV/0! | I48: =I41 -> #DIV/0! | J48: =J41 -> #DIV/0! | K48: =K41 -> #DIV/0!
B49: ='Monthly Cashflow '!B34 -> Cash from Investments | G49: =SUMIF('Monthly Cashflow '!$F$2:$BM$2,$G$2,'Monthly Cashflow '!$F$34:$BM$34) -> 0 | H49: =SUMIF('Monthly Cashflow '!$F$2:$BM$2,$H$2,'Monthly Cashflow '!$F$34:$BM$34) -> 0 | I49: =SUMIF('Monthly Cashflow '!$F$2:$BM$2,$I$2,'Monthly Cashflow '!$F$34:$BM$34) -> 0 | J49: =SUMIF('Monthly Cashflow '!$F$2:$BM$2,$J$2,'Monthly Cashflow '!$F$34:$BM$34) -> 0 | K49: =SUMIF('Monthly Cashflow '!$F$2:$BM$2,$K$2,'Monthly Cashflow '!$F$34:$BM$34) -> 0
B50: ='Monthly Cashflow '!B35 -> Closing Cash | E50: =SUM(E47:E49) -> 0 | F50: =SUM(F47:F49) -> 0 | G50: =SUM(G47:G49) -> #DIV/0! | H50: =SUM(H47:H49) -> #DIV/0! | I50: =SUM(I47:I49) -> #DIV/0! | J50: =SUM(J47:J49) -> #DIV/0! | K50: =SUM(K47:K49) -> #DIV/0!

Sheet Staffing Example
A1: Staffing Projections Example Sheet
A2: Description of the contents in the sheet: "The below staffing projections outline our plan to build…."
A6: Staff and volunteer costs | L6: Comments
B7: FY21 | C7: FY22 | D7: FY23 | E7: FY24 | F7: FY25 | G7: FY26 | H7: FY27 | I7: FY28 | J7: FY29
A8: part of Support costs of xxx activities
A10: Payroll and volunteer costs | B10: =B21 -> 0 | C10: =C21 -> 0 | D10: =D21 -> 0 | E10: =E21 -> 0 | F10: =F21 -> 0 | G10: =G21 -> 0 | H10: =H21 -> 0 | I10: =I21 -> 0 | J10: =J21 -> 0
A11: Office costs | B11: =B29 -> 0 | C11: =C29 -> 0 | D11: =D29 -> 0 | E11: =E29 -> 0 | F11: =F29 -> 0 | G11: =G29 -> 0 | H11: =H29 -> 0 | I11: =I29 -> 0 | J11: =J29 -> 0
A13: Total personnel costs | B13: =SUM(B10:B11) -> 0 | C13: =SUM(C10:C11) -> 0 | D13: =SUM(D10:D11) -> 0 | E13: =SUM(E10:E11) -> 0 | F13: =SUM(F10:F11) -> 0 | G13: =SUM(G10:G11) -> 0 | H13: =SUM(H10:H11) -> 0 | I13: =SUM(I10:I11) -> 0 | J13: =SUM(J10:J11) -> 0
A15: Payroll and volunteer costs
A17: Salary, tax and benefits (below)
A18: Staff and volunteer training | L18: x is an area we want to increase our spend in because…
A19: Staff and volunteer equipment
A21: Total | B21: =SUM(B17:B19) -> 0 | C21: =SUM(C17:C19) -> 0 | D21: =SUM(D17:D19) -> 0 | E21: =SUM(E17:E19) -> 0 | F21: =SUM(F17:F19) -> 0 | G21: =SUM(G17:G19) -> 0 | H21: =SUM(H17:H19) -> 0 | I21: =SUM(I17:I19) -> 0 | J21: =SUM(J17:J19) -> 0
A23: Office costs
A25: Office/workspace rental
A26: Mail handling and shipping
A27: Miscellaneous expenses
A29: Total | B29: =SUM(B25:B27) -> 0 | C29: =SUM(C25:C27) -> 0 | D29: =SUM(D25:D27) -> 0 | E29: =SUM(E25:E27) -> 0 | F29: =SUM(F25:F27) -> 0 | G29: =SUM(G25:G27) -> 0 | H29: =SUM(H25:H27) -> 0 | I29: =SUM(I25:I27) -> 0 | J29: =SUM(J25:J27) -> 0
A32: Headcount growth
A34: Headcount breakdown
A36: Sales roles | J36: =B178 -> 0 | L36: Increase connects to a growth in revenue stream 2
A37: Non-sales roles | J37: =B177-B178 -> 0
A39: Total | B39: =SUM(B36:B37) -> 0 | C39: =SUM(C36:C37) -> 0 | D39: =SUM(D36:D37) -> 0 | E39: =SUM(E36:E37) -> 0 | F39: =SUM(F36:F37) -> 0 | G39: =SUM(G36:G37) -> 0 | H39: =SUM(H36:H37) -> 0 | I39: =SUM(I36:I37) -> 0 | J39: =SUM(J36:J37) -> 0
A41: Salary, tax and benefits - FY23
A43: Title | B43: FTE | C43: Salary | D43: Bonus | E43: ER NI | F43: Pension | G43: Other costs | H43: Total
A44: Role 1 | E44: =(SUM(C44,D44)-9096.12)*0.138 -> -1255.2646 | F44: =SUM(C44,D44)*0.03 -> 0 | H44: =B44*SUM(C44:G44) -> 0
A45: Role 2 | E45: =(SUM(C45,D45)-9096.12)*0.138 -> -1255.2646 | F45: =SUM(C45,D45)*0.03 -> 0 | H45: =B45*SUM(C45:G45) -> 0
A46: Role 3 | E46: =(SUM(C46,D46)-9096.12)*0.138 -> -1255.2646 | F46: =SUM(C46,D46)*0.03 -> 0 | H46: =B46*SUM(C46:G46) -> 0
A47: Role 4 | E47: =(SUM(C47,D47)-9096.12)*0.138 -> -1255.2646 | F47: =SUM(C47,D47)*0.03 -> 0 | H47: =B47*SUM(C47:G47) -> 0
A48: Role 5 | E48: =(SUM(C48,D48)-9096.12)*0.138 -> -1255.2646 | F48: =SUM(C48,D48)*0.03 -> 0 | H48: =B48*SUM(C48:G48) -> 0
A49: Role 6 | E49: 0 | F49: 0 | H49: =(B49*SUM(C49:D49))+G49 -> 0
A50: Role 7 | E50: 0 | F50: 0 | H50: =(B50*SUM(C50:D50))+G50 -> 0
B52: =SUM(B44:B50) -> 0 | C52: FTE total | G52: Total headcount costs: | H52: =SUM(H44:H50) -> 0
B53: =SUMIFS(B44:B50,A44:A50,"*talent*") -> 0 | C53: FTE
A55: Salary, tax and benefits - FY24
A57: Title | B57: FTE | C57: Salary | D57: Bonus | E57: ER NI | F57: Pension | G57: Other costs | H57: Total
A58: Role 1 | E58: =(SUM(C58,D58)-9096.12)*0.138 -> -1255.2646 | F58: =SUM(C58,D58)*0.03 -> 0 | H58: =B58*SUM(C58:G58) -> 0
A59: Role 2 | E59: =(SUM(C59,D59)-9096.12)*0.138 -> -1255.2646 | F59: =SUM(C59,D59)*0.03 -> 0 | H59: =B59*SUM(C59:G59) -> 0
A60: Role 3 | E60: =(SUM(C60,D60)-9096.12)*0.138 -> -1255.2646 | F60: =SUM(C60,D60)*0.03 -> 0 | H60: =B60*SUM(C60:G60) -> 0
A61: Role 4 | E61: =(SUM(C61,D61)-9096.12)*0.138 -> -1255.2646 | F61: =SUM(C61,D61)*0.03 -> 0 | H61: =B61*SUM(C61:G61) -> 0
...
